<robot name = "robot">
    <link name="0">
        <inertial>
            <origin xyz="0 0 0.4496419645709351" rpy="0 0 0"/>
            <mass value="1" />
            <inertia ixx="100" ixy="0" ixz="0" iyy="100" iyz="0" izz="100" />
        </inertial>
        <visual>
            <origin xyz="0 0 0.4496419645709351" rpy="0 0 0"/>
            <geometry>
                <box size="0.41538493373871244 0.7098585893223825 0.18410482550652096" />
            </geometry>
            <material name="sensor">
                <color rgba="0 1 0 1"/>
            </material>
        </visual>
        <collision>
            <origin xyz="0 0 0.4496419645709351" rpy="0 0 0"/>
            <geometry>
                <box size="0.41538493373871244 0.7098585893223825 0.18410482550652096" />
            </geometry>
        </collision>
    </link>
    <joint name="0_2" type="revolute">
       <parent link="0"/>
       <child  link="2"/>
       <origin rpy="0 0 0" xyz="0 0 0.5416943773241956" />
     <axis xyz="0 1 0"/>
       <limit effort="0.0" lower="-3.14159" upper="3.14159" velocity="0.0"/>
    </joint>
    <link name="2">
        <inertial>
            <origin xyz="0 0 0.13990321412966766" rpy="0 0 0"/>
            <mass value="1" />
            <inertia ixx="100" ixy="0" ixz="0" iyy="100" iyz="0" izz="100" />
        </inertial>
        <visual>
            <origin xyz="0 0 0.13990321412966766" rpy="0 0 0"/>
            <geometry>
                <box size="0.1692609422576251 0.002870724188104301 0.2798064282593352" />
            </geometry>
            <material name="sensor">
                <color rgba="0 1 0 1"/>
            </material>
        </visual>
        <collision>
            <origin xyz="0 0 0.13990321412966766" rpy="0 0 0"/>
            <geometry>
                <box size="0.1692609422576251 0.002870724188104301 0.2798064282593352" />
            </geometry>
        </collision>
    </link>
    <joint name="0_1" type="revolute">
       <parent link="0"/>
       <child  link="1"/>
       <origin rpy="0 0 0" xyz="0 -0.3549292946611913 0.4496419645709351" />
     <axis xyz="0 1 0"/>
       <limit effort="0.0" lower="-3.14159" upper="3.14159" velocity="0.0"/>
    </joint>
    <link name="1">
        <inertial>
            <origin xyz="0 -0.1646213799367976 0.0" rpy="0 0 0"/>
            <mass value="1" />
            <inertia ixx="100" ixy="0" ixz="0" iyy="100" iyz="0" izz="100" />
        </inertial>
        <visual>
            <origin xyz="0 -0.1646213799367976 0.0" rpy="0 0 0"/>
            <geometry>
                <box size="0.931595498067392 0.3292427598735952 0.1855121899580079" />
            </geometry>
            <material name="sensor">
                <color rgba="0 1 0 1"/>
            </material>
        </visual>
        <collision>
            <origin xyz="0 -0.1646213799367976 0.0" rpy="0 0 0"/>
            <geometry>
                <box size="0.931595498067392 0.3292427598735952 0.1855121899580079" />
            </geometry>
        </collision>
    </link>
    <joint name="1_4" type="revolute">
       <parent link="1"/>
       <child  link="4"/>
       <origin rpy="0 0 0" xyz="-0.465797749033696 -0.1646213799367976 0.0" />
     <axis xyz="1 0 0"/>
       <limit effort="0.0" lower="-3.14159" upper="3.14159" velocity="0.0"/>
    </joint>
    <link name="4">
        <inertial>
            <origin xyz="-0.06464959282211558 0.0 0.0" rpy="0 0 0"/>
            <mass value="1" />
            <inertia ixx="100" ixy="0" ixz="0" iyy="100" iyz="0" izz="100" />
        </inertial>
        <visual>
            <origin xyz="-0.06464959282211558 0.0 0.0" rpy="0 0 0"/>
            <geometry>
                <box size="0.12929918564423104 0.7766075064904612 0.8095724120616434" />
            </geometry>
            <material name="not">
                <color rgba="0 1 1 1"/>
            </material>
        </visual>
        <collision>
            <origin xyz="-0.06464959282211558 0.0 0.0" rpy="0 0 0"/>
            <geometry>
                <box size="0.12929918564423104 0.7766075064904612 0.8095724120616434" />
            </geometry>
        </collision>
    </link>
    <joint name="4_5" type="revolute">
       <parent link="4"/>
       <child  link="5"/>
       <origin rpy="0 0 0" xyz="-0.06464959282211558 0.3883037532452306 0.0" />
     <axis xyz="0 0 1"/>
       <limit effort="0.0" lower="-3.14159" upper="3.14159" velocity="0.0"/>
    </joint>
    <link name="5">
        <inertial>
            <origin xyz="0.0 0.0952272657354516 0.0" rpy="0 0 0"/>
            <mass value="1" />
            <inertia ixx="100" ixy="0" ixz="0" iyy="100" iyz="0" izz="100" />
        </inertial>
        <visual>
            <origin xyz="0.0 0.0952272657354516 0.0" rpy="0 0 0"/>
            <geometry>
                <box size="0.03175246485776129 0.1904545314709032 0.07879286722511858" />
            </geometry>
            <material name="not">
                <color rgba="0 1 1 1"/>
            </material>
        </visual>
        <collision>
            <origin xyz="0.0 0.0952272657354516 0.0" rpy="0 0 0"/>
            <geometry>
                <box size="0.03175246485776129 0.1904545314709032 0.07879286722511858" />
            </geometry>
        </collision>
    </link>
</robot>