<robot name = "robot">
    <link name="0">
        <inertial>
            <origin xyz="0 0 0.9900248256710366" rpy="0 0 0"/>
            <mass value="1" />
            <inertia ixx="100" ixy="0" ixz="0" iyy="100" iyz="0" izz="100" />
        </inertial>
        <visual>
            <origin xyz="0 0 0.9900248256710366" rpy="0 0 0"/>
            <geometry>
                <box size="0.019817176473073683 0.5494018488970029 0.2893757507238711" />
            </geometry>
            <material name="not">
                <color rgba="0 1 1 1"/>
            </material>
        </visual>
        <collision>
            <origin xyz="0 0 0.9900248256710366" rpy="0 0 0"/>
            <geometry>
                <box size="0.019817176473073683 0.5494018488970029 0.2893757507238711" />
            </geometry>
        </collision>
    </link>
    <joint name="0_1" type="revolute">
       <parent link="0"/>
       <child  link="1"/>
       <origin rpy="0 0 0" xyz="0 0.27470092444850147 0.9900248256710366" />
     <axis xyz="1 0 0"/>
       <limit effort="0.0" lower="-3.14159" upper="3.14159" velocity="0.0"/>
    </joint>
    <link name="1">
        <inertial>
            <origin xyz="0 0.08633226464268445 0.0" rpy="0 0 0"/>
            <mass value="1" />
            <inertia ixx="100" ixy="0" ixz="0" iyy="100" iyz="0" izz="100" />
        </inertial>
        <visual>
            <origin xyz="0 0.08633226464268445 0.0" rpy="0 0 0"/>
            <geometry>
                <box size="0.2766826434414502 0.1726645292853689 0.10618329243153013" />
            </geometry>
            <material name="not">
                <color rgba="0 1 1 1"/>
            </material>
        </visual>
        <collision>
            <origin xyz="0 0.08633226464268445 0.0" rpy="0 0 0"/>
            <geometry>
                <box size="0.2766826434414502 0.1726645292853689 0.10618329243153013" />
            </geometry>
        </collision>
    </link>
    <joint name="1_2" type="revolute">
       <parent link="1"/>
       <child  link="2"/>
       <origin rpy="0 0 0" xyz="-0.1383413217207251 0.08633226464268445 0.0" />
     <axis xyz="0 0 1"/>
       <limit effort="0.0" lower="-3.14159" upper="3.14159" velocity="0.0"/>
    </joint>
    <link name="2">
        <inertial>
            <origin xyz="-0.043359126317460916 0.0 0.0" rpy="0 0 0"/>
            <mass value="1" />
            <inertia ixx="100" ixy="0" ixz="0" iyy="100" iyz="0" izz="100" />
        </inertial>
        <visual>
            <origin xyz="-0.043359126317460916 0.0 0.0" rpy="0 0 0"/>
            <geometry>
                <box size="0.08671825263492183 0.6058518837198799 0.6717014565164733" />
            </geometry>
            <material name="not">
                <color rgba="0 1 1 1"/>
            </material>
        </visual>
        <collision>
            <origin xyz="-0.043359126317460916 0.0 0.0" rpy="0 0 0"/>
            <geometry>
                <box size="0.08671825263492183 0.6058518837198799 0.6717014565164733" />
            </geometry>
        </collision>
    </link>
    <joint name="0_3" type="revolute">
       <parent link="0"/>
       <child  link="3"/>
       <origin rpy="0 0 0" xyz="0 -0.27470092444850147 0.9900248256710366" />
     <axis xyz="1 0 0"/>
       <limit effort="0.0" lower="-3.14159" upper="3.14159" velocity="0.0"/>
    </joint>
    <link name="3">
        <inertial>
            <origin xyz="0 -0.13999879766012058 0.0" rpy="0 0 0"/>
            <mass value="1" />
            <inertia ixx="100" ixy="0" ixz="0" iyy="100" iyz="0" izz="100" />
        </inertial>
        <visual>
            <origin xyz="0 -0.13999879766012058 0.0" rpy="0 0 0"/>
            <geometry>
                <box size="0.2473222201584867 0.27999759532024115 0.944577790309402" />
            </geometry>
            <material name="sensor">
                <color rgba="0 1 0 1"/>
            </material>
        </visual>
        <collision>
            <origin xyz="0 -0.13999879766012058 0.0" rpy="0 0 0"/>
            <geometry>
                <box size="0.2473222201584867 0.27999759532024115 0.944577790309402" />
            </geometry>
        </collision>
    </link>
</robot>