<robot name = "robot">
    <link name="0">
        <inertial>
            <origin xyz="0 0 0.805084948010112" rpy="0 0 0"/>
            <mass value="1" />
            <inertia ixx="100" ixy="0" ixz="0" iyy="100" iyz="0" izz="100" />
        </inertial>
        <visual>
            <origin xyz="0 0 0.805084948010112" rpy="0 0 0"/>
            <geometry>
                <box size="0.9934252369428691 0.5610139859643821 0.004764450985328517" />
            </geometry>
            <material name="sensor">
                <color rgba="0 1 0 1"/>
            </material>
        </visual>
        <collision>
            <origin xyz="0 0 0.805084948010112" rpy="0 0 0"/>
            <geometry>
                <box size="0.9934252369428691 0.5610139859643821 0.004764450985328517" />
            </geometry>
        </collision>
    </link>
    <joint name="0_3" type="revolute">
       <parent link="0"/>
       <child  link="3"/>
       <origin rpy="0 0 0" xyz="0.49671261847143455 0 0.805084948010112" />
     <axis xyz="0 1 0"/>
       <limit effort="0.0" lower="-3.14159" upper="3.14159" velocity="0.0"/>
    </joint>
    <link name="3">
        <inertial>
            <origin xyz="0.08206428844573366 0 0.0" rpy="0 0 0"/>
            <mass value="1" />
            <inertia ixx="100" ixy="0" ixz="0" iyy="100" iyz="0" izz="100" />
        </inertial>
        <visual>
            <origin xyz="0.08206428844573366 0 0.0" rpy="0 0 0"/>
            <geometry>
                <box size="0.1641285768914672 0.6254644776458438 0.384698749141954" />
            </geometry>
            <material name="not">
                <color rgba="0 1 1 1"/>
            </material>
        </visual>
        <collision>
            <origin xyz="0.08206428844573366 0 0.0" rpy="0 0 0"/>
            <geometry>
                <box size="0.1641285768914672 0.6254644776458438 0.384698749141954" />
            </geometry>
        </collision>
    </link>
    <joint name="0_4" type="revolute">
       <parent link="0"/>
       <child  link="4"/>
       <origin rpy="0 0 0" xyz="0 0.28050699298219106 0.805084948010112" />
     <axis xyz="1 0 0"/>
       <limit effort="0.0" lower="-3.14159" upper="3.14159" velocity="0.0"/>
    </joint>
    <link name="4">
        <inertial>
            <origin xyz="0 0.02961354745400052 0.0" rpy="0 0 0"/>
            <mass value="1" />
            <inertia ixx="100" ixy="0" ixz="0" iyy="100" iyz="0" izz="100" />
        </inertial>
        <visual>
            <origin xyz="0 0.02961354745400052 0.0" rpy="0 0 0"/>
            <geometry>
                <box size="0.47220551042978165 0.05922709490800104 0.6508676611709957" />
            </geometry>
            <material name="not">
                <color rgba="0 1 1 1"/>
            </material>
        </visual>
        <collision>
            <origin xyz="0 0.02961354745400052 0.0" rpy="0 0 0"/>
            <geometry>
                <box size="0.47220551042978165 0.05922709490800104 0.6508676611709957" />
            </geometry>
        </collision>
    </link>
    <joint name="0_1" type="revolute">
       <parent link="0"/>
       <child  link="1"/>
       <origin rpy="0 0 0" xyz="0 -0.28050699298219106 0.805084948010112" />
     <axis xyz="0 0 1"/>
       <limit effort="0.0" lower="-3.14159" upper="3.14159" velocity="0.0"/>
    </joint>
    <link name="1">
        <inertial>
            <origin xyz="0 -0.26314901352280184 0.0" rpy="0 0 0"/>
            <mass value="1" />
            <inertia ixx="100" ixy="0" ixz="0" iyy="100" iyz="0" izz="100" />
        </inertial>
        <visual>
            <origin xyz="0 -0.26314901352280184 0.0" rpy="0 0 0"/>
            <geometry>
                <box size="0.8549406333348232 0.5262980270456036 0.009674417954021686" />
            </geometry>
            <material name="not">
                <color rgba="0 1 1 1"/>
            </material>
        </visual>
        <collision>
            <origin xyz="0 -0.26314901352280184 0.0" rpy="0 0 0"/>
            <geometry>
                <box size="0.8549406333348232 0.5262980270456036 0.009674417954021686" />
            </geometry>
        </collision>
    </link>
    <joint name="0_2" type="revolute">
       <parent link="0"/>
       <child  link="2"/>
       <origin rpy="0 0 0" xyz="-0.49671261847143455 0 0.805084948010112" />
     <axis xyz="0 0 1"/>
       <limit effort="0.0" lower="-3.14159" upper="3.14159" velocity="0.0"/>
    </joint>
    <link name="2">
        <inertial>
            <origin xyz="-0.3225717006024932 0 0.0" rpy="0 0 0"/>
            <mass value="1" />
            <inertia ixx="100" ixy="0" ixz="0" iyy="100" iyz="0" izz="100" />
        </inertial>
        <visual>
            <origin xyz="-0.3225717006024932 0 0.0" rpy="0 0 0"/>
            <geometry>
                <box size="0.6451434012049864 0.8052578400289929 0.37222404980584656" />
            </geometry>
            <material name="not">
                <color rgba="0 1 1 1"/>
            </material>
        </visual>
        <collision>
            <origin xyz="-0.3225717006024932 0 0.0" rpy="0 0 0"/>
            <geometry>
                <box size="0.6451434012049864 0.8052578400289929 0.37222404980584656" />
            </geometry>
        </collision>
    </link>
    <joint name="2_5" type="revolute">
       <parent link="2"/>
       <child  link="5"/>
       <origin rpy="0 0 0" xyz="-0.3225717006024932 0 -0.18611202490292322" />
     <axis xyz="1 0 0"/>
       <limit effort="0.0" lower="-3.14159" upper="3.14159" velocity="0.0"/>
    </joint>
    <link name="5">
        <inertial>
            <origin xyz="0.0 0 -0.11239420170488867" rpy="0 0 0"/>
            <mass value="1" />
            <inertia ixx="100" ixy="0" ixz="0" iyy="100" iyz="0" izz="100" />
        </inertial>
        <visual>
            <origin xyz="0.0 0 -0.11239420170488867" rpy="0 0 0"/>
            <geometry>
                <box size="0.5956196489347584 0.05987710910108612 0.22478840340977746" />
            </geometry>
            <material name="not">
                <color rgba="0 1 1 1"/>
            </material>
        </visual>
        <collision>
            <origin xyz="0.0 0 -0.11239420170488867" rpy="0 0 0"/>
            <geometry>
                <box size="0.5956196489347584 0.05987710910108612 0.22478840340977746" />
            </geometry>
        </collision>
    </link>
</robot>