<robot name = "robot">
    <link name="0">
        <inertial>
            <origin xyz="0 0 0.5885654411204988" rpy="0 0 0"/>
            <mass value="1" />
            <inertia ixx="100" ixy="0" ixz="0" iyy="100" iyz="0" izz="100" />
        </inertial>
        <visual>
            <origin xyz="0 0 0.5885654411204988" rpy="0 0 0"/>
            <geometry>
                <box size="0.5328382149012096 0.5506440955211088 0.6908941974381599" />
            </geometry>
            <material name="sensor">
                <color rgba="0 1 0 1"/>
            </material>
        </visual>
        <collision>
            <origin xyz="0 0 0.5885654411204988" rpy="0 0 0"/>
            <geometry>
                <box size="0.5328382149012096 0.5506440955211088 0.6908941974381599" />
            </geometry>
        </collision>
    </link>
    <joint name="0_1" type="revolute">
       <parent link="0"/>
       <child  link="1"/>
       <origin rpy="0 0 0" xyz="0 -0.2753220477605544 0.5885654411204988" />
     <axis xyz="0 0 1"/>
       <limit effort="0.0" lower="-3.14159" upper="3.14159" velocity="0.0"/>
    </joint>
    <link name="1">
        <inertial>
            <origin xyz="0 -0.3811601253219346 0.0" rpy="0 0 0"/>
            <mass value="1" />
            <inertia ixx="100" ixy="0" ixz="0" iyy="100" iyz="0" izz="100" />
        </inertial>
        <visual>
            <origin xyz="0 -0.3811601253219346 0.0" rpy="0 0 0"/>
            <geometry>
                <box size="0.5197363779566518 0.7623202506438691 0.36917061070842383" />
            </geometry>
            <material name="not">
                <color rgba="0 1 1 1"/>
            </material>
        </visual>
        <collision>
            <origin xyz="0 -0.3811601253219346 0.0" rpy="0 0 0"/>
            <geometry>
                <box size="0.5197363779566518 0.7623202506438691 0.36917061070842383" />
            </geometry>
        </collision>
    </link>
    <joint name="1_3" type="revolute">
       <parent link="1"/>
       <child  link="3"/>
       <origin rpy="0 0 0" xyz="0 -0.3811601253219346 -0.18458530535421191" />
     <axis xyz="0 0 1"/>
       <limit effort="0.0" lower="-3.14159" upper="3.14159" velocity="0.0"/>
    </joint>
    <link name="3">
        <inertial>
            <origin xyz="0 0.0 -0.027743280492031508" rpy="0 0 0"/>
            <mass value="1" />
            <inertia ixx="100" ixy="0" ixz="0" iyy="100" iyz="0" izz="100" />
        </inertial>
        <visual>
            <origin xyz="0 0.0 -0.027743280492031508" rpy="0 0 0"/>
            <geometry>
                <box size="0.2800346976177732 0.12195905324710177 0.055486560984063016" />
            </geometry>
            <material name="sensor">
                <color rgba="0 1 0 1"/>
            </material>
        </visual>
        <collision>
            <origin xyz="0 0.0 -0.027743280492031508" rpy="0 0 0"/>
            <geometry>
                <box size="0.2800346976177732 0.12195905324710177 0.055486560984063016" />
            </geometry>
        </collision>
    </link>
    <joint name="1_2" type="revolute">
       <parent link="1"/>
       <child  link="2"/>
       <origin rpy="0 0 0" xyz="0 -0.7623202506438691 0.0" />
     <axis xyz="0 1 0"/>
       <limit effort="0.0" lower="-3.14159" upper="3.14159" velocity="0.0"/>
    </joint>
    <link name="2">
        <inertial>
            <origin xyz="0 -0.2151154591547153 0.0" rpy="0 0 0"/>
            <mass value="1" />
            <inertia ixx="100" ixy="0" ixz="0" iyy="100" iyz="0" izz="100" />
        </inertial>
        <visual>
            <origin xyz="0 -0.2151154591547153 0.0" rpy="0 0 0"/>
            <geometry>
                <box size="0.6684707507216855 0.4302309183094305 0.21310418091054517" />
            </geometry>
            <material name="not">
                <color rgba="0 1 1 1"/>
            </material>
        </visual>
        <collision>
            <origin xyz="0 -0.2151154591547153 0.0" rpy="0 0 0"/>
            <geometry>
                <box size="0.6684707507216855 0.4302309183094305 0.21310418091054517" />
            </geometry>
        </collision>
    </link>
</robot>