<robot name = "robot">
    <link name="0">
        <inertial>
            <origin xyz="0 0 0.12202201864466011" rpy="0 0 0"/>
            <mass value="1" />
            <inertia ixx="100" ixy="0" ixz="0" iyy="100" iyz="0" izz="100" />
        </inertial>
        <visual>
            <origin xyz="0 0 0.12202201864466011" rpy="0 0 0"/>
            <geometry>
                <box size="0.49720804997815415 0.47318774305440836 0.1545194788358194" />
            </geometry>
            <material name="sensor">
                <color rgba="0 1 0 1"/>
            </material>
        </visual>
        <collision>
            <origin xyz="0 0 0.12202201864466011" rpy="0 0 0"/>
            <geometry>
                <box size="0.49720804997815415 0.47318774305440836 0.1545194788358194" />
            </geometry>
        </collision>
    </link>
    <joint name="0_1" type="revolute">
       <parent link="0"/>
       <child  link="1"/>
       <origin rpy="0 0 0" xyz="0.24860402498907708 0 0.12202201864466011" />
     <axis xyz="0 0 1"/>
       <limit effort="0.0" lower="-3.14159" upper="3.14159" velocity="0.0"/>
    </joint>
    <link name="1">
        <inertial>
            <origin xyz="0.4082306934923231 0 0.0" rpy="0 0 0"/>
            <mass value="1" />
            <inertia ixx="100" ixy="0" ixz="0" iyy="100" iyz="0" izz="100" />
        </inertial>
        <visual>
            <origin xyz="0.4082306934923231 0 0.0" rpy="0 0 0"/>
            <geometry>
                <box size="0.8164613869846462 0.4553362594956133 0.05092620996763453" />
            </geometry>
            <material name="sensor">
                <color rgba="0 1 0 1"/>
            </material>
        </visual>
        <collision>
            <origin xyz="0.4082306934923231 0 0.0" rpy="0 0 0"/>
            <geometry>
                <box size="0.8164613869846462 0.4553362594956133 0.05092620996763453" />
            </geometry>
        </collision>
    </link>
    <joint name="1_4" type="revolute">
       <parent link="1"/>
       <child  link="4"/>
       <origin rpy="0 0 0" xyz="0.4082306934923231 0 0.025463104983817264" />
     <axis xyz="0 1 0"/>
       <limit effort="0.0" lower="-3.14159" upper="3.14159" velocity="0.0"/>
    </joint>
    <link name="4">
        <inertial>
            <origin xyz="0.0 0 0.20590145231983642" rpy="0 0 0"/>
            <mass value="1" />
            <inertia ixx="100" ixy="0" ixz="0" iyy="100" iyz="0" izz="100" />
        </inertial>
        <visual>
            <origin xyz="0.0 0 0.20590145231983642" rpy="0 0 0"/>
            <geometry>
                <box size="0.27732911702446716 0.8883975195301577 0.41180290463967284" />
            </geometry>
            <material name="not">
                <color rgba="0 1 1 1"/>
            </material>
        </visual>
        <collision>
            <origin xyz="0.0 0 0.20590145231983642" rpy="0 0 0"/>
            <geometry>
                <box size="0.27732911702446716 0.8883975195301577 0.41180290463967284" />
            </geometry>
        </collision>
    </link>
    <joint name="0_2" type="revolute">
       <parent link="0"/>
       <child  link="2"/>
       <origin rpy="0 0 0" xyz="0 0 0.1992817580625698" />
     <axis xyz="0 0 1"/>
       <limit effort="0.0" lower="-3.14159" upper="3.14159" velocity="0.0"/>
    </joint>
    <link name="2">
        <inertial>
            <origin xyz="0 0 0.11183407765753822" rpy="0 0 0"/>
            <mass value="1" />
            <inertia ixx="100" ixy="0" ixz="0" iyy="100" iyz="0" izz="100" />
        </inertial>
        <visual>
            <origin xyz="0 0 0.11183407765753822" rpy="0 0 0"/>
            <geometry>
                <box size="0.9275799908266388 0.9817309707617923 0.22366815531507644" />
            </geometry>
            <material name="not">
                <color rgba="0 1 1 1"/>
            </material>
        </visual>
        <collision>
            <origin xyz="0 0 0.11183407765753822" rpy="0 0 0"/>
            <geometry>
                <box size="0.9275799908266388 0.9817309707617923 0.22366815531507644" />
            </geometry>
        </collision>
    </link>
    <joint name="2_3" type="revolute">
       <parent link="2"/>
       <child  link="3"/>
       <origin rpy="0 0 0" xyz="0 0 0.22366815531507644" />
     <axis xyz="0 1 0"/>
       <limit effort="0.0" lower="-3.14159" upper="3.14159" velocity="0.0"/>
    </joint>
    <link name="3">
        <inertial>
            <origin xyz="0 0 0.4785260571422754" rpy="0 0 0"/>
            <mass value="1" />
            <inertia ixx="100" ixy="0" ixz="0" iyy="100" iyz="0" izz="100" />
        </inertial>
        <visual>
            <origin xyz="0 0 0.4785260571422754" rpy="0 0 0"/>
            <geometry>
                <box size="0.5162741638881791 0.6251121523324751 0.9570521142845508" />
            </geometry>
            <material name="not">
                <color rgba="0 1 1 1"/>
            </material>
        </visual>
        <collision>
            <origin xyz="0 0 0.4785260571422754" rpy="0 0 0"/>
            <geometry>
                <box size="0.5162741638881791 0.6251121523324751 0.9570521142845508" />
            </geometry>
        </collision>
    </link>
</robot>