<robot name = "robot">
    <link name="0">
        <inertial>
            <origin xyz="0 0 0.4771974966790632" rpy="0 0 0"/>
            <mass value="1" />
            <inertia ixx="100" ixy="0" ixz="0" iyy="100" iyz="0" izz="100" />
        </inertial>
        <visual>
            <origin xyz="0 0 0.4771974966790632" rpy="0 0 0"/>
            <geometry>
                <box size="0.34135265741799514 0.25247484424703104 0.861664716459667" />
            </geometry>
            <material name="not">
                <color rgba="0 1 1 1"/>
            </material>
        </visual>
        <collision>
            <origin xyz="0 0 0.4771974966790632" rpy="0 0 0"/>
            <geometry>
                <box size="0.34135265741799514 0.25247484424703104 0.861664716459667" />
            </geometry>
        </collision>
    </link>
    <joint name="0_1" type="revolute">
       <parent link="0"/>
       <child  link="1"/>
       <origin rpy="0 0 0" xyz="0 0.12623742212351552 0.4771974966790632" />
     <axis xyz="1 0 0"/>
       <limit effort="0.0" lower="-3.14159" upper="3.14159" velocity="0.0"/>
    </joint>
    <link name="1">
        <inertial>
            <origin xyz="0 0.2673185202763885 0.0" rpy="0 0 0"/>
            <mass value="1" />
            <inertia ixx="100" ixy="0" ixz="0" iyy="100" iyz="0" izz="100" />
        </inertial>
        <visual>
            <origin xyz="0 0.2673185202763885 0.0" rpy="0 0 0"/>
            <geometry>
                <box size="0.1973336720632093 0.534637040552777 0.8168108472169229" />
            </geometry>
            <material name="not">
                <color rgba="0 1 1 1"/>
            </material>
        </visual>
        <collision>
            <origin xyz="0 0.2673185202763885 0.0" rpy="0 0 0"/>
            <geometry>
                <box size="0.1973336720632093 0.534637040552777 0.8168108472169229" />
            </geometry>
        </collision>
    </link>
    <joint name="1_2" type="revolute">
       <parent link="1"/>
       <child  link="2"/>
       <origin rpy="0 0 0" xyz="0 0.534637040552777 0.0" />
     <axis xyz="0 0 1"/>
       <limit effort="0.0" lower="-3.14159" upper="3.14159" velocity="0.0"/>
    </joint>
    <link name="2">
        <inertial>
            <origin xyz="0 0.0009043248631895873 0.0" rpy="0 0 0"/>
            <mass value="1" />
            <inertia ixx="100" ixy="0" ixz="0" iyy="100" iyz="0" izz="100" />
        </inertial>
        <visual>
            <origin xyz="0 0.0009043248631895873 0.0" rpy="0 0 0"/>
            <geometry>
                <box size="0.7764976607227775 0.0018086497263791745 0.054833589309793096" />
            </geometry>
            <material name="not">
                <color rgba="0 1 1 1"/>
            </material>
        </visual>
        <collision>
            <origin xyz="0 0.0009043248631895873 0.0" rpy="0 0 0"/>
            <geometry>
                <box size="0.7764976607227775 0.0018086497263791745 0.054833589309793096" />
            </geometry>
        </collision>
    </link>
    <joint name="0_3" type="revolute">
       <parent link="0"/>
       <child  link="3"/>
       <origin rpy="0 0 0" xyz="-0.17067632870899757 0 0.4771974966790632" />
     <axis xyz="0 1 0"/>
       <limit effort="0.0" lower="-3.14159" upper="3.14159" velocity="0.0"/>
    </joint>
    <link name="3">
        <inertial>
            <origin xyz="-0.024916652844908405 0 0.0" rpy="0 0 0"/>
            <mass value="1" />
            <inertia ixx="100" ixy="0" ixz="0" iyy="100" iyz="0" izz="100" />
        </inertial>
        <visual>
            <origin xyz="-0.024916652844908405 0 0.0" rpy="0 0 0"/>
            <geometry>
                <box size="0.04983330568981681 0.48281295578697714 0.0330110926512549" />
            </geometry>
            <material name="not">
                <color rgba="0 1 1 1"/>
            </material>
        </visual>
        <collision>
            <origin xyz="-0.024916652844908405 0 0.0" rpy="0 0 0"/>
            <geometry>
                <box size="0.04983330568981681 0.48281295578697714 0.0330110926512549" />
            </geometry>
        </collision>
    </link>
    <joint name="3_4" type="revolute">
       <parent link="3"/>
       <child  link="4"/>
       <origin rpy="0 0 0" xyz="-0.04983330568981681 0 0.0" />
     <axis xyz="0 1 0"/>
       <limit effort="0.0" lower="-3.14159" upper="3.14159" velocity="0.0"/>
    </joint>
    <link name="4">
        <inertial>
            <origin xyz="-0.15794812201351544 0 0.0" rpy="0 0 0"/>
            <mass value="1" />
            <inertia ixx="100" ixy="0" ixz="0" iyy="100" iyz="0" izz="100" />
        </inertial>
        <visual>
            <origin xyz="-0.15794812201351544 0 0.0" rpy="0 0 0"/>
            <geometry>
                <box size="0.31589624402703087 0.31457980030607535 0.35128955830482467" />
            </geometry>
            <material name="sensor">
                <color rgba="0 1 0 1"/>
            </material>
        </visual>
        <collision>
            <origin xyz="-0.15794812201351544 0 0.0" rpy="0 0 0"/>
            <geometry>
                <box size="0.31589624402703087 0.31457980030607535 0.35128955830482467" />
            </geometry>
        </collision>
    </link>
    <joint name="4_5" type="revolute">
       <parent link="4"/>
       <child  link="5"/>
       <origin rpy="0 0 0" xyz="-0.15794812201351544 0.15728990015303768 0.0" />
     <axis xyz="1 0 0"/>
       <limit effort="0.0" lower="-3.14159" upper="3.14159" velocity="0.0"/>
    </joint>
    <link name="5">
        <inertial>
            <origin xyz="0.0 0.24662052104869175 0.0" rpy="0 0 0"/>
            <mass value="1" />
            <inertia ixx="100" ixy="0" ixz="0" iyy="100" iyz="0" izz="100" />
        </inertial>
        <visual>
            <origin xyz="0.0 0.24662052104869175 0.0" rpy="0 0 0"/>
            <geometry>
                <box size="0.039135995481974106 0.4932410420973835 0.908953450363328" />
            </geometry>
            <material name="not">
                <color rgba="0 1 1 1"/>
            </material>
        </visual>
        <collision>
            <origin xyz="0.0 0.24662052104869175 0.0" rpy="0 0 0"/>
            <geometry>
                <box size="0.039135995481974106 0.4932410420973835 0.908953450363328" />
            </geometry>
        </collision>
    </link>
</robot>