<robot name = "robot">
    <link name="0">
        <inertial>
            <origin xyz="0 0 0.08487199515892163" rpy="0 0 0"/>
            <mass value="1" />
            <inertia ixx="100" ixy="0" ixz="0" iyy="100" iyz="0" izz="100" />
        </inertial>
        <visual>
            <origin xyz="0 0 0.08487199515892163" rpy="0 0 0"/>
            <geometry>
                <box size="0.9560342718892494 0.9478274870593494 0.05655136772680869" />
            </geometry>
            <material name="not">
                <color rgba="0 1 1 1"/>
            </material>
        </visual>
        <collision>
            <origin xyz="0 0 0.08487199515892163" rpy="0 0 0"/>
            <geometry>
                <box size="0.9560342718892494 0.9478274870593494 0.05655136772680869" />
            </geometry>
        </collision>
    </link>
    <joint name="0_1" type="revolute">
       <parent link="0"/>
       <child  link="1"/>
       <origin rpy="0 0 0" xyz="0 0 0.11314767902232598" />
     <axis xyz="1 0 0"/>
       <limit effort="0.0" lower="-3.14159" upper="3.14159" velocity="0.0"/>
    </joint>
    <link name="1">
        <inertial>
            <origin xyz="0 0 0.011929039570391098" rpy="0 0 0"/>
            <mass value="1" />
            <inertia ixx="100" ixy="0" ixz="0" iyy="100" iyz="0" izz="100" />
        </inertial>
        <visual>
            <origin xyz="0 0 0.011929039570391098" rpy="0 0 0"/>
            <geometry>
                <box size="0.5605103610264989 0.23612340711506208 0.023858079140782196" />
            </geometry>
            <material name="not">
                <color rgba="0 1 1 1"/>
            </material>
        </visual>
        <collision>
            <origin xyz="0 0 0.011929039570391098" rpy="0 0 0"/>
            <geometry>
                <box size="0.5605103610264989 0.23612340711506208 0.023858079140782196" />
            </geometry>
        </collision>
    </link>
    <joint name="1_4" type="revolute">
       <parent link="1"/>
       <child  link="4"/>
       <origin rpy="0 0 0" xyz="0 -0.11806170355753104 0.011929039570391098" />
     <axis xyz="0 0 1"/>
       <limit effort="0.0" lower="-3.14159" upper="3.14159" velocity="0.0"/>
    </joint>
    <link name="4">
        <inertial>
            <origin xyz="0 -0.261545705391077 0.0" rpy="0 0 0"/>
            <mass value="1" />
            <inertia ixx="100" ixy="0" ixz="0" iyy="100" iyz="0" izz="100" />
        </inertial>
        <visual>
            <origin xyz="0 -0.261545705391077 0.0" rpy="0 0 0"/>
            <geometry>
                <box size="0.7347870333771318 0.523091410782154 0.0019362523076376092" />
            </geometry>
            <material name="not">
                <color rgba="0 1 1 1"/>
            </material>
        </visual>
        <collision>
            <origin xyz="0 -0.261545705391077 0.0" rpy="0 0 0"/>
            <geometry>
                <box size="0.7347870333771318 0.523091410782154 0.0019362523076376092" />
            </geometry>
        </collision>
    </link>
    <joint name="0_3" type="revolute">
       <parent link="0"/>
       <child  link="3"/>
       <origin rpy="0 0 0" xyz="0 0 0.05659631129551729" />
     <axis xyz="1 0 0"/>
       <limit effort="0.0" lower="-3.14159" upper="3.14159" velocity="0.0"/>
    </joint>
    <link name="3">
        <inertial>
            <origin xyz="0 0 -0.01593653506337256" rpy="0 0 0"/>
            <mass value="1" />
            <inertia ixx="100" ixy="0" ixz="0" iyy="100" iyz="0" izz="100" />
        </inertial>
        <visual>
            <origin xyz="0 0 -0.01593653506337256" rpy="0 0 0"/>
            <geometry>
                <box size="0.42291764838969603 0.7169610989049753 0.03187307012674512" />
            </geometry>
            <material name="sensor">
                <color rgba="0 1 0 1"/>
            </material>
        </visual>
        <collision>
            <origin xyz="0 0 -0.01593653506337256" rpy="0 0 0"/>
            <geometry>
                <box size="0.42291764838969603 0.7169610989049753 0.03187307012674512" />
            </geometry>
        </collision>
    </link>
</robot>