<robot name = "robot">
    <link name="0">
        <inertial>
            <origin xyz="0 0 0.6433379820663967" rpy="0 0 0"/>
            <mass value="1" />
            <inertia ixx="100" ixy="0" ixz="0" iyy="100" iyz="0" izz="100" />
        </inertial>
        <visual>
            <origin xyz="0 0 0.6433379820663967" rpy="0 0 0"/>
            <geometry>
                <box size="0.08194391520150945 0.2706284155045202 0.8787173255722639" />
            </geometry>
            <material name="not">
                <color rgba="0 1 1 1"/>
            </material>
        </visual>
        <collision>
            <origin xyz="0 0 0.6433379820663967" rpy="0 0 0"/>
            <geometry>
                <box size="0.08194391520150945 0.2706284155045202 0.8787173255722639" />
            </geometry>
        </collision>
    </link>
    <joint name="0_2" type="revolute">
       <parent link="0"/>
       <child  link="2"/>
       <origin rpy="0 0 0" xyz="0 0.1353142077522601 0.6433379820663967" />
     <axis xyz="0 0 1"/>
       <limit effort="0.0" lower="-3.14159" upper="3.14159" velocity="0.0"/>
    </joint>
    <link name="2">
        <inertial>
            <origin xyz="0 0.2761769486806595 0.0" rpy="0 0 0"/>
            <mass value="1" />
            <inertia ixx="100" ixy="0" ixz="0" iyy="100" iyz="0" izz="100" />
        </inertial>
        <visual>
            <origin xyz="0 0.2761769486806595 0.0" rpy="0 0 0"/>
            <geometry>
                <box size="0.7237065127532326 0.552353897361319 0.5025491894179654" />
            </geometry>
            <material name="not">
                <color rgba="0 1 1 1"/>
            </material>
        </visual>
        <collision>
            <origin xyz="0 0.2761769486806595 0.0" rpy="0 0 0"/>
            <geometry>
                <box size="0.7237065127532326 0.552353897361319 0.5025491894179654" />
            </geometry>
        </collision>
    </link>
    <joint name="0_1" type="revolute">
       <parent link="0"/>
       <child  link="1"/>
       <origin rpy="0 0 0" xyz="0 -0.1353142077522601 0.6433379820663967" />
     <axis xyz="0 1 0"/>
       <limit effort="0.0" lower="-3.14159" upper="3.14159" velocity="0.0"/>
    </joint>
    <link name="1">
        <inertial>
            <origin xyz="0 -0.4392404694451739 0.0" rpy="0 0 0"/>
            <mass value="1" />
            <inertia ixx="100" ixy="0" ixz="0" iyy="100" iyz="0" izz="100" />
        </inertial>
        <visual>
            <origin xyz="0 -0.4392404694451739 0.0" rpy="0 0 0"/>
            <geometry>
                <box size="0.9526129300146847 0.8784809388903478 0.7194334498145261" />
            </geometry>
            <material name="sensor">
                <color rgba="0 1 0 1"/>
            </material>
        </visual>
        <collision>
            <origin xyz="0 -0.4392404694451739 0.0" rpy="0 0 0"/>
            <geometry>
                <box size="0.9526129300146847 0.8784809388903478 0.7194334498145261" />
            </geometry>
        </collision>
    </link>
    <joint name="1_3" type="revolute">
       <parent link="1"/>
       <child  link="3"/>
       <origin rpy="0 0 0" xyz="0 -0.4392404694451739 0.35971672490726303" />
     <axis xyz="1 0 0"/>
       <limit effort="0.0" lower="-3.14159" upper="3.14159" velocity="0.0"/>
    </joint>
    <link name="3">
        <inertial>
            <origin xyz="0 0.0 0.08401734815319872" rpy="0 0 0"/>
            <mass value="1" />
            <inertia ixx="100" ixy="0" ixz="0" iyy="100" iyz="0" izz="100" />
        </inertial>
        <visual>
            <origin xyz="0 0.0 0.08401734815319872" rpy="0 0 0"/>
            <geometry>
                <box size="0.48419176420266474 0.06780119520402872 0.16803469630639734" />
            </geometry>
            <material name="sensor">
                <color rgba="0 1 0 1"/>
            </material>
        </visual>
        <collision>
            <origin xyz="0 0.0 0.08401734815319872" rpy="0 0 0"/>
            <geometry>
                <box size="0.48419176420266474 0.06780119520402872 0.16803469630639734" />
            </geometry>
        </collision>
    </link>
    <joint name="1_4" type="revolute">
       <parent link="1"/>
       <child  link="4"/>
       <origin rpy="0 0 0" xyz="0 -0.8784809388903477 0.0" />
     <axis xyz="0 1 0"/>
       <limit effort="0.0" lower="-3.14159" upper="3.14159" velocity="0.0"/>
    </joint>
    <link name="4">
        <inertial>
            <origin xyz="0 -0.0639508435439553 0.0" rpy="0 0 0"/>
            <mass value="1" />
            <inertia ixx="100" ixy="0" ixz="0" iyy="100" iyz="0" izz="100" />
        </inertial>
        <visual>
            <origin xyz="0 -0.0639508435439553 0.0" rpy="0 0 0"/>
            <geometry>
                <box size="0.4118848213419374 0.12790168708791072 0.10161547918495206" />
            </geometry>
            <material name="sensor">
                <color rgba="0 1 0 1"/>
            </material>
        </visual>
        <collision>
            <origin xyz="0 -0.0639508435439553 0.0" rpy="0 0 0"/>
            <geometry>
                <box size="0.4118848213419374 0.12790168708791072 0.10161547918495206" />
            </geometry>
        </collision>
    </link>
</robot>