<robot name = "robot">
    <link name="0">
        <inertial>
            <origin xyz="0 0 0.7896231589257826" rpy="0 0 0"/>
            <mass value="1" />
            <inertia ixx="100" ixy="0" ixz="0" iyy="100" iyz="0" izz="100" />
        </inertial>
        <visual>
            <origin xyz="0 0 0.7896231589257826" rpy="0 0 0"/>
            <geometry>
                <box size="0.008897082049078797 0.15102317386398778 0.3334083880298664" />
            </geometry>
            <material name="not">
                <color rgba="0 1 1 1"/>
            </material>
        </visual>
        <collision>
            <origin xyz="0 0 0.7896231589257826" rpy="0 0 0"/>
            <geometry>
                <box size="0.008897082049078797 0.15102317386398778 0.3334083880298664" />
            </geometry>
        </collision>
    </link>
    <joint name="0_1" type="revolute">
       <parent link="0"/>
       <child  link="1"/>
       <origin rpy="0 0 0" xyz="0 0 0.9563273529407158" />
     <axis xyz="0 1 0"/>
       <limit effort="0.0" lower="-3.14159" upper="3.14159" velocity="0.0"/>
    </joint>
    <link name="1">
        <inertial>
            <origin xyz="0 0 0.49095703506265276" rpy="0 0 0"/>
            <mass value="1" />
            <inertia ixx="100" ixy="0" ixz="0" iyy="100" iyz="0" izz="100" />
        </inertial>
        <visual>
            <origin xyz="0 0 0.49095703506265276" rpy="0 0 0"/>
            <geometry>
                <box size="0.041202949506209285 0.16386054567557595 0.9819140701253054" />
            </geometry>
            <material name="sensor">
                <color rgba="0 1 0 1"/>
            </material>
        </visual>
        <collision>
            <origin xyz="0 0 0.49095703506265276" rpy="0 0 0"/>
            <geometry>
                <box size="0.041202949506209285 0.16386054567557595 0.9819140701253054" />
            </geometry>
        </collision>
    </link>
    <joint name="1_3" type="revolute">
       <parent link="1"/>
       <child  link="3"/>
       <origin rpy="0 0 0" xyz="0.020601474753104643 0 0.49095703506265276" />
     <axis xyz="1 0 0"/>
       <limit effort="0.0" lower="-3.14159" upper="3.14159" velocity="0.0"/>
    </joint>
    <link name="3">
        <inertial>
            <origin xyz="0.20158457322254675 0 0.0" rpy="0 0 0"/>
            <mass value="1" />
            <inertia ixx="100" ixy="0" ixz="0" iyy="100" iyz="0" izz="100" />
        </inertial>
        <visual>
            <origin xyz="0.20158457322254675 0 0.0" rpy="0 0 0"/>
            <geometry>
                <box size="0.4031691464450935 0.3285207100154869 0.4147216089714424" />
            </geometry>
            <material name="sensor">
                <color rgba="0 1 0 1"/>
            </material>
        </visual>
        <collision>
            <origin xyz="0.20158457322254675 0 0.0" rpy="0 0 0"/>
            <geometry>
                <box size="0.4031691464450935 0.3285207100154869 0.4147216089714424" />
            </geometry>
        </collision>
    </link>
    <joint name="3_4" type="revolute">
       <parent link="3"/>
       <child  link="4"/>
       <origin rpy="0 0 0" xyz="0.4031691464450935 0 0.0" />
     <axis xyz="0 1 0"/>
       <limit effort="0.0" lower="-3.14159" upper="3.14159" velocity="0.0"/>
    </joint>
    <link name="4">
        <inertial>
            <origin xyz="0.168540272268833 0 0.0" rpy="0 0 0"/>
            <mass value="1" />
            <inertia ixx="100" ixy="0" ixz="0" iyy="100" iyz="0" izz="100" />
        </inertial>
        <visual>
            <origin xyz="0.168540272268833 0 0.0" rpy="0 0 0"/>
            <geometry>
                <box size="0.3370805445376659 0.7978743610995221 0.8123286615584164" />
            </geometry>
            <material name="sensor">
                <color rgba="0 1 0 1"/>
            </material>
        </visual>
        <collision>
            <origin xyz="0.168540272268833 0 0.0" rpy="0 0 0"/>
            <geometry>
                <box size="0.3370805445376659 0.7978743610995221 0.8123286615584164" />
            </geometry>
        </collision>
    </link>
    <joint name="1_2" type="revolute">
       <parent link="1"/>
       <child  link="2"/>
       <origin rpy="0 0 0" xyz="-0.020601474753104643 0 0.49095703506265276" />
     <axis xyz="0 0 1"/>
       <limit effort="0.0" lower="-3.14159" upper="3.14159" velocity="0.0"/>
    </joint>
    <link name="2">
        <inertial>
            <origin xyz="-0.4668770397017015 0 0.0" rpy="0 0 0"/>
            <mass value="1" />
            <inertia ixx="100" ixy="0" ixz="0" iyy="100" iyz="0" izz="100" />
        </inertial>
        <visual>
            <origin xyz="-0.4668770397017015 0 0.0" rpy="0 0 0"/>
            <geometry>
                <box size="0.933754079403403 0.30787976219942303 0.8570365795720385" />
            </geometry>
            <material name="not">
                <color rgba="0 1 1 1"/>
            </material>
        </visual>
        <collision>
            <origin xyz="-0.4668770397017015 0 0.0" rpy="0 0 0"/>
            <geometry>
                <box size="0.933754079403403 0.30787976219942303 0.8570365795720385" />
            </geometry>
        </collision>
    </link>
</robot>