<robot name = "robot">
    <link name="0">
        <inertial>
            <origin xyz="0 0 0.35758461773097183" rpy="0 0 0"/>
            <mass value="1" />
            <inertia ixx="100" ixy="0" ixz="0" iyy="100" iyz="0" izz="100" />
        </inertial>
        <visual>
            <origin xyz="0 0 0.35758461773097183" rpy="0 0 0"/>
            <geometry>
                <box size="0.7772119346497987 0.7235182799831297 0.4979495204296175" />
            </geometry>
            <material name="sensor">
                <color rgba="0 1 0 1"/>
            </material>
        </visual>
        <collision>
            <origin xyz="0 0 0.35758461773097183" rpy="0 0 0"/>
            <geometry>
                <box size="0.7772119346497987 0.7235182799831297 0.4979495204296175" />
            </geometry>
        </collision>
    </link>
    <joint name="0_3" type="revolute">
       <parent link="0"/>
       <child  link="3"/>
       <origin rpy="0 0 0" xyz="0 -0.36175913999156484 0.35758461773097183" />
     <axis xyz="0 0 1"/>
       <limit effort="0.0" lower="-3.14159" upper="3.14159" velocity="0.0"/>
    </joint>
    <link name="3">
        <inertial>
            <origin xyz="0 -0.26199738415698826 0.0" rpy="0 0 0"/>
            <mass value="1" />
            <inertia ixx="100" ixy="0" ixz="0" iyy="100" iyz="0" izz="100" />
        </inertial>
        <visual>
            <origin xyz="0 -0.26199738415698826 0.0" rpy="0 0 0"/>
            <geometry>
                <box size="0.43884583691157797 0.5239947683139765 0.1120702635945241" />
            </geometry>
            <material name="sensor">
                <color rgba="0 1 0 1"/>
            </material>
        </visual>
        <collision>
            <origin xyz="0 -0.26199738415698826 0.0" rpy="0 0 0"/>
            <geometry>
                <box size="0.43884583691157797 0.5239947683139765 0.1120702635945241" />
            </geometry>
        </collision>
    </link>
    <joint name="0_1" type="revolute">
       <parent link="0"/>
       <child  link="1"/>
       <origin rpy="0 0 0" xyz="-0.3886059673248993 0 0.35758461773097183" />
     <axis xyz="1 0 0"/>
       <limit effort="0.0" lower="-3.14159" upper="3.14159" velocity="0.0"/>
    </joint>
    <link name="1">
        <inertial>
            <origin xyz="-0.13447124691382634 0 0.0" rpy="0 0 0"/>
            <mass value="1" />
            <inertia ixx="100" ixy="0" ixz="0" iyy="100" iyz="0" izz="100" />
        </inertial>
        <visual>
            <origin xyz="-0.13447124691382634 0 0.0" rpy="0 0 0"/>
            <geometry>
                <box size="0.26894249382765256 0.5263037448063002 0.47755954205652185" />
            </geometry>
            <material name="sensor">
                <color rgba="0 1 0 1"/>
            </material>
        </visual>
        <collision>
            <origin xyz="-0.13447124691382634 0 0.0" rpy="0 0 0"/>
            <geometry>
                <box size="0.26894249382765256 0.5263037448063002 0.47755954205652185" />
            </geometry>
        </collision>
    </link>
    <joint name="1_4" type="revolute">
       <parent link="1"/>
       <child  link="4"/>
       <origin rpy="0 0 0" xyz="-0.13447124691382634 0.2631518724031501 0.0" />
     <axis xyz="0 1 0"/>
       <limit effort="0.0" lower="-3.14159" upper="3.14159" velocity="0.0"/>
    </joint>
    <link name="4">
        <inertial>
            <origin xyz="0.0 0.3947412247957762 0.0" rpy="0 0 0"/>
            <mass value="1" />
            <inertia ixx="100" ixy="0" ixz="0" iyy="100" iyz="0" izz="100" />
        </inertial>
        <visual>
            <origin xyz="0.0 0.3947412247957762 0.0" rpy="0 0 0"/>
            <geometry>
                <box size="0.003081868946199884 0.7894824495915524 0.42631563781376713" />
            </geometry>
            <material name="sensor">
                <color rgba="0 1 0 1"/>
            </material>
        </visual>
        <collision>
            <origin xyz="0.0 0.3947412247957762 0.0" rpy="0 0 0"/>
            <geometry>
                <box size="0.003081868946199884 0.7894824495915524 0.42631563781376713" />
            </geometry>
        </collision>
    </link>
    <joint name="4_5" type="revolute">
       <parent link="4"/>
       <child  link="5"/>
       <origin rpy="0 0 0" xyz="-0.0015409344730998864 0.3947412247957762 0.0" />
     <axis xyz="0 1 0"/>
       <limit effort="0.0" lower="-3.14159" upper="3.14159" velocity="0.0"/>
    </joint>
    <link name="5">
        <inertial>
            <origin xyz="-0.4396825597658174 0.0 0.0" rpy="0 0 0"/>
            <mass value="1" />
            <inertia ixx="100" ixy="0" ixz="0" iyy="100" iyz="0" izz="100" />
        </inertial>
        <visual>
            <origin xyz="-0.4396825597658174 0.0 0.0" rpy="0 0 0"/>
            <geometry>
                <box size="0.8793651195316349 0.7658888172578397 0.04020225015836498" />
            </geometry>
            <material name="sensor">
                <color rgba="0 1 0 1"/>
            </material>
        </visual>
        <collision>
            <origin xyz="-0.4396825597658174 0.0 0.0" rpy="0 0 0"/>
            <geometry>
                <box size="0.8793651195316349 0.7658888172578397 0.04020225015836498" />
            </geometry>
        </collision>
    </link>
    <joint name="5_6" type="revolute">
       <parent link="5"/>
       <child  link="6"/>
       <origin rpy="0 0 0" xyz="-0.8793651195316348 0.0 0.0" />
     <axis xyz="0 1 0"/>
       <limit effort="0.0" lower="-3.14159" upper="3.14159" velocity="0.0"/>
    </joint>
    <link name="6">
        <inertial>
            <origin xyz="-0.3440049607261284 0.0 0.0" rpy="0 0 0"/>
            <mass value="1" />
            <inertia ixx="100" ixy="0" ixz="0" iyy="100" iyz="0" izz="100" />
        </inertial>
        <visual>
            <origin xyz="-0.3440049607261284 0.0 0.0" rpy="0 0 0"/>
            <geometry>
                <box size="0.6880099214522568 0.598390427435108 0.5078621938118403" />
            </geometry>
            <material name="sensor">
                <color rgba="0 1 0 1"/>
            </material>
        </visual>
        <collision>
            <origin xyz="-0.3440049607261284 0.0 0.0" rpy="0 0 0"/>
            <geometry>
                <box size="0.6880099214522568 0.598390427435108 0.5078621938118403" />
            </geometry>
        </collision>
    </link>
</robot>