<robot name = "robot">
    <link name="0">
        <inertial>
            <origin xyz="0 0 0.32684013409939283" rpy="0 0 0"/>
            <mass value="1" />
            <inertia ixx="100" ixy="0" ixz="0" iyy="100" iyz="0" izz="100" />
        </inertial>
        <visual>
            <origin xyz="0 0 0.32684013409939283" rpy="0 0 0"/>
            <geometry>
                <box size="0.9973567883483517 0.9312456827581534 0.13265410978640746" />
            </geometry>
            <material name="sensor">
                <color rgba="0 1 0 1"/>
            </material>
        </visual>
        <collision>
            <origin xyz="0 0 0.32684013409939283" rpy="0 0 0"/>
            <geometry>
                <box size="0.9973567883483517 0.9312456827581534 0.13265410978640746" />
            </geometry>
        </collision>
    </link>
    <joint name="0_1" type="revolute">
       <parent link="0"/>
       <child  link="1"/>
       <origin rpy="0 0 0" xyz="-0.49867839417417587 0 0.32684013409939283" />
     <axis xyz="1 0 0"/>
       <limit effort="0.0" lower="-3.14159" upper="3.14159" velocity="0.0"/>
    </joint>
    <link name="1">
        <inertial>
            <origin xyz="-0.20741661196344235 0 0.0" rpy="0 0 0"/>
            <mass value="1" />
            <inertia ixx="100" ixy="0" ixz="0" iyy="100" iyz="0" izz="100" />
        </inertial>
        <visual>
            <origin xyz="-0.20741661196344235 0 0.0" rpy="0 0 0"/>
            <geometry>
                <box size="0.4148332239268847 0.9365117358906235 0.5783447227370002" />
            </geometry>
            <material name="sensor">
                <color rgba="0 1 0 1"/>
            </material>
        </visual>
        <collision>
            <origin xyz="-0.20741661196344235 0 0.0" rpy="0 0 0"/>
            <geometry>
                <box size="0.4148332239268847 0.9365117358906235 0.5783447227370002" />
            </geometry>
        </collision>
    </link>
    <joint name="1_2" type="revolute">
       <parent link="1"/>
       <child  link="2"/>
       <origin rpy="0 0 0" xyz="-0.20741661196344235 0 0.2891723613685001" />
     <axis xyz="0 0 1"/>
       <limit effort="0.0" lower="-3.14159" upper="3.14159" velocity="0.0"/>
    </joint>
    <link name="2">
        <inertial>
            <origin xyz="0.0 0 0.4165104855890931" rpy="0 0 0"/>
            <mass value="1" />
            <inertia ixx="100" ixy="0" ixz="0" iyy="100" iyz="0" izz="100" />
        </inertial>
        <visual>
            <origin xyz="0.0 0 0.4165104855890931" rpy="0 0 0"/>
            <geometry>
                <box size="0.2661110660443323 0.9456218665530784 0.8330209711781862" />
            </geometry>
            <material name="sensor">
                <color rgba="0 1 0 1"/>
            </material>
        </visual>
        <collision>
            <origin xyz="0.0 0 0.4165104855890931" rpy="0 0 0"/>
            <geometry>
                <box size="0.2661110660443323 0.9456218665530784 0.8330209711781862" />
            </geometry>
        </collision>
    </link>
    <joint name="2_3" type="revolute">
       <parent link="2"/>
       <child  link="3"/>
       <origin rpy="0 0 0" xyz="0.0 0 0.8330209711781862" />
     <axis xyz="1 0 0"/>
       <limit effort="0.0" lower="-3.14159" upper="3.14159" velocity="0.0"/>
    </joint>
    <link name="3">
        <inertial>
            <origin xyz="0.0 0 0.4684216436440354" rpy="0 0 0"/>
            <mass value="1" />
            <inertia ixx="100" ixy="0" ixz="0" iyy="100" iyz="0" izz="100" />
        </inertial>
        <visual>
            <origin xyz="0.0 0 0.4684216436440354" rpy="0 0 0"/>
            <geometry>
                <box size="0.9715676717950266 0.5336613415839108 0.9368432872880708" />
            </geometry>
            <material name="not">
                <color rgba="0 1 1 1"/>
            </material>
        </visual>
        <collision>
            <origin xyz="0.0 0 0.4684216436440354" rpy="0 0 0"/>
            <geometry>
                <box size="0.9715676717950266 0.5336613415839108 0.9368432872880708" />
            </geometry>
        </collision>
    </link>
    <joint name="3_4" type="revolute">
       <parent link="3"/>
       <child  link="4"/>
       <origin rpy="0 0 0" xyz="0.4857838358975133 0 0.4684216436440354" />
     <axis xyz="1 0 0"/>
       <limit effort="0.0" lower="-3.14159" upper="3.14159" velocity="0.0"/>
    </joint>
    <link name="4">
        <inertial>
            <origin xyz="0.38336222296501227 0 0.0" rpy="0 0 0"/>
            <mass value="1" />
            <inertia ixx="100" ixy="0" ixz="0" iyy="100" iyz="0" izz="100" />
        </inertial>
        <visual>
            <origin xyz="0.38336222296501227 0 0.0" rpy="0 0 0"/>
            <geometry>
                <box size="0.7667244459300245 0.8248724452313679 0.6474371811438113" />
            </geometry>
            <material name="sensor">
                <color rgba="0 1 0 1"/>
            </material>
        </visual>
        <collision>
            <origin xyz="0.38336222296501227 0 0.0" rpy="0 0 0"/>
            <geometry>
                <box size="0.7667244459300245 0.8248724452313679 0.6474371811438113" />
            </geometry>
        </collision>
    </link>
</robot>