<robot name = "robot">
    <link name="0">
        <inertial>
            <origin xyz="0 0 0.277682664989071" rpy="0 0 0"/>
            <mass value="1" />
            <inertia ixx="100" ixy="0" ixz="0" iyy="100" iyz="0" izz="100" />
        </inertial>
        <visual>
            <origin xyz="0 0 0.277682664989071" rpy="0 0 0"/>
            <geometry>
                <box size="0.30193794478071045 0.5193626806002752 0.06751041699060978" />
            </geometry>
            <material name="sensor">
                <color rgba="0 1 0 1"/>
            </material>
        </visual>
        <collision>
            <origin xyz="0 0 0.277682664989071" rpy="0 0 0"/>
            <geometry>
                <box size="0.30193794478071045 0.5193626806002752 0.06751041699060978" />
            </geometry>
        </collision>
    </link>
    <joint name="0_1" type="revolute">
       <parent link="0"/>
       <child  link="1"/>
       <origin rpy="0 0 0" xyz="0 0 0.3114378734843759" />
     <axis xyz="0 1 0"/>
       <limit effort="0.0" lower="-3.14159" upper="3.14159" velocity="0.0"/>
    </joint>
    <link name="1">
        <inertial>
            <origin xyz="0 0 0.22080834483139722" rpy="0 0 0"/>
            <mass value="1" />
            <inertia ixx="100" ixy="0" ixz="0" iyy="100" iyz="0" izz="100" />
        </inertial>
        <visual>
            <origin xyz="0 0 0.22080834483139722" rpy="0 0 0"/>
            <geometry>
                <box size="0.7643791337034044 0.5998851669187714 0.44161668966279444" />
            </geometry>
            <material name="sensor">
                <color rgba="0 1 0 1"/>
            </material>
        </visual>
        <collision>
            <origin xyz="0 0 0.22080834483139722" rpy="0 0 0"/>
            <geometry>
                <box size="0.7643791337034044 0.5998851669187714 0.44161668966279444" />
            </geometry>
        </collision>
    </link>
    <joint name="1_3" type="revolute">
       <parent link="1"/>
       <child  link="3"/>
       <origin rpy="0 0 0" xyz="0 -0.2999425834593857 0.22080834483139722" />
     <axis xyz="0 0 1"/>
       <limit effort="0.0" lower="-3.14159" upper="3.14159" velocity="0.0"/>
    </joint>
    <link name="3">
        <inertial>
            <origin xyz="0 -0.4818312621293343 0.0" rpy="0 0 0"/>
            <mass value="1" />
            <inertia ixx="100" ixy="0" ixz="0" iyy="100" iyz="0" izz="100" />
        </inertial>
        <visual>
            <origin xyz="0 -0.4818312621293343 0.0" rpy="0 0 0"/>
            <geometry>
                <box size="0.6028195797332327 0.9636625242586686 0.17271439561168145" />
            </geometry>
            <material name="not">
                <color rgba="0 1 1 1"/>
            </material>
        </visual>
        <collision>
            <origin xyz="0 -0.4818312621293343 0.0" rpy="0 0 0"/>
            <geometry>
                <box size="0.6028195797332327 0.9636625242586686 0.17271439561168145" />
            </geometry>
        </collision>
    </link>
    <joint name="0_2" type="revolute">
       <parent link="0"/>
       <child  link="2"/>
       <origin rpy="0 0 0" xyz="0 0 0.24392745649376613" />
     <axis xyz="0 1 0"/>
       <limit effort="0.0" lower="-3.14159" upper="3.14159" velocity="0.0"/>
    </joint>
    <link name="2">
        <inertial>
            <origin xyz="0 0 -0.020197483952361484" rpy="0 0 0"/>
            <mass value="1" />
            <inertia ixx="100" ixy="0" ixz="0" iyy="100" iyz="0" izz="100" />
        </inertial>
        <visual>
            <origin xyz="0 0 -0.020197483952361484" rpy="0 0 0"/>
            <geometry>
                <box size="0.2600778328897737 0.24931622530635988 0.04039496790472297" />
            </geometry>
            <material name="not">
                <color rgba="0 1 1 1"/>
            </material>
        </visual>
        <collision>
            <origin xyz="0 0 -0.020197483952361484" rpy="0 0 0"/>
            <geometry>
                <box size="0.2600778328897737 0.24931622530635988 0.04039496790472297" />
            </geometry>
        </collision>
    </link>
    <joint name="2_5" type="revolute">
       <parent link="2"/>
       <child  link="5"/>
       <origin rpy="0 0 0" xyz="0 0 -0.04039496790472297" />
     <axis xyz="0 1 0"/>
       <limit effort="0.0" lower="-3.14159" upper="3.14159" velocity="0.0"/>
    </joint>
    <link name="5">
        <inertial>
            <origin xyz="0 0 -0.060061772619883824" rpy="0 0 0"/>
            <mass value="1" />
            <inertia ixx="100" ixy="0" ixz="0" iyy="100" iyz="0" izz="100" />
        </inertial>
        <visual>
            <origin xyz="0 0 -0.060061772619883824" rpy="0 0 0"/>
            <geometry>
                <box size="0.928017441239376 0.4791968318759957 0.12012354523976765" />
            </geometry>
            <material name="sensor">
                <color rgba="0 1 0 1"/>
            </material>
        </visual>
        <collision>
            <origin xyz="0 0 -0.060061772619883824" rpy="0 0 0"/>
            <geometry>
                <box size="0.928017441239376 0.4791968318759957 0.12012354523976765" />
            </geometry>
        </collision>
    </link>
    <joint name="0_4" type="revolute">
       <parent link="0"/>
       <child  link="4"/>
       <origin rpy="0 0 0" xyz="-0.15096897239035523 0 0.277682664989071" />
     <axis xyz="0 1 0"/>
       <limit effort="0.0" lower="-3.14159" upper="3.14159" velocity="0.0"/>
    </joint>
    <link name="4">
        <inertial>
            <origin xyz="-0.2969290331301494 0 0.0" rpy="0 0 0"/>
            <mass value="1" />
            <inertia ixx="100" ixy="0" ixz="0" iyy="100" iyz="0" izz="100" />
        </inertial>
        <visual>
            <origin xyz="-0.2969290331301494 0 0.0" rpy="0 0 0"/>
            <geometry>
                <box size="0.5938580662602988 0.03632969770836725 0.022509225235640473" />
            </geometry>
            <material name="sensor">
                <color rgba="0 1 0 1"/>
            </material>
        </visual>
        <collision>
            <origin xyz="-0.2969290331301494 0 0.0" rpy="0 0 0"/>
            <geometry>
                <box size="0.5938580662602988 0.03632969770836725 0.022509225235640473" />
            </geometry>
        </collision>
    </link>
    <joint name="4_6" type="revolute">
       <parent link="4"/>
       <child  link="6"/>
       <origin rpy="0 0 0" xyz="-0.2969290331301494 0 0.011254612617820237" />
     <axis xyz="0 0 1"/>
       <limit effort="0.0" lower="-3.14159" upper="3.14159" velocity="0.0"/>
    </joint>
    <link name="6">
        <inertial>
            <origin xyz="0.0 0 0.4640107796495103" rpy="0 0 0"/>
            <mass value="1" />
            <inertia ixx="100" ixy="0" ixz="0" iyy="100" iyz="0" izz="100" />
        </inertial>
        <visual>
            <origin xyz="0.0 0 0.4640107796495103" rpy="0 0 0"/>
            <geometry>
                <box size="0.11809274922190505 0.8535556816992527 0.9280215592990205" />
            </geometry>
            <material name="sensor">
                <color rgba="0 1 0 1"/>
            </material>
        </visual>
        <collision>
            <origin xyz="0.0 0 0.4640107796495103" rpy="0 0 0"/>
            <geometry>
                <box size="0.11809274922190505 0.8535556816992527 0.9280215592990205" />
            </geometry>
        </collision>
    </link>
</robot>