<robot name = "robot">
    <link name="0">
        <inertial>
            <origin xyz="0 0 0.6914255848440284" rpy="0 0 0"/>
            <mass value="1" />
            <inertia ixx="100" ixy="0" ixz="0" iyy="100" iyz="0" izz="100" />
        </inertial>
        <visual>
            <origin xyz="0 0 0.6914255848440284" rpy="0 0 0"/>
            <geometry>
                <box size="0.8366202813538083 0.9373816911418348 0.4772389328692719" />
            </geometry>
            <material name="sensor">
                <color rgba="0 1 0 1"/>
            </material>
        </visual>
        <collision>
            <origin xyz="0 0 0.6914255848440284" rpy="0 0 0"/>
            <geometry>
                <box size="0.8366202813538083 0.9373816911418348 0.4772389328692719" />
            </geometry>
        </collision>
    </link>
    <joint name="0_2" type="revolute">
       <parent link="0"/>
       <child  link="2"/>
       <origin rpy="0 0 0" xyz="0 0.4686908455709174 0.6914255848440284" />
     <axis xyz="0 0 1"/>
       <limit effort="0.0" lower="-3.14159" upper="3.14159" velocity="0.0"/>
    </joint>
    <link name="2">
        <inertial>
            <origin xyz="0 0.22053420776155525 0.0" rpy="0 0 0"/>
            <mass value="1" />
            <inertia ixx="100" ixy="0" ixz="0" iyy="100" iyz="0" izz="100" />
        </inertial>
        <visual>
            <origin xyz="0 0.22053420776155525 0.0" rpy="0 0 0"/>
            <geometry>
                <box size="0.16002306779062903 0.4410684155231104 0.6501170633788611" />
            </geometry>
            <material name="not">
                <color rgba="0 1 1 1"/>
            </material>
        </visual>
        <collision>
            <origin xyz="0 0.22053420776155525 0.0" rpy="0 0 0"/>
            <geometry>
                <box size="0.16002306779062903 0.4410684155231104 0.6501170633788611" />
            </geometry>
        </collision>
    </link>
    <joint name="0_1" type="revolute">
       <parent link="0"/>
       <child  link="1"/>
       <origin rpy="0 0 0" xyz="0 0 0.9300450512786643" />
     <axis xyz="0 0 1"/>
       <limit effort="0.0" lower="-3.14159" upper="3.14159" velocity="0.0"/>
    </joint>
    <link name="1">
        <inertial>
            <origin xyz="0 0 0.43356406925941504" rpy="0 0 0"/>
            <mass value="1" />
            <inertia ixx="100" ixy="0" ixz="0" iyy="100" iyz="0" izz="100" />
        </inertial>
        <visual>
            <origin xyz="0 0 0.43356406925941504" rpy="0 0 0"/>
            <geometry>
                <box size="0.3026660950760326 0.553207820465451 0.8671281385188301" />
            </geometry>
            <material name="not">
                <color rgba="0 1 1 1"/>
            </material>
        </visual>
        <collision>
            <origin xyz="0 0 0.43356406925941504" rpy="0 0 0"/>
            <geometry>
                <box size="0.3026660950760326 0.553207820465451 0.8671281385188301" />
            </geometry>
        </collision>
    </link>
    <joint name="1_4" type="revolute">
       <parent link="1"/>
       <child  link="4"/>
       <origin rpy="0 0 0" xyz="0 -0.2766039102327255 0.43356406925941504" />
     <axis xyz="0 0 1"/>
       <limit effort="0.0" lower="-3.14159" upper="3.14159" velocity="0.0"/>
    </joint>
    <link name="4">
        <inertial>
            <origin xyz="0 -0.4515911615416815 0.0" rpy="0 0 0"/>
            <mass value="1" />
            <inertia ixx="100" ixy="0" ixz="0" iyy="100" iyz="0" izz="100" />
        </inertial>
        <visual>
            <origin xyz="0 -0.4515911615416815 0.0" rpy="0 0 0"/>
            <geometry>
                <box size="0.23784640966367143 0.9031823230833629 0.0006606157907871335" />
            </geometry>
            <material name="sensor">
                <color rgba="0 1 0 1"/>
            </material>
        </visual>
        <collision>
            <origin xyz="0 -0.4515911615416815 0.0" rpy="0 0 0"/>
            <geometry>
                <box size="0.23784640966367143 0.9031823230833629 0.0006606157907871335" />
            </geometry>
        </collision>
    </link>
    <joint name="4_6" type="revolute">
       <parent link="4"/>
       <child  link="6"/>
       <origin rpy="0 0 0" xyz="0.11892320483183572 -0.4515911615416815 0.0" />
     <axis xyz="1 0 0"/>
       <limit effort="0.0" lower="-3.14159" upper="3.14159" velocity="0.0"/>
    </joint>
    <link name="6">
        <inertial>
            <origin xyz="0.05036278396385918 0.0 0.0" rpy="0 0 0"/>
            <mass value="1" />
            <inertia ixx="100" ixy="0" ixz="0" iyy="100" iyz="0" izz="100" />
        </inertial>
        <visual>
            <origin xyz="0.05036278396385918 0.0 0.0" rpy="0 0 0"/>
            <geometry>
                <box size="0.10072556792771836 0.7819714748526417 0.7944120636627088" />
            </geometry>
            <material name="not">
                <color rgba="0 1 1 1"/>
            </material>
        </visual>
        <collision>
            <origin xyz="0.05036278396385918 0.0 0.0" rpy="0 0 0"/>
            <geometry>
                <box size="0.10072556792771836 0.7819714748526417 0.7944120636627088" />
            </geometry>
        </collision>
    </link>
    <joint name="0_7" type="revolute">
       <parent link="0"/>
       <child  link="7"/>
       <origin rpy="0 0 0" xyz="0 0 0.45280611840939244" />
     <axis xyz="0 1 0"/>
       <limit effort="0.0" lower="-3.14159" upper="3.14159" velocity="0.0"/>
    </joint>
    <link name="7">
        <inertial>
            <origin xyz="0 0 -0.22561561857489698" rpy="0 0 0"/>
            <mass value="1" />
            <inertia ixx="100" ixy="0" ixz="0" iyy="100" iyz="0" izz="100" />
        </inertial>
        <visual>
            <origin xyz="0 0 -0.22561561857489698" rpy="0 0 0"/>
            <geometry>
                <box size="0.6996894882612498 0.748276701084894 0.45123123714979396" />
            </geometry>
            <material name="sensor">
                <color rgba="0 1 0 1"/>
            </material>
        </visual>
        <collision>
            <origin xyz="0 0 -0.22561561857489698" rpy="0 0 0"/>
            <geometry>
                <box size="0.6996894882612498 0.748276701084894 0.45123123714979396" />
            </geometry>
        </collision>
    </link>
</robot>