<robot name = "robot">
    <link name="0">
        <inertial>
            <origin xyz="0 0 0.46263554305186805" rpy="0 0 0"/>
            <mass value="1" />
            <inertia ixx="100" ixy="0" ixz="0" iyy="100" iyz="0" izz="100" />
        </inertial>
        <visual>
            <origin xyz="0 0 0.46263554305186805" rpy="0 0 0"/>
            <geometry>
                <box size="0.5064670413283575 0.45350130080122564 0.38985211310481016" />
            </geometry>
            <material name="sensor">
                <color rgba="0 1 0 1"/>
            </material>
        </visual>
        <collision>
            <origin xyz="0 0 0.46263554305186805" rpy="0 0 0"/>
            <geometry>
                <box size="0.5064670413283575 0.45350130080122564 0.38985211310481016" />
            </geometry>
        </collision>
    </link>
    <joint name="0_1" type="revolute">
       <parent link="0"/>
       <child  link="1"/>
       <origin rpy="0 0 0" xyz="0 0.22675065040061282 0.46263554305186805" />
     <axis xyz="0 1 0"/>
       <limit effort="0.0" lower="-3.14159" upper="3.14159" velocity="0.0"/>
    </joint>
    <link name="1">
        <inertial>
            <origin xyz="0 0.3123987368340393 0.0" rpy="0 0 0"/>
            <mass value="1" />
            <inertia ixx="100" ixy="0" ixz="0" iyy="100" iyz="0" izz="100" />
        </inertial>
        <visual>
            <origin xyz="0 0.3123987368340393 0.0" rpy="0 0 0"/>
            <geometry>
                <box size="0.13976522312678064 0.6247974736680786 0.354298262564966" />
            </geometry>
            <material name="sensor">
                <color rgba="0 1 0 1"/>
            </material>
        </visual>
        <collision>
            <origin xyz="0 0.3123987368340393 0.0" rpy="0 0 0"/>
            <geometry>
                <box size="0.13976522312678064 0.6247974736680786 0.354298262564966" />
            </geometry>
        </collision>
    </link>
    <joint name="1_4" type="revolute">
       <parent link="1"/>
       <child  link="4"/>
       <origin rpy="0 0 0" xyz="0.06988261156339032 0.3123987368340393 0.0" />
     <axis xyz="0 1 0"/>
       <limit effort="0.0" lower="-3.14159" upper="3.14159" velocity="0.0"/>
    </joint>
    <link name="4">
        <inertial>
            <origin xyz="0.06710179940647981 0.0 0.0" rpy="0 0 0"/>
            <mass value="1" />
            <inertia ixx="100" ixy="0" ixz="0" iyy="100" iyz="0" izz="100" />
        </inertial>
        <visual>
            <origin xyz="0.06710179940647981 0.0 0.0" rpy="0 0 0"/>
            <geometry>
                <box size="0.13420359881295962 0.07834111986609771 0.21507313837294328" />
            </geometry>
            <material name="sensor">
                <color rgba="0 1 0 1"/>
            </material>
        </visual>
        <collision>
            <origin xyz="0.06710179940647981 0.0 0.0" rpy="0 0 0"/>
            <geometry>
                <box size="0.13420359881295962 0.07834111986609771 0.21507313837294328" />
            </geometry>
        </collision>
    </link>
    <joint name="1_5" type="revolute">
       <parent link="1"/>
       <child  link="5"/>
       <origin rpy="0 0 0" xyz="0 0.3123987368340393 0.177149131282483" />
     <axis xyz="0 0 1"/>
       <limit effort="0.0" lower="-3.14159" upper="3.14159" velocity="0.0"/>
    </joint>
    <link name="5">
        <inertial>
            <origin xyz="0 0.0 0.09483321518168963" rpy="0 0 0"/>
            <mass value="1" />
            <inertia ixx="100" ixy="0" ixz="0" iyy="100" iyz="0" izz="100" />
        </inertial>
        <visual>
            <origin xyz="0 0.0 0.09483321518168963" rpy="0 0 0"/>
            <geometry>
                <box size="0.0578542071407826 0.013025025909400245 0.18966643036337927" />
            </geometry>
            <material name="not">
                <color rgba="0 1 1 1"/>
            </material>
        </visual>
        <collision>
            <origin xyz="0 0.0 0.09483321518168963" rpy="0 0 0"/>
            <geometry>
                <box size="0.0578542071407826 0.013025025909400245 0.18966643036337927" />
            </geometry>
        </collision>
    </link>
    <joint name="1_2" type="revolute">
       <parent link="1"/>
       <child  link="2"/>
       <origin rpy="0 0 0" xyz="-0.06988261156339032 0.3123987368340393 0.0" />
     <axis xyz="1 0 0"/>
       <limit effort="0.0" lower="-3.14159" upper="3.14159" velocity="0.0"/>
    </joint>
    <link name="2">
        <inertial>
            <origin xyz="-0.3613612608280052 0.0 0.0" rpy="0 0 0"/>
            <mass value="1" />
            <inertia ixx="100" ixy="0" ixz="0" iyy="100" iyz="0" izz="100" />
        </inertial>
        <visual>
            <origin xyz="-0.3613612608280052 0.0 0.0" rpy="0 0 0"/>
            <geometry>
                <box size="0.7227225216560104 0.3583123285166151 0.2959126144983111" />
            </geometry>
            <material name="sensor">
                <color rgba="0 1 0 1"/>
            </material>
        </visual>
        <collision>
            <origin xyz="-0.3613612608280052 0.0 0.0" rpy="0 0 0"/>
            <geometry>
                <box size="0.7227225216560104 0.3583123285166151 0.2959126144983111" />
            </geometry>
        </collision>
    </link>
</robot>