<robot name = "robot">
    <link name="0">
        <inertial>
            <origin xyz="0 0 0.6815384931552602" rpy="0 0 0"/>
            <mass value="1" />
            <inertia ixx="100" ixy="0" ixz="0" iyy="100" iyz="0" izz="100" />
        </inertial>
        <visual>
            <origin xyz="0 0 0.6815384931552602" rpy="0 0 0"/>
            <geometry>
                <box size="0.23451401972236074 0.8467904254828078 0.8695114998549054" />
            </geometry>
            <material name="not">
                <color rgba="0 1 1 1"/>
            </material>
        </visual>
        <collision>
            <origin xyz="0 0 0.6815384931552602" rpy="0 0 0"/>
            <geometry>
                <box size="0.23451401972236074 0.8467904254828078 0.8695114998549054" />
            </geometry>
        </collision>
    </link>
    <joint name="0_1" type="revolute">
       <parent link="0"/>
       <child  link="1"/>
       <origin rpy="0 0 0" xyz="0 0.4233952127414039 0.6815384931552602" />
     <axis xyz="1 0 0"/>
       <limit effort="0.0" lower="-3.14159" upper="3.14159" velocity="0.0"/>
    </joint>
    <link name="1">
        <inertial>
            <origin xyz="0 0.21255926976574246 0.0" rpy="0 0 0"/>
            <mass value="1" />
            <inertia ixx="100" ixy="0" ixz="0" iyy="100" iyz="0" izz="100" />
        </inertial>
        <visual>
            <origin xyz="0 0.21255926976574246 0.0" rpy="0 0 0"/>
            <geometry>
                <box size="0.9057561838022631 0.4251185395314848 0.14776203091849427" />
            </geometry>
            <material name="sensor">
                <color rgba="0 1 0 1"/>
            </material>
        </visual>
        <collision>
            <origin xyz="0 0.21255926976574246 0.0" rpy="0 0 0"/>
            <geometry>
                <box size="0.9057561838022631 0.4251185395314848 0.14776203091849427" />
            </geometry>
        </collision>
    </link>
    <joint name="1_2" type="revolute">
       <parent link="1"/>
       <child  link="2"/>
       <origin rpy="0 0 0" xyz="0 0.4251185395314848 0.0" />
     <axis xyz="0 0 1"/>
       <limit effort="0.0" lower="-3.14159" upper="3.14159" velocity="0.0"/>
    </joint>
    <link name="2">
        <inertial>
            <origin xyz="0 0.12650338713006604 0.0" rpy="0 0 0"/>
            <mass value="1" />
            <inertia ixx="100" ixy="0" ixz="0" iyy="100" iyz="0" izz="100" />
        </inertial>
        <visual>
            <origin xyz="0 0.12650338713006604 0.0" rpy="0 0 0"/>
            <geometry>
                <box size="0.656846568359728 0.25300677426013196 0.6939908911553815" />
            </geometry>
            <material name="not">
                <color rgba="0 1 1 1"/>
            </material>
        </visual>
        <collision>
            <origin xyz="0 0.12650338713006604 0.0" rpy="0 0 0"/>
            <geometry>
                <box size="0.656846568359728 0.25300677426013196 0.6939908911553815" />
            </geometry>
        </collision>
    </link>
    <joint name="2_8" type="revolute">
       <parent link="2"/>
       <child  link="8"/>
       <origin rpy="0 0 0" xyz="0 0.12650338713006604 0.3469954455776907" />
     <axis xyz="0 1 0"/>
       <limit effort="0.0" lower="-3.14159" upper="3.14159" velocity="0.0"/>
    </joint>
    <link name="8">
        <inertial>
            <origin xyz="0 0.0 0.03731211669691725" rpy="0 0 0"/>
            <mass value="1" />
            <inertia ixx="100" ixy="0" ixz="0" iyy="100" iyz="0" izz="100" />
        </inertial>
        <visual>
            <origin xyz="0 0.0 0.03731211669691725" rpy="0 0 0"/>
            <geometry>
                <box size="0.19828654265666856 0.6313637936191621 0.07462423339383462" />
            </geometry>
            <material name="sensor">
                <color rgba="0 1 0 1"/>
            </material>
        </visual>
        <collision>
            <origin xyz="0 0.0 0.03731211669691725" rpy="0 0 0"/>
            <geometry>
                <box size="0.19828654265666856 0.6313637936191621 0.07462423339383462" />
            </geometry>
        </collision>
    </link>
    <joint name="2_7" type="revolute">
       <parent link="2"/>
       <child  link="7"/>
       <origin rpy="0 0 0" xyz="0 0.12650338713006604 -0.34699544557769074" />
     <axis xyz="0 1 0"/>
       <limit effort="0.0" lower="-3.14159" upper="3.14159" velocity="0.0"/>
    </joint>
    <link name="7">
        <inertial>
            <origin xyz="0 0.0 -0.13329802852907618" rpy="0 0 0"/>
            <mass value="1" />
            <inertia ixx="100" ixy="0" ixz="0" iyy="100" iyz="0" izz="100" />
        </inertial>
        <visual>
            <origin xyz="0 0.0 -0.13329802852907618" rpy="0 0 0"/>
            <geometry>
                <box size="0.687605247858229 0.5633245764250986 0.26659605705815237" />
            </geometry>
            <material name="sensor">
                <color rgba="0 1 0 1"/>
            </material>
        </visual>
        <collision>
            <origin xyz="0 0.0 -0.13329802852907618" rpy="0 0 0"/>
            <geometry>
                <box size="0.687605247858229 0.5633245764250986 0.26659605705815237" />
            </geometry>
        </collision>
    </link>
    <joint name="1_3" type="revolute">
       <parent link="1"/>
       <child  link="3"/>
       <origin rpy="0 0 0" xyz="-0.45287809190113154 0.21255926976574246 0.0" />
     <axis xyz="0 1 0"/>
       <limit effort="0.0" lower="-3.14159" upper="3.14159" velocity="0.0"/>
    </joint>
    <link name="3">
        <inertial>
            <origin xyz="-0.19843833456707322 0.0 0.0" rpy="0 0 0"/>
            <mass value="1" />
            <inertia ixx="100" ixy="0" ixz="0" iyy="100" iyz="0" izz="100" />
        </inertial>
        <visual>
            <origin xyz="-0.19843833456707322 0.0 0.0" rpy="0 0 0"/>
            <geometry>
                <box size="0.39687666913414643 0.6930824019706248 0.26311347117835093" />
            </geometry>
            <material name="sensor">
                <color rgba="0 1 0 1"/>
            </material>
        </visual>
        <collision>
            <origin xyz="-0.19843833456707322 0.0 0.0" rpy="0 0 0"/>
            <geometry>
                <box size="0.39687666913414643 0.6930824019706248 0.26311347117835093" />
            </geometry>
        </collision>
    </link>
    <joint name="3_6" type="revolute">
       <parent link="3"/>
       <child  link="6"/>
       <origin rpy="0 0 0" xyz="-0.3968766691341465 0.0 0.0" />
     <axis xyz="0 0 1"/>
       <limit effort="0.0" lower="-3.14159" upper="3.14159" velocity="0.0"/>
    </joint>
    <link name="6">
        <inertial>
            <origin xyz="-0.2776339212057817 0.0 0.0" rpy="0 0 0"/>
            <mass value="1" />
            <inertia ixx="100" ixy="0" ixz="0" iyy="100" iyz="0" izz="100" />
        </inertial>
        <visual>
            <origin xyz="-0.2776339212057817 0.0 0.0" rpy="0 0 0"/>
            <geometry>
                <box size="0.5552678424115635 0.9419376121525266 0.42565227838371056" />
            </geometry>
            <material name="not">
                <color rgba="0 1 1 1"/>
            </material>
        </visual>
        <collision>
            <origin xyz="-0.2776339212057817 0.0 0.0" rpy="0 0 0"/>
            <geometry>
                <box size="0.5552678424115635 0.9419376121525266 0.42565227838371056" />
            </geometry>
        </collision>
    </link>
    <joint name="6_9" type="revolute">
       <parent link="6"/>
       <child  link="9"/>
       <origin rpy="0 0 0" xyz="-0.5552678424115634 0.0 0.0" />
     <axis xyz="1 0 0"/>
       <limit effort="0.0" lower="-3.14159" upper="3.14159" velocity="0.0"/>
    </joint>
    <link name="9">
        <inertial>
            <origin xyz="-0.29220390603868407 0.0 0.0" rpy="0 0 0"/>
            <mass value="1" />
            <inertia ixx="100" ixy="0" ixz="0" iyy="100" iyz="0" izz="100" />
        </inertial>
        <visual>
            <origin xyz="-0.29220390603868407 0.0 0.0" rpy="0 0 0"/>
            <geometry>
                <box size="0.5844078120773682 0.24625002503223037 0.8047106380834975" />
            </geometry>
            <material name="not">
                <color rgba="0 1 1 1"/>
            </material>
        </visual>
        <collision>
            <origin xyz="-0.29220390603868407 0.0 0.0" rpy="0 0 0"/>
            <geometry>
                <box size="0.5844078120773682 0.24625002503223037 0.8047106380834975" />
            </geometry>
        </collision>
    </link>
</robot>