<robot name = "robot">
    <link name="0">
        <inertial>
            <origin xyz="0 0 0.7827003757293756" rpy="0 0 0"/>
            <mass value="1" />
            <inertia ixx="100" ixy="0" ixz="0" iyy="100" iyz="0" izz="100" />
        </inertial>
        <visual>
            <origin xyz="0 0 0.7827003757293756" rpy="0 0 0"/>
            <geometry>
                <box size="0.2008530114407594 0.3277407050962675 0.9870497179280261" />
            </geometry>
            <material name="sensor">
                <color rgba="0 1 0 1"/>
            </material>
        </visual>
        <collision>
            <origin xyz="0 0 0.7827003757293756" rpy="0 0 0"/>
            <geometry>
                <box size="0.2008530114407594 0.3277407050962675 0.9870497179280261" />
            </geometry>
        </collision>
    </link>
    <joint name="0_3" type="revolute">
       <parent link="0"/>
       <child  link="3"/>
       <origin rpy="0 0 0" xyz="0 0 1.2762252346933887" />
     <axis xyz="0 1 0"/>
       <limit effort="0.0" lower="-3.14159" upper="3.14159" velocity="0.0"/>
    </joint>
    <link name="3">
        <inertial>
            <origin xyz="0 0 0.1064840974957122" rpy="0 0 0"/>
            <mass value="1" />
            <inertia ixx="100" ixy="0" ixz="0" iyy="100" iyz="0" izz="100" />
        </inertial>
        <visual>
            <origin xyz="0 0 0.1064840974957122" rpy="0 0 0"/>
            <geometry>
                <box size="0.16969414179438758 0.9109877835080679 0.21296819499142416" />
            </geometry>
            <material name="sensor">
                <color rgba="0 1 0 1"/>
            </material>
        </visual>
        <collision>
            <origin xyz="0 0 0.1064840974957122" rpy="0 0 0"/>
            <geometry>
                <box size="0.16969414179438758 0.9109877835080679 0.21296819499142416" />
            </geometry>
        </collision>
    </link>
    <joint name="0_1" type="revolute">
       <parent link="0"/>
       <child  link="1"/>
       <origin rpy="0 0 0" xyz="0 -0.16387035254813376 0.7827003757293756" />
     <axis xyz="1 0 0"/>
       <limit effort="0.0" lower="-3.14159" upper="3.14159" velocity="0.0"/>
    </joint>
    <link name="1">
        <inertial>
            <origin xyz="0 -0.048202551296729845 0.0" rpy="0 0 0"/>
            <mass value="1" />
            <inertia ixx="100" ixy="0" ixz="0" iyy="100" iyz="0" izz="100" />
        </inertial>
        <visual>
            <origin xyz="0 -0.048202551296729845 0.0" rpy="0 0 0"/>
            <geometry>
                <box size="0.2665354510728647 0.09640510259345969 0.37923370996257266" />
            </geometry>
            <material name="sensor">
                <color rgba="0 1 0 1"/>
            </material>
        </visual>
        <collision>
            <origin xyz="0 -0.048202551296729845 0.0" rpy="0 0 0"/>
            <geometry>
                <box size="0.2665354510728647 0.09640510259345969 0.37923370996257266" />
            </geometry>
        </collision>
    </link>
    <joint name="1_2" type="revolute">
       <parent link="1"/>
       <child  link="2"/>
       <origin rpy="0 0 0" xyz="0.13326772553643235 -0.048202551296729845 0.0" />
     <axis xyz="1 0 0"/>
       <limit effort="0.0" lower="-3.14159" upper="3.14159" velocity="0.0"/>
    </joint>
    <link name="2">
        <inertial>
            <origin xyz="0.3839755914565482 0.0 0.0" rpy="0 0 0"/>
            <mass value="1" />
            <inertia ixx="100" ixy="0" ixz="0" iyy="100" iyz="0" izz="100" />
        </inertial>
        <visual>
            <origin xyz="0.3839755914565482 0.0 0.0" rpy="0 0 0"/>
            <geometry>
                <box size="0.7679511829130964 0.5325204151469501 0.06532276962299033" />
            </geometry>
            <material name="not">
                <color rgba="0 1 1 1"/>
            </material>
        </visual>
        <collision>
            <origin xyz="0.3839755914565482 0.0 0.0" rpy="0 0 0"/>
            <geometry>
                <box size="0.7679511829130964 0.5325204151469501 0.06532276962299033" />
            </geometry>
        </collision>
    </link>
    <joint name="2_4" type="revolute">
       <parent link="2"/>
       <child  link="4"/>
       <origin rpy="0 0 0" xyz="0.3839755914565482 -0.26626020757347507 0.0" />
     <axis xyz="1 0 0"/>
       <limit effort="0.0" lower="-3.14159" upper="3.14159" velocity="0.0"/>
    </joint>
    <link name="4">
        <inertial>
            <origin xyz="0.0 -0.056956456196365135 0.0" rpy="0 0 0"/>
            <mass value="1" />
            <inertia ixx="100" ixy="0" ixz="0" iyy="100" iyz="0" izz="100" />
        </inertial>
        <visual>
            <origin xyz="0.0 -0.056956456196365135 0.0" rpy="0 0 0"/>
            <geometry>
                <box size="0.33885158106897195 0.11391291239273016 0.2351895113842175" />
            </geometry>
            <material name="sensor">
                <color rgba="0 1 0 1"/>
            </material>
        </visual>
        <collision>
            <origin xyz="0.0 -0.056956456196365135 0.0" rpy="0 0 0"/>
            <geometry>
                <box size="0.33885158106897195 0.11391291239273016 0.2351895113842175" />
            </geometry>
        </collision>
    </link>
    <joint name="1_5" type="revolute">
       <parent link="1"/>
       <child  link="5"/>
       <origin rpy="0 0 0" xyz="-0.13326772553643235 -0.048202551296729845 0.0" />
     <axis xyz="0 1 0"/>
       <limit effort="0.0" lower="-3.14159" upper="3.14159" velocity="0.0"/>
    </joint>
    <link name="5">
        <inertial>
            <origin xyz="-0.013631273100175478 0.0 0.0" rpy="0 0 0"/>
            <mass value="1" />
            <inertia ixx="100" ixy="0" ixz="0" iyy="100" iyz="0" izz="100" />
        </inertial>
        <visual>
            <origin xyz="-0.013631273100175478 0.0 0.0" rpy="0 0 0"/>
            <geometry>
                <box size="0.027262546200350957 0.7868599517835946 0.9256036750640709" />
            </geometry>
            <material name="sensor">
                <color rgba="0 1 0 1"/>
            </material>
        </visual>
        <collision>
            <origin xyz="-0.013631273100175478 0.0 0.0" rpy="0 0 0"/>
            <geometry>
                <box size="0.027262546200350957 0.7868599517835946 0.9256036750640709" />
            </geometry>
        </collision>
    </link>
</robot>