<robot name = "robot">
    <link name="0">
        <inertial>
            <origin xyz="0 0 0.8509740594889026" rpy="0 0 0"/>
            <mass value="1" />
            <inertia ixx="100" ixy="0" ixz="0" iyy="100" iyz="0" izz="100" />
        </inertial>
        <visual>
            <origin xyz="0 0 0.8509740594889026" rpy="0 0 0"/>
            <geometry>
                <box size="0.8348138080422707 0.614069004388466 0.7160113521541058" />
            </geometry>
            <material name="not">
                <color rgba="0 1 1 1"/>
            </material>
        </visual>
        <collision>
            <origin xyz="0 0 0.8509740594889026" rpy="0 0 0"/>
            <geometry>
                <box size="0.8348138080422707 0.614069004388466 0.7160113521541058" />
            </geometry>
        </collision>
    </link>
    <joint name="0_1" type="revolute">
       <parent link="0"/>
       <child  link="1"/>
       <origin rpy="0 0 0" xyz="0 0 1.2089797355659555" />
     <axis xyz="0 0 1"/>
       <limit effort="0.0" lower="-3.14159" upper="3.14159" velocity="0.0"/>
    </joint>
    <link name="1">
        <inertial>
            <origin xyz="0 0 0.03303568697139103" rpy="0 0 0"/>
            <mass value="1" />
            <inertia ixx="100" ixy="0" ixz="0" iyy="100" iyz="0" izz="100" />
        </inertial>
        <visual>
            <origin xyz="0 0 0.03303568697139103" rpy="0 0 0"/>
            <geometry>
                <box size="0.9895225651741276 0.20132486498602142 0.06607137394278217" />
            </geometry>
            <material name="not">
                <color rgba="0 1 1 1"/>
            </material>
        </visual>
        <collision>
            <origin xyz="0 0 0.03303568697139103" rpy="0 0 0"/>
            <geometry>
                <box size="0.9895225651741276 0.20132486498602142 0.06607137394278217" />
            </geometry>
        </collision>
    </link>
    <joint name="0_2" type="revolute">
       <parent link="0"/>
       <child  link="2"/>
       <origin rpy="0 0 0" xyz="0 0 0.4929683834118497" />
     <axis xyz="0 0 1"/>
       <limit effort="0.0" lower="-3.14159" upper="3.14159" velocity="0.0"/>
    </joint>
    <link name="2">
        <inertial>
            <origin xyz="0 0 -0.08608266793262764" rpy="0 0 0"/>
            <mass value="1" />
            <inertia ixx="100" ixy="0" ixz="0" iyy="100" iyz="0" izz="100" />
        </inertial>
        <visual>
            <origin xyz="0 0 -0.08608266793262764" rpy="0 0 0"/>
            <geometry>
                <box size="0.5340878916483589 0.887608983287202 0.1721653358652553" />
            </geometry>
            <material name="not">
                <color rgba="0 1 1 1"/>
            </material>
        </visual>
        <collision>
            <origin xyz="0 0 -0.08608266793262764" rpy="0 0 0"/>
            <geometry>
                <box size="0.5340878916483589 0.887608983287202 0.1721653358652553" />
            </geometry>
        </collision>
    </link>
</robot>