<robot name = "robot">
    <link name="0">
        <inertial>
            <origin xyz="0 0 0.764800547770313" rpy="0 0 0"/>
            <mass value="1" />
            <inertia ixx="100" ixy="0" ixz="0" iyy="100" iyz="0" izz="100" />
        </inertial>
        <visual>
            <origin xyz="0 0 0.764800547770313" rpy="0 0 0"/>
            <geometry>
                <box size="0.9414905594691287 0.7217352889552988 0.6473481196650006" />
            </geometry>
            <material name="sensor">
                <color rgba="0 1 0 1"/>
            </material>
        </visual>
        <collision>
            <origin xyz="0 0 0.764800547770313" rpy="0 0 0"/>
            <geometry>
                <box size="0.9414905594691287 0.7217352889552988 0.6473481196650006" />
            </geometry>
        </collision>
    </link>
    <joint name="0_1" type="revolute">
       <parent link="0"/>
       <child  link="1"/>
       <origin rpy="0 0 0" xyz="0.47074527973456437 0 0.764800547770313" />
     <axis xyz="0 0 1"/>
       <limit effort="0.0" lower="-3.14159" upper="3.14159" velocity="0.0"/>
    </joint>
    <link name="1">
        <inertial>
            <origin xyz="0.000683019989351219 0 0.0" rpy="0 0 0"/>
            <mass value="1" />
            <inertia ixx="100" ixy="0" ixz="0" iyy="100" iyz="0" izz="100" />
        </inertial>
        <visual>
            <origin xyz="0.000683019989351219 0 0.0" rpy="0 0 0"/>
            <geometry>
                <box size="0.001366039978702438 0.12565177107287062 0.5693822869652517" />
            </geometry>
            <material name="sensor">
                <color rgba="0 1 0 1"/>
            </material>
        </visual>
        <collision>
            <origin xyz="0.000683019989351219 0 0.0" rpy="0 0 0"/>
            <geometry>
                <box size="0.001366039978702438 0.12565177107287062 0.5693822869652517" />
            </geometry>
        </collision>
    </link>
    <joint name="0_3" type="revolute">
       <parent link="0"/>
       <child  link="3"/>
       <origin rpy="0 0 0" xyz="0 0 1.0884746076028133" />
     <axis xyz="0 1 0"/>
       <limit effort="0.0" lower="-3.14159" upper="3.14159" velocity="0.0"/>
    </joint>
    <link name="3">
        <inertial>
            <origin xyz="0 0 0.09585088263482588" rpy="0 0 0"/>
            <mass value="1" />
            <inertia ixx="100" ixy="0" ixz="0" iyy="100" iyz="0" izz="100" />
        </inertial>
        <visual>
            <origin xyz="0 0 0.09585088263482588" rpy="0 0 0"/>
            <geometry>
                <box size="0.3003492841455092 0.9435404582537038 0.19170176526965155" />
            </geometry>
            <material name="not">
                <color rgba="0 1 1 1"/>
            </material>
        </visual>
        <collision>
            <origin xyz="0 0 0.09585088263482588" rpy="0 0 0"/>
            <geometry>
                <box size="0.3003492841455092 0.9435404582537038 0.19170176526965155" />
            </geometry>
        </collision>
    </link>
    <joint name="3_5" type="revolute">
       <parent link="3"/>
       <child  link="5"/>
       <origin rpy="0 0 0" xyz="0 0 0.19170176526965155" />
     <axis xyz="1 0 0"/>
       <limit effort="0.0" lower="-3.14159" upper="3.14159" velocity="0.0"/>
    </joint>
    <link name="5">
        <inertial>
            <origin xyz="0 0 0.21258330097635159" rpy="0 0 0"/>
            <mass value="1" />
            <inertia ixx="100" ixy="0" ixz="0" iyy="100" iyz="0" izz="100" />
        </inertial>
        <visual>
            <origin xyz="0 0 0.21258330097635159" rpy="0 0 0"/>
            <geometry>
                <box size="0.4033962123128759 0.3540918509218929 0.42516660195270317" />
            </geometry>
            <material name="sensor">
                <color rgba="0 1 0 1"/>
            </material>
        </visual>
        <collision>
            <origin xyz="0 0 0.21258330097635159" rpy="0 0 0"/>
            <geometry>
                <box size="0.4033962123128759 0.3540918509218929 0.42516660195270317" />
            </geometry>
        </collision>
    </link>
    <joint name="0_4" type="revolute">
       <parent link="0"/>
       <child  link="4"/>
       <origin rpy="0 0 0" xyz="0 0 0.44112648793781273" />
     <axis xyz="1 0 0"/>
       <limit effort="0.0" lower="-3.14159" upper="3.14159" velocity="0.0"/>
    </joint>
    <link name="4">
        <inertial>
            <origin xyz="0 0 -0.10198821872425734" rpy="0 0 0"/>
            <mass value="1" />
            <inertia ixx="100" ixy="0" ixz="0" iyy="100" iyz="0" izz="100" />
        </inertial>
        <visual>
            <origin xyz="0 0 -0.10198821872425734" rpy="0 0 0"/>
            <geometry>
                <box size="0.36870855346334397 0.14136948469405264 0.20397643744851468" />
            </geometry>
            <material name="not">
                <color rgba="0 1 1 1"/>
            </material>
        </visual>
        <collision>
            <origin xyz="0 0 -0.10198821872425734" rpy="0 0 0"/>
            <geometry>
                <box size="0.36870855346334397 0.14136948469405264 0.20397643744851468" />
            </geometry>
        </collision>
    </link>
</robot>