<robot name = "robot">
    <link name="0">
        <inertial>
            <origin xyz="0 0 0.9447489551908349" rpy="0 0 0"/>
            <mass value="1" />
            <inertia ixx="100" ixy="0" ixz="0" iyy="100" iyz="0" izz="100" />
        </inertial>
        <visual>
            <origin xyz="0 0 0.9447489551908349" rpy="0 0 0"/>
            <geometry>
                <box size="0.39407479041856797 0.0349504714380412 0.37148578842434565" />
            </geometry>
            <material name="sensor">
                <color rgba="0 1 0 1"/>
            </material>
        </visual>
        <collision>
            <origin xyz="0 0 0.9447489551908349" rpy="0 0 0"/>
            <geometry>
                <box size="0.39407479041856797 0.0349504714380412 0.37148578842434565" />
            </geometry>
        </collision>
    </link>
    <joint name="0_1" type="revolute">
       <parent link="0"/>
       <child  link="1"/>
       <origin rpy="0 0 0" xyz="0.19703739520928398 0 0.9447489551908349" />
     <axis xyz="0 1 0"/>
       <limit effort="0.0" lower="-3.14159" upper="3.14159" velocity="0.0"/>
    </joint>
    <link name="1">
        <inertial>
            <origin xyz="0.31071487438904366 0 0.0" rpy="0 0 0"/>
            <mass value="1" />
            <inertia ixx="100" ixy="0" ixz="0" iyy="100" iyz="0" izz="100" />
        </inertial>
        <visual>
            <origin xyz="0.31071487438904366 0 0.0" rpy="0 0 0"/>
            <geometry>
                <box size="0.6214297487780872 0.14322651796238706 0.6883990691190471" />
            </geometry>
            <material name="not">
                <color rgba="0 1 1 1"/>
            </material>
        </visual>
        <collision>
            <origin xyz="0.31071487438904366 0 0.0" rpy="0 0 0"/>
            <geometry>
                <box size="0.6214297487780872 0.14322651796238706 0.6883990691190471" />
            </geometry>
        </collision>
    </link>
    <joint name="1_2" type="revolute">
       <parent link="1"/>
       <child  link="2"/>
       <origin rpy="0 0 0" xyz="0.6214297487780872 0 0.0" />
     <axis xyz="0 0 1"/>
       <limit effort="0.0" lower="-3.14159" upper="3.14159" velocity="0.0"/>
    </joint>
    <link name="2">
        <inertial>
            <origin xyz="0.18635869398369453 0 0.0" rpy="0 0 0"/>
            <mass value="1" />
            <inertia ixx="100" ixy="0" ixz="0" iyy="100" iyz="0" izz="100" />
        </inertial>
        <visual>
            <origin xyz="0.18635869398369453 0 0.0" rpy="0 0 0"/>
            <geometry>
                <box size="0.37271738796738896 0.5023680108756032 0.9878905087802153" />
            </geometry>
            <material name="sensor">
                <color rgba="0 1 0 1"/>
            </material>
        </visual>
        <collision>
            <origin xyz="0.18635869398369453 0 0.0" rpy="0 0 0"/>
            <geometry>
                <box size="0.37271738796738896 0.5023680108756032 0.9878905087802153" />
            </geometry>
        </collision>
    </link>
    <joint name="1_3" type="revolute">
       <parent link="1"/>
       <child  link="3"/>
       <origin rpy="0 0 0" xyz="0.31071487438904366 0.07161325898119353 0.0" />
     <axis xyz="0 1 0"/>
       <limit effort="0.0" lower="-3.14159" upper="3.14159" velocity="0.0"/>
    </joint>
    <link name="3">
        <inertial>
            <origin xyz="0.0 0.15989698711857386 0.0" rpy="0 0 0"/>
            <mass value="1" />
            <inertia ixx="100" ixy="0" ixz="0" iyy="100" iyz="0" izz="100" />
        </inertial>
        <visual>
            <origin xyz="0.0 0.15989698711857386 0.0" rpy="0 0 0"/>
            <geometry>
                <box size="0.10627786030439812 0.3197939742371477 0.1021265646566466" />
            </geometry>
            <material name="not">
                <color rgba="0 1 1 1"/>
            </material>
        </visual>
        <collision>
            <origin xyz="0.0 0.15989698711857386 0.0" rpy="0 0 0"/>
            <geometry>
                <box size="0.10627786030439812 0.3197939742371477 0.1021265646566466" />
            </geometry>
        </collision>
    </link>
    <joint name="3_5" type="revolute">
       <parent link="3"/>
       <child  link="5"/>
       <origin rpy="0 0 0" xyz="0.0 0.3197939742371477 0.0" />
     <axis xyz="1 0 0"/>
       <limit effort="0.0" lower="-3.14159" upper="3.14159" velocity="0.0"/>
    </joint>
    <link name="5">
        <inertial>
            <origin xyz="0.0 0.2616442915400099 0.0" rpy="0 0 0"/>
            <mass value="1" />
            <inertia ixx="100" ixy="0" ixz="0" iyy="100" iyz="0" izz="100" />
        </inertial>
        <visual>
            <origin xyz="0.0 0.2616442915400099 0.0" rpy="0 0 0"/>
            <geometry>
                <box size="0.20319827308229033 0.5232885830800198 0.5900872511695072" />
            </geometry>
            <material name="not">
                <color rgba="0 1 1 1"/>
            </material>
        </visual>
        <collision>
            <origin xyz="0.0 0.2616442915400099 0.0" rpy="0 0 0"/>
            <geometry>
                <box size="0.20319827308229033 0.5232885830800198 0.5900872511695072" />
            </geometry>
        </collision>
    </link>
    <joint name="3_4" type="revolute">
       <parent link="3"/>
       <child  link="4"/>
       <origin rpy="0 0 0" xyz="0.0 0.15989698711857386 0.051063282328323356" />
     <axis xyz="1 0 0"/>
       <limit effort="0.0" lower="-3.14159" upper="3.14159" velocity="0.0"/>
    </joint>
    <link name="4">
        <inertial>
            <origin xyz="0.0 0.0 0.06974653768179673" rpy="0 0 0"/>
            <mass value="1" />
            <inertia ixx="100" ixy="0" ixz="0" iyy="100" iyz="0" izz="100" />
        </inertial>
        <visual>
            <origin xyz="0.0 0.0 0.06974653768179673" rpy="0 0 0"/>
            <geometry>
                <box size="0.4759980332962953 0.1731271095702982 0.13949307536359346" />
            </geometry>
            <material name="not">
                <color rgba="0 1 1 1"/>
            </material>
        </visual>
        <collision>
            <origin xyz="0.0 0.0 0.06974653768179673" rpy="0 0 0"/>
            <geometry>
                <box size="0.4759980332962953 0.1731271095702982 0.13949307536359346" />
            </geometry>
        </collision>
    </link>
    <joint name="0_6" type="revolute">
       <parent link="0"/>
       <child  link="6"/>
       <origin rpy="0 0 0" xyz="0 0.0174752357190206 0.9447489551908349" />
     <axis xyz="1 0 0"/>
       <limit effort="0.0" lower="-3.14159" upper="3.14159" velocity="0.0"/>
    </joint>
    <link name="6">
        <inertial>
            <origin xyz="0 0.44082825556085853 0.0" rpy="0 0 0"/>
            <mass value="1" />
            <inertia ixx="100" ixy="0" ixz="0" iyy="100" iyz="0" izz="100" />
        </inertial>
        <visual>
            <origin xyz="0 0.44082825556085853 0.0" rpy="0 0 0"/>
            <geometry>
                <box size="0.25341974159875236 0.8816565111217171 0.1973032799071317" />
            </geometry>
            <material name="not">
                <color rgba="0 1 1 1"/>
            </material>
        </visual>
        <collision>
            <origin xyz="0 0.44082825556085853 0.0" rpy="0 0 0"/>
            <geometry>
                <box size="0.25341974159875236 0.8816565111217171 0.1973032799071317" />
            </geometry>
        </collision>
    </link>
    <joint name="0_8" type="revolute">
       <parent link="0"/>
       <child  link="8"/>
       <origin rpy="0 0 0" xyz="0 0 1.1304918494030076" />
     <axis xyz="0 1 0"/>
       <limit effort="0.0" lower="-3.14159" upper="3.14159" velocity="0.0"/>
    </joint>
    <link name="8">
        <inertial>
            <origin xyz="0 0 0.15837068429086054" rpy="0 0 0"/>
            <mass value="1" />
            <inertia ixx="100" ixy="0" ixz="0" iyy="100" iyz="0" izz="100" />
        </inertial>
        <visual>
            <origin xyz="0 0 0.15837068429086054" rpy="0 0 0"/>
            <geometry>
                <box size="0.04419392952735568 0.21341103560529306 0.3167413685817212" />
            </geometry>
            <material name="sensor">
                <color rgba="0 1 0 1"/>
            </material>
        </visual>
        <collision>
            <origin xyz="0 0 0.15837068429086054" rpy="0 0 0"/>
            <geometry>
                <box size="0.04419392952735568 0.21341103560529306 0.3167413685817212" />
            </geometry>
        </collision>
    </link>
    <joint name="0_7" type="revolute">
       <parent link="0"/>
       <child  link="7"/>
       <origin rpy="0 0 0" xyz="-0.19703739520928398 0 0.9447489551908349" />
     <axis xyz="0 0 1"/>
       <limit effort="0.0" lower="-3.14159" upper="3.14159" velocity="0.0"/>
    </joint>
    <link name="7">
        <inertial>
            <origin xyz="-0.36803933239212283 0 0.0" rpy="0 0 0"/>
            <mass value="1" />
            <inertia ixx="100" ixy="0" ixz="0" iyy="100" iyz="0" izz="100" />
        </inertial>
        <visual>
            <origin xyz="-0.36803933239212283 0 0.0" rpy="0 0 0"/>
            <geometry>
                <box size="0.7360786647842457 0.7376042837511602 0.5758969433785145" />
            </geometry>
            <material name="sensor">
                <color rgba="0 1 0 1"/>
            </material>
        </visual>
        <collision>
            <origin xyz="-0.36803933239212283 0 0.0" rpy="0 0 0"/>
            <geometry>
                <box size="0.7360786647842457 0.7376042837511602 0.5758969433785145" />
            </geometry>
        </collision>
    </link>
</robot>