<robot name = "robot">
    <link name="0">
        <inertial>
            <origin xyz="0 0 0.3004039733655893" rpy="0 0 0"/>
            <mass value="1" />
            <inertia ixx="100" ixy="0" ixz="0" iyy="100" iyz="0" izz="100" />
        </inertial>
        <visual>
            <origin xyz="0 0 0.3004039733655893" rpy="0 0 0"/>
            <geometry>
                <box size="0.3126706611969108 0.36915397527695404 0.5956215058575365" />
            </geometry>
            <material name="sensor">
                <color rgba="0 1 0 1"/>
            </material>
        </visual>
        <collision>
            <origin xyz="0 0 0.3004039733655893" rpy="0 0 0"/>
            <geometry>
                <box size="0.3126706611969108 0.36915397527695404 0.5956215058575365" />
            </geometry>
        </collision>
    </link>
    <joint name="0_1" type="revolute">
       <parent link="0"/>
       <child  link="1"/>
       <origin rpy="0 0 0" xyz="0 -0.18457698763847702 0.3004039733655893" />
     <axis xyz="0 1 0"/>
       <limit effort="0.0" lower="-3.14159" upper="3.14159" velocity="0.0"/>
    </joint>
    <link name="1">
        <inertial>
            <origin xyz="0 -0.3418664251833155 0.0" rpy="0 0 0"/>
            <mass value="1" />
            <inertia ixx="100" ixy="0" ixz="0" iyy="100" iyz="0" izz="100" />
        </inertial>
        <visual>
            <origin xyz="0 -0.3418664251833155 0.0" rpy="0 0 0"/>
            <geometry>
                <box size="0.9713745010588913 0.683732850366631 0.13142077855778256" />
            </geometry>
            <material name="not">
                <color rgba="0 1 1 1"/>
            </material>
        </visual>
        <collision>
            <origin xyz="0 -0.3418664251833155 0.0" rpy="0 0 0"/>
            <geometry>
                <box size="0.9713745010588913 0.683732850366631 0.13142077855778256" />
            </geometry>
        </collision>
    </link>
    <joint name="1_2" type="revolute">
       <parent link="1"/>
       <child  link="2"/>
       <origin rpy="0 0 0" xyz="-0.48568725052944567 -0.3418664251833155 0.0" />
     <axis xyz="0 1 0"/>
       <limit effort="0.0" lower="-3.14159" upper="3.14159" velocity="0.0"/>
    </joint>
    <link name="2">
        <inertial>
            <origin xyz="-0.11934758844892096 0.0 0.0" rpy="0 0 0"/>
            <mass value="1" />
            <inertia ixx="100" ixy="0" ixz="0" iyy="100" iyz="0" izz="100" />
        </inertial>
        <visual>
            <origin xyz="-0.11934758844892096 0.0 0.0" rpy="0 0 0"/>
            <geometry>
                <box size="0.23869517689784192 0.18739434091794194 0.43523432053282096" />
            </geometry>
            <material name="not">
                <color rgba="0 1 1 1"/>
            </material>
        </visual>
        <collision>
            <origin xyz="-0.11934758844892096 0.0 0.0" rpy="0 0 0"/>
            <geometry>
                <box size="0.23869517689784192 0.18739434091794194 0.43523432053282096" />
            </geometry>
        </collision>
    </link>
</robot>