<robot name = "robot">
    <link name="0">
        <inertial>
            <origin xyz="0 0 0.9152348453283954" rpy="0 0 0"/>
            <mass value="1" />
            <inertia ixx="100" ixy="0" ixz="0" iyy="100" iyz="0" izz="100" />
        </inertial>
        <visual>
            <origin xyz="0 0 0.9152348453283954" rpy="0 0 0"/>
            <geometry>
                <box size="0.818429186133668 0.5623720122394997 0.7843374049030998" />
            </geometry>
            <material name="sensor">
                <color rgba="0 1 0 1"/>
            </material>
        </visual>
        <collision>
            <origin xyz="0 0 0.9152348453283954" rpy="0 0 0"/>
            <geometry>
                <box size="0.818429186133668 0.5623720122394997 0.7843374049030998" />
            </geometry>
        </collision>
    </link>
    <joint name="0_2" type="revolute">
       <parent link="0"/>
       <child  link="2"/>
       <origin rpy="0 0 0" xyz="0.409214593066834 0 0.9152348453283954" />
     <axis xyz="0 1 0"/>
       <limit effort="0.0" lower="-3.14159" upper="3.14159" velocity="0.0"/>
    </joint>
    <link name="2">
        <inertial>
            <origin xyz="0.18128484144691343 0 0.0" rpy="0 0 0"/>
            <mass value="1" />
            <inertia ixx="100" ixy="0" ixz="0" iyy="100" iyz="0" izz="100" />
        </inertial>
        <visual>
            <origin xyz="0.18128484144691343 0 0.0" rpy="0 0 0"/>
            <geometry>
                <box size="0.36256968289382685 0.7675794875552631 0.522986292131511" />
            </geometry>
            <material name="sensor">
                <color rgba="0 1 0 1"/>
            </material>
        </visual>
        <collision>
            <origin xyz="0.18128484144691343 0 0.0" rpy="0 0 0"/>
            <geometry>
                <box size="0.36256968289382685 0.7675794875552631 0.522986292131511" />
            </geometry>
        </collision>
    </link>
    <joint name="2_4" type="revolute">
       <parent link="2"/>
       <child  link="4"/>
       <origin rpy="0 0 0" xyz="0.3625696828938268 0 0.0" />
     <axis xyz="0 1 0"/>
       <limit effort="0.0" lower="-3.14159" upper="3.14159" velocity="0.0"/>
    </joint>
    <link name="4">
        <inertial>
            <origin xyz="0.17994862479274554 0 0.0" rpy="0 0 0"/>
            <mass value="1" />
            <inertia ixx="100" ixy="0" ixz="0" iyy="100" iyz="0" izz="100" />
        </inertial>
        <visual>
            <origin xyz="0.17994862479274554 0 0.0" rpy="0 0 0"/>
            <geometry>
                <box size="0.35989724958549096 0.2651023905073 0.7169313724960542" />
            </geometry>
            <material name="sensor">
                <color rgba="0 1 0 1"/>
            </material>
        </visual>
        <collision>
            <origin xyz="0.17994862479274554 0 0.0" rpy="0 0 0"/>
            <geometry>
                <box size="0.35989724958549096 0.2651023905073 0.7169313724960542" />
            </geometry>
        </collision>
    </link>
    <joint name="2_5" type="revolute">
       <parent link="2"/>
       <child  link="5"/>
       <origin rpy="0 0 0" xyz="0.18128484144691343 0.38378974377763153 0.0" />
     <axis xyz="0 0 1"/>
       <limit effort="0.0" lower="-3.14159" upper="3.14159" velocity="0.0"/>
    </joint>
    <link name="5">
        <inertial>
            <origin xyz="0.0 0.04308387770551064 0.0" rpy="0 0 0"/>
            <mass value="1" />
            <inertia ixx="100" ixy="0" ixz="0" iyy="100" iyz="0" izz="100" />
        </inertial>
        <visual>
            <origin xyz="0.0 0.04308387770551064 0.0" rpy="0 0 0"/>
            <geometry>
                <box size="0.7474773851283802 0.08616775541102129 0.5083888140094397" />
            </geometry>
            <material name="sensor">
                <color rgba="0 1 0 1"/>
            </material>
        </visual>
        <collision>
            <origin xyz="0.0 0.04308387770551064 0.0" rpy="0 0 0"/>
            <geometry>
                <box size="0.7474773851283802 0.08616775541102129 0.5083888140094397" />
            </geometry>
        </collision>
    </link>
    <joint name="0_1" type="revolute">
       <parent link="0"/>
       <child  link="1"/>
       <origin rpy="0 0 0" xyz="0 0 1.3074035477799453" />
     <axis xyz="1 0 0"/>
       <limit effort="0.0" lower="-3.14159" upper="3.14159" velocity="0.0"/>
    </joint>
    <link name="1">
        <inertial>
            <origin xyz="0 0 0.24441561311783744" rpy="0 0 0"/>
            <mass value="1" />
            <inertia ixx="100" ixy="0" ixz="0" iyy="100" iyz="0" izz="100" />
        </inertial>
        <visual>
            <origin xyz="0 0 0.24441561311783744" rpy="0 0 0"/>
            <geometry>
                <box size="0.03418314975073167 0.5944868409105872 0.48883122623567477" />
            </geometry>
            <material name="not">
                <color rgba="0 1 1 1"/>
            </material>
        </visual>
        <collision>
            <origin xyz="0 0 0.24441561311783744" rpy="0 0 0"/>
            <geometry>
                <box size="0.03418314975073167 0.5944868409105872 0.48883122623567477" />
            </geometry>
        </collision>
    </link>
    <joint name="1_6" type="revolute">
       <parent link="1"/>
       <child  link="6"/>
       <origin rpy="0 0 0" xyz="0 -0.2972434204552936 0.24441561311783744" />
     <axis xyz="0 0 1"/>
       <limit effort="0.0" lower="-3.14159" upper="3.14159" velocity="0.0"/>
    </joint>
    <link name="6">
        <inertial>
            <origin xyz="0 -0.4238662377612621 0.0" rpy="0 0 0"/>
            <mass value="1" />
            <inertia ixx="100" ixy="0" ixz="0" iyy="100" iyz="0" izz="100" />
        </inertial>
        <visual>
            <origin xyz="0 -0.4238662377612621 0.0" rpy="0 0 0"/>
            <geometry>
                <box size="0.5095376758071686 0.8477324755225242 0.3437272986547153" />
            </geometry>
            <material name="not">
                <color rgba="0 1 1 1"/>
            </material>
        </visual>
        <collision>
            <origin xyz="0 -0.4238662377612621 0.0" rpy="0 0 0"/>
            <geometry>
                <box size="0.5095376758071686 0.8477324755225242 0.3437272986547153" />
            </geometry>
        </collision>
    </link>
</robot>