<robot name = "robot">
    <link name="0">
        <inertial>
            <origin xyz="0 0 0.7159852928955259" rpy="0 0 0"/>
            <mass value="1" />
            <inertia ixx="100" ixy="0" ixz="0" iyy="100" iyz="0" izz="100" />
        </inertial>
        <visual>
            <origin xyz="0 0 0.7159852928955259" rpy="0 0 0"/>
            <geometry>
                <box size="0.8352324849790723 0.26485844529977043 0.9809566191649657" />
            </geometry>
            <material name="sensor">
                <color rgba="0 1 0 1"/>
            </material>
        </visual>
        <collision>
            <origin xyz="0 0 0.7159852928955259" rpy="0 0 0"/>
            <geometry>
                <box size="0.8352324849790723 0.26485844529977043 0.9809566191649657" />
            </geometry>
        </collision>
    </link>
    <joint name="0_1" type="revolute">
       <parent link="0"/>
       <child  link="1"/>
       <origin rpy="0 0 0" xyz="0 0 1.2064636024780087" />
     <axis xyz="0 0 1"/>
       <limit effort="0.0" lower="-3.14159" upper="3.14159" velocity="0.0"/>
    </joint>
    <link name="1">
        <inertial>
            <origin xyz="0 0 0.16295246657596119" rpy="0 0 0"/>
            <mass value="1" />
            <inertia ixx="100" ixy="0" ixz="0" iyy="100" iyz="0" izz="100" />
        </inertial>
        <visual>
            <origin xyz="0 0 0.16295246657596119" rpy="0 0 0"/>
            <geometry>
                <box size="0.47430384566628103 0.7737170178494772 0.3259049331519225" />
            </geometry>
            <material name="sensor">
                <color rgba="0 1 0 1"/>
            </material>
        </visual>
        <collision>
            <origin xyz="0 0 0.16295246657596119" rpy="0 0 0"/>
            <geometry>
                <box size="0.47430384566628103 0.7737170178494772 0.3259049331519225" />
            </geometry>
        </collision>
    </link>
    <joint name="1_2" type="revolute">
       <parent link="1"/>
       <child  link="2"/>
       <origin rpy="0 0 0" xyz="0 0 0.32590493315192237" />
     <axis xyz="0 1 0"/>
       <limit effort="0.0" lower="-3.14159" upper="3.14159" velocity="0.0"/>
    </joint>
    <link name="2">
        <inertial>
            <origin xyz="0 0 0.398812973337511" rpy="0 0 0"/>
            <mass value="1" />
            <inertia ixx="100" ixy="0" ixz="0" iyy="100" iyz="0" izz="100" />
        </inertial>
        <visual>
            <origin xyz="0 0 0.398812973337511" rpy="0 0 0"/>
            <geometry>
                <box size="0.8166796676840568 0.6474369441988925 0.7976259466750222" />
            </geometry>
            <material name="sensor">
                <color rgba="0 1 0 1"/>
            </material>
        </visual>
        <collision>
            <origin xyz="0 0 0.398812973337511" rpy="0 0 0"/>
            <geometry>
                <box size="0.8166796676840568 0.6474369441988925 0.7976259466750222" />
            </geometry>
        </collision>
    </link>
    <joint name="2_5" type="revolute">
       <parent link="2"/>
       <child  link="5"/>
       <origin rpy="0 0 0" xyz="0.4083398338420284 0 0.398812973337511" />
     <axis xyz="0 0 1"/>
       <limit effort="0.0" lower="-3.14159" upper="3.14159" velocity="0.0"/>
    </joint>
    <link name="5">
        <inertial>
            <origin xyz="0.16220679385516362 0 0.0" rpy="0 0 0"/>
            <mass value="1" />
            <inertia ixx="100" ixy="0" ixz="0" iyy="100" iyz="0" izz="100" />
        </inertial>
        <visual>
            <origin xyz="0.16220679385516362 0 0.0" rpy="0 0 0"/>
            <geometry>
                <box size="0.32441358771032713 0.2821173514287849 0.2172429867504383" />
            </geometry>
            <material name="not">
                <color rgba="0 1 1 1"/>
            </material>
        </visual>
        <collision>
            <origin xyz="0.16220679385516362 0 0.0" rpy="0 0 0"/>
            <geometry>
                <box size="0.32441358771032713 0.2821173514287849 0.2172429867504383" />
            </geometry>
        </collision>
    </link>
    <joint name="2_4" type="revolute">
       <parent link="2"/>
       <child  link="4"/>
       <origin rpy="0 0 0" xyz="0 0 0.797625946675022" />
     <axis xyz="1 0 0"/>
       <limit effort="0.0" lower="-3.14159" upper="3.14159" velocity="0.0"/>
    </joint>
    <link name="4">
        <inertial>
            <origin xyz="0 0 0.264670040384698" rpy="0 0 0"/>
            <mass value="1" />
            <inertia ixx="100" ixy="0" ixz="0" iyy="100" iyz="0" izz="100" />
        </inertial>
        <visual>
            <origin xyz="0 0 0.264670040384698" rpy="0 0 0"/>
            <geometry>
                <box size="0.9565164769764188 0.5181394304473564 0.529340080769396" />
            </geometry>
            <material name="not">
                <color rgba="0 1 1 1"/>
            </material>
        </visual>
        <collision>
            <origin xyz="0 0 0.264670040384698" rpy="0 0 0"/>
            <geometry>
                <box size="0.9565164769764188 0.5181394304473564 0.529340080769396" />
            </geometry>
        </collision>
    </link>
    <joint name="4_6" type="revolute">
       <parent link="4"/>
       <child  link="6"/>
       <origin rpy="0 0 0" xyz="0.4782582384882094 0 0.264670040384698" />
     <axis xyz="1 0 0"/>
       <limit effort="0.0" lower="-3.14159" upper="3.14159" velocity="0.0"/>
    </joint>
    <link name="6">
        <inertial>
            <origin xyz="0.03001702967246539 0 0.0" rpy="0 0 0"/>
            <mass value="1" />
            <inertia ixx="100" ixy="0" ixz="0" iyy="100" iyz="0" izz="100" />
        </inertial>
        <visual>
            <origin xyz="0.03001702967246539 0 0.0" rpy="0 0 0"/>
            <geometry>
                <box size="0.06003405934493067 0.11050945392030986 0.3625804565253964" />
            </geometry>
            <material name="sensor">
                <color rgba="0 1 0 1"/>
            </material>
        </visual>
        <collision>
            <origin xyz="0.03001702967246539 0 0.0" rpy="0 0 0"/>
            <geometry>
                <box size="0.06003405934493067 0.11050945392030986 0.3625804565253964" />
            </geometry>
        </collision>
    </link>
</robot>