<robot name = "robot">
    <link name="0">
        <inertial>
            <origin xyz="0 0 0.9495475342759118" rpy="0 0 0"/>
            <mass value="1" />
            <inertia ixx="100" ixy="0" ixz="0" iyy="100" iyz="0" izz="100" />
        </inertial>
        <visual>
            <origin xyz="0 0 0.9495475342759118" rpy="0 0 0"/>
            <geometry>
                <box size="0.8374483937438901 0.13052175184206272 0.014729286743825787" />
            </geometry>
            <material name="sensor">
                <color rgba="0 1 0 1"/>
            </material>
        </visual>
        <collision>
            <origin xyz="0 0 0.9495475342759118" rpy="0 0 0"/>
            <geometry>
                <box size="0.8374483937438901 0.13052175184206272 0.014729286743825787" />
            </geometry>
        </collision>
    </link>
    <joint name="0_2" type="revolute">
       <parent link="0"/>
       <child  link="2"/>
       <origin rpy="0 0 0" xyz="0.41872419687194506 0 0.9495475342759118" />
     <axis xyz="0 0 1"/>
       <limit effort="0.0" lower="-3.14159" upper="3.14159" velocity="0.0"/>
    </joint>
    <link name="2">
        <inertial>
            <origin xyz="0.050090344531854514 0 0.0" rpy="0 0 0"/>
            <mass value="1" />
            <inertia ixx="100" ixy="0" ixz="0" iyy="100" iyz="0" izz="100" />
        </inertial>
        <visual>
            <origin xyz="0.050090344531854514 0 0.0" rpy="0 0 0"/>
            <geometry>
                <box size="0.10018068906370903 0.8539381095973382 0.39669617733090445" />
            </geometry>
            <material name="not">
                <color rgba="0 1 1 1"/>
            </material>
        </visual>
        <collision>
            <origin xyz="0.050090344531854514 0 0.0" rpy="0 0 0"/>
            <geometry>
                <box size="0.10018068906370903 0.8539381095973382 0.39669617733090445" />
            </geometry>
        </collision>
    </link>
    <joint name="2_4" type="revolute">
       <parent link="2"/>
       <child  link="4"/>
       <origin rpy="0 0 0" xyz="0.050090344531854514 0 -0.19834808866545217" />
     <axis xyz="1 0 0"/>
       <limit effort="0.0" lower="-3.14159" upper="3.14159" velocity="0.0"/>
    </joint>
    <link name="4">
        <inertial>
            <origin xyz="0.0 0 -0.30379824957013823" rpy="0 0 0"/>
            <mass value="1" />
            <inertia ixx="100" ixy="0" ixz="0" iyy="100" iyz="0" izz="100" />
        </inertial>
        <visual>
            <origin xyz="0.0 0 -0.30379824957013823" rpy="0 0 0"/>
            <geometry>
                <box size="0.8463599216128499 0.9612029098073006 0.6075964991402765" />
            </geometry>
            <material name="sensor">
                <color rgba="0 1 0 1"/>
            </material>
        </visual>
        <collision>
            <origin xyz="0.0 0 -0.30379824957013823" rpy="0 0 0"/>
            <geometry>
                <box size="0.8463599216128499 0.9612029098073006 0.6075964991402765" />
            </geometry>
        </collision>
    </link>
    <joint name="0_1" type="revolute">
       <parent link="0"/>
       <child  link="1"/>
       <origin rpy="0 0 0" xyz="0 0 0.9569121776478247" />
     <axis xyz="0 0 1"/>
       <limit effort="0.0" lower="-3.14159" upper="3.14159" velocity="0.0"/>
    </joint>
    <link name="1">
        <inertial>
            <origin xyz="0 0 0.09925818768759753" rpy="0 0 0"/>
            <mass value="1" />
            <inertia ixx="100" ixy="0" ixz="0" iyy="100" iyz="0" izz="100" />
        </inertial>
        <visual>
            <origin xyz="0 0 0.09925818768759753" rpy="0 0 0"/>
            <geometry>
                <box size="0.19045993029254593 0.6083596397136556 0.19851637537519495" />
            </geometry>
            <material name="sensor">
                <color rgba="0 1 0 1"/>
            </material>
        </visual>
        <collision>
            <origin xyz="0 0 0.09925818768759753" rpy="0 0 0"/>
            <geometry>
                <box size="0.19045993029254593 0.6083596397136556 0.19851637537519495" />
            </geometry>
        </collision>
    </link>
    <joint name="1_5" type="revolute">
       <parent link="1"/>
       <child  link="5"/>
       <origin rpy="0 0 0" xyz="0 0.3041798198568278 0.09925818768759753" />
     <axis xyz="0 1 0"/>
       <limit effort="0.0" lower="-3.14159" upper="3.14159" velocity="0.0"/>
    </joint>
    <link name="5">
        <inertial>
            <origin xyz="0 0.4384202822878243 0.0" rpy="0 0 0"/>
            <mass value="1" />
            <inertia ixx="100" ixy="0" ixz="0" iyy="100" iyz="0" izz="100" />
        </inertial>
        <visual>
            <origin xyz="0 0.4384202822878243 0.0" rpy="0 0 0"/>
            <geometry>
                <box size="0.811995686067811 0.8768405645756486 0.1552431358080847" />
            </geometry>
            <material name="not">
                <color rgba="0 1 1 1"/>
            </material>
        </visual>
        <collision>
            <origin xyz="0 0.4384202822878243 0.0" rpy="0 0 0"/>
            <geometry>
                <box size="0.811995686067811 0.8768405645756486 0.1552431358080847" />
            </geometry>
        </collision>
    </link>
</robot>