<robot name = "robot">
    <link name="0">
        <inertial>
            <origin xyz="0 0 0.5997628087966007" rpy="0 0 0"/>
            <mass value="1" />
            <inertia ixx="100" ixy="0" ixz="0" iyy="100" iyz="0" izz="100" />
        </inertial>
        <visual>
            <origin xyz="0 0 0.5997628087966007" rpy="0 0 0"/>
            <geometry>
                <box size="0.9985089453757765 0.309670053476339 0.0769707047054119" />
            </geometry>
            <material name="not">
                <color rgba="0 1 1 1"/>
            </material>
        </visual>
        <collision>
            <origin xyz="0 0 0.5997628087966007" rpy="0 0 0"/>
            <geometry>
                <box size="0.9985089453757765 0.309670053476339 0.0769707047054119" />
            </geometry>
        </collision>
    </link>
    <joint name="0_1" type="revolute">
       <parent link="0"/>
       <child  link="1"/>
       <origin rpy="0 0 0" xyz="0 0 0.6382481611493067" />
     <axis xyz="0 1 0"/>
       <limit effort="0.0" lower="-3.14159" upper="3.14159" velocity="0.0"/>
    </joint>
    <link name="1">
        <inertial>
            <origin xyz="0 0 0.3448665367157602" rpy="0 0 0"/>
            <mass value="1" />
            <inertia ixx="100" ixy="0" ixz="0" iyy="100" iyz="0" izz="100" />
        </inertial>
        <visual>
            <origin xyz="0 0 0.3448665367157602" rpy="0 0 0"/>
            <geometry>
                <box size="0.2916123987024063 0.2633732047393842 0.6897330734315202" />
            </geometry>
            <material name="sensor">
                <color rgba="0 1 0 1"/>
            </material>
        </visual>
        <collision>
            <origin xyz="0 0 0.3448665367157602" rpy="0 0 0"/>
            <geometry>
                <box size="0.2916123987024063 0.2633732047393842 0.6897330734315202" />
            </geometry>
        </collision>
    </link>
    <joint name="1_2" type="revolute">
       <parent link="1"/>
       <child  link="2"/>
       <origin rpy="0 0 0" xyz="0 -0.1316866023696921 0.3448665367157602" />
     <axis xyz="1 0 0"/>
       <limit effort="0.0" lower="-3.14159" upper="3.14159" velocity="0.0"/>
    </joint>
    <link name="2">
        <inertial>
            <origin xyz="0 -0.4483298207138008 0.0" rpy="0 0 0"/>
            <mass value="1" />
            <inertia ixx="100" ixy="0" ixz="0" iyy="100" iyz="0" izz="100" />
        </inertial>
        <visual>
            <origin xyz="0 -0.4483298207138008 0.0" rpy="0 0 0"/>
            <geometry>
                <box size="0.958659426408455 0.8966596414276016 0.3777892394121827" />
            </geometry>
            <material name="sensor">
                <color rgba="0 1 0 1"/>
            </material>
        </visual>
        <collision>
            <origin xyz="0 -0.4483298207138008 0.0" rpy="0 0 0"/>
            <geometry>
                <box size="0.958659426408455 0.8966596414276016 0.3777892394121827" />
            </geometry>
        </collision>
    </link>
    <joint name="2_3" type="revolute">
       <parent link="2"/>
       <child  link="3"/>
       <origin rpy="0 0 0" xyz="0 -0.4483298207138008 0.18889461970609145" />
     <axis xyz="0 0 1"/>
       <limit effort="0.0" lower="-3.14159" upper="3.14159" velocity="0.0"/>
    </joint>
    <link name="3">
        <inertial>
            <origin xyz="0 0.0 0.11881780973239198" rpy="0 0 0"/>
            <mass value="1" />
            <inertia ixx="100" ixy="0" ixz="0" iyy="100" iyz="0" izz="100" />
        </inertial>
        <visual>
            <origin xyz="0 0.0 0.11881780973239198" rpy="0 0 0"/>
            <geometry>
                <box size="0.43119155343093274 0.7203112521441384 0.23763561946478406" />
            </geometry>
            <material name="sensor">
                <color rgba="0 1 0 1"/>
            </material>
        </visual>
        <collision>
            <origin xyz="0 0.0 0.11881780973239198" rpy="0 0 0"/>
            <geometry>
                <box size="0.43119155343093274 0.7203112521441384 0.23763561946478406" />
            </geometry>
        </collision>
    </link>
</robot>