<robot name = "robot">
    <link name="0">
        <inertial>
            <origin xyz="0 0 0.25891675029296335" rpy="0 0 0"/>
            <mass value="1" />
            <inertia ixx="100" ixy="0" ixz="0" iyy="100" iyz="0" izz="100" />
        </inertial>
        <visual>
            <origin xyz="0 0 0.25891675029296335" rpy="0 0 0"/>
            <geometry>
                <box size="0.8444218515250481 0.7579544029403025 0.420571580830845" />
            </geometry>
            <material name="sensor">
                <color rgba="0 1 0 1"/>
            </material>
        </visual>
        <collision>
            <origin xyz="0 0 0.25891675029296335" rpy="0 0 0"/>
            <geometry>
                <box size="0.8444218515250481 0.7579544029403025 0.420571580830845" />
            </geometry>
        </collision>
    </link>
    <joint name="0_1" type="revolute">
       <parent link="0"/>
       <child  link="1"/>
       <origin rpy="0 0 0" xyz="0 0 0.46920254070838585" />
     <axis xyz="0 1 0"/>
       <limit effort="0.0" lower="-3.14159" upper="3.14159" velocity="0.0"/>
    </joint>
    <link name="1">
        <inertial>
            <origin xyz="0 0 0.3091844983376658" rpy="0 0 0"/>
            <mass value="1" />
            <inertia ixx="100" ixy="0" ixz="0" iyy="100" iyz="0" izz="100" />
        </inertial>
        <visual>
            <origin xyz="0 0 0.3091844983376658" rpy="0 0 0"/>
            <geometry>
                <box size="0.28183784439970383 0.7558042041572239 0.6183689966753316" />
            </geometry>
            <material name="not">
                <color rgba="0 1 1 1"/>
            </material>
        </visual>
        <collision>
            <origin xyz="0 0 0.3091844983376658" rpy="0 0 0"/>
            <geometry>
                <box size="0.28183784439970383 0.7558042041572239 0.6183689966753316" />
            </geometry>
        </collision>
    </link>
    <joint name="1_2" type="revolute">
       <parent link="1"/>
       <child  link="2"/>
       <origin rpy="0 0 0" xyz="0 0 0.6183689966753317" />
     <axis xyz="0 0 1"/>
       <limit effort="0.0" lower="-3.14159" upper="3.14159" velocity="0.0"/>
    </joint>
    <link name="2">
        <inertial>
            <origin xyz="0 0 0.4252369131296274" rpy="0 0 0"/>
            <mass value="1" />
            <inertia ixx="100" ixy="0" ixz="0" iyy="100" iyz="0" izz="100" />
        </inertial>
        <visual>
            <origin xyz="0 0 0.4252369131296274" rpy="0 0 0"/>
            <geometry>
                <box size="0.09876334465914771 0.07374243362872512 0.8504738262592548" />
            </geometry>
            <material name="sensor">
                <color rgba="0 1 0 1"/>
            </material>
        </visual>
        <collision>
            <origin xyz="0 0 0.4252369131296274" rpy="0 0 0"/>
            <geometry>
                <box size="0.09876334465914771 0.07374243362872512 0.8504738262592548" />
            </geometry>
        </collision>
    </link>
    <joint name="2_3" type="revolute">
       <parent link="2"/>
       <child  link="3"/>
       <origin rpy="0 0 0" xyz="0 0.03687121681436256 0.4252369131296274" />
     <axis xyz="0 0 1"/>
       <limit effort="0.0" lower="-3.14159" upper="3.14159" velocity="0.0"/>
    </joint>
    <link name="3">
        <inertial>
            <origin xyz="0 0.21708591772689184 0.0" rpy="0 0 0"/>
            <mass value="1" />
            <inertia ixx="100" ixy="0" ixz="0" iyy="100" iyz="0" izz="100" />
        </inertial>
        <visual>
            <origin xyz="0 0.21708591772689184 0.0" rpy="0 0 0"/>
            <geometry>
                <box size="0.1007012080683658 0.4341718354537837 0.6108869734438016" />
            </geometry>
            <material name="sensor">
                <color rgba="0 1 0 1"/>
            </material>
        </visual>
        <collision>
            <origin xyz="0 0.21708591772689184 0.0" rpy="0 0 0"/>
            <geometry>
                <box size="0.1007012080683658 0.4341718354537837 0.6108869734438016" />
            </geometry>
        </collision>
    </link>
    <joint name="3_4" type="revolute">
       <parent link="3"/>
       <child  link="4"/>
       <origin rpy="0 0 0" xyz="-0.0503506040341829 0.21708591772689184 0.0" />
     <axis xyz="0 0 1"/>
       <limit effort="0.0" lower="-3.14159" upper="3.14159" velocity="0.0"/>
    </joint>
    <link name="4">
        <inertial>
            <origin xyz="-0.43265496388582003 0.0 0.0" rpy="0 0 0"/>
            <mass value="1" />
            <inertia ixx="100" ixy="0" ixz="0" iyy="100" iyz="0" izz="100" />
        </inertial>
        <visual>
            <origin xyz="-0.43265496388582003 0.0 0.0" rpy="0 0 0"/>
            <geometry>
                <box size="0.8653099277716401 0.2604923103919594 0.8050278270130223" />
            </geometry>
            <material name="not">
                <color rgba="0 1 1 1"/>
            </material>
        </visual>
        <collision>
            <origin xyz="-0.43265496388582003 0.0 0.0" rpy="0 0 0"/>
            <geometry>
                <box size="0.8653099277716401 0.2604923103919594 0.8050278270130223" />
            </geometry>
        </collision>
    </link>
    <joint name="0_5" type="revolute">
       <parent link="0"/>
       <child  link="5"/>
       <origin rpy="0 0 0" xyz="-0.42221092576252406 0 0.25891675029296335" />
     <axis xyz="1 0 0"/>
       <limit effort="0.0" lower="-3.14159" upper="3.14159" velocity="0.0"/>
    </joint>
    <link name="5">
        <inertial>
            <origin xyz="-0.3059485424070726 0 0.0" rpy="0 0 0"/>
            <mass value="1" />
            <inertia ixx="100" ixy="0" ixz="0" iyy="100" iyz="0" izz="100" />
        </inertial>
        <visual>
            <origin xyz="-0.3059485424070726 0 0.0" rpy="0 0 0"/>
            <geometry>
                <box size="0.6118970848141451 0.8280632784038988 0.3331351372890984" />
            </geometry>
            <material name="sensor">
                <color rgba="0 1 0 1"/>
            </material>
        </visual>
        <collision>
            <origin xyz="-0.3059485424070726 0 0.0" rpy="0 0 0"/>
            <geometry>
                <box size="0.6118970848141451 0.8280632784038988 0.3331351372890984" />
            </geometry>
        </collision>
    </link>
</robot>