<robot name = "robot">
    <link name="0">
        <inertial>
            <origin xyz="0 0 0.5449484743985434" rpy="0 0 0"/>
            <mass value="1" />
            <inertia ixx="100" ixy="0" ixz="0" iyy="100" iyz="0" izz="100" />
        </inertial>
        <visual>
            <origin xyz="0 0 0.5449484743985434" rpy="0 0 0"/>
            <geometry>
                <box size="0.7105117080264377 0.005562124014677927 0.31181714028829965" />
            </geometry>
            <material name="sensor">
                <color rgba="0 1 0 1"/>
            </material>
        </visual>
        <collision>
            <origin xyz="0 0 0.5449484743985434" rpy="0 0 0"/>
            <geometry>
                <box size="0.7105117080264377 0.005562124014677927 0.31181714028829965" />
            </geometry>
        </collision>
    </link>
    <joint name="0_1" type="revolute">
       <parent link="0"/>
       <child  link="1"/>
       <origin rpy="0 0 0" xyz="0 0.0027810620073389636 0.5449484743985434" />
     <axis xyz="0 0 1"/>
       <limit effort="0.0" lower="-3.14159" upper="3.14159" velocity="0.0"/>
    </joint>
    <link name="1">
        <inertial>
            <origin xyz="0 0.20558843332368915 0.0" rpy="0 0 0"/>
            <mass value="1" />
            <inertia ixx="100" ixy="0" ixz="0" iyy="100" iyz="0" izz="100" />
        </inertial>
        <visual>
            <origin xyz="0 0.20558843332368915 0.0" rpy="0 0 0"/>
            <geometry>
                <box size="0.5207145902919856 0.4111768666473783 0.2934509989380133" />
            </geometry>
            <material name="not">
                <color rgba="0 1 1 1"/>
            </material>
        </visual>
        <collision>
            <origin xyz="0 0.20558843332368915 0.0" rpy="0 0 0"/>
            <geometry>
                <box size="0.5207145902919856 0.4111768666473783 0.2934509989380133" />
            </geometry>
        </collision>
    </link>
    <joint name="0_2" type="revolute">
       <parent link="0"/>
       <child  link="2"/>
       <origin rpy="0 0 0" xyz="0 0 0.3890399042543936" />
     <axis xyz="0 0 1"/>
       <limit effort="0.0" lower="-3.14159" upper="3.14159" velocity="0.0"/>
    </joint>
    <link name="2">
        <inertial>
            <origin xyz="0 0 -0.15663628482850178" rpy="0 0 0"/>
            <mass value="1" />
            <inertia ixx="100" ixy="0" ixz="0" iyy="100" iyz="0" izz="100" />
        </inertial>
        <visual>
            <origin xyz="0 0 -0.15663628482850178" rpy="0 0 0"/>
            <geometry>
                <box size="0.6767333526381805 0.6095348813208721 0.31327256965700356" />
            </geometry>
            <material name="sensor">
                <color rgba="0 1 0 1"/>
            </material>
        </visual>
        <collision>
            <origin xyz="0 0 -0.15663628482850178" rpy="0 0 0"/>
            <geometry>
                <box size="0.6767333526381805 0.6095348813208721 0.31327256965700356" />
            </geometry>
        </collision>
    </link>
    <joint name="2_3" type="revolute">
       <parent link="2"/>
       <child  link="3"/>
       <origin rpy="0 0 0" xyz="0 -0.30476744066043604 -0.15663628482850178" />
     <axis xyz="1 0 0"/>
       <limit effort="0.0" lower="-3.14159" upper="3.14159" velocity="0.0"/>
    </joint>
    <link name="3">
        <inertial>
            <origin xyz="0 -0.2940672226741289 0.0" rpy="0 0 0"/>
            <mass value="1" />
            <inertia ixx="100" ixy="0" ixz="0" iyy="100" iyz="0" izz="100" />
        </inertial>
        <visual>
            <origin xyz="0 -0.2940672226741289 0.0" rpy="0 0 0"/>
            <geometry>
                <box size="0.4382905990746948 0.5881344453482577 0.25128347563663345" />
            </geometry>
            <material name="sensor">
                <color rgba="0 1 0 1"/>
            </material>
        </visual>
        <collision>
            <origin xyz="0 -0.2940672226741289 0.0" rpy="0 0 0"/>
            <geometry>
                <box size="0.4382905990746948 0.5881344453482577 0.25128347563663345" />
            </geometry>
        </collision>
    </link>
    <joint name="3_5" type="revolute">
       <parent link="3"/>
       <child  link="5"/>
       <origin rpy="0 0 0" xyz="0 -0.5881344453482577 0.0" />
     <axis xyz="1 0 0"/>
       <limit effort="0.0" lower="-3.14159" upper="3.14159" velocity="0.0"/>
    </joint>
    <link name="5">
        <inertial>
            <origin xyz="0 -0.4739641586202552 0.0" rpy="0 0 0"/>
            <mass value="1" />
            <inertia ixx="100" ixy="0" ixz="0" iyy="100" iyz="0" izz="100" />
        </inertial>
        <visual>
            <origin xyz="0 -0.4739641586202552 0.0" rpy="0 0 0"/>
            <geometry>
                <box size="0.29921358177544666 0.9479283172405103 0.16331961302390163" />
            </geometry>
            <material name="sensor">
                <color rgba="0 1 0 1"/>
            </material>
        </visual>
        <collision>
            <origin xyz="0 -0.4739641586202552 0.0" rpy="0 0 0"/>
            <geometry>
                <box size="0.29921358177544666 0.9479283172405103 0.16331961302390163" />
            </geometry>
        </collision>
    </link>
</robot>