<robot name = "robot">
    <link name="0">
        <inertial>
            <origin xyz="0 0 0.5077883316269493" rpy="0 0 0"/>
            <mass value="1" />
            <inertia ixx="100" ixy="0" ixz="0" iyy="100" iyz="0" izz="100" />
        </inertial>
        <visual>
            <origin xyz="0 0 0.5077883316269493" rpy="0 0 0"/>
            <geometry>
                <box size="0.7813891646784018 0.6338085603126118 0.6295099683578158" />
            </geometry>
            <material name="sensor">
                <color rgba="0 1 0 1"/>
            </material>
        </visual>
        <collision>
            <origin xyz="0 0 0.5077883316269493" rpy="0 0 0"/>
            <geometry>
                <box size="0.7813891646784018 0.6338085603126118 0.6295099683578158" />
            </geometry>
        </collision>
    </link>
    <joint name="0_1" type="revolute">
       <parent link="0"/>
       <child  link="1"/>
       <origin rpy="0 0 0" xyz="-0.3906945823392009 0 0.5077883316269493" />
     <axis xyz="1 0 0"/>
       <limit effort="0.0" lower="-3.14159" upper="3.14159" velocity="0.0"/>
    </joint>
    <link name="1">
        <inertial>
            <origin xyz="-0.06130387136594051 0 0.0" rpy="0 0 0"/>
            <mass value="1" />
            <inertia ixx="100" ixy="0" ixz="0" iyy="100" iyz="0" izz="100" />
        </inertial>
        <visual>
            <origin xyz="-0.06130387136594051 0 0.0" rpy="0 0 0"/>
            <geometry>
                <box size="0.12260774273188102 0.5154901144118035 0.4703988873236512" />
            </geometry>
            <material name="sensor">
                <color rgba="0 1 0 1"/>
            </material>
        </visual>
        <collision>
            <origin xyz="-0.06130387136594051 0 0.0" rpy="0 0 0"/>
            <geometry>
                <box size="0.12260774273188102 0.5154901144118035 0.4703988873236512" />
            </geometry>
        </collision>
    </link>
    <joint name="1_4" type="revolute">
       <parent link="1"/>
       <child  link="4"/>
       <origin rpy="0 0 0" xyz="-0.06130387136594051 0.25774505720590174 0.0" />
     <axis xyz="1 0 0"/>
       <limit effort="0.0" lower="-3.14159" upper="3.14159" velocity="0.0"/>
    </joint>
    <link name="4">
        <inertial>
            <origin xyz="0.0 0.028873552970883898 0.0" rpy="0 0 0"/>
            <mass value="1" />
            <inertia ixx="100" ixy="0" ixz="0" iyy="100" iyz="0" izz="100" />
        </inertial>
        <visual>
            <origin xyz="0.0 0.028873552970883898 0.0" rpy="0 0 0"/>
            <geometry>
                <box size="0.02231118308041724 0.057747105941767796 0.5168454606157238" />
            </geometry>
            <material name="not">
                <color rgba="0 1 1 1"/>
            </material>
        </visual>
        <collision>
            <origin xyz="0.0 0.028873552970883898 0.0" rpy="0 0 0"/>
            <geometry>
                <box size="0.02231118308041724 0.057747105941767796 0.5168454606157238" />
            </geometry>
        </collision>
    </link>
    <joint name="1_7" type="revolute">
       <parent link="1"/>
       <child  link="7"/>
       <origin rpy="0 0 0" xyz="-0.06130387136594051 0 0.23519944366182555" />
     <axis xyz="0 0 1"/>
       <limit effort="0.0" lower="-3.14159" upper="3.14159" velocity="0.0"/>
    </joint>
    <link name="7">
        <inertial>
            <origin xyz="0.0 0 0.10624774177704555" rpy="0 0 0"/>
            <mass value="1" />
            <inertia ixx="100" ixy="0" ixz="0" iyy="100" iyz="0" izz="100" />
        </inertial>
        <visual>
            <origin xyz="0.0 0 0.10624774177704555" rpy="0 0 0"/>
            <geometry>
                <box size="0.03803770038155263 0.03807963054843466 0.21249548355409098" />
            </geometry>
            <material name="not">
                <color rgba="0 1 1 1"/>
            </material>
        </visual>
        <collision>
            <origin xyz="0.0 0 0.10624774177704555" rpy="0 0 0"/>
            <geometry>
                <box size="0.03803770038155263 0.03807963054843466 0.21249548355409098" />
            </geometry>
        </collision>
    </link>
    <joint name="1_2" type="revolute">
       <parent link="1"/>
       <child  link="2"/>
       <origin rpy="0 0 0" xyz="-0.12260774273188108 0 0.0" />
     <axis xyz="0 1 0"/>
       <limit effort="0.0" lower="-3.14159" upper="3.14159" velocity="0.0"/>
    </joint>
    <link name="2">
        <inertial>
            <origin xyz="-0.13183826725818437 0 0.0" rpy="0 0 0"/>
            <mass value="1" />
            <inertia ixx="100" ixy="0" ixz="0" iyy="100" iyz="0" izz="100" />
        </inertial>
        <visual>
            <origin xyz="-0.13183826725818437 0 0.0" rpy="0 0 0"/>
            <geometry>
                <box size="0.26367653451636863 0.0038384531112014564 0.152494144853762" />
            </geometry>
            <material name="not">
                <color rgba="0 1 1 1"/>
            </material>
        </visual>
        <collision>
            <origin xyz="-0.13183826725818437 0 0.0" rpy="0 0 0"/>
            <geometry>
                <box size="0.26367653451636863 0.0038384531112014564 0.152494144853762" />
            </geometry>
        </collision>
    </link>
    <joint name="2_3" type="revolute">
       <parent link="2"/>
       <child  link="3"/>
       <origin rpy="0 0 0" xyz="-0.13183826725818437 0.0019192265556007282 0.0" />
     <axis xyz="1 0 0"/>
       <limit effort="0.0" lower="-3.14159" upper="3.14159" velocity="0.0"/>
    </joint>
    <link name="3">
        <inertial>
            <origin xyz="0.0 0.005022954087553599 0.0" rpy="0 0 0"/>
            <mass value="1" />
            <inertia ixx="100" ixy="0" ixz="0" iyy="100" iyz="0" izz="100" />
        </inertial>
        <visual>
            <origin xyz="0.0 0.005022954087553599 0.0" rpy="0 0 0"/>
            <geometry>
                <box size="0.1192677614056501 0.010045908175107199 0.8099995189586744" />
            </geometry>
            <material name="not">
                <color rgba="0 1 1 1"/>
            </material>
        </visual>
        <collision>
            <origin xyz="0.0 0.005022954087553599 0.0" rpy="0 0 0"/>
            <geometry>
                <box size="0.1192677614056501 0.010045908175107199 0.8099995189586744" />
            </geometry>
        </collision>
    </link>
    <joint name="3_8" type="revolute">
       <parent link="3"/>
       <child  link="8"/>
       <origin rpy="0 0 0" xyz="0.0 0.010045908175107199 0.0" />
     <axis xyz="0 0 1"/>
       <limit effort="0.0" lower="-3.14159" upper="3.14159" velocity="0.0"/>
    </joint>
    <link name="8">
        <inertial>
            <origin xyz="0.0 0.022206583249738232 0.0" rpy="0 0 0"/>
            <mass value="1" />
            <inertia ixx="100" ixy="0" ixz="0" iyy="100" iyz="0" izz="100" />
        </inertial>
        <visual>
            <origin xyz="0.0 0.022206583249738232 0.0" rpy="0 0 0"/>
            <geometry>
                <box size="0.1184447178831518 0.044413166499476464 0.41895426351576437" />
            </geometry>
            <material name="not">
                <color rgba="0 1 1 1"/>
            </material>
        </visual>
        <collision>
            <origin xyz="0.0 0.022206583249738232 0.0" rpy="0 0 0"/>
            <geometry>
                <box size="0.1184447178831518 0.044413166499476464 0.41895426351576437" />
            </geometry>
        </collision>
    </link>
    <joint name="3_5" type="revolute">
       <parent link="3"/>
       <child  link="5"/>
       <origin rpy="0 0 0" xyz="0.0 0.005022954087553599 0.4049997594793372" />
     <axis xyz="1 0 0"/>
       <limit effort="0.0" lower="-3.14159" upper="3.14159" velocity="0.0"/>
    </joint>
    <link name="5">
        <inertial>
            <origin xyz="0.0 0.0 0.09352691061064156" rpy="0 0 0"/>
            <mass value="1" />
            <inertia ixx="100" ixy="0" ixz="0" iyy="100" iyz="0" izz="100" />
        </inertial>
        <visual>
            <origin xyz="0.0 0.0 0.09352691061064156" rpy="0 0 0"/>
            <geometry>
                <box size="0.3116491934616692 0.610536260611792 0.1870538212212831" />
            </geometry>
            <material name="sensor">
                <color rgba="0 1 0 1"/>
            </material>
        </visual>
        <collision>
            <origin xyz="0.0 0.0 0.09352691061064156" rpy="0 0 0"/>
            <geometry>
                <box size="0.3116491934616692 0.610536260611792 0.1870538212212831" />
            </geometry>
        </collision>
    </link>
    <joint name="3_6" type="revolute">
       <parent link="3"/>
       <child  link="6"/>
       <origin rpy="0 0 0" xyz="0.0 0.005022954087553599 -0.4049997594793372" />
     <axis xyz="1 0 0"/>
       <limit effort="0.0" lower="-3.14159" upper="3.14159" velocity="0.0"/>
    </joint>
    <link name="6">
        <inertial>
            <origin xyz="0.0 0.0 -0.0482953731161091" rpy="0 0 0"/>
            <mass value="1" />
            <inertia ixx="100" ixy="0" ixz="0" iyy="100" iyz="0" izz="100" />
        </inertial>
        <visual>
            <origin xyz="0.0 0.0 -0.0482953731161091" rpy="0 0 0"/>
            <geometry>
                <box size="0.8914281440706424 0.5803086832510361 0.0965907462322182" />
            </geometry>
            <material name="not">
                <color rgba="0 1 1 1"/>
            </material>
        </visual>
        <collision>
            <origin xyz="0.0 0.0 -0.0482953731161091" rpy="0 0 0"/>
            <geometry>
                <box size="0.8914281440706424 0.5803086832510361 0.0965907462322182" />
            </geometry>
        </collision>
    </link>
</robot>