<robot name = "robot">
    <link name="0">
        <inertial>
            <origin xyz="0 0 0.764800547770313" rpy="0 0 0"/>
            <mass value="1" />
            <inertia ixx="100" ixy="0" ixz="0" iyy="100" iyz="0" izz="100" />
        </inertial>
        <visual>
            <origin xyz="0 0 0.764800547770313" rpy="0 0 0"/>
            <geometry>
                <box size="0.9414905594691287 0.7217352889552988 0.6473481196650006" />
            </geometry>
            <material name="sensor">
                <color rgba="0 1 0 1"/>
            </material>
        </visual>
        <collision>
            <origin xyz="0 0 0.764800547770313" rpy="0 0 0"/>
            <geometry>
                <box size="0.9414905594691287 0.7217352889552988 0.6473481196650006" />
            </geometry>
        </collision>
    </link>
    <joint name="0_1" type="revolute">
       <parent link="0"/>
       <child  link="1"/>
       <origin rpy="0 0 0" xyz="0.47074527973456437 0 0.764800547770313" />
     <axis xyz="0 0 1"/>
       <limit effort="0.0" lower="-3.14159" upper="3.14159" velocity="0.0"/>
    </joint>
    <link name="1">
        <inertial>
            <origin xyz="0.000683019989351219 0 0.0" rpy="0 0 0"/>
            <mass value="1" />
            <inertia ixx="100" ixy="0" ixz="0" iyy="100" iyz="0" izz="100" />
        </inertial>
        <visual>
            <origin xyz="0.000683019989351219 0 0.0" rpy="0 0 0"/>
            <geometry>
                <box size="0.001366039978702438 0.12565177107287062 0.5693822869652517" />
            </geometry>
            <material name="sensor">
                <color rgba="0 1 0 1"/>
            </material>
        </visual>
        <collision>
            <origin xyz="0.000683019989351219 0 0.0" rpy="0 0 0"/>
            <geometry>
                <box size="0.001366039978702438 0.12565177107287062 0.5693822869652517" />
            </geometry>
        </collision>
    </link>
    <joint name="0_2" type="revolute">
       <parent link="0"/>
       <child  link="2"/>
       <origin rpy="0 0 0" xyz="0 0.3608676444776494 0.764800547770313" />
     <axis xyz="0 0 1"/>
       <limit effort="0.0" lower="-3.14159" upper="3.14159" velocity="0.0"/>
    </joint>
    <link name="2">
        <inertial>
            <origin xyz="0 0.2641265714030381 0.0" rpy="0 0 0"/>
            <mass value="1" />
            <inertia ixx="100" ixy="0" ixz="0" iyy="100" iyz="0" izz="100" />
        </inertial>
        <visual>
            <origin xyz="0 0.2641265714030381 0.0" rpy="0 0 0"/>
            <geometry>
                <box size="0.6264727357908632 0.5282531428060762 0.43743052854077447" />
            </geometry>
            <material name="not">
                <color rgba="0 1 1 1"/>
            </material>
        </visual>
        <collision>
            <origin xyz="0 0.2641265714030381 0.0" rpy="0 0 0"/>
            <geometry>
                <box size="0.6264727357908632 0.5282531428060762 0.43743052854077447" />
            </geometry>
        </collision>
    </link>
    <joint name="0_3" type="revolute">
       <parent link="0"/>
       <child  link="3"/>
       <origin rpy="0 0 0" xyz="0 0 1.0884746076028133" />
     <axis xyz="0 1 0"/>
       <limit effort="0.0" lower="-3.14159" upper="3.14159" velocity="0.0"/>
    </joint>
    <link name="3">
        <inertial>
            <origin xyz="0 0 0.09585088263482588" rpy="0 0 0"/>
            <mass value="1" />
            <inertia ixx="100" ixy="0" ixz="0" iyy="100" iyz="0" izz="100" />
        </inertial>
        <visual>
            <origin xyz="0 0 0.09585088263482588" rpy="0 0 0"/>
            <geometry>
                <box size="0.3003492841455092 0.9435404582537038 0.19170176526965155" />
            </geometry>
            <material name="not">
                <color rgba="0 1 1 1"/>
            </material>
        </visual>
        <collision>
            <origin xyz="0 0 0.09585088263482588" rpy="0 0 0"/>
            <geometry>
                <box size="0.3003492841455092 0.9435404582537038 0.19170176526965155" />
            </geometry>
        </collision>
    </link>
</robot>