<robot name = "robot">
    <link name="0">
        <inertial>
            <origin xyz="0 0 0.5433786768747104" rpy="0 0 0"/>
            <mass value="1" />
            <inertia ixx="100" ixy="0" ixz="0" iyy="100" iyz="0" izz="100" />
        </inertial>
        <visual>
            <origin xyz="0 0 0.5433786768747104" rpy="0 0 0"/>
            <geometry>
                <box size="0.8376889627196834 0.8275614758933684 0.08514101028344034" />
            </geometry>
            <material name="sensor">
                <color rgba="0 1 0 1"/>
            </material>
        </visual>
        <collision>
            <origin xyz="0 0 0.5433786768747104" rpy="0 0 0"/>
            <geometry>
                <box size="0.8376889627196834 0.8275614758933684 0.08514101028344034" />
            </geometry>
        </collision>
    </link>
    <joint name="0_1" type="revolute">
       <parent link="0"/>
       <child  link="1"/>
       <origin rpy="0 0 0" xyz="0 0 0.5859491820164306" />
     <axis xyz="0 0 1"/>
       <limit effort="0.0" lower="-3.14159" upper="3.14159" velocity="0.0"/>
    </joint>
    <link name="1">
        <inertial>
            <origin xyz="0 0 0.39917679088317937" rpy="0 0 0"/>
            <mass value="1" />
            <inertia ixx="100" ixy="0" ixz="0" iyy="100" iyz="0" izz="100" />
        </inertial>
        <visual>
            <origin xyz="0 0 0.39917679088317937" rpy="0 0 0"/>
            <geometry>
                <box size="0.0771942519728177 0.915755395747436 0.7983535817663586" />
            </geometry>
            <material name="sensor">
                <color rgba="0 1 0 1"/>
            </material>
        </visual>
        <collision>
            <origin xyz="0 0 0.39917679088317937" rpy="0 0 0"/>
            <geometry>
                <box size="0.0771942519728177 0.915755395747436 0.7983535817663586" />
            </geometry>
        </collision>
    </link>
    <joint name="1_2" type="revolute">
       <parent link="1"/>
       <child  link="2"/>
       <origin rpy="0 0 0" xyz="0 0.457877697873718 0.39917679088317937" />
     <axis xyz="0 1 0"/>
       <limit effort="0.0" lower="-3.14159" upper="3.14159" velocity="0.0"/>
    </joint>
    <link name="2">
        <inertial>
            <origin xyz="0 0.3882931189396954 0.0" rpy="0 0 0"/>
            <mass value="1" />
            <inertia ixx="100" ixy="0" ixz="0" iyy="100" iyz="0" izz="100" />
        </inertial>
        <visual>
            <origin xyz="0 0.3882931189396954 0.0" rpy="0 0 0"/>
            <geometry>
                <box size="0.8578439556899257 0.7765862378793907 0.06691787115180847" />
            </geometry>
            <material name="sensor">
                <color rgba="0 1 0 1"/>
            </material>
        </visual>
        <collision>
            <origin xyz="0 0.3882931189396954 0.0" rpy="0 0 0"/>
            <geometry>
                <box size="0.8578439556899257 0.7765862378793907 0.06691787115180847" />
            </geometry>
        </collision>
    </link>
    <joint name="1_3" type="revolute">
       <parent link="1"/>
       <child  link="3"/>
       <origin rpy="0 0 0" xyz="0 0 0.7983535817663587" />
     <axis xyz="0 0 1"/>
       <limit effort="0.0" lower="-3.14159" upper="3.14159" velocity="0.0"/>
    </joint>
    <link name="3">
        <inertial>
            <origin xyz="0 0 0.08368848402650264" rpy="0 0 0"/>
            <mass value="1" />
            <inertia ixx="100" ixy="0" ixz="0" iyy="100" iyz="0" izz="100" />
        </inertial>
        <visual>
            <origin xyz="0 0 0.08368848402650264" rpy="0 0 0"/>
            <geometry>
                <box size="0.42246444611379863 0.7983488705626961 0.16737696805300517" />
            </geometry>
            <material name="not">
                <color rgba="0 1 1 1"/>
            </material>
        </visual>
        <collision>
            <origin xyz="0 0 0.08368848402650264" rpy="0 0 0"/>
            <geometry>
                <box size="0.42246444611379863 0.7983488705626961 0.16737696805300517" />
            </geometry>
        </collision>
    </link>
</robot>