<robot name = "robot">
    <link name="0">
        <inertial>
            <origin xyz="0 0 0.7048169228716079" rpy="0 0 0"/>
            <mass value="1" />
            <inertia ixx="100" ixy="0" ixz="0" iyy="100" iyz="0" izz="100" />
        </inertial>
        <visual>
            <origin xyz="0 0 0.7048169228716079" rpy="0 0 0"/>
            <geometry>
                <box size="0.2267058593810488 0.9622950358343828 0.12633089865085956" />
            </geometry>
            <material name="not">
                <color rgba="0 1 1 1"/>
            </material>
        </visual>
        <collision>
            <origin xyz="0 0 0.7048169228716079" rpy="0 0 0"/>
            <geometry>
                <box size="0.2267058593810488 0.9622950358343828 0.12633089865085956" />
            </geometry>
        </collision>
    </link>
    <joint name="0_1" type="revolute">
       <parent link="0"/>
       <child  link="1"/>
       <origin rpy="0 0 0" xyz="0.1133529296905244 0 0.7048169228716079" />
     <axis xyz="0 0 1"/>
       <limit effort="0.0" lower="-3.14159" upper="3.14159" velocity="0.0"/>
    </joint>
    <link name="1">
        <inertial>
            <origin xyz="0.4056320227650126 0 0.0" rpy="0 0 0"/>
            <mass value="1" />
            <inertia ixx="100" ixy="0" ixz="0" iyy="100" iyz="0" izz="100" />
        </inertial>
        <visual>
            <origin xyz="0.4056320227650126 0 0.0" rpy="0 0 0"/>
            <geometry>
                <box size="0.8112640455300252 0.506360390852374 0.4007102373381587" />
            </geometry>
            <material name="sensor">
                <color rgba="0 1 0 1"/>
            </material>
        </visual>
        <collision>
            <origin xyz="0.4056320227650126 0 0.0" rpy="0 0 0"/>
            <geometry>
                <box size="0.8112640455300252 0.506360390852374 0.4007102373381587" />
            </geometry>
        </collision>
    </link>
    <joint name="1_2" type="revolute">
       <parent link="1"/>
       <child  link="2"/>
       <origin rpy="0 0 0" xyz="0.4056320227650126 0 -0.2003551186690793" />
     <axis xyz="0 0 1"/>
       <limit effort="0.0" lower="-3.14159" upper="3.14159" velocity="0.0"/>
    </joint>
    <link name="2">
        <inertial>
            <origin xyz="0.0 0 -0.09611542112134108" rpy="0 0 0"/>
            <mass value="1" />
            <inertia ixx="100" ixy="0" ixz="0" iyy="100" iyz="0" izz="100" />
        </inertial>
        <visual>
            <origin xyz="0.0 0 -0.09611542112134108" rpy="0 0 0"/>
            <geometry>
                <box size="0.45313243113814283 0.4949826938891777 0.19223084224268217" />
            </geometry>
            <material name="not">
                <color rgba="0 1 1 1"/>
            </material>
        </visual>
        <collision>
            <origin xyz="0.0 0 -0.09611542112134108" rpy="0 0 0"/>
            <geometry>
                <box size="0.45313243113814283 0.4949826938891777 0.19223084224268217" />
            </geometry>
        </collision>
    </link>
    <joint name="1_3" type="revolute">
       <parent link="1"/>
       <child  link="3"/>
       <origin rpy="0 0 0" xyz="0.4056320227650126 -0.253180195426187 0.0" />
     <axis xyz="1 0 0"/>
       <limit effort="0.0" lower="-3.14159" upper="3.14159" velocity="0.0"/>
    </joint>
    <link name="3">
        <inertial>
            <origin xyz="0.0 -0.009995653112090386 0.0" rpy="0 0 0"/>
            <mass value="1" />
            <inertia ixx="100" ixy="0" ixz="0" iyy="100" iyz="0" izz="100" />
        </inertial>
        <visual>
            <origin xyz="0.0 -0.009995653112090386 0.0" rpy="0 0 0"/>
            <geometry>
                <box size="0.23418295948970536 0.01999130622418077 0.2667674610031978" />
            </geometry>
            <material name="sensor">
                <color rgba="0 1 0 1"/>
            </material>
        </visual>
        <collision>
            <origin xyz="0.0 -0.009995653112090386 0.0" rpy="0 0 0"/>
            <geometry>
                <box size="0.23418295948970536 0.01999130622418077 0.2667674610031978" />
            </geometry>
        </collision>
    </link>
    <joint name="3_5" type="revolute">
       <parent link="3"/>
       <child  link="5"/>
       <origin rpy="0 0 0" xyz="0.11709147974485268 -0.009995653112090386 0.0" />
     <axis xyz="0 1 0"/>
       <limit effort="0.0" lower="-3.14159" upper="3.14159" velocity="0.0"/>
    </joint>
    <link name="5">
        <inertial>
            <origin xyz="0.14085672496845436 0.0 0.0" rpy="0 0 0"/>
            <mass value="1" />
            <inertia ixx="100" ixy="0" ixz="0" iyy="100" iyz="0" izz="100" />
        </inertial>
        <visual>
            <origin xyz="0.14085672496845436 0.0 0.0" rpy="0 0 0"/>
            <geometry>
                <box size="0.2817134499369087 0.0153161521290901 0.49825370779507727" />
            </geometry>
            <material name="not">
                <color rgba="0 1 1 1"/>
            </material>
        </visual>
        <collision>
            <origin xyz="0.14085672496845436 0.0 0.0" rpy="0 0 0"/>
            <geometry>
                <box size="0.2817134499369087 0.0153161521290901 0.49825370779507727" />
            </geometry>
        </collision>
    </link>
    <joint name="3_4" type="revolute">
       <parent link="3"/>
       <child  link="4"/>
       <origin rpy="0 0 0" xyz="0.0 -0.01999130622418077 0.0" />
     <axis xyz="0 0 1"/>
       <limit effort="0.0" lower="-3.14159" upper="3.14159" velocity="0.0"/>
    </joint>
    <link name="4">
        <inertial>
            <origin xyz="0.0 -0.43015627406150764 0.0" rpy="0 0 0"/>
            <mass value="1" />
            <inertia ixx="100" ixy="0" ixz="0" iyy="100" iyz="0" izz="100" />
        </inertial>
        <visual>
            <origin xyz="0.0 -0.43015627406150764 0.0" rpy="0 0 0"/>
            <geometry>
                <box size="0.14820779074761503 0.8603125481230153 0.4562631750773002" />
            </geometry>
            <material name="sensor">
                <color rgba="0 1 0 1"/>
            </material>
        </visual>
        <collision>
            <origin xyz="0.0 -0.43015627406150764 0.0" rpy="0 0 0"/>
            <geometry>
                <box size="0.14820779074761503 0.8603125481230153 0.4562631750773002" />
            </geometry>
        </collision>
    </link>
</robot>