<robot name = "robot">
    <link name="0">
        <inertial>
            <origin xyz="0 0 0.6424939208853032" rpy="0 0 0"/>
            <mass value="1" />
            <inertia ixx="100" ixy="0" ixz="0" iyy="100" iyz="0" izz="100" />
        </inertial>
        <visual>
            <origin xyz="0 0 0.6424939208853032" rpy="0 0 0"/>
            <geometry>
                <box size="0.33658958447132015 0.6569089999141473 0.7995046593300813" />
            </geometry>
            <material name="sensor">
                <color rgba="0 1 0 1"/>
            </material>
        </visual>
        <collision>
            <origin xyz="0 0 0.6424939208853032" rpy="0 0 0"/>
            <geometry>
                <box size="0.33658958447132015 0.6569089999141473 0.7995046593300813" />
            </geometry>
        </collision>
    </link>
    <joint name="0_2" type="revolute">
       <parent link="0"/>
       <child  link="2"/>
       <origin rpy="0 0 0" xyz="0 0.32845449995707365 0.6424939208853032" />
     <axis xyz="0 1 0"/>
       <limit effort="0.0" lower="-3.14159" upper="3.14159" velocity="0.0"/>
    </joint>
    <link name="2">
        <inertial>
            <origin xyz="0 0.10927073209737703 0.0" rpy="0 0 0"/>
            <mass value="1" />
            <inertia ixx="100" ixy="0" ixz="0" iyy="100" iyz="0" izz="100" />
        </inertial>
        <visual>
            <origin xyz="0 0.10927073209737703 0.0" rpy="0 0 0"/>
            <geometry>
                <box size="0.9274809464100172 0.21854146419475406 0.0032730267285946413" />
            </geometry>
            <material name="not">
                <color rgba="0 1 1 1"/>
            </material>
        </visual>
        <collision>
            <origin xyz="0 0.10927073209737703 0.0" rpy="0 0 0"/>
            <geometry>
                <box size="0.9274809464100172 0.21854146419475406 0.0032730267285946413" />
            </geometry>
        </collision>
    </link>
    <joint name="2_3" type="revolute">
       <parent link="2"/>
       <child  link="3"/>
       <origin rpy="0 0 0" xyz="-0.4637404732050086 0.10927073209737703 0.0" />
     <axis xyz="0 0 1"/>
       <limit effort="0.0" lower="-3.14159" upper="3.14159" velocity="0.0"/>
    </joint>
    <link name="3">
        <inertial>
            <origin xyz="-0.27530419846400916 0.0 0.0" rpy="0 0 0"/>
            <mass value="1" />
            <inertia ixx="100" ixy="0" ixz="0" iyy="100" iyz="0" izz="100" />
        </inertial>
        <visual>
            <origin xyz="-0.27530419846400916 0.0 0.0" rpy="0 0 0"/>
            <geometry>
                <box size="0.5506083969280183 0.878707468144288 0.20166944833026434" />
            </geometry>
            <material name="sensor">
                <color rgba="0 1 0 1"/>
            </material>
        </visual>
        <collision>
            <origin xyz="-0.27530419846400916 0.0 0.0" rpy="0 0 0"/>
            <geometry>
                <box size="0.5506083969280183 0.878707468144288 0.20166944833026434" />
            </geometry>
        </collision>
    </link>
    <joint name="0_1" type="revolute">
       <parent link="0"/>
       <child  link="1"/>
       <origin rpy="0 0 0" xyz="0 0 1.0422462505503438" />
     <axis xyz="0 0 1"/>
       <limit effort="0.0" lower="-3.14159" upper="3.14159" velocity="0.0"/>
    </joint>
    <link name="1">
        <inertial>
            <origin xyz="0 0 0.2481952200620643" rpy="0 0 0"/>
            <mass value="1" />
            <inertia ixx="100" ixy="0" ixz="0" iyy="100" iyz="0" izz="100" />
        </inertial>
        <visual>
            <origin xyz="0 0 0.2481952200620643" rpy="0 0 0"/>
            <geometry>
                <box size="0.33853061439692944 0.3921818580946256 0.4963904401241285" />
            </geometry>
            <material name="not">
                <color rgba="0 1 1 1"/>
            </material>
        </visual>
        <collision>
            <origin xyz="0 0 0.2481952200620643" rpy="0 0 0"/>
            <geometry>
                <box size="0.33853061439692944 0.3921818580946256 0.4963904401241285" />
            </geometry>
        </collision>
    </link>
</robot>