<robot name = "robot">
    <link name="0">
        <inertial>
            <origin xyz="0 0 0.35737961969641396" rpy="0 0 0"/>
            <mass value="1" />
            <inertia ixx="100" ixy="0" ixz="0" iyy="100" iyz="0" izz="100" />
        </inertial>
        <visual>
            <origin xyz="0 0 0.35737961969641396" rpy="0 0 0"/>
            <geometry>
                <box size="0.6334784504873784 0.24489570857396148 0.42968860495332184" />
            </geometry>
            <material name="not">
                <color rgba="0 1 1 1"/>
            </material>
        </visual>
        <collision>
            <origin xyz="0 0 0.35737961969641396" rpy="0 0 0"/>
            <geometry>
                <box size="0.6334784504873784 0.24489570857396148 0.42968860495332184" />
            </geometry>
        </collision>
    </link>
    <joint name="0_1" type="revolute">
       <parent link="0"/>
       <child  link="1"/>
       <origin rpy="0 0 0" xyz="0 0.12244785428698074 0.35737961969641396" />
     <axis xyz="0 1 0"/>
       <limit effort="0.0" lower="-3.14159" upper="3.14159" velocity="0.0"/>
    </joint>
    <link name="1">
        <inertial>
            <origin xyz="0 0.331370585664677 0.0" rpy="0 0 0"/>
            <mass value="1" />
            <inertia ixx="100" ixy="0" ixz="0" iyy="100" iyz="0" izz="100" />
        </inertial>
        <visual>
            <origin xyz="0 0.331370585664677 0.0" rpy="0 0 0"/>
            <geometry>
                <box size="0.11682439303553394 0.662741171329354 0.31228066026421886" />
            </geometry>
            <material name="sensor">
                <color rgba="0 1 0 1"/>
            </material>
        </visual>
        <collision>
            <origin xyz="0 0.331370585664677 0.0" rpy="0 0 0"/>
            <geometry>
                <box size="0.11682439303553394 0.662741171329354 0.31228066026421886" />
            </geometry>
        </collision>
    </link>
    <joint name="1_3" type="revolute">
       <parent link="1"/>
       <child  link="3"/>
       <origin rpy="0 0 0" xyz="0 0.6627411713293541 0.0" />
     <axis xyz="1 0 0"/>
       <limit effort="0.0" lower="-3.14159" upper="3.14159" velocity="0.0"/>
    </joint>
    <link name="3">
        <inertial>
            <origin xyz="0 0.1329098584181002 0.0" rpy="0 0 0"/>
            <mass value="1" />
            <inertia ixx="100" ixy="0" ixz="0" iyy="100" iyz="0" izz="100" />
        </inertial>
        <visual>
            <origin xyz="0 0.1329098584181002 0.0" rpy="0 0 0"/>
            <geometry>
                <box size="0.7465158900631942 0.2658197168362004 0.4876639971332798" />
            </geometry>
            <material name="not">
                <color rgba="0 1 1 1"/>
            </material>
        </visual>
        <collision>
            <origin xyz="0 0.1329098584181002 0.0" rpy="0 0 0"/>
            <geometry>
                <box size="0.7465158900631942 0.2658197168362004 0.4876639971332798" />
            </geometry>
        </collision>
    </link>
    <joint name="1_2" type="revolute">
       <parent link="1"/>
       <child  link="2"/>
       <origin rpy="0 0 0" xyz="-0.05841219651776697 0.331370585664677 0.0" />
     <axis xyz="0 1 0"/>
       <limit effort="0.0" lower="-3.14159" upper="3.14159" velocity="0.0"/>
    </joint>
    <link name="2">
        <inertial>
            <origin xyz="-0.0943733333723899 0.0 0.0" rpy="0 0 0"/>
            <mass value="1" />
            <inertia ixx="100" ixy="0" ixz="0" iyy="100" iyz="0" izz="100" />
        </inertial>
        <visual>
            <origin xyz="-0.0943733333723899 0.0 0.0" rpy="0 0 0"/>
            <geometry>
                <box size="0.1887466667447798 0.16914279771639962 0.6479872117408518" />
            </geometry>
            <material name="sensor">
                <color rgba="0 1 0 1"/>
            </material>
        </visual>
        <collision>
            <origin xyz="-0.0943733333723899 0.0 0.0" rpy="0 0 0"/>
            <geometry>
                <box size="0.1887466667447798 0.16914279771639962 0.6479872117408518" />
            </geometry>
        </collision>
    </link>
</robot>