<robot name = "robot">
    <link name="0">
        <inertial>
            <origin xyz="0 0 0.22684582673072795" rpy="0 0 0"/>
            <mass value="1" />
            <inertia ixx="100" ixy="0" ixz="0" iyy="100" iyz="0" izz="100" />
        </inertial>
        <visual>
            <origin xyz="0 0 0.22684582673072795" rpy="0 0 0"/>
            <geometry>
                <box size="0.9550006313213332 0.3646358853618661 0.22046232299623747" />
            </geometry>
            <material name="not">
                <color rgba="0 1 1 1"/>
            </material>
        </visual>
        <collision>
            <origin xyz="0 0 0.22684582673072795" rpy="0 0 0"/>
            <geometry>
                <box size="0.9550006313213332 0.3646358853618661 0.22046232299623747" />
            </geometry>
        </collision>
    </link>
    <joint name="0_6" type="revolute">
       <parent link="0"/>
       <child  link="6"/>
       <origin rpy="0 0 0" xyz="0 0 0.3370769882288467" />
     <axis xyz="0 0 1"/>
       <limit effort="0.0" lower="-3.14159" upper="3.14159" velocity="0.0"/>
    </joint>
    <link name="6">
        <inertial>
            <origin xyz="0 0 0.10634489979398304" rpy="0 0 0"/>
            <mass value="1" />
            <inertia ixx="100" ixy="0" ixz="0" iyy="100" iyz="0" izz="100" />
        </inertial>
        <visual>
            <origin xyz="0 0 0.10634489979398304" rpy="0 0 0"/>
            <geometry>
                <box size="0.6711554470705893 0.4283386772358474 0.21268979958796608" />
            </geometry>
            <material name="not">
                <color rgba="0 1 1 1"/>
            </material>
        </visual>
        <collision>
            <origin xyz="0 0 0.10634489979398304" rpy="0 0 0"/>
            <geometry>
                <box size="0.6711554470705893 0.4283386772358474 0.21268979958796608" />
            </geometry>
        </collision>
    </link>
    <joint name="6_7" type="revolute">
       <parent link="6"/>
       <child  link="7"/>
       <origin rpy="0 0 0" xyz="0 0.2141693386179237 0.10634489979398304" />
     <axis xyz="1 0 0"/>
       <limit effort="0.0" lower="-3.14159" upper="3.14159" velocity="0.0"/>
    </joint>
    <link name="7">
        <inertial>
            <origin xyz="0 0.3580599413940981 0.0" rpy="0 0 0"/>
            <mass value="1" />
            <inertia ixx="100" ixy="0" ixz="0" iyy="100" iyz="0" izz="100" />
        </inertial>
        <visual>
            <origin xyz="0 0.3580599413940981 0.0" rpy="0 0 0"/>
            <geometry>
                <box size="0.15444662376869212 0.7161198827881962 0.6602565151913709" />
            </geometry>
            <material name="sensor">
                <color rgba="0 1 0 1"/>
            </material>
        </visual>
        <collision>
            <origin xyz="0 0.3580599413940981 0.0" rpy="0 0 0"/>
            <geometry>
                <box size="0.15444662376869212 0.7161198827881962 0.6602565151913709" />
            </geometry>
        </collision>
    </link>
    <joint name="0_1" type="revolute">
       <parent link="0"/>
       <child  link="1"/>
       <origin rpy="0 0 0" xyz="-0.4775003156606666 0 0.22684582673072795" />
     <axis xyz="1 0 0"/>
       <limit effort="0.0" lower="-3.14159" upper="3.14159" velocity="0.0"/>
    </joint>
    <link name="1">
        <inertial>
            <origin xyz="-0.2169625378740409 0 0.0" rpy="0 0 0"/>
            <mass value="1" />
            <inertia ixx="100" ixy="0" ixz="0" iyy="100" iyz="0" izz="100" />
        </inertial>
        <visual>
            <origin xyz="-0.2169625378740409 0 0.0" rpy="0 0 0"/>
            <geometry>
                <box size="0.4339250757480817 0.6358422214725404 0.08674985767024423" />
            </geometry>
            <material name="sensor">
                <color rgba="0 1 0 1"/>
            </material>
        </visual>
        <collision>
            <origin xyz="-0.2169625378740409 0 0.0" rpy="0 0 0"/>
            <geometry>
                <box size="0.4339250757480817 0.6358422214725404 0.08674985767024423" />
            </geometry>
        </collision>
    </link>
    <joint name="1_2" type="revolute">
       <parent link="1"/>
       <child  link="2"/>
       <origin rpy="0 0 0" xyz="-0.43392507574808176 0 0.0" />
     <axis xyz="0 1 0"/>
       <limit effort="0.0" lower="-3.14159" upper="3.14159" velocity="0.0"/>
    </joint>
    <link name="2">
        <inertial>
            <origin xyz="-0.27433002199338963 0 0.0" rpy="0 0 0"/>
            <mass value="1" />
            <inertia ixx="100" ixy="0" ixz="0" iyy="100" iyz="0" izz="100" />
        </inertial>
        <visual>
            <origin xyz="-0.27433002199338963 0 0.0" rpy="0 0 0"/>
            <geometry>
                <box size="0.5486600439867791 0.1309838520094504 0.014242938156105556" />
            </geometry>
            <material name="not">
                <color rgba="0 1 1 1"/>
            </material>
        </visual>
        <collision>
            <origin xyz="-0.27433002199338963 0 0.0" rpy="0 0 0"/>
            <geometry>
                <box size="0.5486600439867791 0.1309838520094504 0.014242938156105556" />
            </geometry>
        </collision>
    </link>
    <joint name="2_3" type="revolute">
       <parent link="2"/>
       <child  link="3"/>
       <origin rpy="0 0 0" xyz="-0.5486600439867791 0 0.0" />
     <axis xyz="0 0 1"/>
       <limit effort="0.0" lower="-3.14159" upper="3.14159" velocity="0.0"/>
    </joint>
    <link name="3">
        <inertial>
            <origin xyz="-0.12968239763510514 0 0.0" rpy="0 0 0"/>
            <mass value="1" />
            <inertia ixx="100" ixy="0" ixz="0" iyy="100" iyz="0" izz="100" />
        </inertial>
        <visual>
            <origin xyz="-0.12968239763510514 0 0.0" rpy="0 0 0"/>
            <geometry>
                <box size="0.25936479527021017 0.41901255275454363 0.13107367650348334" />
            </geometry>
            <material name="sensor">
                <color rgba="0 1 0 1"/>
            </material>
        </visual>
        <collision>
            <origin xyz="-0.12968239763510514 0 0.0" rpy="0 0 0"/>
            <geometry>
                <box size="0.25936479527021017 0.41901255275454363 0.13107367650348334" />
            </geometry>
        </collision>
    </link>
    <joint name="3_4" type="revolute">
       <parent link="3"/>
       <child  link="4"/>
       <origin rpy="0 0 0" xyz="-0.12968239763510514 0 -0.06553683825174167" />
     <axis xyz="0 1 0"/>
       <limit effort="0.0" lower="-3.14159" upper="3.14159" velocity="0.0"/>
    </joint>
    <link name="4">
        <inertial>
            <origin xyz="0.0 0 -0.009352433952710015" rpy="0 0 0"/>
            <mass value="1" />
            <inertia ixx="100" ixy="0" ixz="0" iyy="100" iyz="0" izz="100" />
        </inertial>
        <visual>
            <origin xyz="0.0 0 -0.009352433952710015" rpy="0 0 0"/>
            <geometry>
                <box size="0.5318249624359338 0.5235065855871663 0.01870486790542003" />
            </geometry>
            <material name="not">
                <color rgba="0 1 1 1"/>
            </material>
        </visual>
        <collision>
            <origin xyz="0.0 0 -0.009352433952710015" rpy="0 0 0"/>
            <geometry>
                <box size="0.5318249624359338 0.5235065855871663 0.01870486790542003" />
            </geometry>
        </collision>
    </link>
    <joint name="4_5" type="revolute">
       <parent link="4"/>
       <child  link="5"/>
       <origin rpy="0 0 0" xyz="0.0 0 -0.01870486790542003" />
     <axis xyz="1 0 0"/>
       <limit effort="0.0" lower="-3.14159" upper="3.14159" velocity="0.0"/>
    </joint>
    <link name="5">
        <inertial>
            <origin xyz="0.0 0 -0.06081097719209033" rpy="0 0 0"/>
            <mass value="1" />
            <inertia ixx="100" ixy="0" ixz="0" iyy="100" iyz="0" izz="100" />
        </inertial>
        <visual>
            <origin xyz="0.0 0 -0.06081097719209033" rpy="0 0 0"/>
            <geometry>
                <box size="0.8399997833932058 0.13713443589685148 0.12162195438418066" />
            </geometry>
            <material name="sensor">
                <color rgba="0 1 0 1"/>
            </material>
        </visual>
        <collision>
            <origin xyz="0.0 0 -0.06081097719209033" rpy="0 0 0"/>
            <geometry>
                <box size="0.8399997833932058 0.13713443589685148 0.12162195438418066" />
            </geometry>
        </collision>
    </link>
</robot>