<robot name = "robot">
    <link name="0">
        <inertial>
            <origin xyz="0 0 0.20995480637147712" rpy="0 0 0"/>
            <mass value="1" />
            <inertia ixx="100" ixy="0" ixz="0" iyy="100" iyz="0" izz="100" />
        </inertial>
        <visual>
            <origin xyz="0 0 0.20995480637147712" rpy="0 0 0"/>
            <geometry>
                <box size="0.7609624449125756 0.47224524357611664 0.37961522332372777" />
            </geometry>
            <material name="sensor">
                <color rgba="0 1 0 1"/>
            </material>
        </visual>
        <collision>
            <origin xyz="0 0 0.20995480637147712" rpy="0 0 0"/>
            <geometry>
                <box size="0.7609624449125756 0.47224524357611664 0.37961522332372777" />
            </geometry>
        </collision>
    </link>
    <joint name="0_2" type="revolute">
       <parent link="0"/>
       <child  link="2"/>
       <origin rpy="0 0 0" xyz="0.3804812224562878 0 0.20995480637147712" />
     <axis xyz="0 0 1"/>
       <limit effort="0.0" lower="-3.14159" upper="3.14159" velocity="0.0"/>
    </joint>
    <link name="2">
        <inertial>
            <origin xyz="0.29557671750065195 0 0.0" rpy="0 0 0"/>
            <mass value="1" />
            <inertia ixx="100" ixy="0" ixz="0" iyy="100" iyz="0" izz="100" />
        </inertial>
        <visual>
            <origin xyz="0.29557671750065195 0 0.0" rpy="0 0 0"/>
            <geometry>
                <box size="0.5911534350013039 0.10222715811004823 0.3174296321763842" />
            </geometry>
            <material name="not">
                <color rgba="0 1 1 1"/>
            </material>
        </visual>
        <collision>
            <origin xyz="0.29557671750065195 0 0.0" rpy="0 0 0"/>
            <geometry>
                <box size="0.5911534350013039 0.10222715811004823 0.3174296321763842" />
            </geometry>
        </collision>
    </link>
    <joint name="0_1" type="revolute">
       <parent link="0"/>
       <child  link="1"/>
       <origin rpy="0 0 0" xyz="0 0 0.020147194709613236" />
     <axis xyz="1 0 0"/>
       <limit effort="0.0" lower="-3.14159" upper="3.14159" velocity="0.0"/>
    </joint>
    <link name="1">
        <inertial>
            <origin xyz="0 0 -0.0010530266755553463" rpy="0 0 0"/>
            <mass value="1" />
            <inertia ixx="100" ixy="0" ixz="0" iyy="100" iyz="0" izz="100" />
        </inertial>
        <visual>
            <origin xyz="0 0 -0.0010530266755553463" rpy="0 0 0"/>
            <geometry>
                <box size="0.43276706790505337 0.762280082457942 0.0021060533511106927" />
            </geometry>
            <material name="sensor">
                <color rgba="0 1 0 1"/>
            </material>
        </visual>
        <collision>
            <origin xyz="0 0 -0.0010530266755553463" rpy="0 0 0"/>
            <geometry>
                <box size="0.43276706790505337 0.762280082457942 0.0021060533511106927" />
            </geometry>
        </collision>
    </link>
</robot>