<robot name = "robot">
    <link name="0">
        <inertial>
            <origin xyz="0 0 0.954394476089788" rpy="0 0 0"/>
            <mass value="1" />
            <inertia ixx="100" ixy="0" ixz="0" iyy="100" iyz="0" izz="100" />
        </inertial>
        <visual>
            <origin xyz="0 0 0.954394476089788" rpy="0 0 0"/>
            <geometry>
                <box size="0.45282225345616867 0.7077582566508612 0.6237130310772351" />
            </geometry>
            <material name="not">
                <color rgba="0 1 1 1"/>
            </material>
        </visual>
        <collision>
            <origin xyz="0 0 0.954394476089788" rpy="0 0 0"/>
            <geometry>
                <box size="0.45282225345616867 0.7077582566508612 0.6237130310772351" />
            </geometry>
        </collision>
    </link>
    <joint name="0_1" type="revolute">
       <parent link="0"/>
       <child  link="1"/>
       <origin rpy="0 0 0" xyz="0 0 0.6425379605511705" />
     <axis xyz="0 1 0"/>
       <limit effort="0.0" lower="-3.14159" upper="3.14159" velocity="0.0"/>
    </joint>
    <link name="1">
        <inertial>
            <origin xyz="0 0 -0.26235091034656" rpy="0 0 0"/>
            <mass value="1" />
            <inertia ixx="100" ixy="0" ixz="0" iyy="100" iyz="0" izz="100" />
        </inertial>
        <visual>
            <origin xyz="0 0 -0.26235091034656" rpy="0 0 0"/>
            <geometry>
                <box size="0.34438181305301196 0.35479320505791223 0.52470182069312" />
            </geometry>
            <material name="not">
                <color rgba="0 1 1 1"/>
            </material>
        </visual>
        <collision>
            <origin xyz="0 0 -0.26235091034656" rpy="0 0 0"/>
            <geometry>
                <box size="0.34438181305301196 0.35479320505791223 0.52470182069312" />
            </geometry>
        </collision>
    </link>
    <joint name="1_3" type="revolute">
       <parent link="1"/>
       <child  link="3"/>
       <origin rpy="0 0 0" xyz="0 0 -0.52470182069312" />
     <axis xyz="0 1 0"/>
       <limit effort="0.0" lower="-3.14159" upper="3.14159" velocity="0.0"/>
    </joint>
    <link name="3">
        <inertial>
            <origin xyz="0 0 -0.05331530484862945" rpy="0 0 0"/>
            <mass value="1" />
            <inertia ixx="100" ixy="0" ixz="0" iyy="100" iyz="0" izz="100" />
        </inertial>
        <visual>
            <origin xyz="0 0 -0.05331530484862945" rpy="0 0 0"/>
            <geometry>
                <box size="0.6303992934263946 0.788009549780357 0.1066306096972589" />
            </geometry>
            <material name="sensor">
                <color rgba="0 1 0 1"/>
            </material>
        </visual>
        <collision>
            <origin xyz="0 0 -0.05331530484862945" rpy="0 0 0"/>
            <geometry>
                <box size="0.6303992934263946 0.788009549780357 0.1066306096972589" />
            </geometry>
        </collision>
    </link>
    <joint name="3_7" type="revolute">
       <parent link="3"/>
       <child  link="7"/>
       <origin rpy="0 0 0" xyz="0 0.3940047748901785 -0.05331530484862945" />
     <axis xyz="0 0 1"/>
       <limit effort="0.0" lower="-3.14159" upper="3.14159" velocity="0.0"/>
    </joint>
    <link name="7">
        <inertial>
            <origin xyz="0 5.805609591513772e-05 0.0" rpy="0 0 0"/>
            <mass value="1" />
            <inertia ixx="100" ixy="0" ixz="0" iyy="100" iyz="0" izz="100" />
        </inertial>
        <visual>
            <origin xyz="0 5.805609591513772e-05 0.0" rpy="0 0 0"/>
            <geometry>
                <box size="0.36381341842000137 0.00011611219183027544 0.11949940615351196" />
            </geometry>
            <material name="not">
                <color rgba="0 1 1 1"/>
            </material>
        </visual>
        <collision>
            <origin xyz="0 5.805609591513772e-05 0.0" rpy="0 0 0"/>
            <geometry>
                <box size="0.36381341842000137 0.00011611219183027544 0.11949940615351196" />
            </geometry>
        </collision>
    </link>
    <joint name="1_4" type="revolute">
       <parent link="1"/>
       <child  link="4"/>
       <origin rpy="0 0 0" xyz="0 -0.17739660252895612 -0.26235091034656" />
     <axis xyz="1 0 0"/>
       <limit effort="0.0" lower="-3.14159" upper="3.14159" velocity="0.0"/>
    </joint>
    <link name="4">
        <inertial>
            <origin xyz="0 -0.21032291015540405 0.0" rpy="0 0 0"/>
            <mass value="1" />
            <inertia ixx="100" ixy="0" ixz="0" iyy="100" iyz="0" izz="100" />
        </inertial>
        <visual>
            <origin xyz="0 -0.21032291015540405 0.0" rpy="0 0 0"/>
            <geometry>
                <box size="0.05877061817596774 0.4206458203108081 0.14120240847136756" />
            </geometry>
            <material name="not">
                <color rgba="0 1 1 1"/>
            </material>
        </visual>
        <collision>
            <origin xyz="0 -0.21032291015540405 0.0" rpy="0 0 0"/>
            <geometry>
                <box size="0.05877061817596774 0.4206458203108081 0.14120240847136756" />
            </geometry>
        </collision>
    </link>
    <joint name="4_5" type="revolute">
       <parent link="4"/>
       <child  link="5"/>
       <origin rpy="0 0 0" xyz="0 -0.21032291015540405 -0.07060120423568378" />
     <axis xyz="0 0 1"/>
       <limit effort="0.0" lower="-3.14159" upper="3.14159" velocity="0.0"/>
    </joint>
    <link name="5">
        <inertial>
            <origin xyz="0 0.0 -0.07325318125099073" rpy="0 0 0"/>
            <mass value="1" />
            <inertia ixx="100" ixy="0" ixz="0" iyy="100" iyz="0" izz="100" />
        </inertial>
        <visual>
            <origin xyz="0 0.0 -0.07325318125099073" rpy="0 0 0"/>
            <geometry>
                <box size="0.29102261714697497 0.40378941522434697 0.14650636250198146" />
            </geometry>
            <material name="not">
                <color rgba="0 1 1 1"/>
            </material>
        </visual>
        <collision>
            <origin xyz="0 0.0 -0.07325318125099073" rpy="0 0 0"/>
            <geometry>
                <box size="0.29102261714697497 0.40378941522434697 0.14650636250198146" />
            </geometry>
        </collision>
    </link>
    <joint name="5_6" type="revolute">
       <parent link="5"/>
       <child  link="6"/>
       <origin rpy="0 0 0" xyz="-0.14551130857348749 0.0 -0.07325318125099073" />
     <axis xyz="1 0 0"/>
       <limit effort="0.0" lower="-3.14159" upper="3.14159" velocity="0.0"/>
    </joint>
    <link name="6">
        <inertial>
            <origin xyz="-0.3669654067803707 0.0 0.0" rpy="0 0 0"/>
            <mass value="1" />
            <inertia ixx="100" ixy="0" ixz="0" iyy="100" iyz="0" izz="100" />
        </inertial>
        <visual>
            <origin xyz="-0.3669654067803707 0.0 0.0" rpy="0 0 0"/>
            <geometry>
                <box size="0.7339308135607414 0.041419853029814546 0.10876911572911863" />
            </geometry>
            <material name="not">
                <color rgba="0 1 1 1"/>
            </material>
        </visual>
        <collision>
            <origin xyz="-0.3669654067803707 0.0 0.0" rpy="0 0 0"/>
            <geometry>
                <box size="0.7339308135607414 0.041419853029814546 0.10876911572911863" />
            </geometry>
        </collision>
    </link>
    <joint name="4_8" type="revolute">
       <parent link="4"/>
       <child  link="8"/>
       <origin rpy="0 0 0" xyz="0 -0.42064582031080816 0.0" />
     <axis xyz="0 0 1"/>
       <limit effort="0.0" lower="-3.14159" upper="3.14159" velocity="0.0"/>
    </joint>
    <link name="8">
        <inertial>
            <origin xyz="0 -0.3290543222552865 0.0" rpy="0 0 0"/>
            <mass value="1" />
            <inertia ixx="100" ixy="0" ixz="0" iyy="100" iyz="0" izz="100" />
        </inertial>
        <visual>
            <origin xyz="0 -0.3290543222552865 0.0" rpy="0 0 0"/>
            <geometry>
                <box size="0.8015557115384049 0.658108644510573 0.2624436322187057" />
            </geometry>
            <material name="sensor">
                <color rgba="0 1 0 1"/>
            </material>
        </visual>
        <collision>
            <origin xyz="0 -0.3290543222552865 0.0" rpy="0 0 0"/>
            <geometry>
                <box size="0.8015557115384049 0.658108644510573 0.2624436322187057" />
            </geometry>
        </collision>
    </link>
    <joint name="4_9" type="revolute">
       <parent link="4"/>
       <child  link="9"/>
       <origin rpy="0 0 0" xyz="-0.02938530908798387 -0.21032291015540405 0.0" />
     <axis xyz="0 0 1"/>
       <limit effort="0.0" lower="-3.14159" upper="3.14159" velocity="0.0"/>
    </joint>
    <link name="9">
        <inertial>
            <origin xyz="-0.48935936050514905 0.0 0.0" rpy="0 0 0"/>
            <mass value="1" />
            <inertia ixx="100" ixy="0" ixz="0" iyy="100" iyz="0" izz="100" />
        </inertial>
        <visual>
            <origin xyz="-0.48935936050514905 0.0 0.0" rpy="0 0 0"/>
            <geometry>
                <box size="0.9787187210102981 0.047730772492347806 0.13196756615144345" />
            </geometry>
            <material name="sensor">
                <color rgba="0 1 0 1"/>
            </material>
        </visual>
        <collision>
            <origin xyz="-0.48935936050514905 0.0 0.0" rpy="0 0 0"/>
            <geometry>
                <box size="0.9787187210102981 0.047730772492347806 0.13196756615144345" />
            </geometry>
        </collision>
    </link>
    <joint name="1_2" type="revolute">
       <parent link="1"/>
       <child  link="2"/>
       <origin rpy="0 0 0" xyz="-0.17219090652650598 0 -0.26235091034656" />
     <axis xyz="0 0 1"/>
       <limit effort="0.0" lower="-3.14159" upper="3.14159" velocity="0.0"/>
    </joint>
    <link name="2">
        <inertial>
            <origin xyz="-0.08873888775249428 0 0.0" rpy="0 0 0"/>
            <mass value="1" />
            <inertia ixx="100" ixy="0" ixz="0" iyy="100" iyz="0" izz="100" />
        </inertial>
        <visual>
            <origin xyz="-0.08873888775249428 0 0.0" rpy="0 0 0"/>
            <geometry>
                <box size="0.17747777550498856 0.07819623222057348 0.14886804462324854" />
            </geometry>
            <material name="sensor">
                <color rgba="0 1 0 1"/>
            </material>
        </visual>
        <collision>
            <origin xyz="-0.08873888775249428 0 0.0" rpy="0 0 0"/>
            <geometry>
                <box size="0.17747777550498856 0.07819623222057348 0.14886804462324854" />
            </geometry>
        </collision>
    </link>
</robot>