<robot name = "robot">
    <link name="0">
        <inertial>
            <origin xyz="0 0 0.24988239085478592" rpy="0 0 0"/>
            <mass value="1" />
            <inertia ixx="100" ixy="0" ixz="0" iyy="100" iyz="0" izz="100" />
        </inertial>
        <visual>
            <origin xyz="0 0 0.24988239085478592" rpy="0 0 0"/>
            <geometry>
                <box size="0.32259815609842624 0.23756146211933615 0.1931392359583871" />
            </geometry>
            <material name="sensor">
                <color rgba="0 1 0 1"/>
            </material>
        </visual>
        <collision>
            <origin xyz="0 0 0.24988239085478592" rpy="0 0 0"/>
            <geometry>
                <box size="0.32259815609842624 0.23756146211933615 0.1931392359583871" />
            </geometry>
        </collision>
    </link>
    <joint name="0_1" type="revolute">
       <parent link="0"/>
       <child  link="1"/>
       <origin rpy="0 0 0" xyz="0.16129907804921312 0 0.24988239085478592" />
     <axis xyz="0 1 0"/>
       <limit effort="0.0" lower="-3.14159" upper="3.14159" velocity="0.0"/>
    </joint>
    <link name="1">
        <inertial>
            <origin xyz="0.1524339061949978 0 0.0" rpy="0 0 0"/>
            <mass value="1" />
            <inertia ixx="100" ixy="0" ixz="0" iyy="100" iyz="0" izz="100" />
        </inertial>
        <visual>
            <origin xyz="0.1524339061949978 0 0.0" rpy="0 0 0"/>
            <geometry>
                <box size="0.3048678123899956 0.5270467364524493 0.4910530416107093" />
            </geometry>
            <material name="not">
                <color rgba="0 1 1 1"/>
            </material>
        </visual>
        <collision>
            <origin xyz="0.1524339061949978 0 0.0" rpy="0 0 0"/>
            <geometry>
                <box size="0.3048678123899956 0.5270467364524493 0.4910530416107093" />
            </geometry>
        </collision>
    </link>
    <joint name="1_2" type="revolute">
       <parent link="1"/>
       <child  link="2"/>
       <origin rpy="0 0 0" xyz="0.3048678123899956 0 0.0" />
     <axis xyz="0 1 0"/>
       <limit effort="0.0" lower="-3.14159" upper="3.14159" velocity="0.0"/>
    </joint>
    <link name="2">
        <inertial>
            <origin xyz="0.4360229130331896 0 0.0" rpy="0 0 0"/>
            <mass value="1" />
            <inertia ixx="100" ixy="0" ixz="0" iyy="100" iyz="0" izz="100" />
        </inertial>
        <visual>
            <origin xyz="0.4360229130331896 0 0.0" rpy="0 0 0"/>
            <geometry>
                <box size="0.872045826066379 0.4244286162229982 0.4500873394346646" />
            </geometry>
            <material name="not">
                <color rgba="0 1 1 1"/>
            </material>
        </visual>
        <collision>
            <origin xyz="0.4360229130331896 0 0.0" rpy="0 0 0"/>
            <geometry>
                <box size="0.872045826066379 0.4244286162229982 0.4500873394346646" />
            </geometry>
        </collision>
    </link>
</robot>