<robot name = "robot">
    <link name="0">
        <inertial>
            <origin xyz="0 0 0.8174104069416209" rpy="0 0 0"/>
            <mass value="1" />
            <inertia ixx="100" ixy="0" ixz="0" iyy="100" iyz="0" izz="100" />
        </inertial>
        <visual>
            <origin xyz="0 0 0.8174104069416209" rpy="0 0 0"/>
            <geometry>
                <box size="0.937502334100213 0.061026943100534026 0.504096562551434" />
            </geometry>
            <material name="not">
                <color rgba="0 1 1 1"/>
            </material>
        </visual>
        <collision>
            <origin xyz="0 0 0.8174104069416209" rpy="0 0 0"/>
            <geometry>
                <box size="0.937502334100213 0.061026943100534026 0.504096562551434" />
            </geometry>
        </collision>
    </link>
    <joint name="0_1" type="revolute">
       <parent link="0"/>
       <child  link="1"/>
       <origin rpy="0 0 0" xyz="-0.4687511670501065 0 0.8174104069416209" />
     <axis xyz="0 0 1"/>
       <limit effort="0.0" lower="-3.14159" upper="3.14159" velocity="0.0"/>
    </joint>
    <link name="1">
        <inertial>
            <origin xyz="-0.03038292169051532 0 0.0" rpy="0 0 0"/>
            <mass value="1" />
            <inertia ixx="100" ixy="0" ixz="0" iyy="100" iyz="0" izz="100" />
        </inertial>
        <visual>
            <origin xyz="-0.03038292169051532 0 0.0" rpy="0 0 0"/>
            <geometry>
                <box size="0.06076584338103064 0.4305558989466314 0.09058739376492753" />
            </geometry>
            <material name="sensor">
                <color rgba="0 1 0 1"/>
            </material>
        </visual>
        <collision>
            <origin xyz="-0.03038292169051532 0 0.0" rpy="0 0 0"/>
            <geometry>
                <box size="0.06076584338103064 0.4305558989466314 0.09058739376492753" />
            </geometry>
        </collision>
    </link>
    <joint name="1_2" type="revolute">
       <parent link="1"/>
       <child  link="2"/>
       <origin rpy="0 0 0" xyz="-0.03038292169051532 0 -0.04529369688246376" />
     <axis xyz="1 0 0"/>
       <limit effort="0.0" lower="-3.14159" upper="3.14159" velocity="0.0"/>
    </joint>
    <link name="2">
        <inertial>
            <origin xyz="0.0 0 -0.15461379418447452" rpy="0 0 0"/>
            <mass value="1" />
            <inertia ixx="100" ixy="0" ixz="0" iyy="100" iyz="0" izz="100" />
        </inertial>
        <visual>
            <origin xyz="0.0 0 -0.15461379418447452" rpy="0 0 0"/>
            <geometry>
                <box size="0.0011979197211340331 0.26592927213697315 0.30922758836894904" />
            </geometry>
            <material name="sensor">
                <color rgba="0 1 0 1"/>
            </material>
        </visual>
        <collision>
            <origin xyz="0.0 0 -0.15461379418447452" rpy="0 0 0"/>
            <geometry>
                <box size="0.0011979197211340331 0.26592927213697315 0.30922758836894904" />
            </geometry>
        </collision>
    </link>
    <joint name="2_3" type="revolute">
       <parent link="2"/>
       <child  link="3"/>
       <origin rpy="0 0 0" xyz="0.0 0 -0.30922758836894904" />
     <axis xyz="0 0 1"/>
       <limit effort="0.0" lower="-3.14159" upper="3.14159" velocity="0.0"/>
    </joint>
    <link name="3">
        <inertial>
            <origin xyz="0.0 0 -0.1285313810922113" rpy="0 0 0"/>
            <mass value="1" />
            <inertia ixx="100" ixy="0" ixz="0" iyy="100" iyz="0" izz="100" />
        </inertial>
        <visual>
            <origin xyz="0.0 0 -0.1285313810922113" rpy="0 0 0"/>
            <geometry>
                <box size="0.8017433993188108 0.4468450600417184 0.2570627621844226" />
            </geometry>
            <material name="not">
                <color rgba="0 1 1 1"/>
            </material>
        </visual>
        <collision>
            <origin xyz="0.0 0 -0.1285313810922113" rpy="0 0 0"/>
            <geometry>
                <box size="0.8017433993188108 0.4468450600417184 0.2570627621844226" />
            </geometry>
        </collision>
    </link>
</robot>