<robot name = "robot">
    <link name="0">
        <inertial>
            <origin xyz="0 0 0.881437043979886" rpy="0 0 0"/>
            <mass value="1" />
            <inertia ixx="100" ixy="0" ixz="0" iyy="100" iyz="0" izz="100" />
        </inertial>
        <visual>
            <origin xyz="0 0 0.881437043979886" rpy="0 0 0"/>
            <geometry>
                <box size="0.42559895300493644 0.021322627224596546 0.5913428817036356" />
            </geometry>
            <material name="not">
                <color rgba="0 1 1 1"/>
            </material>
        </visual>
        <collision>
            <origin xyz="0 0 0.881437043979886" rpy="0 0 0"/>
            <geometry>
                <box size="0.42559895300493644 0.021322627224596546 0.5913428817036356" />
            </geometry>
        </collision>
    </link>
    <joint name="0_1" type="revolute">
       <parent link="0"/>
       <child  link="1"/>
       <origin rpy="0 0 0" xyz="0 -0.010661313612298273 0.881437043979886" />
     <axis xyz="0 0 1"/>
       <limit effort="0.0" lower="-3.14159" upper="3.14159" velocity="0.0"/>
    </joint>
    <link name="1">
        <inertial>
            <origin xyz="0 -0.25960484504949277 0.0" rpy="0 0 0"/>
            <mass value="1" />
            <inertia ixx="100" ixy="0" ixz="0" iyy="100" iyz="0" izz="100" />
        </inertial>
        <visual>
            <origin xyz="0 -0.25960484504949277 0.0" rpy="0 0 0"/>
            <geometry>
                <box size="0.3661839665433979 0.5192096900989855 0.9214503475918693" />
            </geometry>
            <material name="sensor">
                <color rgba="0 1 0 1"/>
            </material>
        </visual>
        <collision>
            <origin xyz="0 -0.25960484504949277 0.0" rpy="0 0 0"/>
            <geometry>
                <box size="0.3661839665433979 0.5192096900989855 0.9214503475918693" />
            </geometry>
        </collision>
    </link>
    <joint name="1_2" type="revolute">
       <parent link="1"/>
       <child  link="2"/>
       <origin rpy="0 0 0" xyz="-0.18309198327169895 -0.25960484504949277 0.0" />
     <axis xyz="0 1 0"/>
       <limit effort="0.0" lower="-3.14159" upper="3.14159" velocity="0.0"/>
    </joint>
    <link name="2">
        <inertial>
            <origin xyz="-0.05058093780657841 0.0 0.0" rpy="0 0 0"/>
            <mass value="1" />
            <inertia ixx="100" ixy="0" ixz="0" iyy="100" iyz="0" izz="100" />
        </inertial>
        <visual>
            <origin xyz="-0.05058093780657841 0.0 0.0" rpy="0 0 0"/>
            <geometry>
                <box size="0.10116187561315682 0.3059223607062649 0.8406116871188408" />
            </geometry>
            <material name="not">
                <color rgba="0 1 1 1"/>
            </material>
        </visual>
        <collision>
            <origin xyz="-0.05058093780657841 0.0 0.0" rpy="0 0 0"/>
            <geometry>
                <box size="0.10116187561315682 0.3059223607062649 0.8406116871188408" />
            </geometry>
        </collision>
    </link>
</robot>