<robot name = "robot">
    <link name="0">
        <inertial>
            <origin xyz="0 0 0.2841765785526914" rpy="0 0 0"/>
            <mass value="1" />
            <inertia ixx="100" ixy="0" ixz="0" iyy="100" iyz="0" izz="100" />
        </inertial>
        <visual>
            <origin xyz="0 0 0.2841765785526914" rpy="0 0 0"/>
            <geometry>
                <box size="0.764311345861366 0.7206772713715515 0.4941907536198433" />
            </geometry>
            <material name="not">
                <color rgba="0 1 1 1"/>
            </material>
        </visual>
        <collision>
            <origin xyz="0 0 0.2841765785526914" rpy="0 0 0"/>
            <geometry>
                <box size="0.764311345861366 0.7206772713715515 0.4941907536198433" />
            </geometry>
        </collision>
    </link>
    <joint name="0_2" type="revolute">
       <parent link="0"/>
       <child  link="2"/>
       <origin rpy="0 0 0" xyz="0 0 0.5312719553626131" />
     <axis xyz="1 0 0"/>
       <limit effort="0.0" lower="-3.14159" upper="3.14159" velocity="0.0"/>
    </joint>
    <link name="2">
        <inertial>
            <origin xyz="0 0 0.36839416427112526" rpy="0 0 0"/>
            <mass value="1" />
            <inertia ixx="100" ixy="0" ixz="0" iyy="100" iyz="0" izz="100" />
        </inertial>
        <visual>
            <origin xyz="0 0 0.36839416427112526" rpy="0 0 0"/>
            <geometry>
                <box size="0.6592994893043499 0.06605035622215194 0.7367883285422505" />
            </geometry>
            <material name="not">
                <color rgba="0 1 1 1"/>
            </material>
        </visual>
        <collision>
            <origin xyz="0 0 0.36839416427112526" rpy="0 0 0"/>
            <geometry>
                <box size="0.6592994893043499 0.06605035622215194 0.7367883285422505" />
            </geometry>
        </collision>
    </link>
    <joint name="2_3" type="revolute">
       <parent link="2"/>
       <child  link="3"/>
       <origin rpy="0 0 0" xyz="0 -0.03302517811107597 0.36839416427112526" />
     <axis xyz="1 0 0"/>
       <limit effort="0.0" lower="-3.14159" upper="3.14159" velocity="0.0"/>
    </joint>
    <link name="3">
        <inertial>
            <origin xyz="0 -0.11693313012742013 0.0" rpy="0 0 0"/>
            <mass value="1" />
            <inertia ixx="100" ixy="0" ixz="0" iyy="100" iyz="0" izz="100" />
        </inertial>
        <visual>
            <origin xyz="0 -0.11693313012742013 0.0" rpy="0 0 0"/>
            <geometry>
                <box size="0.02425670494152843 0.23386626025484025 0.4751890578536032" />
            </geometry>
            <material name="sensor">
                <color rgba="0 1 0 1"/>
            </material>
        </visual>
        <collision>
            <origin xyz="0 -0.11693313012742013 0.0" rpy="0 0 0"/>
            <geometry>
                <box size="0.02425670494152843 0.23386626025484025 0.4751890578536032" />
            </geometry>
        </collision>
    </link>
    <joint name="3_5" type="revolute">
       <parent link="3"/>
       <child  link="5"/>
       <origin rpy="0 0 0" xyz="0 -0.23386626025484025 0.0" />
     <axis xyz="1 0 0"/>
       <limit effort="0.0" lower="-3.14159" upper="3.14159" velocity="0.0"/>
    </joint>
    <link name="5">
        <inertial>
            <origin xyz="0 -0.202576046350947 0.0" rpy="0 0 0"/>
            <mass value="1" />
            <inertia ixx="100" ixy="0" ixz="0" iyy="100" iyz="0" izz="100" />
        </inertial>
        <visual>
            <origin xyz="0 -0.202576046350947 0.0" rpy="0 0 0"/>
            <geometry>
                <box size="0.21647616269041814 0.405152092701894 0.6293437403321508" />
            </geometry>
            <material name="not">
                <color rgba="0 1 1 1"/>
            </material>
        </visual>
        <collision>
            <origin xyz="0 -0.202576046350947 0.0" rpy="0 0 0"/>
            <geometry>
                <box size="0.21647616269041814 0.405152092701894 0.6293437403321508" />
            </geometry>
        </collision>
    </link>
    <joint name="0_6" type="revolute">
       <parent link="0"/>
       <child  link="6"/>
       <origin rpy="0 0 0" xyz="0 0 0.03708120174276974" />
     <axis xyz="1 0 0"/>
       <limit effort="0.0" lower="-3.14159" upper="3.14159" velocity="0.0"/>
    </joint>
    <link name="6">
        <inertial>
            <origin xyz="0 0 -0.015441000528008175" rpy="0 0 0"/>
            <mass value="1" />
            <inertia ixx="100" ixy="0" ixz="0" iyy="100" iyz="0" izz="100" />
        </inertial>
        <visual>
            <origin xyz="0 0 -0.015441000528008175" rpy="0 0 0"/>
            <geometry>
                <box size="0.4460225185454515 0.06726317444852647 0.03088200105601635" />
            </geometry>
            <material name="sensor">
                <color rgba="0 1 0 1"/>
            </material>
        </visual>
        <collision>
            <origin xyz="0 0 -0.015441000528008175" rpy="0 0 0"/>
            <geometry>
                <box size="0.4460225185454515 0.06726317444852647 0.03088200105601635" />
            </geometry>
        </collision>
    </link>
    <joint name="0_1" type="revolute">
       <parent link="0"/>
       <child  link="1"/>
       <origin rpy="0 0 0" xyz="0 -0.36033863568577573 0.2841765785526914" />
     <axis xyz="0 0 1"/>
       <limit effort="0.0" lower="-3.14159" upper="3.14159" velocity="0.0"/>
    </joint>
    <link name="1">
        <inertial>
            <origin xyz="0 -0.406109457856197 0.0" rpy="0 0 0"/>
            <mass value="1" />
            <inertia ixx="100" ixy="0" ixz="0" iyy="100" iyz="0" izz="100" />
        </inertial>
        <visual>
            <origin xyz="0 -0.406109457856197 0.0" rpy="0 0 0"/>
            <geometry>
                <box size="0.7338521234769618 0.812218915712394 0.13930761001920433" />
            </geometry>
            <material name="not">
                <color rgba="0 1 1 1"/>
            </material>
        </visual>
        <collision>
            <origin xyz="0 -0.406109457856197 0.0" rpy="0 0 0"/>
            <geometry>
                <box size="0.7338521234769618 0.812218915712394 0.13930761001920433" />
            </geometry>
        </collision>
    </link>
    <joint name="0_7" type="revolute">
       <parent link="0"/>
       <child  link="7"/>
       <origin rpy="0 0 0" xyz="-0.382155672930683 0 0.2841765785526914" />
     <axis xyz="0 0 1"/>
       <limit effort="0.0" lower="-3.14159" upper="3.14159" velocity="0.0"/>
    </joint>
    <link name="7">
        <inertial>
            <origin xyz="-0.3737657716820163 0 0.0" rpy="0 0 0"/>
            <mass value="1" />
            <inertia ixx="100" ixy="0" ixz="0" iyy="100" iyz="0" izz="100" />
        </inertial>
        <visual>
            <origin xyz="-0.3737657716820163 0 0.0" rpy="0 0 0"/>
            <geometry>
                <box size="0.7475315433640326 0.22994171758522275 0.37000324139096785" />
            </geometry>
            <material name="not">
                <color rgba="0 1 1 1"/>
            </material>
        </visual>
        <collision>
            <origin xyz="-0.3737657716820163 0 0.0" rpy="0 0 0"/>
            <geometry>
                <box size="0.7475315433640326 0.22994171758522275 0.37000324139096785" />
            </geometry>
        </collision>
    </link>
</robot>