<robot name = "robot">
    <link name="0">
        <inertial>
            <origin xyz="0 0 0.14371128020388346" rpy="0 0 0"/>
            <mass value="1" />
            <inertia ixx="100" ixy="0" ixz="0" iyy="100" iyz="0" izz="100" />
        </inertial>
        <visual>
            <origin xyz="0 0 0.14371128020388346" rpy="0 0 0"/>
            <geometry>
                <box size="0.9082105307140484 0.7546342096756357 0.27280774179809586" />
            </geometry>
            <material name="sensor">
                <color rgba="0 1 0 1"/>
            </material>
        </visual>
        <collision>
            <origin xyz="0 0 0.14371128020388346" rpy="0 0 0"/>
            <geometry>
                <box size="0.9082105307140484 0.7546342096756357 0.27280774179809586" />
            </geometry>
        </collision>
    </link>
    <joint name="0_1" type="revolute">
       <parent link="0"/>
       <child  link="1"/>
       <origin rpy="0 0 0" xyz="0 0.37731710483781783 0.14371128020388346" />
     <axis xyz="0 1 0"/>
       <limit effort="0.0" lower="-3.14159" upper="3.14159" velocity="0.0"/>
    </joint>
    <link name="1">
        <inertial>
            <origin xyz="0 0.46443626785398934 0.0" rpy="0 0 0"/>
            <mass value="1" />
            <inertia ixx="100" ixy="0" ixz="0" iyy="100" iyz="0" izz="100" />
        </inertial>
        <visual>
            <origin xyz="0 0.46443626785398934 0.0" rpy="0 0 0"/>
            <geometry>
                <box size="0.5454109927906635 0.9288725357079786 0.026227828700591038" />
            </geometry>
            <material name="not">
                <color rgba="0 1 1 1"/>
            </material>
        </visual>
        <collision>
            <origin xyz="0 0.46443626785398934 0.0" rpy="0 0 0"/>
            <geometry>
                <box size="0.5454109927906635 0.9288725357079786 0.026227828700591038" />
            </geometry>
        </collision>
    </link>
    <joint name="1_5" type="revolute">
       <parent link="1"/>
       <child  link="5"/>
       <origin rpy="0 0 0" xyz="0 0.9288725357079786 0.0" />
     <axis xyz="1 0 0"/>
       <limit effort="0.0" lower="-3.14159" upper="3.14159" velocity="0.0"/>
    </joint>
    <link name="5">
        <inertial>
            <origin xyz="0 0.4823009136864911 0.0" rpy="0 0 0"/>
            <mass value="1" />
            <inertia ixx="100" ixy="0" ixz="0" iyy="100" iyz="0" izz="100" />
        </inertial>
        <visual>
            <origin xyz="0 0.4823009136864911 0.0" rpy="0 0 0"/>
            <geometry>
                <box size="0.454031336786608 0.9646018273729823 0.041917237001459884" />
            </geometry>
            <material name="not">
                <color rgba="0 1 1 1"/>
            </material>
        </visual>
        <collision>
            <origin xyz="0 0.4823009136864911 0.0" rpy="0 0 0"/>
            <geometry>
                <box size="0.454031336786608 0.9646018273729823 0.041917237001459884" />
            </geometry>
        </collision>
    </link>
    <joint name="5_9" type="revolute">
       <parent link="5"/>
       <child  link="9"/>
       <origin rpy="0 0 0" xyz="0 0.4823009136864911 0.020958618500729942" />
     <axis xyz="0 0 1"/>
       <limit effort="0.0" lower="-3.14159" upper="3.14159" velocity="0.0"/>
    </joint>
    <link name="9">
        <inertial>
            <origin xyz="0 0.0 0.1383821683277408" rpy="0 0 0"/>
            <mass value="1" />
            <inertia ixx="100" ixy="0" ixz="0" iyy="100" iyz="0" izz="100" />
        </inertial>
        <visual>
            <origin xyz="0 0.0 0.1383821683277408" rpy="0 0 0"/>
            <geometry>
                <box size="0.16119476388422538 0.5456414469554568 0.2767643366554816" />
            </geometry>
            <material name="sensor">
                <color rgba="0 1 0 1"/>
            </material>
        </visual>
        <collision>
            <origin xyz="0 0.0 0.1383821683277408" rpy="0 0 0"/>
            <geometry>
                <box size="0.16119476388422538 0.5456414469554568 0.2767643366554816" />
            </geometry>
        </collision>
    </link>
    <joint name="5_8" type="revolute">
       <parent link="5"/>
       <child  link="8"/>
       <origin rpy="0 0 0" xyz="-0.227015668393304 0.4823009136864911 0.0" />
     <axis xyz="1 0 0"/>
       <limit effort="0.0" lower="-3.14159" upper="3.14159" velocity="0.0"/>
    </joint>
    <link name="8">
        <inertial>
            <origin xyz="-0.04453318211024415 0.0 0.0" rpy="0 0 0"/>
            <mass value="1" />
            <inertia ixx="100" ixy="0" ixz="0" iyy="100" iyz="0" izz="100" />
        </inertial>
        <visual>
            <origin xyz="-0.04453318211024415 0.0 0.0" rpy="0 0 0"/>
            <geometry>
                <box size="0.0890663642204883 0.21064914777403265 0.2583558473010218" />
            </geometry>
            <material name="sensor">
                <color rgba="0 1 0 1"/>
            </material>
        </visual>
        <collision>
            <origin xyz="-0.04453318211024415 0.0 0.0" rpy="0 0 0"/>
            <geometry>
                <box size="0.0890663642204883 0.21064914777403265 0.2583558473010218" />
            </geometry>
        </collision>
    </link>
    <joint name="1_2" type="revolute">
       <parent link="1"/>
       <child  link="2"/>
       <origin rpy="0 0 0" xyz="0 0.46443626785398934 0.013113914350295519" />
     <axis xyz="1 0 0"/>
       <limit effort="0.0" lower="-3.14159" upper="3.14159" velocity="0.0"/>
    </joint>
    <link name="2">
        <inertial>
            <origin xyz="0 0.0 0.33112047813766077" rpy="0 0 0"/>
            <mass value="1" />
            <inertia ixx="100" ixy="0" ixz="0" iyy="100" iyz="0" izz="100" />
        </inertial>
        <visual>
            <origin xyz="0 0.0 0.33112047813766077" rpy="0 0 0"/>
            <geometry>
                <box size="0.7609282399055616 0.012045859790343783 0.6622409562753215" />
            </geometry>
            <material name="not">
                <color rgba="0 1 1 1"/>
            </material>
        </visual>
        <collision>
            <origin xyz="0 0.0 0.33112047813766077" rpy="0 0 0"/>
            <geometry>
                <box size="0.7609282399055616 0.012045859790343783 0.6622409562753215" />
            </geometry>
        </collision>
    </link>
    <joint name="2_4" type="revolute">
       <parent link="2"/>
       <child  link="4"/>
       <origin rpy="0 0 0" xyz="0.3804641199527808 0.0 0.33112047813766077" />
     <axis xyz="0 0 1"/>
       <limit effort="0.0" lower="-3.14159" upper="3.14159" velocity="0.0"/>
    </joint>
    <link name="4">
        <inertial>
            <origin xyz="0.35357988301578197 0.0 0.0" rpy="0 0 0"/>
            <mass value="1" />
            <inertia ixx="100" ixy="0" ixz="0" iyy="100" iyz="0" izz="100" />
        </inertial>
        <visual>
            <origin xyz="0.35357988301578197 0.0 0.0" rpy="0 0 0"/>
            <geometry>
                <box size="0.7071597660315639 0.33024992270506215 0.395593785018185" />
            </geometry>
            <material name="sensor">
                <color rgba="0 1 0 1"/>
            </material>
        </visual>
        <collision>
            <origin xyz="0.35357988301578197 0.0 0.0" rpy="0 0 0"/>
            <geometry>
                <box size="0.7071597660315639 0.33024992270506215 0.395593785018185" />
            </geometry>
        </collision>
    </link>
    <joint name="4_6" type="revolute">
       <parent link="4"/>
       <child  link="6"/>
       <origin rpy="0 0 0" xyz="0.35357988301578197 0.16512496135253119 0.0" />
     <axis xyz="0 0 1"/>
       <limit effort="0.0" lower="-3.14159" upper="3.14159" velocity="0.0"/>
    </joint>
    <link name="6">
        <inertial>
            <origin xyz="0.0 0.39492988916133354 0.0" rpy="0 0 0"/>
            <mass value="1" />
            <inertia ixx="100" ixy="0" ixz="0" iyy="100" iyz="0" izz="100" />
        </inertial>
        <visual>
            <origin xyz="0.0 0.39492988916133354 0.0" rpy="0 0 0"/>
            <geometry>
                <box size="0.8449996915225704 0.7898597783226671 0.9223291836811264" />
            </geometry>
            <material name="sensor">
                <color rgba="0 1 0 1"/>
            </material>
        </visual>
        <collision>
            <origin xyz="0.0 0.39492988916133354 0.0" rpy="0 0 0"/>
            <geometry>
                <box size="0.8449996915225704 0.7898597783226671 0.9223291836811264" />
            </geometry>
        </collision>
    </link>
    <joint name="0_3" type="revolute">
       <parent link="0"/>
       <child  link="3"/>
       <origin rpy="0 0 0" xyz="0 0 0.2801151511029314" />
     <axis xyz="0 0 1"/>
       <limit effort="0.0" lower="-3.14159" upper="3.14159" velocity="0.0"/>
    </joint>
    <link name="3">
        <inertial>
            <origin xyz="0 0 0.2932992114911397" rpy="0 0 0"/>
            <mass value="1" />
            <inertia ixx="100" ixy="0" ixz="0" iyy="100" iyz="0" izz="100" />
        </inertial>
        <visual>
            <origin xyz="0 0 0.2932992114911397" rpy="0 0 0"/>
            <geometry>
                <box size="0.02810065490374114 0.7164168123444158 0.5865984229822794" />
            </geometry>
            <material name="sensor">
                <color rgba="0 1 0 1"/>
            </material>
        </visual>
        <collision>
            <origin xyz="0 0 0.2932992114911397" rpy="0 0 0"/>
            <geometry>
                <box size="0.02810065490374114 0.7164168123444158 0.5865984229822794" />
            </geometry>
        </collision>
    </link>
    <joint name="0_7" type="revolute">
       <parent link="0"/>
       <child  link="7"/>
       <origin rpy="0 0 0" xyz="-0.4541052653570242 0 0.14371128020388346" />
     <axis xyz="1 0 0"/>
       <limit effort="0.0" lower="-3.14159" upper="3.14159" velocity="0.0"/>
    </joint>
    <link name="7">
        <inertial>
            <origin xyz="-0.3343684846021616 0 0.0" rpy="0 0 0"/>
            <mass value="1" />
            <inertia ixx="100" ixy="0" ixz="0" iyy="100" iyz="0" izz="100" />
        </inertial>
        <visual>
            <origin xyz="-0.3343684846021616 0 0.0" rpy="0 0 0"/>
            <geometry>
                <box size="0.6687369692043232 0.4146482194677874 0.2718546045579924" />
            </geometry>
            <material name="sensor">
                <color rgba="0 1 0 1"/>
            </material>
        </visual>
        <collision>
            <origin xyz="-0.3343684846021616 0 0.0" rpy="0 0 0"/>
            <geometry>
                <box size="0.6687369692043232 0.4146482194677874 0.2718546045579924" />
            </geometry>
        </collision>
    </link>
</robot>