<robot name = "robot">
    <link name="0">
        <inertial>
            <origin xyz="0 0 0.9525041289189863" rpy="0 0 0"/>
            <mass value="1" />
            <inertia ixx="100" ixy="0" ixz="0" iyy="100" iyz="0" izz="100" />
        </inertial>
        <visual>
            <origin xyz="0 0 0.9525041289189863" rpy="0 0 0"/>
            <geometry>
                <box size="0.8828328336570754 0.9675447826663839 0.21958783080191968" />
            </geometry>
            <material name="sensor">
                <color rgba="0 1 0 1"/>
            </material>
        </visual>
        <collision>
            <origin xyz="0 0 0.9525041289189863" rpy="0 0 0"/>
            <geometry>
                <box size="0.8828328336570754 0.9675447826663839 0.21958783080191968" />
            </geometry>
        </collision>
    </link>
    <joint name="0_7" type="revolute">
       <parent link="0"/>
       <child  link="7"/>
       <origin rpy="0 0 0" xyz="0.4414164168285377 0 0.9525041289189863" />
     <axis xyz="1 0 0"/>
       <limit effort="0.0" lower="-3.14159" upper="3.14159" velocity="0.0"/>
    </joint>
    <link name="7">
        <inertial>
            <origin xyz="0.12408969739353526 0 0.0" rpy="0 0 0"/>
            <mass value="1" />
            <inertia ixx="100" ixy="0" ixz="0" iyy="100" iyz="0" izz="100" />
        </inertial>
        <visual>
            <origin xyz="0.12408969739353526 0 0.0" rpy="0 0 0"/>
            <geometry>
                <box size="0.2481793947870704 0.7762380764257202 0.09085169631368428" />
            </geometry>
            <material name="not">
                <color rgba="0 1 1 1"/>
            </material>
        </visual>
        <collision>
            <origin xyz="0.12408969739353526 0 0.0" rpy="0 0 0"/>
            <geometry>
                <box size="0.2481793947870704 0.7762380764257202 0.09085169631368428" />
            </geometry>
        </collision>
    </link>
    <joint name="0_6" type="revolute">
       <parent link="0"/>
       <child  link="6"/>
       <origin rpy="0 0 0" xyz="0 0.48377239133319194 0.9525041289189863" />
     <axis xyz="0 0 1"/>
       <limit effort="0.0" lower="-3.14159" upper="3.14159" velocity="0.0"/>
    </joint>
    <link name="6">
        <inertial>
            <origin xyz="0 0.37044459909146377 0.0" rpy="0 0 0"/>
            <mass value="1" />
            <inertia ixx="100" ixy="0" ixz="0" iyy="100" iyz="0" izz="100" />
        </inertial>
        <visual>
            <origin xyz="0 0.37044459909146377 0.0" rpy="0 0 0"/>
            <geometry>
                <box size="0.07072281558400617 0.7408891981829275 0.2555938767696969" />
            </geometry>
            <material name="not">
                <color rgba="0 1 1 1"/>
            </material>
        </visual>
        <collision>
            <origin xyz="0 0.37044459909146377 0.0" rpy="0 0 0"/>
            <geometry>
                <box size="0.07072281558400617 0.7408891981829275 0.2555938767696969" />
            </geometry>
        </collision>
    </link>
    <joint name="6_10" type="revolute">
       <parent link="6"/>
       <child  link="10"/>
       <origin rpy="0 0 0" xyz="0.035361407792003086 0.37044459909146377 0.0" />
     <axis xyz="0 0 1"/>
       <limit effort="0.0" lower="-3.14159" upper="3.14159" velocity="0.0"/>
    </joint>
    <link name="10">
        <inertial>
            <origin xyz="0.1642768628941138 0.0 0.0" rpy="0 0 0"/>
            <mass value="1" />
            <inertia ixx="100" ixy="0" ixz="0" iyy="100" iyz="0" izz="100" />
        </inertial>
        <visual>
            <origin xyz="0.1642768628941138 0.0 0.0" rpy="0 0 0"/>
            <geometry>
                <box size="0.3285537257882276 0.23916775270885915 0.9075683940345639" />
            </geometry>
            <material name="sensor">
                <color rgba="0 1 0 1"/>
            </material>
        </visual>
        <collision>
            <origin xyz="0.1642768628941138 0.0 0.0" rpy="0 0 0"/>
            <geometry>
                <box size="0.3285537257882276 0.23916775270885915 0.9075683940345639" />
            </geometry>
        </collision>
    </link>
    <joint name="6_8" type="revolute">
       <parent link="6"/>
       <child  link="8"/>
       <origin rpy="0 0 0" xyz="-0.035361407792003086 0.37044459909146377 0.0" />
     <axis xyz="0 0 1"/>
       <limit effort="0.0" lower="-3.14159" upper="3.14159" velocity="0.0"/>
    </joint>
    <link name="8">
        <inertial>
            <origin xyz="-0.2934003660144916 0.0 0.0" rpy="0 0 0"/>
            <mass value="1" />
            <inertia ixx="100" ixy="0" ixz="0" iyy="100" iyz="0" izz="100" />
        </inertial>
        <visual>
            <origin xyz="-0.2934003660144916 0.0 0.0" rpy="0 0 0"/>
            <geometry>
                <box size="0.5868007320289832 0.39397864060472054 0.2996460594553094" />
            </geometry>
            <material name="not">
                <color rgba="0 1 1 1"/>
            </material>
        </visual>
        <collision>
            <origin xyz="-0.2934003660144916 0.0 0.0" rpy="0 0 0"/>
            <geometry>
                <box size="0.5868007320289832 0.39397864060472054 0.2996460594553094" />
            </geometry>
        </collision>
    </link>
    <joint name="0_4" type="revolute">
       <parent link="0"/>
       <child  link="4"/>
       <origin rpy="0 0 0" xyz="0 0 1.0622980443199461" />
     <axis xyz="0 1 0"/>
       <limit effort="0.0" lower="-3.14159" upper="3.14159" velocity="0.0"/>
    </joint>
    <link name="4">
        <inertial>
            <origin xyz="0 0 0.3894987150339462" rpy="0 0 0"/>
            <mass value="1" />
            <inertia ixx="100" ixy="0" ixz="0" iyy="100" iyz="0" izz="100" />
        </inertial>
        <visual>
            <origin xyz="0 0 0.3894987150339462" rpy="0 0 0"/>
            <geometry>
                <box size="0.26556427234351976 0.03958818991406765 0.7789974300678922" />
            </geometry>
            <material name="not">
                <color rgba="0 1 1 1"/>
            </material>
        </visual>
        <collision>
            <origin xyz="0 0 0.3894987150339462" rpy="0 0 0"/>
            <geometry>
                <box size="0.26556427234351976 0.03958818991406765 0.7789974300678922" />
            </geometry>
        </collision>
    </link>
    <joint name="0_1" type="revolute">
       <parent link="0"/>
       <child  link="1"/>
       <origin rpy="0 0 0" xyz="0 0 0.8427102135180264" />
     <axis xyz="0 0 1"/>
       <limit effort="0.0" lower="-3.14159" upper="3.14159" velocity="0.0"/>
    </joint>
    <link name="1">
        <inertial>
            <origin xyz="0 0 -0.08073302994043963" rpy="0 0 0"/>
            <mass value="1" />
            <inertia ixx="100" ixy="0" ixz="0" iyy="100" iyz="0" izz="100" />
        </inertial>
        <visual>
            <origin xyz="0 0 -0.08073302994043963" rpy="0 0 0"/>
            <geometry>
                <box size="0.9898714547442865 0.8324446694829476 0.16146605988087914" />
            </geometry>
            <material name="sensor">
                <color rgba="0 1 0 1"/>
            </material>
        </visual>
        <collision>
            <origin xyz="0 0 -0.08073302994043963" rpy="0 0 0"/>
            <geometry>
                <box size="0.9898714547442865 0.8324446694829476 0.16146605988087914" />
            </geometry>
        </collision>
    </link>
    <joint name="1_2" type="revolute">
       <parent link="1"/>
       <child  link="2"/>
       <origin rpy="0 0 0" xyz="0 0 -0.16146605988087925" />
     <axis xyz="0 0 1"/>
       <limit effort="0.0" lower="-3.14159" upper="3.14159" velocity="0.0"/>
    </joint>
    <link name="2">
        <inertial>
            <origin xyz="0 0 -0.046097013064290704" rpy="0 0 0"/>
            <mass value="1" />
            <inertia ixx="100" ixy="0" ixz="0" iyy="100" iyz="0" izz="100" />
        </inertial>
        <visual>
            <origin xyz="0 0 -0.046097013064290704" rpy="0 0 0"/>
            <geometry>
                <box size="0.4212764739673187 0.35661479323003864 0.09219402612858141" />
            </geometry>
            <material name="not">
                <color rgba="0 1 1 1"/>
            </material>
        </visual>
        <collision>
            <origin xyz="0 0 -0.046097013064290704" rpy="0 0 0"/>
            <geometry>
                <box size="0.4212764739673187 0.35661479323003864 0.09219402612858141" />
            </geometry>
        </collision>
    </link>
    <joint name="1_3" type="revolute">
       <parent link="1"/>
       <child  link="3"/>
       <origin rpy="0 0 0" xyz="0 -0.4162223347414738 -0.08073302994043963" />
     <axis xyz="0 1 0"/>
       <limit effort="0.0" lower="-3.14159" upper="3.14159" velocity="0.0"/>
    </joint>
    <link name="3">
        <inertial>
            <origin xyz="0 -0.2202290509013511 0.0" rpy="0 0 0"/>
            <mass value="1" />
            <inertia ixx="100" ixy="0" ixz="0" iyy="100" iyz="0" izz="100" />
        </inertial>
        <visual>
            <origin xyz="0 -0.2202290509013511 0.0" rpy="0 0 0"/>
            <geometry>
                <box size="0.554050247808328 0.44045810180270206 0.018081980827037603" />
            </geometry>
            <material name="sensor">
                <color rgba="0 1 0 1"/>
            </material>
        </visual>
        <collision>
            <origin xyz="0 -0.2202290509013511 0.0" rpy="0 0 0"/>
            <geometry>
                <box size="0.554050247808328 0.44045810180270206 0.018081980827037603" />
            </geometry>
        </collision>
    </link>
    <joint name="3_5" type="revolute">
       <parent link="3"/>
       <child  link="5"/>
       <origin rpy="0 0 0" xyz="0 -0.4404581018027021 0.0" />
     <axis xyz="1 0 0"/>
       <limit effort="0.0" lower="-3.14159" upper="3.14159" velocity="0.0"/>
    </joint>
    <link name="5">
        <inertial>
            <origin xyz="0 -0.13392987333872708 0.0" rpy="0 0 0"/>
            <mass value="1" />
            <inertia ixx="100" ixy="0" ixz="0" iyy="100" iyz="0" izz="100" />
        </inertial>
        <visual>
            <origin xyz="0 -0.13392987333872708 0.0" rpy="0 0 0"/>
            <geometry>
                <box size="0.9266692840712272 0.26785974667745416 0.12922479989532887" />
            </geometry>
            <material name="not">
                <color rgba="0 1 1 1"/>
            </material>
        </visual>
        <collision>
            <origin xyz="0 -0.13392987333872708 0.0" rpy="0 0 0"/>
            <geometry>
                <box size="0.9266692840712272 0.26785974667745416 0.12922479989532887" />
            </geometry>
        </collision>
    </link>
</robot>