<robot name = "robot">
    <link name="0">
        <inertial>
            <origin xyz="0 0 0.2616214829446579" rpy="0 0 0"/>
            <mass value="1" />
            <inertia ixx="100" ixy="0" ixz="0" iyy="100" iyz="0" izz="100" />
        </inertial>
        <visual>
            <origin xyz="0 0 0.2616214829446579" rpy="0 0 0"/>
            <geometry>
                <box size="0.793340083761663 0.8219540423197268 0.4850346279309453" />
            </geometry>
            <material name="not">
                <color rgba="0 1 1 1"/>
            </material>
        </visual>
        <collision>
            <origin xyz="0 0 0.2616214829446579" rpy="0 0 0"/>
            <geometry>
                <box size="0.793340083761663 0.8219540423197268 0.4850346279309453" />
            </geometry>
        </collision>
    </link>
    <joint name="0_1" type="revolute">
       <parent link="0"/>
       <child  link="1"/>
       <origin rpy="0 0 0" xyz="0.3966700418808315 0 0.2616214829446579" />
     <axis xyz="0 1 0"/>
       <limit effort="0.0" lower="-3.14159" upper="3.14159" velocity="0.0"/>
    </joint>
    <link name="1">
        <inertial>
            <origin xyz="0.4827588862170675 0 0.0" rpy="0 0 0"/>
            <mass value="1" />
            <inertia ixx="100" ixy="0" ixz="0" iyy="100" iyz="0" izz="100" />
        </inertial>
        <visual>
            <origin xyz="0.4827588862170675 0 0.0" rpy="0 0 0"/>
            <geometry>
                <box size="0.965517772434135 0.7348362682250169 0.31938566841289273" />
            </geometry>
            <material name="sensor">
                <color rgba="0 1 0 1"/>
            </material>
        </visual>
        <collision>
            <origin xyz="0.4827588862170675 0 0.0" rpy="0 0 0"/>
            <geometry>
                <box size="0.965517772434135 0.7348362682250169 0.31938566841289273" />
            </geometry>
        </collision>
    </link>
    <joint name="1_2" type="revolute">
       <parent link="1"/>
       <child  link="2"/>
       <origin rpy="0 0 0" xyz="0.4827588862170675 -0.36741813411250845 0.0" />
     <axis xyz="1 0 0"/>
       <limit effort="0.0" lower="-3.14159" upper="3.14159" velocity="0.0"/>
    </joint>
    <link name="2">
        <inertial>
            <origin xyz="0.0 -0.364912416311008 0.0" rpy="0 0 0"/>
            <mass value="1" />
            <inertia ixx="100" ixy="0" ixz="0" iyy="100" iyz="0" izz="100" />
        </inertial>
        <visual>
            <origin xyz="0.0 -0.364912416311008 0.0" rpy="0 0 0"/>
            <geometry>
                <box size="0.8019154831626036 0.729824832622016 0.4140064411653034" />
            </geometry>
            <material name="not">
                <color rgba="0 1 1 1"/>
            </material>
        </visual>
        <collision>
            <origin xyz="0.0 -0.364912416311008 0.0" rpy="0 0 0"/>
            <geometry>
                <box size="0.8019154831626036 0.729824832622016 0.4140064411653034" />
            </geometry>
        </collision>
    </link>
    <joint name="0_4" type="revolute">
       <parent link="0"/>
       <child  link="4"/>
       <origin rpy="0 0 0" xyz="0 -0.4109770211598634 0.2616214829446579" />
     <axis xyz="0 0 1"/>
       <limit effort="0.0" lower="-3.14159" upper="3.14159" velocity="0.0"/>
    </joint>
    <link name="4">
        <inertial>
            <origin xyz="0 -0.4163615513947278 0.0" rpy="0 0 0"/>
            <mass value="1" />
            <inertia ixx="100" ixy="0" ixz="0" iyy="100" iyz="0" izz="100" />
        </inertial>
        <visual>
            <origin xyz="0 -0.4163615513947278 0.0" rpy="0 0 0"/>
            <geometry>
                <box size="0.4867020691390127 0.8327231027894556 0.19372301932164393" />
            </geometry>
            <material name="not">
                <color rgba="0 1 1 1"/>
            </material>
        </visual>
        <collision>
            <origin xyz="0 -0.4163615513947278 0.0" rpy="0 0 0"/>
            <geometry>
                <box size="0.4867020691390127 0.8327231027894556 0.19372301932164393" />
            </geometry>
        </collision>
    </link>
    <joint name="0_3" type="revolute">
       <parent link="0"/>
       <child  link="3"/>
       <origin rpy="0 0 0" xyz="-0.3966700418808315 0 0.2616214829446579" />
     <axis xyz="0 1 0"/>
       <limit effort="0.0" lower="-3.14159" upper="3.14159" velocity="0.0"/>
    </joint>
    <link name="3">
        <inertial>
            <origin xyz="-0.2226062070564216 0 0.0" rpy="0 0 0"/>
            <mass value="1" />
            <inertia ixx="100" ixy="0" ixz="0" iyy="100" iyz="0" izz="100" />
        </inertial>
        <visual>
            <origin xyz="-0.2226062070564216 0 0.0" rpy="0 0 0"/>
            <geometry>
                <box size="0.4452124141128432 0.09378037419593965 0.1971620447989344" />
            </geometry>
            <material name="sensor">
                <color rgba="0 1 0 1"/>
            </material>
        </visual>
        <collision>
            <origin xyz="-0.2226062070564216 0 0.0" rpy="0 0 0"/>
            <geometry>
                <box size="0.4452124141128432 0.09378037419593965 0.1971620447989344" />
            </geometry>
        </collision>
    </link>
</robot>