<robot name = "robot">
    <link name="0">
        <inertial>
            <origin xyz="0 0 0.8161263591200314" rpy="0 0 0"/>
            <mass value="1" />
            <inertia ixx="100" ixy="0" ixz="0" iyy="100" iyz="0" izz="100" />
        </inertial>
        <visual>
            <origin xyz="0 0 0.8161263591200314" rpy="0 0 0"/>
            <geometry>
                <box size="0.14425508335743753 0.11779223807836836 0.30848182410193437" />
            </geometry>
            <material name="not">
                <color rgba="0 1 1 1"/>
            </material>
        </visual>
        <collision>
            <origin xyz="0 0 0.8161263591200314" rpy="0 0 0"/>
            <geometry>
                <box size="0.14425508335743753 0.11779223807836836 0.30848182410193437" />
            </geometry>
        </collision>
    </link>
    <joint name="0_1" type="revolute">
       <parent link="0"/>
       <child  link="1"/>
       <origin rpy="0 0 0" xyz="0.07212754167871877 0 0.8161263591200314" />
     <axis xyz="0 1 0"/>
       <limit effort="0.0" lower="-3.14159" upper="3.14159" velocity="0.0"/>
    </joint>
    <link name="1">
        <inertial>
            <origin xyz="0.1861987713628656 0 0.0" rpy="0 0 0"/>
            <mass value="1" />
            <inertia ixx="100" ixy="0" ixz="0" iyy="100" iyz="0" izz="100" />
        </inertial>
        <visual>
            <origin xyz="0.1861987713628656 0 0.0" rpy="0 0 0"/>
            <geometry>
                <box size="0.3723975427257312 0.5477444657095578 0.06278897497332314" />
            </geometry>
            <material name="not">
                <color rgba="0 1 1 1"/>
            </material>
        </visual>
        <collision>
            <origin xyz="0.1861987713628656 0 0.0" rpy="0 0 0"/>
            <geometry>
                <box size="0.3723975427257312 0.5477444657095578 0.06278897497332314" />
            </geometry>
        </collision>
    </link>
    <joint name="1_3" type="revolute">
       <parent link="1"/>
       <child  link="3"/>
       <origin rpy="0 0 0" xyz="0.1861987713628656 0.2738722328547789 0.0" />
     <axis xyz="0 1 0"/>
       <limit effort="0.0" lower="-3.14159" upper="3.14159" velocity="0.0"/>
    </joint>
    <link name="3">
        <inertial>
            <origin xyz="0.0 0.3971897407612456 0.0" rpy="0 0 0"/>
            <mass value="1" />
            <inertia ixx="100" ixy="0" ixz="0" iyy="100" iyz="0" izz="100" />
        </inertial>
        <visual>
            <origin xyz="0.0 0.3971897407612456 0.0" rpy="0 0 0"/>
            <geometry>
                <box size="0.29976699686368236 0.7943794815224912 0.6989944337295713" />
            </geometry>
            <material name="not">
                <color rgba="0 1 1 1"/>
            </material>
        </visual>
        <collision>
            <origin xyz="0.0 0.3971897407612456 0.0" rpy="0 0 0"/>
            <geometry>
                <box size="0.29976699686368236 0.7943794815224912 0.6989944337295713" />
            </geometry>
        </collision>
    </link>
    <joint name="1_2" type="revolute">
       <parent link="1"/>
       <child  link="2"/>
       <origin rpy="0 0 0" xyz="0.1861987713628656 -0.2738722328547789 0.0" />
     <axis xyz="0 1 0"/>
       <limit effort="0.0" lower="-3.14159" upper="3.14159" velocity="0.0"/>
    </joint>
    <link name="2">
        <inertial>
            <origin xyz="0.0 -0.21379615283470144 0.0" rpy="0 0 0"/>
            <mass value="1" />
            <inertia ixx="100" ixy="0" ixz="0" iyy="100" iyz="0" izz="100" />
        </inertial>
        <visual>
            <origin xyz="0.0 -0.21379615283470144 0.0" rpy="0 0 0"/>
            <geometry>
                <box size="0.6803999731817859 0.4275923056694029 0.3141471703767915" />
            </geometry>
            <material name="sensor">
                <color rgba="0 1 0 1"/>
            </material>
        </visual>
        <collision>
            <origin xyz="0.0 -0.21379615283470144 0.0" rpy="0 0 0"/>
            <geometry>
                <box size="0.6803999731817859 0.4275923056694029 0.3141471703767915" />
            </geometry>
        </collision>
    </link>
</robot>