<robot name = "robot">
    <link name="0">
        <inertial>
            <origin xyz="0 0 0.5329244852787135" rpy="0 0 0"/>
            <mass value="1" />
            <inertia ixx="100" ixy="0" ixz="0" iyy="100" iyz="0" izz="100" />
        </inertial>
        <visual>
            <origin xyz="0 0 0.5329244852787135" rpy="0 0 0"/>
            <geometry>
                <box size="0.07419717159602979 0.47806378575147657 0.5877270322471857" />
            </geometry>
            <material name="not">
                <color rgba="0 1 1 1"/>
            </material>
        </visual>
        <collision>
            <origin xyz="0 0 0.5329244852787135" rpy="0 0 0"/>
            <geometry>
                <box size="0.07419717159602979 0.47806378575147657 0.5877270322471857" />
            </geometry>
        </collision>
    </link>
    <joint name="0_1" type="revolute">
       <parent link="0"/>
       <child  link="1"/>
       <origin rpy="0 0 0" xyz="0.037098585798014894 0 0.5329244852787135" />
     <axis xyz="1 0 0"/>
       <limit effort="0.0" lower="-3.14159" upper="3.14159" velocity="0.0"/>
    </joint>
    <link name="1">
        <inertial>
            <origin xyz="0.2678496297337104 0 0.0" rpy="0 0 0"/>
            <mass value="1" />
            <inertia ixx="100" ixy="0" ixz="0" iyy="100" iyz="0" izz="100" />
        </inertial>
        <visual>
            <origin xyz="0.2678496297337104 0 0.0" rpy="0 0 0"/>
            <geometry>
                <box size="0.5356992594674208 0.9396076062059259 0.577622640947989" />
            </geometry>
            <material name="sensor">
                <color rgba="0 1 0 1"/>
            </material>
        </visual>
        <collision>
            <origin xyz="0.2678496297337104 0 0.0" rpy="0 0 0"/>
            <geometry>
                <box size="0.5356992594674208 0.9396076062059259 0.577622640947989" />
            </geometry>
        </collision>
    </link>
    <joint name="1_2" type="revolute">
       <parent link="1"/>
       <child  link="2"/>
       <origin rpy="0 0 0" xyz="0.5356992594674208 0 0.0" />
     <axis xyz="0 1 0"/>
       <limit effort="0.0" lower="-3.14159" upper="3.14159" velocity="0.0"/>
    </joint>
    <link name="2">
        <inertial>
            <origin xyz="0.35103032210273144 0 0.0" rpy="0 0 0"/>
            <mass value="1" />
            <inertia ixx="100" ixy="0" ixz="0" iyy="100" iyz="0" izz="100" />
        </inertial>
        <visual>
            <origin xyz="0.35103032210273144 0 0.0" rpy="0 0 0"/>
            <geometry>
                <box size="0.7020606442054629 0.07979859307458714 0.9650134412186798" />
            </geometry>
            <material name="sensor">
                <color rgba="0 1 0 1"/>
            </material>
        </visual>
        <collision>
            <origin xyz="0.35103032210273144 0 0.0" rpy="0 0 0"/>
            <geometry>
                <box size="0.7020606442054629 0.07979859307458714 0.9650134412186798" />
            </geometry>
        </collision>
    </link>
    <joint name="2_4" type="revolute">
       <parent link="2"/>
       <child  link="4"/>
       <origin rpy="0 0 0" xyz="0.7020606442054629 0 0.0" />
     <axis xyz="0 1 0"/>
       <limit effort="0.0" lower="-3.14159" upper="3.14159" velocity="0.0"/>
    </joint>
    <link name="4">
        <inertial>
            <origin xyz="0.16546632899749403 0 0.0" rpy="0 0 0"/>
            <mass value="1" />
            <inertia ixx="100" ixy="0" ixz="0" iyy="100" iyz="0" izz="100" />
        </inertial>
        <visual>
            <origin xyz="0.16546632899749403 0 0.0" rpy="0 0 0"/>
            <geometry>
                <box size="0.33093265799498794 0.08197933347057285 0.783181587797383" />
            </geometry>
            <material name="sensor">
                <color rgba="0 1 0 1"/>
            </material>
        </visual>
        <collision>
            <origin xyz="0.16546632899749403 0 0.0" rpy="0 0 0"/>
            <geometry>
                <box size="0.33093265799498794 0.08197933347057285 0.783181587797383" />
            </geometry>
        </collision>
    </link>
    <joint name="2_8" type="revolute">
       <parent link="2"/>
       <child  link="8"/>
       <origin rpy="0 0 0" xyz="0.35103032210273144 0 0.48250672060933997" />
     <axis xyz="0 0 1"/>
       <limit effort="0.0" lower="-3.14159" upper="3.14159" velocity="0.0"/>
    </joint>
    <link name="8">
        <inertial>
            <origin xyz="0.0 0 0.40234071076936573" rpy="0 0 0"/>
            <mass value="1" />
            <inertia ixx="100" ixy="0" ixz="0" iyy="100" iyz="0" izz="100" />
        </inertial>
        <visual>
            <origin xyz="0.0 0 0.40234071076936573" rpy="0 0 0"/>
            <geometry>
                <box size="0.1397774881726903 0.020744266389112753 0.8046814215387313" />
            </geometry>
            <material name="not">
                <color rgba="0 1 1 1"/>
            </material>
        </visual>
        <collision>
            <origin xyz="0.0 0 0.40234071076936573" rpy="0 0 0"/>
            <geometry>
                <box size="0.1397774881726903 0.020744266389112753 0.8046814215387313" />
            </geometry>
        </collision>
    </link>
    <joint name="2_3" type="revolute">
       <parent link="2"/>
       <child  link="3"/>
       <origin rpy="0 0 0" xyz="0.35103032210273144 -0.03989929653729357 0.0" />
     <axis xyz="0 0 1"/>
       <limit effort="0.0" lower="-3.14159" upper="3.14159" velocity="0.0"/>
    </joint>
    <link name="3">
        <inertial>
            <origin xyz="0.0 -0.0033858300911228656 0.0" rpy="0 0 0"/>
            <mass value="1" />
            <inertia ixx="100" ixy="0" ixz="0" iyy="100" iyz="0" izz="100" />
        </inertial>
        <visual>
            <origin xyz="0.0 -0.0033858300911228656 0.0" rpy="0 0 0"/>
            <geometry>
                <box size="0.16992055829995412 0.006771660182245731 0.8730489934215308" />
            </geometry>
            <material name="sensor">
                <color rgba="0 1 0 1"/>
            </material>
        </visual>
        <collision>
            <origin xyz="0.0 -0.0033858300911228656 0.0" rpy="0 0 0"/>
            <geometry>
                <box size="0.16992055829995412 0.006771660182245731 0.8730489934215308" />
            </geometry>
        </collision>
    </link>
    <joint name="3_10" type="revolute">
       <parent link="3"/>
       <child  link="10"/>
       <origin rpy="0 0 0" xyz="0.0 -0.006771660182245731 0.0" />
     <axis xyz="1 0 0"/>
       <limit effort="0.0" lower="-3.14159" upper="3.14159" velocity="0.0"/>
    </joint>
    <link name="10">
        <inertial>
            <origin xyz="0.0 -0.26967875020669896 0.0" rpy="0 0 0"/>
            <mass value="1" />
            <inertia ixx="100" ixy="0" ixz="0" iyy="100" iyz="0" izz="100" />
        </inertial>
        <visual>
            <origin xyz="0.0 -0.26967875020669896 0.0" rpy="0 0 0"/>
            <geometry>
                <box size="0.5397739415527791 0.5393575004133979 0.14374880946574276" />
            </geometry>
            <material name="sensor">
                <color rgba="0 1 0 1"/>
            </material>
        </visual>
        <collision>
            <origin xyz="0.0 -0.26967875020669896 0.0" rpy="0 0 0"/>
            <geometry>
                <box size="0.5397739415527791 0.5393575004133979 0.14374880946574276" />
            </geometry>
        </collision>
    </link>
    <joint name="0_9" type="revolute">
       <parent link="0"/>
       <child  link="9"/>
       <origin rpy="0 0 0" xyz="0 0 0.8267880014023063" />
     <axis xyz="1 0 0"/>
       <limit effort="0.0" lower="-3.14159" upper="3.14159" velocity="0.0"/>
    </joint>
    <link name="9">
        <inertial>
            <origin xyz="0 0 0.17191218645617834" rpy="0 0 0"/>
            <mass value="1" />
            <inertia ixx="100" ixy="0" ixz="0" iyy="100" iyz="0" izz="100" />
        </inertial>
        <visual>
            <origin xyz="0 0 0.17191218645617834" rpy="0 0 0"/>
            <geometry>
                <box size="0.47347269163290995 0.46662814401191377 0.3438243729123567" />
            </geometry>
            <material name="sensor">
                <color rgba="0 1 0 1"/>
            </material>
        </visual>
        <collision>
            <origin xyz="0 0 0.17191218645617834" rpy="0 0 0"/>
            <geometry>
                <box size="0.47347269163290995 0.46662814401191377 0.3438243729123567" />
            </geometry>
        </collision>
    </link>
    <joint name="9_11" type="revolute">
       <parent link="9"/>
       <child  link="11"/>
       <origin rpy="0 0 0" xyz="0 -0.23331407200595689 0.17191218645617834" />
     <axis xyz="1 0 0"/>
       <limit effort="0.0" lower="-3.14159" upper="3.14159" velocity="0.0"/>
    </joint>
    <link name="11">
        <inertial>
            <origin xyz="0 -0.1221356772877128 0.0" rpy="0 0 0"/>
            <mass value="1" />
            <inertia ixx="100" ixy="0" ixz="0" iyy="100" iyz="0" izz="100" />
        </inertial>
        <visual>
            <origin xyz="0 -0.1221356772877128 0.0" rpy="0 0 0"/>
            <geometry>
                <box size="0.3916063535238927 0.2442713545754256 0.29839288301353417" />
            </geometry>
            <material name="not">
                <color rgba="0 1 1 1"/>
            </material>
        </visual>
        <collision>
            <origin xyz="0 -0.1221356772877128 0.0" rpy="0 0 0"/>
            <geometry>
                <box size="0.3916063535238927 0.2442713545754256 0.29839288301353417" />
            </geometry>
        </collision>
    </link>
    <joint name="0_5" type="revolute">
       <parent link="0"/>
       <child  link="5"/>
       <origin rpy="0 0 0" xyz="-0.037098585798014894 0 0.5329244852787135" />
     <axis xyz="1 0 0"/>
       <limit effort="0.0" lower="-3.14159" upper="3.14159" velocity="0.0"/>
    </joint>
    <link name="5">
        <inertial>
            <origin xyz="-0.3146784207678563 0 0.0" rpy="0 0 0"/>
            <mass value="1" />
            <inertia ixx="100" ixy="0" ixz="0" iyy="100" iyz="0" izz="100" />
        </inertial>
        <visual>
            <origin xyz="-0.3146784207678563 0 0.0" rpy="0 0 0"/>
            <geometry>
                <box size="0.6293568415357126 0.26003017442630283 0.20015553912586415" />
            </geometry>
            <material name="not">
                <color rgba="0 1 1 1"/>
            </material>
        </visual>
        <collision>
            <origin xyz="-0.3146784207678563 0 0.0" rpy="0 0 0"/>
            <geometry>
                <box size="0.6293568415357126 0.26003017442630283 0.20015553912586415" />
            </geometry>
        </collision>
    </link>
</robot>