<robot name = "robot">
    <link name="0">
        <inertial>
            <origin xyz="0 0 0.47274908866546683" rpy="0 0 0"/>
            <mass value="1" />
            <inertia ixx="100" ixy="0" ixz="0" iyy="100" iyz="0" izz="100" />
        </inertial>
        <visual>
            <origin xyz="0 0 0.47274908866546683" rpy="0 0 0"/>
            <geometry>
                <box size="0.3012676595157123 0.031011751469749993 0.8655272369789456" />
            </geometry>
            <material name="sensor">
                <color rgba="0 1 0 1"/>
            </material>
        </visual>
        <collision>
            <origin xyz="0 0 0.47274908866546683" rpy="0 0 0"/>
            <geometry>
                <box size="0.3012676595157123 0.031011751469749993 0.8655272369789456" />
            </geometry>
        </collision>
    </link>
    <joint name="0_1" type="revolute">
       <parent link="0"/>
       <child  link="1"/>
       <origin rpy="0 0 0" xyz="-0.15063382975785616 0 0.47274908866546683" />
     <axis xyz="0 1 0"/>
       <limit effort="0.0" lower="-3.14159" upper="3.14159" velocity="0.0"/>
    </joint>
    <link name="1">
        <inertial>
            <origin xyz="-0.048727154865438604 0 0.0" rpy="0 0 0"/>
            <mass value="1" />
            <inertia ixx="100" ixy="0" ixz="0" iyy="100" iyz="0" izz="100" />
        </inertial>
        <visual>
            <origin xyz="-0.048727154865438604 0 0.0" rpy="0 0 0"/>
            <geometry>
                <box size="0.09745430973087721 0.1359688602006689 0.21698694123313733" />
            </geometry>
            <material name="sensor">
                <color rgba="0 1 0 1"/>
            </material>
        </visual>
        <collision>
            <origin xyz="-0.048727154865438604 0 0.0" rpy="0 0 0"/>
            <geometry>
                <box size="0.09745430973087721 0.1359688602006689 0.21698694123313733" />
            </geometry>
        </collision>
    </link>
    <joint name="1_4" type="revolute">
       <parent link="1"/>
       <child  link="4"/>
       <origin rpy="0 0 0" xyz="-0.048727154865438604 0.06798443010033445 0.0" />
     <axis xyz="0 0 1"/>
       <limit effort="0.0" lower="-3.14159" upper="3.14159" velocity="0.0"/>
    </joint>
    <link name="4">
        <inertial>
            <origin xyz="0.0 0.03330600787126203 0.0" rpy="0 0 0"/>
            <mass value="1" />
            <inertia ixx="100" ixy="0" ixz="0" iyy="100" iyz="0" izz="100" />
        </inertial>
        <visual>
            <origin xyz="0.0 0.03330600787126203 0.0" rpy="0 0 0"/>
            <geometry>
                <box size="0.3440802007957944 0.06661201574252407 0.8970961581972642" />
            </geometry>
            <material name="sensor">
                <color rgba="0 1 0 1"/>
            </material>
        </visual>
        <collision>
            <origin xyz="0.0 0.03330600787126203 0.0" rpy="0 0 0"/>
            <geometry>
                <box size="0.3440802007957944 0.06661201574252407 0.8970961581972642" />
            </geometry>
        </collision>
    </link>
    <joint name="1_2" type="revolute">
       <parent link="1"/>
       <child  link="2"/>
       <origin rpy="0 0 0" xyz="-0.048727154865438604 -0.06798443010033445 0.0" />
     <axis xyz="1 0 0"/>
       <limit effort="0.0" lower="-3.14159" upper="3.14159" velocity="0.0"/>
    </joint>
    <link name="2">
        <inertial>
            <origin xyz="0.0 -0.41673855999807363 0.0" rpy="0 0 0"/>
            <mass value="1" />
            <inertia ixx="100" ixy="0" ixz="0" iyy="100" iyz="0" izz="100" />
        </inertial>
        <visual>
            <origin xyz="0.0 -0.41673855999807363 0.0" rpy="0 0 0"/>
            <geometry>
                <box size="0.42114851256640984 0.8334771199961473 0.5740227352895624" />
            </geometry>
            <material name="sensor">
                <color rgba="0 1 0 1"/>
            </material>
        </visual>
        <collision>
            <origin xyz="0.0 -0.41673855999807363 0.0" rpy="0 0 0"/>
            <geometry>
                <box size="0.42114851256640984 0.8334771199961473 0.5740227352895624" />
            </geometry>
        </collision>
    </link>
    <joint name="2_3" type="revolute">
       <parent link="2"/>
       <child  link="3"/>
       <origin rpy="0 0 0" xyz="0.21057425628320492 -0.41673855999807363 0.0" />
     <axis xyz="1 0 0"/>
       <limit effort="0.0" lower="-3.14159" upper="3.14159" velocity="0.0"/>
    </joint>
    <link name="3">
        <inertial>
            <origin xyz="0.11619323828891576 0.0 0.0" rpy="0 0 0"/>
            <mass value="1" />
            <inertia ixx="100" ixy="0" ixz="0" iyy="100" iyz="0" izz="100" />
        </inertial>
        <visual>
            <origin xyz="0.11619323828891576 0.0 0.0" rpy="0 0 0"/>
            <geometry>
                <box size="0.2323864765778315 0.33676501126574077 0.9157307962249637" />
            </geometry>
            <material name="sensor">
                <color rgba="0 1 0 1"/>
            </material>
        </visual>
        <collision>
            <origin xyz="0.11619323828891576 0.0 0.0" rpy="0 0 0"/>
            <geometry>
                <box size="0.2323864765778315 0.33676501126574077 0.9157307962249637" />
            </geometry>
        </collision>
    </link>
    <joint name="3_5" type="revolute">
       <parent link="3"/>
       <child  link="5"/>
       <origin rpy="0 0 0" xyz="0.11619323828891576 0.0 0.45786539811248184" />
     <axis xyz="0 1 0"/>
       <limit effort="0.0" lower="-3.14159" upper="3.14159" velocity="0.0"/>
    </joint>
    <link name="5">
        <inertial>
            <origin xyz="0.0 0.0 0.2754257205162396" rpy="0 0 0"/>
            <mass value="1" />
            <inertia ixx="100" ixy="0" ixz="0" iyy="100" iyz="0" izz="100" />
        </inertial>
        <visual>
            <origin xyz="0.0 0.0 0.2754257205162396" rpy="0 0 0"/>
            <geometry>
                <box size="0.37780476896793 0.5863750974159996 0.550851441032479" />
            </geometry>
            <material name="not">
                <color rgba="0 1 1 1"/>
            </material>
        </visual>
        <collision>
            <origin xyz="0.0 0.0 0.2754257205162396" rpy="0 0 0"/>
            <geometry>
                <box size="0.37780476896793 0.5863750974159996 0.550851441032479" />
            </geometry>
        </collision>
    </link>
</robot>