<robot name = "robot">
    <link name="0">
        <inertial>
            <origin xyz="0 0 0.36104912450581095" rpy="0 0 0"/>
            <mass value="1" />
            <inertia ixx="100" ixy="0" ixz="0" iyy="100" iyz="0" izz="100" />
        </inertial>
        <visual>
            <origin xyz="0 0 0.36104912450581095" rpy="0 0 0"/>
            <geometry>
                <box size="0.02187335891978648 0.12349531241608813 0.5894155636562263" />
            </geometry>
            <material name="sensor">
                <color rgba="0 1 0 1"/>
            </material>
        </visual>
        <collision>
            <origin xyz="0 0 0.36104912450581095" rpy="0 0 0"/>
            <geometry>
                <box size="0.02187335891978648 0.12349531241608813 0.5894155636562263" />
            </geometry>
        </collision>
    </link>
    <joint name="0_1" type="revolute">
       <parent link="0"/>
       <child  link="1"/>
       <origin rpy="0 0 0" xyz="0 0.061747656208044066 0.36104912450581095" />
     <axis xyz="0 0 1"/>
       <limit effort="0.0" lower="-3.14159" upper="3.14159" velocity="0.0"/>
    </joint>
    <link name="1">
        <inertial>
            <origin xyz="0 0.2373544635485394 0.0" rpy="0 0 0"/>
            <mass value="1" />
            <inertia ixx="100" ixy="0" ixz="0" iyy="100" iyz="0" izz="100" />
        </inertial>
        <visual>
            <origin xyz="0 0.2373544635485394 0.0" rpy="0 0 0"/>
            <geometry>
                <box size="0.26793750079337697 0.4747089270970788 0.47853898623602176" />
            </geometry>
            <material name="sensor">
                <color rgba="0 1 0 1"/>
            </material>
        </visual>
        <collision>
            <origin xyz="0 0.2373544635485394 0.0" rpy="0 0 0"/>
            <geometry>
                <box size="0.26793750079337697 0.4747089270970788 0.47853898623602176" />
            </geometry>
        </collision>
    </link>
    <joint name="1_2" type="revolute">
       <parent link="1"/>
       <child  link="2"/>
       <origin rpy="0 0 0" xyz="-0.13396875039668849 0.2373544635485394 0.0" />
     <axis xyz="0 0 1"/>
       <limit effort="0.0" lower="-3.14159" upper="3.14159" velocity="0.0"/>
    </joint>
    <link name="2">
        <inertial>
            <origin xyz="-0.15283676473225882 0.0 0.0" rpy="0 0 0"/>
            <mass value="1" />
            <inertia ixx="100" ixy="0" ixz="0" iyy="100" iyz="0" izz="100" />
        </inertial>
        <visual>
            <origin xyz="-0.15283676473225882 0.0 0.0" rpy="0 0 0"/>
            <geometry>
                <box size="0.30567352946451765 0.804740983748892 0.3233902481680886" />
            </geometry>
            <material name="not">
                <color rgba="0 1 1 1"/>
            </material>
        </visual>
        <collision>
            <origin xyz="-0.15283676473225882 0.0 0.0" rpy="0 0 0"/>
            <geometry>
                <box size="0.30567352946451765 0.804740983748892 0.3233902481680886" />
            </geometry>
        </collision>
    </link>
    <joint name="2_4" type="revolute">
       <parent link="2"/>
       <child  link="4"/>
       <origin rpy="0 0 0" xyz="-0.15283676473225882 0.402370491874446 0.0" />
     <axis xyz="0 0 1"/>
       <limit effort="0.0" lower="-3.14159" upper="3.14159" velocity="0.0"/>
    </joint>
    <link name="4">
        <inertial>
            <origin xyz="0.0 0.11603328995464368 0.0" rpy="0 0 0"/>
            <mass value="1" />
            <inertia ixx="100" ixy="0" ixz="0" iyy="100" iyz="0" izz="100" />
        </inertial>
        <visual>
            <origin xyz="0.0 0.11603328995464368 0.0" rpy="0 0 0"/>
            <geometry>
                <box size="0.07581929466798243 0.23206657990928747 0.3709134560970365" />
            </geometry>
            <material name="not">
                <color rgba="0 1 1 1"/>
            </material>
        </visual>
        <collision>
            <origin xyz="0.0 0.11603328995464368 0.0" rpy="0 0 0"/>
            <geometry>
                <box size="0.07581929466798243 0.23206657990928747 0.3709134560970365" />
            </geometry>
        </collision>
    </link>
    <joint name="4_8" type="revolute">
       <parent link="4"/>
       <child  link="8"/>
       <origin rpy="0 0 0" xyz="0.0 0.23206657990928736 0.0" />
     <axis xyz="1 0 0"/>
       <limit effort="0.0" lower="-3.14159" upper="3.14159" velocity="0.0"/>
    </joint>
    <link name="8">
        <inertial>
            <origin xyz="0.0 0.12478791108865894 0.0" rpy="0 0 0"/>
            <mass value="1" />
            <inertia ixx="100" ixy="0" ixz="0" iyy="100" iyz="0" izz="100" />
        </inertial>
        <visual>
            <origin xyz="0.0 0.12478791108865894 0.0" rpy="0 0 0"/>
            <geometry>
                <box size="0.7137837118330853 0.24957582217731777 0.6046707975758063" />
            </geometry>
            <material name="not">
                <color rgba="0 1 1 1"/>
            </material>
        </visual>
        <collision>
            <origin xyz="0.0 0.12478791108865894 0.0" rpy="0 0 0"/>
            <geometry>
                <box size="0.7137837118330853 0.24957582217731777 0.6046707975758063" />
            </geometry>
        </collision>
    </link>
    <joint name="4_5" type="revolute">
       <parent link="4"/>
       <child  link="5"/>
       <origin rpy="0 0 0" xyz="-0.037909647333991214 0.11603328995464368 0.0" />
     <axis xyz="0 1 0"/>
       <limit effort="0.0" lower="-3.14159" upper="3.14159" velocity="0.0"/>
    </joint>
    <link name="5">
        <inertial>
            <origin xyz="-0.15916282364828988 0.0 0.0" rpy="0 0 0"/>
            <mass value="1" />
            <inertia ixx="100" ixy="0" ixz="0" iyy="100" iyz="0" izz="100" />
        </inertial>
        <visual>
            <origin xyz="-0.15916282364828988 0.0 0.0" rpy="0 0 0"/>
            <geometry>
                <box size="0.31832564729657975 0.037680332571323194 0.6681580252745912" />
            </geometry>
            <material name="not">
                <color rgba="0 1 1 1"/>
            </material>
        </visual>
        <collision>
            <origin xyz="-0.15916282364828988 0.0 0.0" rpy="0 0 0"/>
            <geometry>
                <box size="0.31832564729657975 0.037680332571323194 0.6681580252745912" />
            </geometry>
        </collision>
    </link>
    <joint name="2_3" type="revolute">
       <parent link="2"/>
       <child  link="3"/>
       <origin rpy="0 0 0" xyz="-0.15283676473225882 -0.402370491874446 0.0" />
     <axis xyz="1 0 0"/>
       <limit effort="0.0" lower="-3.14159" upper="3.14159" velocity="0.0"/>
    </joint>
    <link name="3">
        <inertial>
            <origin xyz="0.0 -0.4823280016225019 0.0" rpy="0 0 0"/>
            <mass value="1" />
            <inertia ixx="100" ixy="0" ixz="0" iyy="100" iyz="0" izz="100" />
        </inertial>
        <visual>
            <origin xyz="0.0 -0.4823280016225019 0.0" rpy="0 0 0"/>
            <geometry>
                <box size="0.623783986638168 0.9646560032450038 0.18257821373725425" />
            </geometry>
            <material name="not">
                <color rgba="0 1 1 1"/>
            </material>
        </visual>
        <collision>
            <origin xyz="0.0 -0.4823280016225019 0.0" rpy="0 0 0"/>
            <geometry>
                <box size="0.623783986638168 0.9646560032450038 0.18257821373725425" />
            </geometry>
        </collision>
    </link>
    <joint name="3_7" type="revolute">
       <parent link="3"/>
       <child  link="7"/>
       <origin rpy="0 0 0" xyz="-0.31189199331908396 -0.4823280016225019 0.0" />
     <axis xyz="0 0 1"/>
       <limit effort="0.0" lower="-3.14159" upper="3.14159" velocity="0.0"/>
    </joint>
    <link name="7">
        <inertial>
            <origin xyz="-0.3892490097860958 0.0 0.0" rpy="0 0 0"/>
            <mass value="1" />
            <inertia ixx="100" ixy="0" ixz="0" iyy="100" iyz="0" izz="100" />
        </inertial>
        <visual>
            <origin xyz="-0.3892490097860958 0.0 0.0" rpy="0 0 0"/>
            <geometry>
                <box size="0.7784980195721916 0.44707866429232035 0.276407066564499" />
            </geometry>
            <material name="not">
                <color rgba="0 1 1 1"/>
            </material>
        </visual>
        <collision>
            <origin xyz="-0.3892490097860958 0.0 0.0" rpy="0 0 0"/>
            <geometry>
                <box size="0.7784980195721916 0.44707866429232035 0.276407066564499" />
            </geometry>
        </collision>
    </link>
    <joint name="0_6" type="revolute">
       <parent link="0"/>
       <child  link="6"/>
       <origin rpy="0 0 0" xyz="0 0 0.6557569063339241" />
     <axis xyz="1 0 0"/>
       <limit effort="0.0" lower="-3.14159" upper="3.14159" velocity="0.0"/>
    </joint>
    <link name="6">
        <inertial>
            <origin xyz="0 0 0.3187246178726554" rpy="0 0 0"/>
            <mass value="1" />
            <inertia ixx="100" ixy="0" ixz="0" iyy="100" iyz="0" izz="100" />
        </inertial>
        <visual>
            <origin xyz="0 0 0.3187246178726554" rpy="0 0 0"/>
            <geometry>
                <box size="0.4996924452021747 0.020283004576954755 0.6374492357453108" />
            </geometry>
            <material name="sensor">
                <color rgba="0 1 0 1"/>
            </material>
        </visual>
        <collision>
            <origin xyz="0 0 0.3187246178726554" rpy="0 0 0"/>
            <geometry>
                <box size="0.4996924452021747 0.020283004576954755 0.6374492357453108" />
            </geometry>
        </collision>
    </link>
    <joint name="0_10" type="revolute">
       <parent link="0"/>
       <child  link="10"/>
       <origin rpy="0 0 0" xyz="0 0 0.06634134267769781" />
     <axis xyz="0 1 0"/>
       <limit effort="0.0" lower="-3.14159" upper="3.14159" velocity="0.0"/>
    </joint>
    <link name="10">
        <inertial>
            <origin xyz="0 0 -0.022136557929644363" rpy="0 0 0"/>
            <mass value="1" />
            <inertia ixx="100" ixy="0" ixz="0" iyy="100" iyz="0" izz="100" />
        </inertial>
        <visual>
            <origin xyz="0 0 -0.022136557929644363" rpy="0 0 0"/>
            <geometry>
                <box size="0.40239531844764354 0.7079582765419368 0.044273115859288725" />
            </geometry>
            <material name="sensor">
                <color rgba="0 1 0 1"/>
            </material>
        </visual>
        <collision>
            <origin xyz="0 0 -0.022136557929644363" rpy="0 0 0"/>
            <geometry>
                <box size="0.40239531844764354 0.7079582765419368 0.044273115859288725" />
            </geometry>
        </collision>
    </link>
</robot>