<robot name = "robot">
    <link name="0">
        <inertial>
            <origin xyz="0 0 0.5756417862252692" rpy="0 0 0"/>
            <mass value="1" />
            <inertia ixx="100" ixy="0" ixz="0" iyy="100" iyz="0" izz="100" />
        </inertial>
        <visual>
            <origin xyz="0 0 0.5756417862252692" rpy="0 0 0"/>
            <geometry>
                <box size="0.014560516399670598 0.7783826649750103 0.4277315333105033" />
            </geometry>
            <material name="sensor">
                <color rgba="0 1 0 1"/>
            </material>
        </visual>
        <collision>
            <origin xyz="0 0 0.5756417862252692" rpy="0 0 0"/>
            <geometry>
                <box size="0.014560516399670598 0.7783826649750103 0.4277315333105033" />
            </geometry>
        </collision>
    </link>
    <joint name="0_2" type="revolute">
       <parent link="0"/>
       <child  link="2"/>
       <origin rpy="0 0 0" xyz="0 0.38919133248750515 0.5756417862252692" />
     <axis xyz="0 1 0"/>
       <limit effort="0.0" lower="-3.14159" upper="3.14159" velocity="0.0"/>
    </joint>
    <link name="2">
        <inertial>
            <origin xyz="0 0.23622483726842558 0.0" rpy="0 0 0"/>
            <mass value="1" />
            <inertia ixx="100" ixy="0" ixz="0" iyy="100" iyz="0" izz="100" />
        </inertial>
        <visual>
            <origin xyz="0 0.23622483726842558 0.0" rpy="0 0 0"/>
            <geometry>
                <box size="0.6483945830220665 0.47244967453685116 0.31095066027853024" />
            </geometry>
            <material name="sensor">
                <color rgba="0 1 0 1"/>
            </material>
        </visual>
        <collision>
            <origin xyz="0 0.23622483726842558 0.0" rpy="0 0 0"/>
            <geometry>
                <box size="0.6483945830220665 0.47244967453685116 0.31095066027853024" />
            </geometry>
        </collision>
    </link>
    <joint name="2_3" type="revolute">
       <parent link="2"/>
       <child  link="3"/>
       <origin rpy="0 0 0" xyz="0 0.47244967453685116 0.0" />
     <axis xyz="1 0 0"/>
       <limit effort="0.0" lower="-3.14159" upper="3.14159" velocity="0.0"/>
    </joint>
    <link name="3">
        <inertial>
            <origin xyz="0 0.24884096150443646 0.0" rpy="0 0 0"/>
            <mass value="1" />
            <inertia ixx="100" ixy="0" ixz="0" iyy="100" iyz="0" izz="100" />
        </inertial>
        <visual>
            <origin xyz="0 0.24884096150443646 0.0" rpy="0 0 0"/>
            <geometry>
                <box size="0.5490953392437847 0.4976819230088728 0.3307370062019286" />
            </geometry>
            <material name="sensor">
                <color rgba="0 1 0 1"/>
            </material>
        </visual>
        <collision>
            <origin xyz="0 0.24884096150443646 0.0" rpy="0 0 0"/>
            <geometry>
                <box size="0.5490953392437847 0.4976819230088728 0.3307370062019286" />
            </geometry>
        </collision>
    </link>
    <joint name="2_8" type="revolute">
       <parent link="2"/>
       <child  link="8"/>
       <origin rpy="0 0 0" xyz="-0.32419729151103327 0.23622483726842558 0.0" />
     <axis xyz="0 1 0"/>
       <limit effort="0.0" lower="-3.14159" upper="3.14159" velocity="0.0"/>
    </joint>
    <link name="8">
        <inertial>
            <origin xyz="-0.3486481394422213 0.0 0.0" rpy="0 0 0"/>
            <mass value="1" />
            <inertia ixx="100" ixy="0" ixz="0" iyy="100" iyz="0" izz="100" />
        </inertial>
        <visual>
            <origin xyz="-0.3486481394422213 0.0 0.0" rpy="0 0 0"/>
            <geometry>
                <box size="0.6972962788844425 0.15110920793301008 0.6313459327664014" />
            </geometry>
            <material name="sensor">
                <color rgba="0 1 0 1"/>
            </material>
        </visual>
        <collision>
            <origin xyz="-0.3486481394422213 0.0 0.0" rpy="0 0 0"/>
            <geometry>
                <box size="0.6972962788844425 0.15110920793301008 0.6313459327664014" />
            </geometry>
        </collision>
    </link>
    <joint name="0_1" type="revolute">
       <parent link="0"/>
       <child  link="1"/>
       <origin rpy="0 0 0" xyz="0 0 0.7895075528805209" />
     <axis xyz="0 0 1"/>
       <limit effort="0.0" lower="-3.14159" upper="3.14159" velocity="0.0"/>
    </joint>
    <link name="1">
        <inertial>
            <origin xyz="0 0 0.09823407940155704" rpy="0 0 0"/>
            <mass value="1" />
            <inertia ixx="100" ixy="0" ixz="0" iyy="100" iyz="0" izz="100" />
        </inertial>
        <visual>
            <origin xyz="0 0 0.09823407940155704" rpy="0 0 0"/>
            <geometry>
                <box size="0.39186569066590216 0.8519013875693786 0.19646815880311408" />
            </geometry>
            <material name="sensor">
                <color rgba="0 1 0 1"/>
            </material>
        </visual>
        <collision>
            <origin xyz="0 0 0.09823407940155704" rpy="0 0 0"/>
            <geometry>
                <box size="0.39186569066590216 0.8519013875693786 0.19646815880311408" />
            </geometry>
        </collision>
    </link>
    <joint name="0_4" type="revolute">
       <parent link="0"/>
       <child  link="4"/>
       <origin rpy="0 0 0" xyz="0 0 0.36177601957001754" />
     <axis xyz="0 1 0"/>
       <limit effort="0.0" lower="-3.14159" upper="3.14159" velocity="0.0"/>
    </joint>
    <link name="4">
        <inertial>
            <origin xyz="0 0 -0.03435230627035524" rpy="0 0 0"/>
            <mass value="1" />
            <inertia ixx="100" ixy="0" ixz="0" iyy="100" iyz="0" izz="100" />
        </inertial>
        <visual>
            <origin xyz="0 0 -0.03435230627035524" rpy="0 0 0"/>
            <geometry>
                <box size="0.3330515974953665 0.4293361826143115 0.06870461254071047" />
            </geometry>
            <material name="sensor">
                <color rgba="0 1 0 1"/>
            </material>
        </visual>
        <collision>
            <origin xyz="0 0 -0.03435230627035524" rpy="0 0 0"/>
            <geometry>
                <box size="0.3330515974953665 0.4293361826143115 0.06870461254071047" />
            </geometry>
        </collision>
    </link>
    <joint name="0_5" type="revolute">
       <parent link="0"/>
       <child  link="5"/>
       <origin rpy="0 0 0" xyz="0 -0.38919133248750515 0.5756417862252692" />
     <axis xyz="0 1 0"/>
       <limit effort="0.0" lower="-3.14159" upper="3.14159" velocity="0.0"/>
    </joint>
    <link name="5">
        <inertial>
            <origin xyz="0 -0.37276303422452484 0.0" rpy="0 0 0"/>
            <mass value="1" />
            <inertia ixx="100" ixy="0" ixz="0" iyy="100" iyz="0" izz="100" />
        </inertial>
        <visual>
            <origin xyz="0 -0.37276303422452484 0.0" rpy="0 0 0"/>
            <geometry>
                <box size="0.6602117000460553 0.7455260684490497 0.2798704211232158" />
            </geometry>
            <material name="not">
                <color rgba="0 1 1 1"/>
            </material>
        </visual>
        <collision>
            <origin xyz="0 -0.37276303422452484 0.0" rpy="0 0 0"/>
            <geometry>
                <box size="0.6602117000460553 0.7455260684490497 0.2798704211232158" />
            </geometry>
        </collision>
    </link>
    <joint name="5_6" type="revolute">
       <parent link="5"/>
       <child  link="6"/>
       <origin rpy="0 0 0" xyz="0.33010585002302767 -0.37276303422452484 0.0" />
     <axis xyz="1 0 0"/>
       <limit effort="0.0" lower="-3.14159" upper="3.14159" velocity="0.0"/>
    </joint>
    <link name="6">
        <inertial>
            <origin xyz="0.19926525607130346 0.0 0.0" rpy="0 0 0"/>
            <mass value="1" />
            <inertia ixx="100" ixy="0" ixz="0" iyy="100" iyz="0" izz="100" />
        </inertial>
        <visual>
            <origin xyz="0.19926525607130346 0.0 0.0" rpy="0 0 0"/>
            <geometry>
                <box size="0.39853051214260693 0.6237197900886302 0.009968894956041141" />
            </geometry>
            <material name="sensor">
                <color rgba="0 1 0 1"/>
            </material>
        </visual>
        <collision>
            <origin xyz="0.19926525607130346 0.0 0.0" rpy="0 0 0"/>
            <geometry>
                <box size="0.39853051214260693 0.6237197900886302 0.009968894956041141" />
            </geometry>
        </collision>
    </link>
    <joint name="5_7" type="revolute">
       <parent link="5"/>
       <child  link="7"/>
       <origin rpy="0 0 0" xyz="0 -0.37276303422452484 0.13993521056160785" />
     <axis xyz="0 1 0"/>
       <limit effort="0.0" lower="-3.14159" upper="3.14159" velocity="0.0"/>
    </joint>
    <link name="7">
        <inertial>
            <origin xyz="0 0.0 0.46926900616345835" rpy="0 0 0"/>
            <mass value="1" />
            <inertia ixx="100" ixy="0" ixz="0" iyy="100" iyz="0" izz="100" />
        </inertial>
        <visual>
            <origin xyz="0 0.0 0.46926900616345835" rpy="0 0 0"/>
            <geometry>
                <box size="0.6002176291454119 0.48957976217123034 0.9385380123269165" />
            </geometry>
            <material name="not">
                <color rgba="0 1 1 1"/>
            </material>
        </visual>
        <collision>
            <origin xyz="0 0.0 0.46926900616345835" rpy="0 0 0"/>
            <geometry>
                <box size="0.6002176291454119 0.48957976217123034 0.9385380123269165" />
            </geometry>
        </collision>
    </link>
</robot>