<robot name = "robot">
    <link name="0">
        <inertial>
            <origin xyz="0 0 0.5472430391153666" rpy="0 0 0"/>
            <mass value="1" />
            <inertia ixx="100" ixy="0" ixz="0" iyy="100" iyz="0" izz="100" />
        </inertial>
        <visual>
            <origin xyz="0 0 0.5472430391153666" rpy="0 0 0"/>
            <geometry>
                <box size="0.8558547229322963 0.8664012410869779 0.6888553487611566" />
            </geometry>
            <material name="not">
                <color rgba="0 1 1 1"/>
            </material>
        </visual>
        <collision>
            <origin xyz="0 0 0.5472430391153666" rpy="0 0 0"/>
            <geometry>
                <box size="0.8558547229322963 0.8664012410869779 0.6888553487611566" />
            </geometry>
        </collision>
    </link>
    <joint name="0_2" type="revolute">
       <parent link="0"/>
       <child  link="2"/>
       <origin rpy="0 0 0" xyz="0 0.43320062054348896 0.5472430391153666" />
     <axis xyz="1 0 0"/>
       <limit effort="0.0" lower="-3.14159" upper="3.14159" velocity="0.0"/>
    </joint>
    <link name="2">
        <inertial>
            <origin xyz="0 0.2979688211632757 0.0" rpy="0 0 0"/>
            <mass value="1" />
            <inertia ixx="100" ixy="0" ixz="0" iyy="100" iyz="0" izz="100" />
        </inertial>
        <visual>
            <origin xyz="0 0.2979688211632757 0.0" rpy="0 0 0"/>
            <geometry>
                <box size="0.14211248723250214 0.5959376423265513 0.5638591384666509" />
            </geometry>
            <material name="not">
                <color rgba="0 1 1 1"/>
            </material>
        </visual>
        <collision>
            <origin xyz="0 0.2979688211632757 0.0" rpy="0 0 0"/>
            <geometry>
                <box size="0.14211248723250214 0.5959376423265513 0.5638591384666509" />
            </geometry>
        </collision>
    </link>
    <joint name="2_3" type="revolute">
       <parent link="2"/>
       <child  link="3"/>
       <origin rpy="0 0 0" xyz="0.07105624361625107 0.2979688211632757 0.0" />
     <axis xyz="0 0 1"/>
       <limit effort="0.0" lower="-3.14159" upper="3.14159" velocity="0.0"/>
    </joint>
    <link name="3">
        <inertial>
            <origin xyz="0.3705131112820676 0.0 0.0" rpy="0 0 0"/>
            <mass value="1" />
            <inertia ixx="100" ixy="0" ixz="0" iyy="100" iyz="0" izz="100" />
        </inertial>
        <visual>
            <origin xyz="0.3705131112820676 0.0 0.0" rpy="0 0 0"/>
            <geometry>
                <box size="0.7410262225641352 0.30080270391930264 0.25106828224280264" />
            </geometry>
            <material name="sensor">
                <color rgba="0 1 0 1"/>
            </material>
        </visual>
        <collision>
            <origin xyz="0.3705131112820676 0.0 0.0" rpy="0 0 0"/>
            <geometry>
                <box size="0.7410262225641352 0.30080270391930264 0.25106828224280264" />
            </geometry>
        </collision>
    </link>
    <joint name="2_4" type="revolute">
       <parent link="2"/>
       <child  link="4"/>
       <origin rpy="0 0 0" xyz="0 0.5959376423265513 0.0" />
     <axis xyz="1 0 0"/>
       <limit effort="0.0" lower="-3.14159" upper="3.14159" velocity="0.0"/>
    </joint>
    <link name="4">
        <inertial>
            <origin xyz="0 0.1431991761300393 0.0" rpy="0 0 0"/>
            <mass value="1" />
            <inertia ixx="100" ixy="0" ixz="0" iyy="100" iyz="0" izz="100" />
        </inertial>
        <visual>
            <origin xyz="0 0.1431991761300393 0.0" rpy="0 0 0"/>
            <geometry>
                <box size="0.4917547175999324 0.2863983522600786 0.4769356997592369" />
            </geometry>
            <material name="sensor">
                <color rgba="0 1 0 1"/>
            </material>
        </visual>
        <collision>
            <origin xyz="0 0.1431991761300393 0.0" rpy="0 0 0"/>
            <geometry>
                <box size="0.4917547175999324 0.2863983522600786 0.4769356997592369" />
            </geometry>
        </collision>
    </link>
    <joint name="4_6" type="revolute">
       <parent link="4"/>
       <child  link="6"/>
       <origin rpy="0 0 0" xyz="0.2458773587999662 0.1431991761300393 0.0" />
     <axis xyz="1 0 0"/>
       <limit effort="0.0" lower="-3.14159" upper="3.14159" velocity="0.0"/>
    </joint>
    <link name="6">
        <inertial>
            <origin xyz="0.28015769747565544 0.0 0.0" rpy="0 0 0"/>
            <mass value="1" />
            <inertia ixx="100" ixy="0" ixz="0" iyy="100" iyz="0" izz="100" />
        </inertial>
        <visual>
            <origin xyz="0.28015769747565544 0.0 0.0" rpy="0 0 0"/>
            <geometry>
                <box size="0.5603153949513109 0.24347173374334818 0.47427801625361465" />
            </geometry>
            <material name="not">
                <color rgba="0 1 1 1"/>
            </material>
        </visual>
        <collision>
            <origin xyz="0.28015769747565544 0.0 0.0" rpy="0 0 0"/>
            <geometry>
                <box size="0.5603153949513109 0.24347173374334818 0.47427801625361465" />
            </geometry>
        </collision>
    </link>
    <joint name="4_7" type="revolute">
       <parent link="4"/>
       <child  link="7"/>
       <origin rpy="0 0 0" xyz="0 0.2863983522600786 0.0" />
     <axis xyz="0 0 1"/>
       <limit effort="0.0" lower="-3.14159" upper="3.14159" velocity="0.0"/>
    </joint>
    <link name="7">
        <inertial>
            <origin xyz="0 0.3488026428512867 0.0" rpy="0 0 0"/>
            <mass value="1" />
            <inertia ixx="100" ixy="0" ixz="0" iyy="100" iyz="0" izz="100" />
        </inertial>
        <visual>
            <origin xyz="0 0.3488026428512867 0.0" rpy="0 0 0"/>
            <geometry>
                <box size="0.328543547564508 0.6976052857025734 0.7645814171477043" />
            </geometry>
            <material name="sensor">
                <color rgba="0 1 0 1"/>
            </material>
        </visual>
        <collision>
            <origin xyz="0 0.3488026428512867 0.0" rpy="0 0 0"/>
            <geometry>
                <box size="0.328543547564508 0.6976052857025734 0.7645814171477043" />
            </geometry>
        </collision>
    </link>
    <joint name="0_1" type="revolute">
       <parent link="0"/>
       <child  link="1"/>
       <origin rpy="0 0 0" xyz="0 0 0.891670713495945" />
     <axis xyz="1 0 0"/>
       <limit effort="0.0" lower="-3.14159" upper="3.14159" velocity="0.0"/>
    </joint>
    <link name="1">
        <inertial>
            <origin xyz="0 0 0.47555145465171433" rpy="0 0 0"/>
            <mass value="1" />
            <inertia ixx="100" ixy="0" ixz="0" iyy="100" iyz="0" izz="100" />
        </inertial>
        <visual>
            <origin xyz="0 0 0.47555145465171433" rpy="0 0 0"/>
            <geometry>
                <box size="0.2952813323231105 0.5126476983679332 0.9511029093034284" />
            </geometry>
            <material name="sensor">
                <color rgba="0 1 0 1"/>
            </material>
        </visual>
        <collision>
            <origin xyz="0 0 0.47555145465171433" rpy="0 0 0"/>
            <geometry>
                <box size="0.2952813323231105 0.5126476983679332 0.9511029093034284" />
            </geometry>
        </collision>
    </link>
    <joint name="1_5" type="revolute">
       <parent link="1"/>
       <child  link="5"/>
       <origin rpy="0 0 0" xyz="0.14764066616155525 0 0.47555145465171433" />
     <axis xyz="0 1 0"/>
       <limit effort="0.0" lower="-3.14159" upper="3.14159" velocity="0.0"/>
    </joint>
    <link name="5">
        <inertial>
            <origin xyz="0.1465515495835859 0 0.0" rpy="0 0 0"/>
            <mass value="1" />
            <inertia ixx="100" ixy="0" ixz="0" iyy="100" iyz="0" izz="100" />
        </inertial>
        <visual>
            <origin xyz="0.1465515495835859 0 0.0" rpy="0 0 0"/>
            <geometry>
                <box size="0.2931030991671718 0.7817062969240562 0.8268053039341334" />
            </geometry>
            <material name="sensor">
                <color rgba="0 1 0 1"/>
            </material>
        </visual>
        <collision>
            <origin xyz="0.1465515495835859 0 0.0" rpy="0 0 0"/>
            <geometry>
                <box size="0.2931030991671718 0.7817062969240562 0.8268053039341334" />
            </geometry>
        </collision>
    </link>
    <joint name="5_9" type="revolute">
       <parent link="5"/>
       <child  link="9"/>
       <origin rpy="0 0 0" xyz="0.2931030991671718 0 0.0" />
     <axis xyz="1 0 0"/>
       <limit effort="0.0" lower="-3.14159" upper="3.14159" velocity="0.0"/>
    </joint>
    <link name="9">
        <inertial>
            <origin xyz="0.09549812966129667 0 0.0" rpy="0 0 0"/>
            <mass value="1" />
            <inertia ixx="100" ixy="0" ixz="0" iyy="100" iyz="0" izz="100" />
        </inertial>
        <visual>
            <origin xyz="0.09549812966129667 0 0.0" rpy="0 0 0"/>
            <geometry>
                <box size="0.19099625932259334 0.9993905066845336 0.08400926668113518" />
            </geometry>
            <material name="sensor">
                <color rgba="0 1 0 1"/>
            </material>
        </visual>
        <collision>
            <origin xyz="0.09549812966129667 0 0.0" rpy="0 0 0"/>
            <geometry>
                <box size="0.19099625932259334 0.9993905066845336 0.08400926668113518" />
            </geometry>
        </collision>
    </link>
    <joint name="0_8" type="revolute">
       <parent link="0"/>
       <child  link="8"/>
       <origin rpy="0 0 0" xyz="0 0 0.20281536473478834" />
     <axis xyz="0 0 1"/>
       <limit effort="0.0" lower="-3.14159" upper="3.14159" velocity="0.0"/>
    </joint>
    <link name="8">
        <inertial>
            <origin xyz="0 0 -0.08500145371498624" rpy="0 0 0"/>
            <mass value="1" />
            <inertia ixx="100" ixy="0" ixz="0" iyy="100" iyz="0" izz="100" />
        </inertial>
        <visual>
            <origin xyz="0 0 -0.08500145371498624" rpy="0 0 0"/>
            <geometry>
                <box size="0.38686600143344985 0.037279430147598824 0.17000290742997248" />
            </geometry>
            <material name="sensor">
                <color rgba="0 1 0 1"/>
            </material>
        </visual>
        <collision>
            <origin xyz="0 0 -0.08500145371498624" rpy="0 0 0"/>
            <geometry>
                <box size="0.38686600143344985 0.037279430147598824 0.17000290742997248" />
            </geometry>
        </collision>
    </link>
</robot>