<robot name = "robot">
    <link name="0">
        <inertial>
            <origin xyz="0 0 0.6864838541790798" rpy="0 0 0"/>
            <mass value="1" />
            <inertia ixx="100" ixy="0" ixz="0" iyy="100" iyz="0" izz="100" />
        </inertial>
        <visual>
            <origin xyz="0 0 0.6864838541790798" rpy="0 0 0"/>
            <geometry>
                <box size="0.6495461355254983 0.009204938554384978 0.8812338589221554" />
            </geometry>
            <material name="sensor">
                <color rgba="0 1 0 1"/>
            </material>
        </visual>
        <collision>
            <origin xyz="0 0 0.6864838541790798" rpy="0 0 0"/>
            <geometry>
                <box size="0.6495461355254983 0.009204938554384978 0.8812338589221554" />
            </geometry>
        </collision>
    </link>
    <joint name="0_2" type="revolute">
       <parent link="0"/>
       <child  link="2"/>
       <origin rpy="0 0 0" xyz="0.32477306776274917 0 0.6864838541790798" />
     <axis xyz="0 0 1"/>
       <limit effort="0.0" lower="-3.14159" upper="3.14159" velocity="0.0"/>
    </joint>
    <link name="2">
        <inertial>
            <origin xyz="0.09295313294735885 0 0.0" rpy="0 0 0"/>
            <mass value="1" />
            <inertia ixx="100" ixy="0" ixz="0" iyy="100" iyz="0" izz="100" />
        </inertial>
        <visual>
            <origin xyz="0.09295313294735885 0 0.0" rpy="0 0 0"/>
            <geometry>
                <box size="0.1859062658947177 0.9925434121760651 0.8599465287952899" />
            </geometry>
            <material name="sensor">
                <color rgba="0 1 0 1"/>
            </material>
        </visual>
        <collision>
            <origin xyz="0.09295313294735885 0 0.0" rpy="0 0 0"/>
            <geometry>
                <box size="0.1859062658947177 0.9925434121760651 0.8599465287952899" />
            </geometry>
        </collision>
    </link>
    <joint name="0_1" type="revolute">
       <parent link="0"/>
       <child  link="1"/>
       <origin rpy="0 0 0" xyz="0 0 1.1271007836401574" />
     <axis xyz="0 1 0"/>
       <limit effort="0.0" lower="-3.14159" upper="3.14159" velocity="0.0"/>
    </joint>
    <link name="1">
        <inertial>
            <origin xyz="0 0 0.27642978814648256" rpy="0 0 0"/>
            <mass value="1" />
            <inertia ixx="100" ixy="0" ixz="0" iyy="100" iyz="0" izz="100" />
        </inertial>
        <visual>
            <origin xyz="0 0 0.27642978814648256" rpy="0 0 0"/>
            <geometry>
                <box size="0.7637009951314895 0.9391670189485866 0.5528595762929651" />
            </geometry>
            <material name="not">
                <color rgba="0 1 1 1"/>
            </material>
        </visual>
        <collision>
            <origin xyz="0 0 0.27642978814648256" rpy="0 0 0"/>
            <geometry>
                <box size="0.7637009951314895 0.9391670189485866 0.5528595762929651" />
            </geometry>
        </collision>
    </link>
    <joint name="1_3" type="revolute">
       <parent link="1"/>
       <child  link="3"/>
       <origin rpy="0 0 0" xyz="0.38185049756574474 0 0.27642978814648256" />
     <axis xyz="1 0 0"/>
       <limit effort="0.0" lower="-3.14159" upper="3.14159" velocity="0.0"/>
    </joint>
    <link name="3">
        <inertial>
            <origin xyz="0.4709109637533667 0 0.0" rpy="0 0 0"/>
            <mass value="1" />
            <inertia ixx="100" ixy="0" ixz="0" iyy="100" iyz="0" izz="100" />
        </inertial>
        <visual>
            <origin xyz="0.4709109637533667 0 0.0" rpy="0 0 0"/>
            <geometry>
                <box size="0.9418219275067334 0.6977303741012196 0.006825903023294777" />
            </geometry>
            <material name="not">
                <color rgba="0 1 1 1"/>
            </material>
        </visual>
        <collision>
            <origin xyz="0.4709109637533667 0 0.0" rpy="0 0 0"/>
            <geometry>
                <box size="0.9418219275067334 0.6977303741012196 0.006825903023294777" />
            </geometry>
        </collision>
    </link>
    <joint name="3_4" type="revolute">
       <parent link="3"/>
       <child  link="4"/>
       <origin rpy="0 0 0" xyz="0.9418219275067335 0 0.0" />
     <axis xyz="0 0 1"/>
       <limit effort="0.0" lower="-3.14159" upper="3.14159" velocity="0.0"/>
    </joint>
    <link name="4">
        <inertial>
            <origin xyz="0.21850305916945034 0 0.0" rpy="0 0 0"/>
            <mass value="1" />
            <inertia ixx="100" ixy="0" ixz="0" iyy="100" iyz="0" izz="100" />
        </inertial>
        <visual>
            <origin xyz="0.21850305916945034 0 0.0" rpy="0 0 0"/>
            <geometry>
                <box size="0.4370061183389008 0.5421890681333738 0.6377611379649377" />
            </geometry>
            <material name="sensor">
                <color rgba="0 1 0 1"/>
            </material>
        </visual>
        <collision>
            <origin xyz="0.21850305916945034 0 0.0" rpy="0 0 0"/>
            <geometry>
                <box size="0.4370061183389008 0.5421890681333738 0.6377611379649377" />
            </geometry>
        </collision>
    </link>
    <joint name="4_5" type="revolute">
       <parent link="4"/>
       <child  link="5"/>
       <origin rpy="0 0 0" xyz="0.21850305916945034 0 -0.31888056898246897" />
     <axis xyz="0 1 0"/>
       <limit effort="0.0" lower="-3.14159" upper="3.14159" velocity="0.0"/>
    </joint>
    <link name="5">
        <inertial>
            <origin xyz="0.0 0 -0.16869574419050992" rpy="0 0 0"/>
            <mass value="1" />
            <inertia ixx="100" ixy="0" ixz="0" iyy="100" iyz="0" izz="100" />
        </inertial>
        <visual>
            <origin xyz="0.0 0 -0.16869574419050992" rpy="0 0 0"/>
            <geometry>
                <box size="0.47736039473028724 0.717507397244771 0.33739148838101995" />
            </geometry>
            <material name="sensor">
                <color rgba="0 1 0 1"/>
            </material>
        </visual>
        <collision>
            <origin xyz="0.0 0 -0.16869574419050992" rpy="0 0 0"/>
            <geometry>
                <box size="0.47736039473028724 0.717507397244771 0.33739148838101995" />
            </geometry>
        </collision>
    </link>
</robot>