<robot name = "robot">
    <link name="0">
        <inertial>
            <origin xyz="0 0 0.797433214008021" rpy="0 0 0"/>
            <mass value="1" />
            <inertia ixx="100" ixy="0" ixz="0" iyy="100" iyz="0" izz="100" />
        </inertial>
        <visual>
            <origin xyz="0 0 0.797433214008021" rpy="0 0 0"/>
            <geometry>
                <box size="0.2564796746315954 0.6409972685732053 0.9970404948887329" />
            </geometry>
            <material name="not">
                <color rgba="0 1 1 1"/>
            </material>
        </visual>
        <collision>
            <origin xyz="0 0 0.797433214008021" rpy="0 0 0"/>
            <geometry>
                <box size="0.2564796746315954 0.6409972685732053 0.9970404948887329" />
            </geometry>
        </collision>
    </link>
    <joint name="0_1" type="revolute">
       <parent link="0"/>
       <child  link="1"/>
       <origin rpy="0 0 0" xyz="0.1282398373157977 0 0.797433214008021" />
     <axis xyz="0 0 1"/>
       <limit effort="0.0" lower="-3.14159" upper="3.14159" velocity="0.0"/>
    </joint>
    <link name="1">
        <inertial>
            <origin xyz="0.22920402280253155 0 0.0" rpy="0 0 0"/>
            <mass value="1" />
            <inertia ixx="100" ixy="0" ixz="0" iyy="100" iyz="0" izz="100" />
        </inertial>
        <visual>
            <origin xyz="0.22920402280253155 0 0.0" rpy="0 0 0"/>
            <geometry>
                <box size="0.4584080456050631 0.3616420965372864 0.8269865896652219" />
            </geometry>
            <material name="sensor">
                <color rgba="0 1 0 1"/>
            </material>
        </visual>
        <collision>
            <origin xyz="0.22920402280253155 0 0.0" rpy="0 0 0"/>
            <geometry>
                <box size="0.4584080456050631 0.3616420965372864 0.8269865896652219" />
            </geometry>
        </collision>
    </link>
    <joint name="0_2" type="revolute">
       <parent link="0"/>
       <child  link="2"/>
       <origin rpy="0 0 0" xyz="-0.1282398373157977 0 0.797433214008021" />
     <axis xyz="0 1 0"/>
       <limit effort="0.0" lower="-3.14159" upper="3.14159" velocity="0.0"/>
    </joint>
    <link name="2">
        <inertial>
            <origin xyz="-0.27140453684989585 0 0.0" rpy="0 0 0"/>
            <mass value="1" />
            <inertia ixx="100" ixy="0" ixz="0" iyy="100" iyz="0" izz="100" />
        </inertial>
        <visual>
            <origin xyz="-0.27140453684989585 0 0.0" rpy="0 0 0"/>
            <geometry>
                <box size="0.5428090736997917 0.9313134045807503 0.009704659433814156" />
            </geometry>
            <material name="sensor">
                <color rgba="0 1 0 1"/>
            </material>
        </visual>
        <collision>
            <origin xyz="-0.27140453684989585 0 0.0" rpy="0 0 0"/>
            <geometry>
                <box size="0.5428090736997917 0.9313134045807503 0.009704659433814156" />
            </geometry>
        </collision>
    </link>
</robot>