<robot name = "robot">
    <link name="0">
        <inertial>
            <origin xyz="0 0 0.9963740517250494" rpy="0 0 0"/>
            <mass value="1" />
            <inertia ixx="100" ixy="0" ixz="0" iyy="100" iyz="0" izz="100" />
        </inertial>
        <visual>
            <origin xyz="0 0 0.9963740517250494" rpy="0 0 0"/>
            <geometry>
                <box size="0.7904871970494158 0.001152023751002762 0.5374763183409071" />
            </geometry>
            <material name="sensor">
                <color rgba="0 1 0 1"/>
            </material>
        </visual>
        <collision>
            <origin xyz="0 0 0.9963740517250494" rpy="0 0 0"/>
            <geometry>
                <box size="0.7904871970494158 0.001152023751002762 0.5374763183409071" />
            </geometry>
        </collision>
    </link>
    <joint name="0_3" type="revolute">
       <parent link="0"/>
       <child  link="3"/>
       <origin rpy="0 0 0" xyz="0.3952435985247079 0 0.9963740517250494" />
     <axis xyz="0 0 1"/>
       <limit effort="0.0" lower="-3.14159" upper="3.14159" velocity="0.0"/>
    </joint>
    <link name="3">
        <inertial>
            <origin xyz="0.003376732755691614 0 0.0" rpy="0 0 0"/>
            <mass value="1" />
            <inertia ixx="100" ixy="0" ixz="0" iyy="100" iyz="0" izz="100" />
        </inertial>
        <visual>
            <origin xyz="0.003376732755691614 0 0.0" rpy="0 0 0"/>
            <geometry>
                <box size="0.006753465511383228 0.29211120858139705 0.8451497219866394" />
            </geometry>
            <material name="not">
                <color rgba="0 1 1 1"/>
            </material>
        </visual>
        <collision>
            <origin xyz="0.003376732755691614 0 0.0" rpy="0 0 0"/>
            <geometry>
                <box size="0.006753465511383228 0.29211120858139705 0.8451497219866394" />
            </geometry>
        </collision>
    </link>
    <joint name="3_4" type="revolute">
       <parent link="3"/>
       <child  link="4"/>
       <origin rpy="0 0 0" xyz="0.003376732755691614 0.14605560429069853 0.0" />
     <axis xyz="0 0 1"/>
       <limit effort="0.0" lower="-3.14159" upper="3.14159" velocity="0.0"/>
    </joint>
    <link name="4">
        <inertial>
            <origin xyz="0.0 0.15585787134564333 0.0" rpy="0 0 0"/>
            <mass value="1" />
            <inertia ixx="100" ixy="0" ixz="0" iyy="100" iyz="0" izz="100" />
        </inertial>
        <visual>
            <origin xyz="0.0 0.15585787134564333 0.0" rpy="0 0 0"/>
            <geometry>
                <box size="0.9698587223918274 0.31171574269128666 0.8200044944430386" />
            </geometry>
            <material name="sensor">
                <color rgba="0 1 0 1"/>
            </material>
        </visual>
        <collision>
            <origin xyz="0.0 0.15585787134564333 0.0" rpy="0 0 0"/>
            <geometry>
                <box size="0.9698587223918274 0.31171574269128666 0.8200044944430386" />
            </geometry>
        </collision>
    </link>
    <joint name="4_6" type="revolute">
       <parent link="4"/>
       <child  link="6"/>
       <origin rpy="0 0 0" xyz="-0.4849293611959137 0.15585787134564333 0.0" />
     <axis xyz="1 0 0"/>
       <limit effort="0.0" lower="-3.14159" upper="3.14159" velocity="0.0"/>
    </joint>
    <link name="6">
        <inertial>
            <origin xyz="-0.09365660658656128 0.0 0.0" rpy="0 0 0"/>
            <mass value="1" />
            <inertia ixx="100" ixy="0" ixz="0" iyy="100" iyz="0" izz="100" />
        </inertial>
        <visual>
            <origin xyz="-0.09365660658656128 0.0 0.0" rpy="0 0 0"/>
            <geometry>
                <box size="0.18731321317312255 0.22332413855979394 0.4170290821075141" />
            </geometry>
            <material name="not">
                <color rgba="0 1 1 1"/>
            </material>
        </visual>
        <collision>
            <origin xyz="-0.09365660658656128 0.0 0.0" rpy="0 0 0"/>
            <geometry>
                <box size="0.18731321317312255 0.22332413855979394 0.4170290821075141" />
            </geometry>
        </collision>
    </link>
    <joint name="0_1" type="revolute">
       <parent link="0"/>
       <child  link="1"/>
       <origin rpy="0 0 0" xyz="0 0 0.7276358925545958" />
     <axis xyz="0 0 1"/>
       <limit effort="0.0" lower="-3.14159" upper="3.14159" velocity="0.0"/>
    </joint>
    <link name="1">
        <inertial>
            <origin xyz="0 0 -0.1235291921693118" rpy="0 0 0"/>
            <mass value="1" />
            <inertia ixx="100" ixy="0" ixz="0" iyy="100" iyz="0" izz="100" />
        </inertial>
        <visual>
            <origin xyz="0 0 -0.1235291921693118" rpy="0 0 0"/>
            <geometry>
                <box size="0.4753042200675436 0.23476809670777787 0.2470583843386236" />
            </geometry>
            <material name="sensor">
                <color rgba="0 1 0 1"/>
            </material>
        </visual>
        <collision>
            <origin xyz="0 0 -0.1235291921693118" rpy="0 0 0"/>
            <geometry>
                <box size="0.4753042200675436 0.23476809670777787 0.2470583843386236" />
            </geometry>
        </collision>
    </link>
</robot>