<robot name = "robot">
    <link name="0">
        <inertial>
            <origin xyz="0 0 0.46333982950632935" rpy="0 0 0"/>
            <mass value="1" />
            <inertia ixx="100" ixy="0" ixz="0" iyy="100" iyz="0" izz="100" />
        </inertial>
        <visual>
            <origin xyz="0 0 0.46333982950632935" rpy="0 0 0"/>
            <geometry>
                <box size="0.8120604042069871 0.059990774174588646 0.6372948101599734" />
            </geometry>
            <material name="not">
                <color rgba="0 1 1 1"/>
            </material>
        </visual>
        <collision>
            <origin xyz="0 0 0.46333982950632935" rpy="0 0 0"/>
            <geometry>
                <box size="0.8120604042069871 0.059990774174588646 0.6372948101599734" />
            </geometry>
        </collision>
    </link>
    <joint name="0_2" type="revolute">
       <parent link="0"/>
       <child  link="2"/>
       <origin rpy="0 0 0" xyz="0.40603020210349355 0 0.46333982950632935" />
     <axis xyz="0 1 0"/>
       <limit effort="0.0" lower="-3.14159" upper="3.14159" velocity="0.0"/>
    </joint>
    <link name="2">
        <inertial>
            <origin xyz="0.1975212800789315 0 0.0" rpy="0 0 0"/>
            <mass value="1" />
            <inertia ixx="100" ixy="0" ixz="0" iyy="100" iyz="0" izz="100" />
        </inertial>
        <visual>
            <origin xyz="0.1975212800789315 0 0.0" rpy="0 0 0"/>
            <geometry>
                <box size="0.3950425601578629 0.12172948013366958 0.12177009972153996" />
            </geometry>
            <material name="sensor">
                <color rgba="0 1 0 1"/>
            </material>
        </visual>
        <collision>
            <origin xyz="0.1975212800789315 0 0.0" rpy="0 0 0"/>
            <geometry>
                <box size="0.3950425601578629 0.12172948013366958 0.12177009972153996" />
            </geometry>
        </collision>
    </link>
    <joint name="0_1" type="revolute">
       <parent link="0"/>
       <child  link="1"/>
       <origin rpy="0 0 0" xyz="0 0.029995387087294323 0.46333982950632935" />
     <axis xyz="1 0 0"/>
       <limit effort="0.0" lower="-3.14159" upper="3.14159" velocity="0.0"/>
    </joint>
    <link name="1">
        <inertial>
            <origin xyz="0 0.15291069423880588 0.0" rpy="0 0 0"/>
            <mass value="1" />
            <inertia ixx="100" ixy="0" ixz="0" iyy="100" iyz="0" izz="100" />
        </inertial>
        <visual>
            <origin xyz="0 0.15291069423880588 0.0" rpy="0 0 0"/>
            <geometry>
                <box size="0.024141970074937458 0.30582138847761176 0.7235649978857355" />
            </geometry>
            <material name="sensor">
                <color rgba="0 1 0 1"/>
            </material>
        </visual>
        <collision>
            <origin xyz="0 0.15291069423880588 0.0" rpy="0 0 0"/>
            <geometry>
                <box size="0.024141970074937458 0.30582138847761176 0.7235649978857355" />
            </geometry>
        </collision>
    </link>
</robot>