<robot name = "robot">
    <link name="0">
        <inertial>
            <origin xyz="0 0 0.2024075179964182" rpy="0 0 0"/>
            <mass value="1" />
            <inertia ixx="100" ixy="0" ixz="0" iyy="100" iyz="0" izz="100" />
        </inertial>
        <visual>
            <origin xyz="0 0 0.2024075179964182" rpy="0 0 0"/>
            <geometry>
                <box size="0.39550989913405066 0.09699875143991565 0.033165590363306796" />
            </geometry>
            <material name="not">
                <color rgba="0 1 1 1"/>
            </material>
        </visual>
        <collision>
            <origin xyz="0 0 0.2024075179964182" rpy="0 0 0"/>
            <geometry>
                <box size="0.39550989913405066 0.09699875143991565 0.033165590363306796" />
            </geometry>
        </collision>
    </link>
    <joint name="0_8" type="revolute">
       <parent link="0"/>
       <child  link="8"/>
       <origin rpy="0 0 0" xyz="0 0.04849937571995783 0.2024075179964182" />
     <axis xyz="0 0 1"/>
       <limit effort="0.0" lower="-3.14159" upper="3.14159" velocity="0.0"/>
    </joint>
    <link name="8">
        <inertial>
            <origin xyz="0 0.028416929630706578 0.0" rpy="0 0 0"/>
            <mass value="1" />
            <inertia ixx="100" ixy="0" ixz="0" iyy="100" iyz="0" izz="100" />
        </inertial>
        <visual>
            <origin xyz="0 0.028416929630706578 0.0" rpy="0 0 0"/>
            <geometry>
                <box size="0.14745310266111533 0.056833859261413155 0.014476591270675243" />
            </geometry>
            <material name="not">
                <color rgba="0 1 1 1"/>
            </material>
        </visual>
        <collision>
            <origin xyz="0 0.028416929630706578 0.0" rpy="0 0 0"/>
            <geometry>
                <box size="0.14745310266111533 0.056833859261413155 0.014476591270675243" />
            </geometry>
        </collision>
    </link>
    <joint name="0_1" type="revolute">
       <parent link="0"/>
       <child  link="1"/>
       <origin rpy="0 0 0" xyz="0 0 0.2189903131780716" />
     <axis xyz="1 0 0"/>
       <limit effort="0.0" lower="-3.14159" upper="3.14159" velocity="0.0"/>
    </joint>
    <link name="1">
        <inertial>
            <origin xyz="0 0 0.21349384065786958" rpy="0 0 0"/>
            <mass value="1" />
            <inertia ixx="100" ixy="0" ixz="0" iyy="100" iyz="0" izz="100" />
        </inertial>
        <visual>
            <origin xyz="0 0 0.21349384065786958" rpy="0 0 0"/>
            <geometry>
                <box size="0.6612473633911264 0.34851759672492466 0.42698768131573916" />
            </geometry>
            <material name="sensor">
                <color rgba="0 1 0 1"/>
            </material>
        </visual>
        <collision>
            <origin xyz="0 0 0.21349384065786958" rpy="0 0 0"/>
            <geometry>
                <box size="0.6612473633911264 0.34851759672492466 0.42698768131573916" />
            </geometry>
        </collision>
    </link>
    <joint name="1_2" type="revolute">
       <parent link="1"/>
       <child  link="2"/>
       <origin rpy="0 0 0" xyz="0 0.17425879836246233 0.21349384065786958" />
     <axis xyz="1 0 0"/>
       <limit effort="0.0" lower="-3.14159" upper="3.14159" velocity="0.0"/>
    </joint>
    <link name="2">
        <inertial>
            <origin xyz="0 0.04987422448248385 0.0" rpy="0 0 0"/>
            <mass value="1" />
            <inertia ixx="100" ixy="0" ixz="0" iyy="100" iyz="0" izz="100" />
        </inertial>
        <visual>
            <origin xyz="0 0.04987422448248385 0.0" rpy="0 0 0"/>
            <geometry>
                <box size="0.46557349310739315 0.0997484489649677 0.1546732608479392" />
            </geometry>
            <material name="not">
                <color rgba="0 1 1 1"/>
            </material>
        </visual>
        <collision>
            <origin xyz="0 0.04987422448248385 0.0" rpy="0 0 0"/>
            <geometry>
                <box size="0.46557349310739315 0.0997484489649677 0.1546732608479392" />
            </geometry>
        </collision>
    </link>
    <joint name="2_5" type="revolute">
       <parent link="2"/>
       <child  link="5"/>
       <origin rpy="0 0 0" xyz="0 0.0997484489649677 0.0" />
     <axis xyz="1 0 0"/>
       <limit effort="0.0" lower="-3.14159" upper="3.14159" velocity="0.0"/>
    </joint>
    <link name="5">
        <inertial>
            <origin xyz="0 0.047648512825965494 0.0" rpy="0 0 0"/>
            <mass value="1" />
            <inertia ixx="100" ixy="0" ixz="0" iyy="100" iyz="0" izz="100" />
        </inertial>
        <visual>
            <origin xyz="0 0.047648512825965494 0.0" rpy="0 0 0"/>
            <geometry>
                <box size="0.7268331571142126 0.09529702565193099 0.5303122893417169" />
            </geometry>
            <material name="not">
                <color rgba="0 1 1 1"/>
            </material>
        </visual>
        <collision>
            <origin xyz="0 0.047648512825965494 0.0" rpy="0 0 0"/>
            <geometry>
                <box size="0.7268331571142126 0.09529702565193099 0.5303122893417169" />
            </geometry>
        </collision>
    </link>
    <joint name="2_9" type="revolute">
       <parent link="2"/>
       <child  link="9"/>
       <origin rpy="0 0 0" xyz="-0.23278674655369658 0.04987422448248385 0.0" />
     <axis xyz="0 1 0"/>
       <limit effort="0.0" lower="-3.14159" upper="3.14159" velocity="0.0"/>
    </joint>
    <link name="9">
        <inertial>
            <origin xyz="-0.26088850227949595 0.0 0.0" rpy="0 0 0"/>
            <mass value="1" />
            <inertia ixx="100" ixy="0" ixz="0" iyy="100" iyz="0" izz="100" />
        </inertial>
        <visual>
            <origin xyz="-0.26088850227949595 0.0 0.0" rpy="0 0 0"/>
            <geometry>
                <box size="0.5217770045589919 0.024797795483913254 0.795264852785218" />
            </geometry>
            <material name="sensor">
                <color rgba="0 1 0 1"/>
            </material>
        </visual>
        <collision>
            <origin xyz="-0.26088850227949595 0.0 0.0" rpy="0 0 0"/>
            <geometry>
                <box size="0.5217770045589919 0.024797795483913254 0.795264852785218" />
            </geometry>
        </collision>
    </link>
    <joint name="1_3" type="revolute">
       <parent link="1"/>
       <child  link="3"/>
       <origin rpy="0 0 0" xyz="0 -0.17425879836246233 0.21349384065786958" />
     <axis xyz="0 1 0"/>
       <limit effort="0.0" lower="-3.14159" upper="3.14159" velocity="0.0"/>
    </joint>
    <link name="3">
        <inertial>
            <origin xyz="0 -0.43445824042090336 0.0" rpy="0 0 0"/>
            <mass value="1" />
            <inertia ixx="100" ixy="0" ixz="0" iyy="100" iyz="0" izz="100" />
        </inertial>
        <visual>
            <origin xyz="0 -0.43445824042090336 0.0" rpy="0 0 0"/>
            <geometry>
                <box size="0.8690671949510088 0.8689164808418067 0.46966007465209003" />
            </geometry>
            <material name="sensor">
                <color rgba="0 1 0 1"/>
            </material>
        </visual>
        <collision>
            <origin xyz="0 -0.43445824042090336 0.0" rpy="0 0 0"/>
            <geometry>
                <box size="0.8690671949510088 0.8689164808418067 0.46966007465209003" />
            </geometry>
        </collision>
    </link>
    <joint name="3_7" type="revolute">
       <parent link="3"/>
       <child  link="7"/>
       <origin rpy="0 0 0" xyz="0.4345335974755044 -0.43445824042090336 0.0" />
     <axis xyz="0 0 1"/>
       <limit effort="0.0" lower="-3.14159" upper="3.14159" velocity="0.0"/>
    </joint>
    <link name="7">
        <inertial>
            <origin xyz="0.051781524445410565 0.0 0.0" rpy="0 0 0"/>
            <mass value="1" />
            <inertia ixx="100" ixy="0" ixz="0" iyy="100" iyz="0" izz="100" />
        </inertial>
        <visual>
            <origin xyz="0.051781524445410565 0.0 0.0" rpy="0 0 0"/>
            <geometry>
                <box size="0.10356304889082113 0.8142588648982915 0.41945728425307693" />
            </geometry>
            <material name="not">
                <color rgba="0 1 1 1"/>
            </material>
        </visual>
        <collision>
            <origin xyz="0.051781524445410565 0.0 0.0" rpy="0 0 0"/>
            <geometry>
                <box size="0.10356304889082113 0.8142588648982915 0.41945728425307693" />
            </geometry>
        </collision>
    </link>
    <joint name="3_6" type="revolute">
       <parent link="3"/>
       <child  link="6"/>
       <origin rpy="0 0 0" xyz="0 -0.43445824042090336 0.23483003732604502" />
     <axis xyz="0 1 0"/>
       <limit effort="0.0" lower="-3.14159" upper="3.14159" velocity="0.0"/>
    </joint>
    <link name="6">
        <inertial>
            <origin xyz="0 0.0 0.2147286315195367" rpy="0 0 0"/>
            <mass value="1" />
            <inertia ixx="100" ixy="0" ixz="0" iyy="100" iyz="0" izz="100" />
        </inertial>
        <visual>
            <origin xyz="0 0.0 0.2147286315195367" rpy="0 0 0"/>
            <geometry>
                <box size="0.7646836261342285 0.4345593586174823 0.4294572630390734" />
            </geometry>
            <material name="sensor">
                <color rgba="0 1 0 1"/>
            </material>
        </visual>
        <collision>
            <origin xyz="0 0.0 0.2147286315195367" rpy="0 0 0"/>
            <geometry>
                <box size="0.7646836261342285 0.4345593586174823 0.4294572630390734" />
            </geometry>
        </collision>
    </link>
    <joint name="0_4" type="revolute">
       <parent link="0"/>
       <child  link="4"/>
       <origin rpy="0 0 0" xyz="0 0 0.1858247228147648" />
     <axis xyz="0 1 0"/>
       <limit effort="0.0" lower="-3.14159" upper="3.14159" velocity="0.0"/>
    </joint>
    <link name="4">
        <inertial>
            <origin xyz="0 0 -0.06866506957483293" rpy="0 0 0"/>
            <mass value="1" />
            <inertia ixx="100" ixy="0" ixz="0" iyy="100" iyz="0" izz="100" />
        </inertial>
        <visual>
            <origin xyz="0 0 -0.06866506957483293" rpy="0 0 0"/>
            <geometry>
                <box size="0.32127810318715033 0.30644464618982936 0.13733013914966585" />
            </geometry>
            <material name="sensor">
                <color rgba="0 1 0 1"/>
            </material>
        </visual>
        <collision>
            <origin xyz="0 0 -0.06866506957483293" rpy="0 0 0"/>
            <geometry>
                <box size="0.32127810318715033 0.30644464618982936 0.13733013914966585" />
            </geometry>
        </collision>
    </link>
</robot>