<robot name = "robot">
    <link name="0">
        <inertial>
            <origin xyz="0 0 0.8335388915573088" rpy="0 0 0"/>
            <mass value="1" />
            <inertia ixx="100" ixy="0" ixz="0" iyy="100" iyz="0" izz="100" />
        </inertial>
        <visual>
            <origin xyz="0 0 0.8335388915573088" rpy="0 0 0"/>
            <geometry>
                <box size="0.10184169263187148 0.32196598462126447 0.33375365044867533" />
            </geometry>
            <material name="sensor">
                <color rgba="0 1 0 1"/>
            </material>
        </visual>
        <collision>
            <origin xyz="0 0 0.8335388915573088" rpy="0 0 0"/>
            <geometry>
                <box size="0.10184169263187148 0.32196598462126447 0.33375365044867533" />
            </geometry>
        </collision>
    </link>
    <joint name="0_1" type="revolute">
       <parent link="0"/>
       <child  link="1"/>
       <origin rpy="0 0 0" xyz="0 0.16098299231063223 0.8335388915573088" />
     <axis xyz="1 0 0"/>
       <limit effort="0.0" lower="-3.14159" upper="3.14159" velocity="0.0"/>
    </joint>
    <link name="1">
        <inertial>
            <origin xyz="0 0.06045966235514322 0.0" rpy="0 0 0"/>
            <mass value="1" />
            <inertia ixx="100" ixy="0" ixz="0" iyy="100" iyz="0" izz="100" />
        </inertial>
        <visual>
            <origin xyz="0 0.06045966235514322 0.0" rpy="0 0 0"/>
            <geometry>
                <box size="0.22502784272288479 0.12091932471028644 0.5296276283083933" />
            </geometry>
            <material name="sensor">
                <color rgba="0 1 0 1"/>
            </material>
        </visual>
        <collision>
            <origin xyz="0 0.06045966235514322 0.0" rpy="0 0 0"/>
            <geometry>
                <box size="0.22502784272288479 0.12091932471028644 0.5296276283083933" />
            </geometry>
        </collision>
    </link>
    <joint name="0_2" type="revolute">
       <parent link="0"/>
       <child  link="2"/>
       <origin rpy="0 0 0" xyz="0 -0.16098299231063223 0.8335388915573088" />
     <axis xyz="0 1 0"/>
       <limit effort="0.0" lower="-3.14159" upper="3.14159" velocity="0.0"/>
    </joint>
    <link name="2">
        <inertial>
            <origin xyz="0 -0.07799892946917958 0.0" rpy="0 0 0"/>
            <mass value="1" />
            <inertia ixx="100" ixy="0" ixz="0" iyy="100" iyz="0" izz="100" />
        </inertial>
        <visual>
            <origin xyz="0 -0.07799892946917958 0.0" rpy="0 0 0"/>
            <geometry>
                <box size="0.9206123829876306 0.15599785893835916 0.00466179458314564" />
            </geometry>
            <material name="sensor">
                <color rgba="0 1 0 1"/>
            </material>
        </visual>
        <collision>
            <origin xyz="0 -0.07799892946917958 0.0" rpy="0 0 0"/>
            <geometry>
                <box size="0.9206123829876306 0.15599785893835916 0.00466179458314564" />
            </geometry>
        </collision>
    </link>
    <joint name="2_4" type="revolute">
       <parent link="2"/>
       <child  link="4"/>
       <origin rpy="0 0 0" xyz="0 -0.15599785893835916 0.0" />
     <axis xyz="0 1 0"/>
       <limit effort="0.0" lower="-3.14159" upper="3.14159" velocity="0.0"/>
    </joint>
    <link name="4">
        <inertial>
            <origin xyz="0 -0.1458816939448026 0.0" rpy="0 0 0"/>
            <mass value="1" />
            <inertia ixx="100" ixy="0" ixz="0" iyy="100" iyz="0" izz="100" />
        </inertial>
        <visual>
            <origin xyz="0 -0.1458816939448026 0.0" rpy="0 0 0"/>
            <geometry>
                <box size="0.8339291432034306 0.2917633878896052 0.3566610846844087" />
            </geometry>
            <material name="sensor">
                <color rgba="0 1 0 1"/>
            </material>
        </visual>
        <collision>
            <origin xyz="0 -0.1458816939448026 0.0" rpy="0 0 0"/>
            <geometry>
                <box size="0.8339291432034306 0.2917633878896052 0.3566610846844087" />
            </geometry>
        </collision>
    </link>
    <joint name="4_5" type="revolute">
       <parent link="4"/>
       <child  link="5"/>
       <origin rpy="0 0 0" xyz="0 -0.1458816939448026 0.17833054234220436" />
     <axis xyz="0 0 1"/>
       <limit effort="0.0" lower="-3.14159" upper="3.14159" velocity="0.0"/>
    </joint>
    <link name="5">
        <inertial>
            <origin xyz="0 0.0 0.27592885916577026" rpy="0 0 0"/>
            <mass value="1" />
            <inertia ixx="100" ixy="0" ixz="0" iyy="100" iyz="0" izz="100" />
        </inertial>
        <visual>
            <origin xyz="0 0.0 0.27592885916577026" rpy="0 0 0"/>
            <geometry>
                <box size="0.5088301878465372 0.830996791552341 0.5518577183315405" />
            </geometry>
            <material name="not">
                <color rgba="0 1 1 1"/>
            </material>
        </visual>
        <collision>
            <origin xyz="0 0.0 0.27592885916577026" rpy="0 0 0"/>
            <geometry>
                <box size="0.5088301878465372 0.830996791552341 0.5518577183315405" />
            </geometry>
        </collision>
    </link>
    <joint name="2_6" type="revolute">
       <parent link="2"/>
       <child  link="6"/>
       <origin rpy="0 0 0" xyz="-0.4603061914938153 -0.07799892946917958 0.0" />
     <axis xyz="0 1 0"/>
       <limit effort="0.0" lower="-3.14159" upper="3.14159" velocity="0.0"/>
    </joint>
    <link name="6">
        <inertial>
            <origin xyz="-0.44484127057454287 0.0 0.0" rpy="0 0 0"/>
            <mass value="1" />
            <inertia ixx="100" ixy="0" ixz="0" iyy="100" iyz="0" izz="100" />
        </inertial>
        <visual>
            <origin xyz="-0.44484127057454287 0.0 0.0" rpy="0 0 0"/>
            <geometry>
                <box size="0.8896825411490857 0.20812162331765782 0.8618532169892983" />
            </geometry>
            <material name="sensor">
                <color rgba="0 1 0 1"/>
            </material>
        </visual>
        <collision>
            <origin xyz="-0.44484127057454287 0.0 0.0" rpy="0 0 0"/>
            <geometry>
                <box size="0.8896825411490857 0.20812162331765782 0.8618532169892983" />
            </geometry>
        </collision>
    </link>
</robot>