<robot name = "robot">
    <link name="0">
        <inertial>
            <origin xyz="0 0 0.4626697423037196" rpy="0 0 0"/>
            <mass value="1" />
            <inertia ixx="100" ixy="0" ixz="0" iyy="100" iyz="0" izz="100" />
        </inertial>
        <visual>
            <origin xyz="0 0 0.4626697423037196" rpy="0 0 0"/>
            <geometry>
                <box size="0.25965514639461273 0.7973908487203603 0.08107546006382993" />
            </geometry>
            <material name="sensor">
                <color rgba="0 1 0 1"/>
            </material>
        </visual>
        <collision>
            <origin xyz="0 0 0.4626697423037196" rpy="0 0 0"/>
            <geometry>
                <box size="0.25965514639461273 0.7973908487203603 0.08107546006382993" />
            </geometry>
        </collision>
    </link>
    <joint name="0_4" type="revolute">
       <parent link="0"/>
       <child  link="4"/>
       <origin rpy="0 0 0" xyz="0.12982757319730637 0 0.4626697423037196" />
     <axis xyz="0 0 1"/>
       <limit effort="0.0" lower="-3.14159" upper="3.14159" velocity="0.0"/>
    </joint>
    <link name="4">
        <inertial>
            <origin xyz="0.16553349768586734 0 0.0" rpy="0 0 0"/>
            <mass value="1" />
            <inertia ixx="100" ixy="0" ixz="0" iyy="100" iyz="0" izz="100" />
        </inertial>
        <visual>
            <origin xyz="0.16553349768586734 0 0.0" rpy="0 0 0"/>
            <geometry>
                <box size="0.3310669953717347 0.17753969349655696 0.45901875217017585" />
            </geometry>
            <material name="sensor">
                <color rgba="0 1 0 1"/>
            </material>
        </visual>
        <collision>
            <origin xyz="0.16553349768586734 0 0.0" rpy="0 0 0"/>
            <geometry>
                <box size="0.3310669953717347 0.17753969349655696 0.45901875217017585" />
            </geometry>
        </collision>
    </link>
    <joint name="0_1" type="revolute">
       <parent link="0"/>
       <child  link="1"/>
       <origin rpy="0 0 0" xyz="0 0.39869542436018013 0.4626697423037196" />
     <axis xyz="0 1 0"/>
       <limit effort="0.0" lower="-3.14159" upper="3.14159" velocity="0.0"/>
    </joint>
    <link name="1">
        <inertial>
            <origin xyz="0 0.3368894055320826 0.0" rpy="0 0 0"/>
            <mass value="1" />
            <inertia ixx="100" ixy="0" ixz="0" iyy="100" iyz="0" izz="100" />
        </inertial>
        <visual>
            <origin xyz="0 0.3368894055320826 0.0" rpy="0 0 0"/>
            <geometry>
                <box size="0.14506275949834935 0.673778811064165 0.0664384693860609" />
            </geometry>
            <material name="sensor">
                <color rgba="0 1 0 1"/>
            </material>
        </visual>
        <collision>
            <origin xyz="0 0.3368894055320826 0.0" rpy="0 0 0"/>
            <geometry>
                <box size="0.14506275949834935 0.673778811064165 0.0664384693860609" />
            </geometry>
        </collision>
    </link>
    <joint name="1_3" type="revolute">
       <parent link="1"/>
       <child  link="3"/>
       <origin rpy="0 0 0" xyz="0.07253137974917467 0.3368894055320826 0.0" />
     <axis xyz="0 1 0"/>
       <limit effort="0.0" lower="-3.14159" upper="3.14159" velocity="0.0"/>
    </joint>
    <link name="3">
        <inertial>
            <origin xyz="0.05048971935892976 0.0 0.0" rpy="0 0 0"/>
            <mass value="1" />
            <inertia ixx="100" ixy="0" ixz="0" iyy="100" iyz="0" izz="100" />
        </inertial>
        <visual>
            <origin xyz="0.05048971935892976 0.0 0.0" rpy="0 0 0"/>
            <geometry>
                <box size="0.10097943871785953 0.061610242040175844 0.22886944023876477" />
            </geometry>
            <material name="not">
                <color rgba="0 1 1 1"/>
            </material>
        </visual>
        <collision>
            <origin xyz="0.05048971935892976 0.0 0.0" rpy="0 0 0"/>
            <geometry>
                <box size="0.10097943871785953 0.061610242040175844 0.22886944023876477" />
            </geometry>
        </collision>
    </link>
    <joint name="1_2" type="revolute">
       <parent link="1"/>
       <child  link="2"/>
       <origin rpy="0 0 0" xyz="-0.07253137974917467 0.3368894055320826 0.0" />
     <axis xyz="0 1 0"/>
       <limit effort="0.0" lower="-3.14159" upper="3.14159" velocity="0.0"/>
    </joint>
    <link name="2">
        <inertial>
            <origin xyz="-0.09185182435747513 0.0 0.0" rpy="0 0 0"/>
            <mass value="1" />
            <inertia ixx="100" ixy="0" ixz="0" iyy="100" iyz="0" izz="100" />
        </inertial>
        <visual>
            <origin xyz="-0.09185182435747513 0.0 0.0" rpy="0 0 0"/>
            <geometry>
                <box size="0.18370364871495026 0.4359243344287773 0.5887686783125169" />
            </geometry>
            <material name="not">
                <color rgba="0 1 1 1"/>
            </material>
        </visual>
        <collision>
            <origin xyz="-0.09185182435747513 0.0 0.0" rpy="0 0 0"/>
            <geometry>
                <box size="0.18370364871495026 0.4359243344287773 0.5887686783125169" />
            </geometry>
        </collision>
    </link>
    <joint name="0_5" type="revolute">
       <parent link="0"/>
       <child  link="5"/>
       <origin rpy="0 0 0" xyz="-0.12982757319730637 0 0.4626697423037196" />
     <axis xyz="0 1 0"/>
       <limit effort="0.0" lower="-3.14159" upper="3.14159" velocity="0.0"/>
    </joint>
    <link name="5">
        <inertial>
            <origin xyz="-0.16140513229741327 0 0.0" rpy="0 0 0"/>
            <mass value="1" />
            <inertia ixx="100" ixy="0" ixz="0" iyy="100" iyz="0" izz="100" />
        </inertial>
        <visual>
            <origin xyz="-0.16140513229741327 0 0.0" rpy="0 0 0"/>
            <geometry>
                <box size="0.32281026459482653 0.3216761199087408 0.15290962737232017" />
            </geometry>
            <material name="sensor">
                <color rgba="0 1 0 1"/>
            </material>
        </visual>
        <collision>
            <origin xyz="-0.16140513229741327 0 0.0" rpy="0 0 0"/>
            <geometry>
                <box size="0.32281026459482653 0.3216761199087408 0.15290962737232017" />
            </geometry>
        </collision>
    </link>
</robot>