<robot name = "robot">
    <link name="0">
        <inertial>
            <origin xyz="0 0 0.11652048861011899" rpy="0 0 0"/>
            <mass value="1" />
            <inertia ixx="100" ixy="0" ixz="0" iyy="100" iyz="0" izz="100" />
        </inertial>
        <visual>
            <origin xyz="0 0 0.11652048861011899" rpy="0 0 0"/>
            <geometry>
                <box size="0.13996620007992855 0.49210291356971725 0.13176352188090934" />
            </geometry>
            <material name="not">
                <color rgba="0 1 1 1"/>
            </material>
        </visual>
        <collision>
            <origin xyz="0 0 0.11652048861011899" rpy="0 0 0"/>
            <geometry>
                <box size="0.13996620007992855 0.49210291356971725 0.13176352188090934" />
            </geometry>
        </collision>
    </link>
    <joint name="0_1" type="revolute">
       <parent link="0"/>
       <child  link="1"/>
       <origin rpy="0 0 0" xyz="0 0 0.18240224955057366" />
     <axis xyz="0 0 1"/>
       <limit effort="0.0" lower="-3.14159" upper="3.14159" velocity="0.0"/>
    </joint>
    <link name="1">
        <inertial>
            <origin xyz="0 0 0.31318812586043654" rpy="0 0 0"/>
            <mass value="1" />
            <inertia ixx="100" ixy="0" ixz="0" iyy="100" iyz="0" izz="100" />
        </inertial>
        <visual>
            <origin xyz="0 0 0.31318812586043654" rpy="0 0 0"/>
            <geometry>
                <box size="0.7979438383367402 0.6160362974942997 0.6263762517208731" />
            </geometry>
            <material name="sensor">
                <color rgba="0 1 0 1"/>
            </material>
        </visual>
        <collision>
            <origin xyz="0 0 0.31318812586043654" rpy="0 0 0"/>
            <geometry>
                <box size="0.7979438383367402 0.6160362974942997 0.6263762517208731" />
            </geometry>
        </collision>
    </link>
    <joint name="0_3" type="revolute">
       <parent link="0"/>
       <child  link="3"/>
       <origin rpy="0 0 0" xyz="0 0 0.05063872766966432" />
     <axis xyz="0 0 1"/>
       <limit effort="0.0" lower="-3.14159" upper="3.14159" velocity="0.0"/>
    </joint>
    <link name="3">
        <inertial>
            <origin xyz="0 0 -0.0017913730957508367" rpy="0 0 0"/>
            <mass value="1" />
            <inertia ixx="100" ixy="0" ixz="0" iyy="100" iyz="0" izz="100" />
        </inertial>
        <visual>
            <origin xyz="0 0 -0.0017913730957508367" rpy="0 0 0"/>
            <geometry>
                <box size="0.6029071282270586 0.5435326224157314 0.0035827461915016734" />
            </geometry>
            <material name="sensor">
                <color rgba="0 1 0 1"/>
            </material>
        </visual>
        <collision>
            <origin xyz="0 0 -0.0017913730957508367" rpy="0 0 0"/>
            <geometry>
                <box size="0.6029071282270586 0.5435326224157314 0.0035827461915016734" />
            </geometry>
        </collision>
    </link>
    <joint name="3_4" type="revolute">
       <parent link="3"/>
       <child  link="4"/>
       <origin rpy="0 0 0" xyz="0 0 -0.0035827461915016734" />
     <axis xyz="0 0 1"/>
       <limit effort="0.0" lower="-3.14159" upper="3.14159" velocity="0.0"/>
    </joint>
    <link name="4">
        <inertial>
            <origin xyz="0 0 -0.013952897587889423" rpy="0 0 0"/>
            <mass value="1" />
            <inertia ixx="100" ixy="0" ixz="0" iyy="100" iyz="0" izz="100" />
        </inertial>
        <visual>
            <origin xyz="0 0 -0.013952897587889423" rpy="0 0 0"/>
            <geometry>
                <box size="0.8212603956063385 0.6215408506672343 0.027905795175778847" />
            </geometry>
            <material name="not">
                <color rgba="0 1 1 1"/>
            </material>
        </visual>
        <collision>
            <origin xyz="0 0 -0.013952897587889423" rpy="0 0 0"/>
            <geometry>
                <box size="0.8212603956063385 0.6215408506672343 0.027905795175778847" />
            </geometry>
        </collision>
    </link>
    <joint name="4_5" type="revolute">
       <parent link="4"/>
       <child  link="5"/>
       <origin rpy="0 0 0" xyz="0 0 -0.027905795175778847" />
     <axis xyz="0 0 1"/>
       <limit effort="0.0" lower="-3.14159" upper="3.14159" velocity="0.0"/>
    </joint>
    <link name="5">
        <inertial>
            <origin xyz="0 0 -0.004704815632931458" rpy="0 0 0"/>
            <mass value="1" />
            <inertia ixx="100" ixy="0" ixz="0" iyy="100" iyz="0" izz="100" />
        </inertial>
        <visual>
            <origin xyz="0 0 -0.004704815632931458" rpy="0 0 0"/>
            <geometry>
                <box size="0.13999715234461263 0.7071610245946833 0.009409631265862917" />
            </geometry>
            <material name="sensor">
                <color rgba="0 1 0 1"/>
            </material>
        </visual>
        <collision>
            <origin xyz="0 0 -0.004704815632931458" rpy="0 0 0"/>
            <geometry>
                <box size="0.13999715234461263 0.7071610245946833 0.009409631265862917" />
            </geometry>
        </collision>
    </link>
    <joint name="0_2" type="revolute">
       <parent link="0"/>
       <child  link="2"/>
       <origin rpy="0 0 0" xyz="-0.06998310003996427 0 0.11652048861011899" />
     <axis xyz="1 0 0"/>
       <limit effort="0.0" lower="-3.14159" upper="3.14159" velocity="0.0"/>
    </joint>
    <link name="2">
        <inertial>
            <origin xyz="-0.22767980507544322 0 0.0" rpy="0 0 0"/>
            <mass value="1" />
            <inertia ixx="100" ixy="0" ixz="0" iyy="100" iyz="0" izz="100" />
        </inertial>
        <visual>
            <origin xyz="-0.22767980507544322 0 0.0" rpy="0 0 0"/>
            <geometry>
                <box size="0.45535961015088644 0.6592549820399763 0.12203408506851332" />
            </geometry>
            <material name="sensor">
                <color rgba="0 1 0 1"/>
            </material>
        </visual>
        <collision>
            <origin xyz="-0.22767980507544322 0 0.0" rpy="0 0 0"/>
            <geometry>
                <box size="0.45535961015088644 0.6592549820399763 0.12203408506851332" />
            </geometry>
        </collision>
    </link>
</robot>