<robot name = "robot">
    <link name="0">
        <inertial>
            <origin xyz="0 0 0.6039200385961945" rpy="0 0 0"/>
            <mass value="1" />
            <inertia ixx="100" ixy="0" ixz="0" iyy="100" iyz="0" izz="100" />
        </inertial>
        <visual>
            <origin xyz="0 0 0.6039200385961945" rpy="0 0 0"/>
            <geometry>
                <box size="0.23796462709189137 0.5442292252959519 0.36995516654807925" />
            </geometry>
            <material name="not">
                <color rgba="0 1 1 1"/>
            </material>
        </visual>
        <collision>
            <origin xyz="0 0 0.6039200385961945" rpy="0 0 0"/>
            <geometry>
                <box size="0.23796462709189137 0.5442292252959519 0.36995516654807925" />
            </geometry>
        </collision>
    </link>
    <joint name="0_1" type="revolute">
       <parent link="0"/>
       <child  link="1"/>
       <origin rpy="0 0 0" xyz="0 0.27211461264797593 0.6039200385961945" />
     <axis xyz="0 1 0"/>
       <limit effort="0.0" lower="-3.14159" upper="3.14159" velocity="0.0"/>
    </joint>
    <link name="1">
        <inertial>
            <origin xyz="0 0.2346161688095108 0.0" rpy="0 0 0"/>
            <mass value="1" />
            <inertia ixx="100" ixy="0" ixz="0" iyy="100" iyz="0" izz="100" />
        </inertial>
        <visual>
            <origin xyz="0 0.2346161688095108 0.0" rpy="0 0 0"/>
            <geometry>
                <box size="0.9088184001853248 0.4692323376190216 0.5507846417600732" />
            </geometry>
            <material name="sensor">
                <color rgba="0 1 0 1"/>
            </material>
        </visual>
        <collision>
            <origin xyz="0 0.2346161688095108 0.0" rpy="0 0 0"/>
            <geometry>
                <box size="0.9088184001853248 0.4692323376190216 0.5507846417600732" />
            </geometry>
        </collision>
    </link>
    <joint name="1_2" type="revolute">
       <parent link="1"/>
       <child  link="2"/>
       <origin rpy="0 0 0" xyz="0 0.46923233761902167 0.0" />
     <axis xyz="0 1 0"/>
       <limit effort="0.0" lower="-3.14159" upper="3.14159" velocity="0.0"/>
    </joint>
    <link name="2">
        <inertial>
            <origin xyz="0 0.4305110542126611 0.0" rpy="0 0 0"/>
            <mass value="1" />
            <inertia ixx="100" ixy="0" ixz="0" iyy="100" iyz="0" izz="100" />
        </inertial>
        <visual>
            <origin xyz="0 0.4305110542126611 0.0" rpy="0 0 0"/>
            <geometry>
                <box size="0.39713457702896093 0.8610221084253223 0.23192200537667162" />
            </geometry>
            <material name="sensor">
                <color rgba="0 1 0 1"/>
            </material>
        </visual>
        <collision>
            <origin xyz="0 0.4305110542126611 0.0" rpy="0 0 0"/>
            <geometry>
                <box size="0.39713457702896093 0.8610221084253223 0.23192200537667162" />
            </geometry>
        </collision>
    </link>
    <joint name="2_4" type="revolute">
       <parent link="2"/>
       <child  link="4"/>
       <origin rpy="0 0 0" xyz="0.19856728851448047 0.4305110542126611 0.0" />
     <axis xyz="1 0 0"/>
       <limit effort="0.0" lower="-3.14159" upper="3.14159" velocity="0.0"/>
    </joint>
    <link name="4">
        <inertial>
            <origin xyz="0.39003824454177827 0.0 0.0" rpy="0 0 0"/>
            <mass value="1" />
            <inertia ixx="100" ixy="0" ixz="0" iyy="100" iyz="0" izz="100" />
        </inertial>
        <visual>
            <origin xyz="0.39003824454177827 0.0 0.0" rpy="0 0 0"/>
            <geometry>
                <box size="0.7800764890835564 0.8235705112332644 0.26943166906199667" />
            </geometry>
            <material name="sensor">
                <color rgba="0 1 0 1"/>
            </material>
        </visual>
        <collision>
            <origin xyz="0.39003824454177827 0.0 0.0" rpy="0 0 0"/>
            <geometry>
                <box size="0.7800764890835564 0.8235705112332644 0.26943166906199667" />
            </geometry>
        </collision>
    </link>
    <joint name="4_7" type="revolute">
       <parent link="4"/>
       <child  link="7"/>
       <origin rpy="0 0 0" xyz="0.7800764890835565 0.0 0.0" />
     <axis xyz="1 0 0"/>
       <limit effort="0.0" lower="-3.14159" upper="3.14159" velocity="0.0"/>
    </joint>
    <link name="7">
        <inertial>
            <origin xyz="0.440452653623679 0.0 0.0" rpy="0 0 0"/>
            <mass value="1" />
            <inertia ixx="100" ixy="0" ixz="0" iyy="100" iyz="0" izz="100" />
        </inertial>
        <visual>
            <origin xyz="0.440452653623679 0.0 0.0" rpy="0 0 0"/>
            <geometry>
                <box size="0.880905307247358 0.9806357568433396 0.505420373648044" />
            </geometry>
            <material name="sensor">
                <color rgba="0 1 0 1"/>
            </material>
        </visual>
        <collision>
            <origin xyz="0.440452653623679 0.0 0.0" rpy="0 0 0"/>
            <geometry>
                <box size="0.880905307247358 0.9806357568433396 0.505420373648044" />
            </geometry>
        </collision>
    </link>
    <joint name="2_3" type="revolute">
       <parent link="2"/>
       <child  link="3"/>
       <origin rpy="0 0 0" xyz="-0.19856728851448047 0.4305110542126611 0.0" />
     <axis xyz="1 0 0"/>
       <limit effort="0.0" lower="-3.14159" upper="3.14159" velocity="0.0"/>
    </joint>
    <link name="3">
        <inertial>
            <origin xyz="-0.007573368666363767 0.0 0.0" rpy="0 0 0"/>
            <mass value="1" />
            <inertia ixx="100" ixy="0" ixz="0" iyy="100" iyz="0" izz="100" />
        </inertial>
        <visual>
            <origin xyz="-0.007573368666363767 0.0 0.0" rpy="0 0 0"/>
            <geometry>
                <box size="0.015146737332727533 0.777234681427713 0.15939993976228117" />
            </geometry>
            <material name="not">
                <color rgba="0 1 1 1"/>
            </material>
        </visual>
        <collision>
            <origin xyz="-0.007573368666363767 0.0 0.0" rpy="0 0 0"/>
            <geometry>
                <box size="0.015146737332727533 0.777234681427713 0.15939993976228117" />
            </geometry>
        </collision>
    </link>
    <joint name="3_5" type="revolute">
       <parent link="3"/>
       <child  link="5"/>
       <origin rpy="0 0 0" xyz="-0.015146737332727533 0.0 0.0" />
     <axis xyz="1 0 0"/>
       <limit effort="0.0" lower="-3.14159" upper="3.14159" velocity="0.0"/>
    </joint>
    <link name="5">
        <inertial>
            <origin xyz="-0.048727154865438604 0.0 0.0" rpy="0 0 0"/>
            <mass value="1" />
            <inertia ixx="100" ixy="0" ixz="0" iyy="100" iyz="0" izz="100" />
        </inertial>
        <visual>
            <origin xyz="-0.048727154865438604 0.0 0.0" rpy="0 0 0"/>
            <geometry>
                <box size="0.09745430973087721 0.1359688602006689 0.21698694123313733" />
            </geometry>
            <material name="sensor">
                <color rgba="0 1 0 1"/>
            </material>
        </visual>
        <collision>
            <origin xyz="-0.048727154865438604 0.0 0.0" rpy="0 0 0"/>
            <geometry>
                <box size="0.09745430973087721 0.1359688602006689 0.21698694123313733" />
            </geometry>
        </collision>
    </link>
    <joint name="5_6" type="revolute">
       <parent link="5"/>
       <child  link="6"/>
       <origin rpy="0 0 0" xyz="-0.09745430973087721 0.0 0.0" />
     <axis xyz="1 0 0"/>
       <limit effort="0.0" lower="-3.14159" upper="3.14159" velocity="0.0"/>
    </joint>
    <link name="6">
        <inertial>
            <origin xyz="-0.02209503056477169 0.0 0.0" rpy="0 0 0"/>
            <mass value="1" />
            <inertia ixx="100" ixy="0" ixz="0" iyy="100" iyz="0" izz="100" />
        </inertial>
        <visual>
            <origin xyz="-0.02209503056477169 0.0 0.0" rpy="0 0 0"/>
            <geometry>
                <box size="0.04419006112954338 0.6145325285318086 0.0449402434960362" />
            </geometry>
            <material name="sensor">
                <color rgba="0 1 0 1"/>
            </material>
        </visual>
        <collision>
            <origin xyz="-0.02209503056477169 0.0 0.0" rpy="0 0 0"/>
            <geometry>
                <box size="0.04419006112954338 0.6145325285318086 0.0449402434960362" />
            </geometry>
        </collision>
    </link>
    <joint name="0_8" type="revolute">
       <parent link="0"/>
       <child  link="8"/>
       <origin rpy="0 0 0" xyz="0 0 0.7888976218702342" />
     <axis xyz="0 0 1"/>
       <limit effort="0.0" lower="-3.14159" upper="3.14159" velocity="0.0"/>
    </joint>
    <link name="8">
        <inertial>
            <origin xyz="0 0 0.3448665367157602" rpy="0 0 0"/>
            <mass value="1" />
            <inertia ixx="100" ixy="0" ixz="0" iyy="100" iyz="0" izz="100" />
        </inertial>
        <visual>
            <origin xyz="0 0 0.3448665367157602" rpy="0 0 0"/>
            <geometry>
                <box size="0.2916123987024063 0.2633732047393842 0.6897330734315202" />
            </geometry>
            <material name="sensor">
                <color rgba="0 1 0 1"/>
            </material>
        </visual>
        <collision>
            <origin xyz="0 0 0.3448665367157602" rpy="0 0 0"/>
            <geometry>
                <box size="0.2916123987024063 0.2633732047393842 0.6897330734315202" />
            </geometry>
        </collision>
    </link>
</robot>