<robot name = "robot">
    <link name="0">
        <inertial>
            <origin xyz="0 0 0.4487693199751305" rpy="0 0 0"/>
            <mass value="1" />
            <inertia ixx="100" ixy="0" ixz="0" iyy="100" iyz="0" izz="100" />
        </inertial>
        <visual>
            <origin xyz="0 0 0.4487693199751305" rpy="0 0 0"/>
            <geometry>
                <box size="0.5139436257318284 0.5082461360848922 0.4010247881691028" />
            </geometry>
            <material name="sensor">
                <color rgba="0 1 0 1"/>
            </material>
        </visual>
        <collision>
            <origin xyz="0 0 0.4487693199751305" rpy="0 0 0"/>
            <geometry>
                <box size="0.5139436257318284 0.5082461360848922 0.4010247881691028" />
            </geometry>
        </collision>
    </link>
    <joint name="0_1" type="revolute">
       <parent link="0"/>
       <child  link="1"/>
       <origin rpy="0 0 0" xyz="0 0.2541230680424461 0.4487693199751305" />
     <axis xyz="0 1 0"/>
       <limit effort="0.0" lower="-3.14159" upper="3.14159" velocity="0.0"/>
    </joint>
    <link name="1">
        <inertial>
            <origin xyz="0 0.30724854212367514 0.0" rpy="0 0 0"/>
            <mass value="1" />
            <inertia ixx="100" ixy="0" ixz="0" iyy="100" iyz="0" izz="100" />
        </inertial>
        <visual>
            <origin xyz="0 0.30724854212367514 0.0" rpy="0 0 0"/>
            <geometry>
                <box size="0.5737068423880805 0.6144970842473502 0.8076051823563635" />
            </geometry>
            <material name="sensor">
                <color rgba="0 1 0 1"/>
            </material>
        </visual>
        <collision>
            <origin xyz="0 0.30724854212367514 0.0" rpy="0 0 0"/>
            <geometry>
                <box size="0.5737068423880805 0.6144970842473502 0.8076051823563635" />
            </geometry>
        </collision>
    </link>
    <joint name="1_4" type="revolute">
       <parent link="1"/>
       <child  link="4"/>
       <origin rpy="0 0 0" xyz="0 0.6144970842473502 0.0" />
     <axis xyz="1 0 0"/>
       <limit effort="0.0" lower="-3.14159" upper="3.14159" velocity="0.0"/>
    </joint>
    <link name="4">
        <inertial>
            <origin xyz="0 0.050647920172993355 0.0" rpy="0 0 0"/>
            <mass value="1" />
            <inertia ixx="100" ixy="0" ixz="0" iyy="100" iyz="0" izz="100" />
        </inertial>
        <visual>
            <origin xyz="0 0.050647920172993355 0.0" rpy="0 0 0"/>
            <geometry>
                <box size="0.1814500718924137 0.10129584034598671 0.12379765646160201" />
            </geometry>
            <material name="sensor">
                <color rgba="0 1 0 1"/>
            </material>
        </visual>
        <collision>
            <origin xyz="0 0.050647920172993355 0.0" rpy="0 0 0"/>
            <geometry>
                <box size="0.1814500718924137 0.10129584034598671 0.12379765646160201" />
            </geometry>
        </collision>
    </link>
    <joint name="1_2" type="revolute">
       <parent link="1"/>
       <child  link="2"/>
       <origin rpy="0 0 0" xyz="0 0.30724854212367514 0.40380259117818174" />
     <axis xyz="1 0 0"/>
       <limit effort="0.0" lower="-3.14159" upper="3.14159" velocity="0.0"/>
    </joint>
    <link name="2">
        <inertial>
            <origin xyz="0 0.0 0.4427857506891092" rpy="0 0 0"/>
            <mass value="1" />
            <inertia ixx="100" ixy="0" ixz="0" iyy="100" iyz="0" izz="100" />
        </inertial>
        <visual>
            <origin xyz="0 0.0 0.4427857506891092" rpy="0 0 0"/>
            <geometry>
                <box size="0.29800834625426376 0.7483822464374331 0.8855715013782184" />
            </geometry>
            <material name="sensor">
                <color rgba="0 1 0 1"/>
            </material>
        </visual>
        <collision>
            <origin xyz="0 0.0 0.4427857506891092" rpy="0 0 0"/>
            <geometry>
                <box size="0.29800834625426376 0.7483822464374331 0.8855715013782184" />
            </geometry>
        </collision>
    </link>
    <joint name="2_3" type="revolute">
       <parent link="2"/>
       <child  link="3"/>
       <origin rpy="0 0 0" xyz="0 -0.37419112321871656 0.4427857506891092" />
     <axis xyz="0 1 0"/>
       <limit effort="0.0" lower="-3.14159" upper="3.14159" velocity="0.0"/>
    </joint>
    <link name="3">
        <inertial>
            <origin xyz="0 -0.35714299215545053 0.0" rpy="0 0 0"/>
            <mass value="1" />
            <inertia ixx="100" ixy="0" ixz="0" iyy="100" iyz="0" izz="100" />
        </inertial>
        <visual>
            <origin xyz="0 -0.35714299215545053 0.0" rpy="0 0 0"/>
            <geometry>
                <box size="0.5519171568233109 0.7142859843109011 0.6884038036448685" />
            </geometry>
            <material name="sensor">
                <color rgba="0 1 0 1"/>
            </material>
        </visual>
        <collision>
            <origin xyz="0 -0.35714299215545053 0.0" rpy="0 0 0"/>
            <geometry>
                <box size="0.5519171568233109 0.7142859843109011 0.6884038036448685" />
            </geometry>
        </collision>
    </link>
</robot>