<robot name = "robot">
    <link name="0">
        <inertial>
            <origin xyz="0 0 0.8665618499863413" rpy="0 0 0"/>
            <mass value="1" />
            <inertia ixx="100" ixy="0" ixz="0" iyy="100" iyz="0" izz="100" />
        </inertial>
        <visual>
            <origin xyz="0 0 0.8665618499863413" rpy="0 0 0"/>
            <geometry>
                <box size="0.46300735781502145 0.37331193139504204 0.13853941251445523" />
            </geometry>
            <material name="not">
                <color rgba="0 1 1 1"/>
            </material>
        </visual>
        <collision>
            <origin xyz="0 0 0.8665618499863413" rpy="0 0 0"/>
            <geometry>
                <box size="0.46300735781502145 0.37331193139504204 0.13853941251445523" />
            </geometry>
        </collision>
    </link>
    <joint name="0_7" type="revolute">
       <parent link="0"/>
       <child  link="7"/>
       <origin rpy="0 0 0" xyz="0 0.18665596569752102 0.8665618499863413" />
     <axis xyz="0 0 1"/>
       <limit effort="0.0" lower="-3.14159" upper="3.14159" velocity="0.0"/>
    </joint>
    <link name="7">
        <inertial>
            <origin xyz="0 0.05311765109259148 0.0" rpy="0 0 0"/>
            <mass value="1" />
            <inertia ixx="100" ixy="0" ixz="0" iyy="100" iyz="0" izz="100" />
        </inertial>
        <visual>
            <origin xyz="0 0.05311765109259148 0.0" rpy="0 0 0"/>
            <geometry>
                <box size="0.8327843855165492 0.10623530218518296 0.34876346343187126" />
            </geometry>
            <material name="sensor">
                <color rgba="0 1 0 1"/>
            </material>
        </visual>
        <collision>
            <origin xyz="0 0.05311765109259148 0.0" rpy="0 0 0"/>
            <geometry>
                <box size="0.8327843855165492 0.10623530218518296 0.34876346343187126" />
            </geometry>
        </collision>
    </link>
    <joint name="0_1" type="revolute">
       <parent link="0"/>
       <child  link="1"/>
       <origin rpy="0 0 0" xyz="0 -0.18665596569752102 0.8665618499863413" />
     <axis xyz="1 0 0"/>
       <limit effort="0.0" lower="-3.14159" upper="3.14159" velocity="0.0"/>
    </joint>
    <link name="1">
        <inertial>
            <origin xyz="0 -0.04040732359150051 0.0" rpy="0 0 0"/>
            <mass value="1" />
            <inertia ixx="100" ixy="0" ixz="0" iyy="100" iyz="0" izz="100" />
        </inertial>
        <visual>
            <origin xyz="0 -0.04040732359150051 0.0" rpy="0 0 0"/>
            <geometry>
                <box size="0.8982979700319381 0.08081464718300102 0.5542704681782861" />
            </geometry>
            <material name="not">
                <color rgba="0 1 1 1"/>
            </material>
        </visual>
        <collision>
            <origin xyz="0 -0.04040732359150051 0.0" rpy="0 0 0"/>
            <geometry>
                <box size="0.8982979700319381 0.08081464718300102 0.5542704681782861" />
            </geometry>
        </collision>
    </link>
    <joint name="1_2" type="revolute">
       <parent link="1"/>
       <child  link="2"/>
       <origin rpy="0 0 0" xyz="0 -0.08081464718300102 0.0" />
     <axis xyz="0 0 1"/>
       <limit effort="0.0" lower="-3.14159" upper="3.14159" velocity="0.0"/>
    </joint>
    <link name="2">
        <inertial>
            <origin xyz="0 -0.025667012151135205 0.0" rpy="0 0 0"/>
            <mass value="1" />
            <inertia ixx="100" ixy="0" ixz="0" iyy="100" iyz="0" izz="100" />
        </inertial>
        <visual>
            <origin xyz="0 -0.025667012151135205 0.0" rpy="0 0 0"/>
            <geometry>
                <box size="0.16842797575900104 0.05133402430227041 0.13242557276985822" />
            </geometry>
            <material name="not">
                <color rgba="0 1 1 1"/>
            </material>
        </visual>
        <collision>
            <origin xyz="0 -0.025667012151135205 0.0" rpy="0 0 0"/>
            <geometry>
                <box size="0.16842797575900104 0.05133402430227041 0.13242557276985822" />
            </geometry>
        </collision>
    </link>
    <joint name="2_3" type="revolute">
       <parent link="2"/>
       <child  link="3"/>
       <origin rpy="0 0 0" xyz="0 -0.05133402430227041 0.0" />
     <axis xyz="0 0 1"/>
       <limit effort="0.0" lower="-3.14159" upper="3.14159" velocity="0.0"/>
    </joint>
    <link name="3">
        <inertial>
            <origin xyz="0 -0.42283290875749563 0.0" rpy="0 0 0"/>
            <mass value="1" />
            <inertia ixx="100" ixy="0" ixz="0" iyy="100" iyz="0" izz="100" />
        </inertial>
        <visual>
            <origin xyz="0 -0.42283290875749563 0.0" rpy="0 0 0"/>
            <geometry>
                <box size="0.7359957126226041 0.8456658175149913 0.5220589309205043" />
            </geometry>
            <material name="not">
                <color rgba="0 1 1 1"/>
            </material>
        </visual>
        <collision>
            <origin xyz="0 -0.42283290875749563 0.0" rpy="0 0 0"/>
            <geometry>
                <box size="0.7359957126226041 0.8456658175149913 0.5220589309205043" />
            </geometry>
        </collision>
    </link>
    <joint name="3_5" type="revolute">
       <parent link="3"/>
       <child  link="5"/>
       <origin rpy="0 0 0" xyz="0 -0.8456658175149914 0.0" />
     <axis xyz="0 0 1"/>
       <limit effort="0.0" lower="-3.14159" upper="3.14159" velocity="0.0"/>
    </joint>
    <link name="5">
        <inertial>
            <origin xyz="0 -0.03448236763752055 0.0" rpy="0 0 0"/>
            <mass value="1" />
            <inertia ixx="100" ixy="0" ixz="0" iyy="100" iyz="0" izz="100" />
        </inertial>
        <visual>
            <origin xyz="0 -0.03448236763752055 0.0" rpy="0 0 0"/>
            <geometry>
                <box size="0.4066764756184559 0.06896473527504121 0.18909005846165816" />
            </geometry>
            <material name="not">
                <color rgba="0 1 1 1"/>
            </material>
        </visual>
        <collision>
            <origin xyz="0 -0.03448236763752055 0.0" rpy="0 0 0"/>
            <geometry>
                <box size="0.4066764756184559 0.06896473527504121 0.18909005846165816" />
            </geometry>
        </collision>
    </link>
    <joint name="2_4" type="revolute">
       <parent link="2"/>
       <child  link="4"/>
       <origin rpy="0 0 0" xyz="-0.08421398787950052 -0.025667012151135205 0.0" />
     <axis xyz="1 0 0"/>
       <limit effort="0.0" lower="-3.14159" upper="3.14159" velocity="0.0"/>
    </joint>
    <link name="4">
        <inertial>
            <origin xyz="-0.43792469517553523 0.0 0.0" rpy="0 0 0"/>
            <mass value="1" />
            <inertia ixx="100" ixy="0" ixz="0" iyy="100" iyz="0" izz="100" />
        </inertial>
        <visual>
            <origin xyz="-0.43792469517553523 0.0 0.0" rpy="0 0 0"/>
            <geometry>
                <box size="0.8758493903510705 0.03599895255602692 0.5969592190133913" />
            </geometry>
            <material name="not">
                <color rgba="0 1 1 1"/>
            </material>
        </visual>
        <collision>
            <origin xyz="-0.43792469517553523 0.0 0.0" rpy="0 0 0"/>
            <geometry>
                <box size="0.8758493903510705 0.03599895255602692 0.5969592190133913" />
            </geometry>
        </collision>
    </link>
    <joint name="0_6" type="revolute">
       <parent link="0"/>
       <child  link="6"/>
       <origin rpy="0 0 0" xyz="-0.23150367890751072 0 0.8665618499863413" />
     <axis xyz="0 1 0"/>
       <limit effort="0.0" lower="-3.14159" upper="3.14159" velocity="0.0"/>
    </joint>
    <link name="6">
        <inertial>
            <origin xyz="-0.032438274584200066 0 0.0" rpy="0 0 0"/>
            <mass value="1" />
            <inertia ixx="100" ixy="0" ixz="0" iyy="100" iyz="0" izz="100" />
        </inertial>
        <visual>
            <origin xyz="-0.032438274584200066 0 0.0" rpy="0 0 0"/>
            <geometry>
                <box size="0.06487654916840013 0.3547942237898688 0.4702417220698075" />
            </geometry>
            <material name="sensor">
                <color rgba="0 1 0 1"/>
            </material>
        </visual>
        <collision>
            <origin xyz="-0.032438274584200066 0 0.0" rpy="0 0 0"/>
            <geometry>
                <box size="0.06487654916840013 0.3547942237898688 0.4702417220698075" />
            </geometry>
        </collision>
    </link>
</robot>