<robot name = "robot">
    <link name="0">
        <inertial>
            <origin xyz="0 0 0.7603951551306644" rpy="0 0 0"/>
            <mass value="1" />
            <inertia ixx="100" ixy="0" ixz="0" iyy="100" iyz="0" izz="100" />
        </inertial>
        <visual>
            <origin xyz="0 0 0.7603951551306644" rpy="0 0 0"/>
            <geometry>
                <box size="0.43617925642203026 0.9783754984487277 0.42382424881854275" />
            </geometry>
            <material name="not">
                <color rgba="0 1 1 1"/>
            </material>
        </visual>
        <collision>
            <origin xyz="0 0 0.7603951551306644" rpy="0 0 0"/>
            <geometry>
                <box size="0.43617925642203026 0.9783754984487277 0.42382424881854275" />
            </geometry>
        </collision>
    </link>
    <joint name="0_3" type="revolute">
       <parent link="0"/>
       <child  link="3"/>
       <origin rpy="0 0 0" xyz="0.21808962821101513 0 0.7603951551306644" />
     <axis xyz="0 0 1"/>
       <limit effort="0.0" lower="-3.14159" upper="3.14159" velocity="0.0"/>
    </joint>
    <link name="3">
        <inertial>
            <origin xyz="0.29639557964049806 0 0.0" rpy="0 0 0"/>
            <mass value="1" />
            <inertia ixx="100" ixy="0" ixz="0" iyy="100" iyz="0" izz="100" />
        </inertial>
        <visual>
            <origin xyz="0.29639557964049806 0 0.0" rpy="0 0 0"/>
            <geometry>
                <box size="0.5927911592809961 0.005814106769266969 0.4405747548545692" />
            </geometry>
            <material name="sensor">
                <color rgba="0 1 0 1"/>
            </material>
        </visual>
        <collision>
            <origin xyz="0.29639557964049806 0 0.0" rpy="0 0 0"/>
            <geometry>
                <box size="0.5927911592809961 0.005814106769266969 0.4405747548545692" />
            </geometry>
        </collision>
    </link>
    <joint name="3_5" type="revolute">
       <parent link="3"/>
       <child  link="5"/>
       <origin rpy="0 0 0" xyz="0.29639557964049806 -0.0029070533846334845 0.0" />
     <axis xyz="0 1 0"/>
       <limit effort="0.0" lower="-3.14159" upper="3.14159" velocity="0.0"/>
    </joint>
    <link name="5">
        <inertial>
            <origin xyz="0.0 -0.3648232127528624 0.0" rpy="0 0 0"/>
            <mass value="1" />
            <inertia ixx="100" ixy="0" ixz="0" iyy="100" iyz="0" izz="100" />
        </inertial>
        <visual>
            <origin xyz="0.0 -0.3648232127528624 0.0" rpy="0 0 0"/>
            <geometry>
                <box size="0.28420649210581794 0.7296464255057248 0.807455798625946" />
            </geometry>
            <material name="sensor">
                <color rgba="0 1 0 1"/>
            </material>
        </visual>
        <collision>
            <origin xyz="0.0 -0.3648232127528624 0.0" rpy="0 0 0"/>
            <geometry>
                <box size="0.28420649210581794 0.7296464255057248 0.807455798625946" />
            </geometry>
        </collision>
    </link>
    <joint name="5_6" type="revolute">
       <parent link="5"/>
       <child  link="6"/>
       <origin rpy="0 0 0" xyz="0.0 -0.7296464255057248 0.0" />
     <axis xyz="1 0 0"/>
       <limit effort="0.0" lower="-3.14159" upper="3.14159" velocity="0.0"/>
    </joint>
    <link name="6">
        <inertial>
            <origin xyz="0.0 -0.4303538145996706 0.0" rpy="0 0 0"/>
            <mass value="1" />
            <inertia ixx="100" ixy="0" ixz="0" iyy="100" iyz="0" izz="100" />
        </inertial>
        <visual>
            <origin xyz="0.0 -0.4303538145996706 0.0" rpy="0 0 0"/>
            <geometry>
                <box size="0.5063201768181246 0.860707629199341 0.058444146740126324" />
            </geometry>
            <material name="sensor">
                <color rgba="0 1 0 1"/>
            </material>
        </visual>
        <collision>
            <origin xyz="0.0 -0.4303538145996706 0.0" rpy="0 0 0"/>
            <geometry>
                <box size="0.5063201768181246 0.860707629199341 0.058444146740126324" />
            </geometry>
        </collision>
    </link>
    <joint name="6_7" type="revolute">
       <parent link="6"/>
       <child  link="7"/>
       <origin rpy="0 0 0" xyz="-0.2531600884090623 -0.4303538145996706 0.0" />
     <axis xyz="0 1 0"/>
       <limit effort="0.0" lower="-3.14159" upper="3.14159" velocity="0.0"/>
    </joint>
    <link name="7">
        <inertial>
            <origin xyz="-0.04440661922669081 0.0 0.0" rpy="0 0 0"/>
            <mass value="1" />
            <inertia ixx="100" ixy="0" ixz="0" iyy="100" iyz="0" izz="100" />
        </inertial>
        <visual>
            <origin xyz="-0.04440661922669081 0.0 0.0" rpy="0 0 0"/>
            <geometry>
                <box size="0.08881323845338163 0.40768691714079797 0.7779997277361933" />
            </geometry>
            <material name="sensor">
                <color rgba="0 1 0 1"/>
            </material>
        </visual>
        <collision>
            <origin xyz="-0.04440661922669081 0.0 0.0" rpy="0 0 0"/>
            <geometry>
                <box size="0.08881323845338163 0.40768691714079797 0.7779997277361933" />
            </geometry>
        </collision>
    </link>
    <joint name="0_2" type="revolute">
       <parent link="0"/>
       <child  link="2"/>
       <origin rpy="0 0 0" xyz="0 0.48918774922436387 0.7603951551306644" />
     <axis xyz="0 1 0"/>
       <limit effort="0.0" lower="-3.14159" upper="3.14159" velocity="0.0"/>
    </joint>
    <link name="2">
        <inertial>
            <origin xyz="0 0.217741556759191 0.0" rpy="0 0 0"/>
            <mass value="1" />
            <inertia ixx="100" ixy="0" ixz="0" iyy="100" iyz="0" izz="100" />
        </inertial>
        <visual>
            <origin xyz="0 0.217741556759191 0.0" rpy="0 0 0"/>
            <geometry>
                <box size="0.019125255264475838 0.43548311351838187 0.39011342271260796" />
            </geometry>
            <material name="sensor">
                <color rgba="0 1 0 1"/>
            </material>
        </visual>
        <collision>
            <origin xyz="0 0.217741556759191 0.0" rpy="0 0 0"/>
            <geometry>
                <box size="0.019125255264475838 0.43548311351838187 0.39011342271260796" />
            </geometry>
        </collision>
    </link>
    <joint name="2_4" type="revolute">
       <parent link="2"/>
       <child  link="4"/>
       <origin rpy="0 0 0" xyz="0 0.4354831135183819 0.0" />
     <axis xyz="0 0 1"/>
       <limit effort="0.0" lower="-3.14159" upper="3.14159" velocity="0.0"/>
    </joint>
    <link name="4">
        <inertial>
            <origin xyz="0 0.3724781923782341 0.0" rpy="0 0 0"/>
            <mass value="1" />
            <inertia ixx="100" ixy="0" ixz="0" iyy="100" iyz="0" izz="100" />
        </inertial>
        <visual>
            <origin xyz="0 0.3724781923782341 0.0" rpy="0 0 0"/>
            <geometry>
                <box size="0.14400662377473739 0.7449563847564682 0.889567652208593" />
            </geometry>
            <material name="sensor">
                <color rgba="0 1 0 1"/>
            </material>
        </visual>
        <collision>
            <origin xyz="0 0.3724781923782341 0.0" rpy="0 0 0"/>
            <geometry>
                <box size="0.14400662377473739 0.7449563847564682 0.889567652208593" />
            </geometry>
        </collision>
    </link>
    <joint name="0_1" type="revolute">
       <parent link="0"/>
       <child  link="1"/>
       <origin rpy="0 0 0" xyz="0 0 0.548483030721393" />
     <axis xyz="1 0 0"/>
       <limit effort="0.0" lower="-3.14159" upper="3.14159" velocity="0.0"/>
    </joint>
    <link name="1">
        <inertial>
            <origin xyz="0 0 -0.18721210235764874" rpy="0 0 0"/>
            <mass value="1" />
            <inertia ixx="100" ixy="0" ixz="0" iyy="100" iyz="0" izz="100" />
        </inertial>
        <visual>
            <origin xyz="0 0 -0.18721210235764874" rpy="0 0 0"/>
            <geometry>
                <box size="0.41281265958860314 0.36490782687109025 0.37442420471529747" />
            </geometry>
            <material name="not">
                <color rgba="0 1 1 1"/>
            </material>
        </visual>
        <collision>
            <origin xyz="0 0 -0.18721210235764874" rpy="0 0 0"/>
            <geometry>
                <box size="0.41281265958860314 0.36490782687109025 0.37442420471529747" />
            </geometry>
        </collision>
    </link>
</robot>