<robot name = "robot">
    <link name="0">
        <inertial>
            <origin xyz="0 0 0.5134412166930334" rpy="0 0 0"/>
            <mass value="1" />
            <inertia ixx="100" ixy="0" ixz="0" iyy="100" iyz="0" izz="100" />
        </inertial>
        <visual>
            <origin xyz="0 0 0.5134412166930334" rpy="0 0 0"/>
            <geometry>
                <box size="0.00848430106284992 0.6786959129154532 0.4820562247461908" />
            </geometry>
            <material name="not">
                <color rgba="0 1 1 1"/>
            </material>
        </visual>
        <collision>
            <origin xyz="0 0 0.5134412166930334" rpy="0 0 0"/>
            <geometry>
                <box size="0.00848430106284992 0.6786959129154532 0.4820562247461908" />
            </geometry>
        </collision>
    </link>
    <joint name="0_3" type="revolute">
       <parent link="0"/>
       <child  link="3"/>
       <origin rpy="0 0 0" xyz="0.00424215053142496 0 0.5134412166930334" />
     <axis xyz="0 1 0"/>
       <limit effort="0.0" lower="-3.14159" upper="3.14159" velocity="0.0"/>
    </joint>
    <link name="3">
        <inertial>
            <origin xyz="0.14132741301291313 0 0.0" rpy="0 0 0"/>
            <mass value="1" />
            <inertia ixx="100" ixy="0" ixz="0" iyy="100" iyz="0" izz="100" />
        </inertial>
        <visual>
            <origin xyz="0.14132741301291313 0 0.0" rpy="0 0 0"/>
            <geometry>
                <box size="0.28265482602582626 0.4673919973292482 0.0018199113492644026" />
            </geometry>
            <material name="sensor">
                <color rgba="0 1 0 1"/>
            </material>
        </visual>
        <collision>
            <origin xyz="0.14132741301291313 0 0.0" rpy="0 0 0"/>
            <geometry>
                <box size="0.28265482602582626 0.4673919973292482 0.0018199113492644026" />
            </geometry>
        </collision>
    </link>
    <joint name="3_4" type="revolute">
       <parent link="3"/>
       <child  link="4"/>
       <origin rpy="0 0 0" xyz="0.28265482602582626 0 0.0" />
     <axis xyz="0 0 1"/>
       <limit effort="0.0" lower="-3.14159" upper="3.14159" velocity="0.0"/>
    </joint>
    <link name="4">
        <inertial>
            <origin xyz="0.20013005960171365 0 0.0" rpy="0 0 0"/>
            <mass value="1" />
            <inertia ixx="100" ixy="0" ixz="0" iyy="100" iyz="0" izz="100" />
        </inertial>
        <visual>
            <origin xyz="0.20013005960171365 0 0.0" rpy="0 0 0"/>
            <geometry>
                <box size="0.4002601192034273 0.8235191162632183 0.34225324750501185" />
            </geometry>
            <material name="sensor">
                <color rgba="0 1 0 1"/>
            </material>
        </visual>
        <collision>
            <origin xyz="0.20013005960171365 0 0.0" rpy="0 0 0"/>
            <geometry>
                <box size="0.4002601192034273 0.8235191162632183 0.34225324750501185" />
            </geometry>
        </collision>
    </link>
    <joint name="3_5" type="revolute">
       <parent link="3"/>
       <child  link="5"/>
       <origin rpy="0 0 0" xyz="0.14132741301291313 0 -0.0009099556746322568" />
     <axis xyz="1 0 0"/>
       <limit effort="0.0" lower="-3.14159" upper="3.14159" velocity="0.0"/>
    </joint>
    <link name="5">
        <inertial>
            <origin xyz="0.0 0 -0.15743962288152236" rpy="0 0 0"/>
            <mass value="1" />
            <inertia ixx="100" ixy="0" ixz="0" iyy="100" iyz="0" izz="100" />
        </inertial>
        <visual>
            <origin xyz="0.0 0 -0.15743962288152236" rpy="0 0 0"/>
            <geometry>
                <box size="0.08769748280618384 0.9235152765098965 0.3148792457630447" />
            </geometry>
            <material name="not">
                <color rgba="0 1 1 1"/>
            </material>
        </visual>
        <collision>
            <origin xyz="0.0 0 -0.15743962288152236" rpy="0 0 0"/>
            <geometry>
                <box size="0.08769748280618384 0.9235152765098965 0.3148792457630447" />
            </geometry>
        </collision>
    </link>
    <joint name="0_1" type="revolute">
       <parent link="0"/>
       <child  link="1"/>
       <origin rpy="0 0 0" xyz="0 0 0.7544693290661288" />
     <axis xyz="0 0 1"/>
       <limit effort="0.0" lower="-3.14159" upper="3.14159" velocity="0.0"/>
    </joint>
    <link name="1">
        <inertial>
            <origin xyz="0 0 0.3374011774444936" rpy="0 0 0"/>
            <mass value="1" />
            <inertia ixx="100" ixy="0" ixz="0" iyy="100" iyz="0" izz="100" />
        </inertial>
        <visual>
            <origin xyz="0 0 0.3374011774444936" rpy="0 0 0"/>
            <geometry>
                <box size="0.7546695887413734 0.4850004533300901 0.6748023548889873" />
            </geometry>
            <material name="sensor">
                <color rgba="0 1 0 1"/>
            </material>
        </visual>
        <collision>
            <origin xyz="0 0 0.3374011774444936" rpy="0 0 0"/>
            <geometry>
                <box size="0.7546695887413734 0.4850004533300901 0.6748023548889873" />
            </geometry>
        </collision>
    </link>
    <joint name="1_2" type="revolute">
       <parent link="1"/>
       <child  link="2"/>
       <origin rpy="0 0 0" xyz="0 0 0.6748023548889872" />
     <axis xyz="1 0 0"/>
       <limit effort="0.0" lower="-3.14159" upper="3.14159" velocity="0.0"/>
    </joint>
    <link name="2">
        <inertial>
            <origin xyz="0 0 0.2323283466535715" rpy="0 0 0"/>
            <mass value="1" />
            <inertia ixx="100" ixy="0" ixz="0" iyy="100" iyz="0" izz="100" />
        </inertial>
        <visual>
            <origin xyz="0 0 0.2323283466535715" rpy="0 0 0"/>
            <geometry>
                <box size="0.16257014497729083 0.3816634192488769 0.46465669330714277" />
            </geometry>
            <material name="not">
                <color rgba="0 1 1 1"/>
            </material>
        </visual>
        <collision>
            <origin xyz="0 0 0.2323283466535715" rpy="0 0 0"/>
            <geometry>
                <box size="0.16257014497729083 0.3816634192488769 0.46465669330714277" />
            </geometry>
        </collision>
    </link>
</robot>