<robot name = "robot">
    <link name="0">
        <inertial>
            <origin xyz="0 0 0.8765754623518652" rpy="0 0 0"/>
            <mass value="1" />
            <inertia ixx="100" ixy="0" ixz="0" iyy="100" iyz="0" izz="100" />
        </inertial>
        <visual>
            <origin xyz="0 0 0.8765754623518652" rpy="0 0 0"/>
            <geometry>
                <box size="0.7862887157618957 0.9017498001695733 0.9306808561627072" />
            </geometry>
            <material name="sensor">
                <color rgba="0 1 0 1"/>
            </material>
        </visual>
        <collision>
            <origin xyz="0 0 0.8765754623518652" rpy="0 0 0"/>
            <geometry>
                <box size="0.7862887157618957 0.9017498001695733 0.9306808561627072" />
            </geometry>
        </collision>
    </link>
    <joint name="0_1" type="revolute">
       <parent link="0"/>
       <child  link="1"/>
       <origin rpy="0 0 0" xyz="0.39314435788094787 0 0.8765754623518652" />
     <axis xyz="0 1 0"/>
       <limit effort="0.0" lower="-3.14159" upper="3.14159" velocity="0.0"/>
    </joint>
    <link name="1">
        <inertial>
            <origin xyz="0.4404135973643664 0 0.0" rpy="0 0 0"/>
            <mass value="1" />
            <inertia ixx="100" ixy="0" ixz="0" iyy="100" iyz="0" izz="100" />
        </inertial>
        <visual>
            <origin xyz="0.4404135973643664 0 0.0" rpy="0 0 0"/>
            <geometry>
                <box size="0.8808271947287327 0.8924657657674832 0.43008400655487466" />
            </geometry>
            <material name="sensor">
                <color rgba="0 1 0 1"/>
            </material>
        </visual>
        <collision>
            <origin xyz="0.4404135973643664 0 0.0" rpy="0 0 0"/>
            <geometry>
                <box size="0.8808271947287327 0.8924657657674832 0.43008400655487466" />
            </geometry>
        </collision>
    </link>
    <joint name="0_4" type="revolute">
       <parent link="0"/>
       <child  link="4"/>
       <origin rpy="0 0 0" xyz="0 -0.45087490008478665 0.8765754623518652" />
     <axis xyz="0 1 0"/>
       <limit effort="0.0" lower="-3.14159" upper="3.14159" velocity="0.0"/>
    </joint>
    <link name="4">
        <inertial>
            <origin xyz="0 -0.23133398656508325 0.0" rpy="0 0 0"/>
            <mass value="1" />
            <inertia ixx="100" ixy="0" ixz="0" iyy="100" iyz="0" izz="100" />
        </inertial>
        <visual>
            <origin xyz="0 -0.23133398656508325 0.0" rpy="0 0 0"/>
            <geometry>
                <box size="0.8563836021957464 0.4626679731301665 0.47958990318604056" />
            </geometry>
            <material name="not">
                <color rgba="0 1 1 1"/>
            </material>
        </visual>
        <collision>
            <origin xyz="0 -0.23133398656508325 0.0" rpy="0 0 0"/>
            <geometry>
                <box size="0.8563836021957464 0.4626679731301665 0.47958990318604056" />
            </geometry>
        </collision>
    </link>
</robot>