<robot name = "robot">
    <link name="0">
        <inertial>
            <origin xyz="0 0 0.8174104069416209" rpy="0 0 0"/>
            <mass value="1" />
            <inertia ixx="100" ixy="0" ixz="0" iyy="100" iyz="0" izz="100" />
        </inertial>
        <visual>
            <origin xyz="0 0 0.8174104069416209" rpy="0 0 0"/>
            <geometry>
                <box size="0.937502334100213 0.061026943100534026 0.504096562551434" />
            </geometry>
            <material name="not">
                <color rgba="0 1 1 1"/>
            </material>
        </visual>
        <collision>
            <origin xyz="0 0 0.8174104069416209" rpy="0 0 0"/>
            <geometry>
                <box size="0.937502334100213 0.061026943100534026 0.504096562551434" />
            </geometry>
        </collision>
    </link>
    <joint name="0_1" type="revolute">
       <parent link="0"/>
       <child  link="1"/>
       <origin rpy="0 0 0" xyz="-0.4687511670501065 0 0.8174104069416209" />
     <axis xyz="0 0 1"/>
       <limit effort="0.0" lower="-3.14159" upper="3.14159" velocity="0.0"/>
    </joint>
    <link name="1">
        <inertial>
            <origin xyz="-0.03038292169051532 0 0.0" rpy="0 0 0"/>
            <mass value="1" />
            <inertia ixx="100" ixy="0" ixz="0" iyy="100" iyz="0" izz="100" />
        </inertial>
        <visual>
            <origin xyz="-0.03038292169051532 0 0.0" rpy="0 0 0"/>
            <geometry>
                <box size="0.06076584338103064 0.4305558989466314 0.09058739376492753" />
            </geometry>
            <material name="sensor">
                <color rgba="0 1 0 1"/>
            </material>
        </visual>
        <collision>
            <origin xyz="-0.03038292169051532 0 0.0" rpy="0 0 0"/>
            <geometry>
                <box size="0.06076584338103064 0.4305558989466314 0.09058739376492753" />
            </geometry>
        </collision>
    </link>
    <joint name="1_2" type="revolute">
       <parent link="1"/>
       <child  link="2"/>
       <origin rpy="0 0 0" xyz="-0.03038292169051532 0 -0.04529369688246376" />
     <axis xyz="1 0 0"/>
       <limit effort="0.0" lower="-3.14159" upper="3.14159" velocity="0.0"/>
    </joint>
    <link name="2">
        <inertial>
            <origin xyz="0.0 0 -0.15461379418447452" rpy="0 0 0"/>
            <mass value="1" />
            <inertia ixx="100" ixy="0" ixz="0" iyy="100" iyz="0" izz="100" />
        </inertial>
        <visual>
            <origin xyz="0.0 0 -0.15461379418447452" rpy="0 0 0"/>
            <geometry>
                <box size="0.0011979197211340331 0.26592927213697315 0.30922758836894904" />
            </geometry>
            <material name="sensor">
                <color rgba="0 1 0 1"/>
            </material>
        </visual>
        <collision>
            <origin xyz="0.0 0 -0.15461379418447452" rpy="0 0 0"/>
            <geometry>
                <box size="0.0011979197211340331 0.26592927213697315 0.30922758836894904" />
            </geometry>
        </collision>
    </link>
    <joint name="2_4" type="revolute">
       <parent link="2"/>
       <child  link="4"/>
       <origin rpy="0 0 0" xyz="0.0 0.13296463606848657 -0.15461379418447452" />
     <axis xyz="0 0 1"/>
       <limit effort="0.0" lower="-3.14159" upper="3.14159" velocity="0.0"/>
    </joint>
    <link name="4">
        <inertial>
            <origin xyz="0.0 0.4444113500333186 0.0" rpy="0 0 0"/>
            <mass value="1" />
            <inertia ixx="100" ixy="0" ixz="0" iyy="100" iyz="0" izz="100" />
        </inertial>
        <visual>
            <origin xyz="0.0 0.4444113500333186 0.0" rpy="0 0 0"/>
            <geometry>
                <box size="0.0677373291471034 0.8888227000666372 0.01711201272040097" />
            </geometry>
            <material name="not">
                <color rgba="0 1 1 1"/>
            </material>
        </visual>
        <collision>
            <origin xyz="0.0 0.4444113500333186 0.0" rpy="0 0 0"/>
            <geometry>
                <box size="0.0677373291471034 0.8888227000666372 0.01711201272040097" />
            </geometry>
        </collision>
    </link>
    <joint name="4_5" type="revolute">
       <parent link="4"/>
       <child  link="5"/>
       <origin rpy="0 0 0" xyz="-0.03386866457355164 0.4444113500333186 0.0" />
     <axis xyz="1 0 0"/>
       <limit effort="0.0" lower="-3.14159" upper="3.14159" velocity="0.0"/>
    </joint>
    <link name="5">
        <inertial>
            <origin xyz="-0.2690120211450452 0.0 0.0" rpy="0 0 0"/>
            <mass value="1" />
            <inertia ixx="100" ixy="0" ixz="0" iyy="100" iyz="0" izz="100" />
        </inertial>
        <visual>
            <origin xyz="-0.2690120211450452 0.0 0.0" rpy="0 0 0"/>
            <geometry>
                <box size="0.5380240422900904 0.5192065665161915 0.26651663666840775" />
            </geometry>
            <material name="not">
                <color rgba="0 1 1 1"/>
            </material>
        </visual>
        <collision>
            <origin xyz="-0.2690120211450452 0.0 0.0" rpy="0 0 0"/>
            <geometry>
                <box size="0.5380240422900904 0.5192065665161915 0.26651663666840775" />
            </geometry>
        </collision>
    </link>
    <joint name="5_6" type="revolute">
       <parent link="5"/>
       <child  link="6"/>
       <origin rpy="0 0 0" xyz="-0.2690120211450452 0.0 0.13325831833420387" />
     <axis xyz="0 0 1"/>
       <limit effort="0.0" lower="-3.14159" upper="3.14159" velocity="0.0"/>
    </joint>
    <link name="6">
        <inertial>
            <origin xyz="0.0 0.0 0.02908219949121915" rpy="0 0 0"/>
            <mass value="1" />
            <inertia ixx="100" ixy="0" ixz="0" iyy="100" iyz="0" izz="100" />
        </inertial>
        <visual>
            <origin xyz="0.0 0.0 0.02908219949121915" rpy="0 0 0"/>
            <geometry>
                <box size="0.8235928507741034 0.32701177250708136 0.058164398982438414" />
            </geometry>
            <material name="not">
                <color rgba="0 1 1 1"/>
            </material>
        </visual>
        <collision>
            <origin xyz="0.0 0.0 0.02908219949121915" rpy="0 0 0"/>
            <geometry>
                <box size="0.8235928507741034 0.32701177250708136 0.058164398982438414" />
            </geometry>
        </collision>
    </link>
</robot>