<robot name = "robot">
    <link name="0">
        <inertial>
            <origin xyz="0 0 0.9700116469079472" rpy="0 0 0"/>
            <mass value="1" />
            <inertia ixx="100" ixy="0" ixz="0" iyy="100" iyz="0" izz="100" />
        </inertial>
        <visual>
            <origin xyz="0 0 0.9700116469079472" rpy="0 0 0"/>
            <geometry>
                <box size="0.6879759521867292 0.2919489747258276 0.22154272215569504" />
            </geometry>
            <material name="sensor">
                <color rgba="0 1 0 1"/>
            </material>
        </visual>
        <collision>
            <origin xyz="0 0 0.9700116469079472" rpy="0 0 0"/>
            <geometry>
                <box size="0.6879759521867292 0.2919489747258276 0.22154272215569504" />
            </geometry>
        </collision>
    </link>
    <joint name="0_1" type="revolute">
       <parent link="0"/>
       <child  link="1"/>
       <origin rpy="0 0 0" xyz="-0.3439879760933646 0 0.9700116469079472" />
     <axis xyz="1 0 0"/>
       <limit effort="0.0" lower="-3.14159" upper="3.14159" velocity="0.0"/>
    </joint>
    <link name="1">
        <inertial>
            <origin xyz="-0.30593228115327764 0 0.0" rpy="0 0 0"/>
            <mass value="1" />
            <inertia ixx="100" ixy="0" ixz="0" iyy="100" iyz="0" izz="100" />
        </inertial>
        <visual>
            <origin xyz="-0.30593228115327764 0 0.0" rpy="0 0 0"/>
            <geometry>
                <box size="0.6118645623065554 0.014393410372095294 0.8718654522397898" />
            </geometry>
            <material name="sensor">
                <color rgba="0 1 0 1"/>
            </material>
        </visual>
        <collision>
            <origin xyz="-0.30593228115327764 0 0.0" rpy="0 0 0"/>
            <geometry>
                <box size="0.6118645623065554 0.014393410372095294 0.8718654522397898" />
            </geometry>
        </collision>
    </link>
    <joint name="1_3" type="revolute">
       <parent link="1"/>
       <child  link="3"/>
       <origin rpy="0 0 0" xyz="-0.30593228115327764 0 0.43593272611989486" />
     <axis xyz="0 1 0"/>
       <limit effort="0.0" lower="-3.14159" upper="3.14159" velocity="0.0"/>
    </joint>
    <link name="3">
        <inertial>
            <origin xyz="0.0 0 0.12437644004495896" rpy="0 0 0"/>
            <mass value="1" />
            <inertia ixx="100" ixy="0" ixz="0" iyy="100" iyz="0" izz="100" />
        </inertial>
        <visual>
            <origin xyz="0.0 0 0.12437644004495896" rpy="0 0 0"/>
            <geometry>
                <box size="0.9295297162973252 0.842605021699377 0.24875288008991803" />
            </geometry>
            <material name="sensor">
                <color rgba="0 1 0 1"/>
            </material>
        </visual>
        <collision>
            <origin xyz="0.0 0 0.12437644004495896" rpy="0 0 0"/>
            <geometry>
                <box size="0.9295297162973252 0.842605021699377 0.24875288008991803" />
            </geometry>
        </collision>
    </link>
    <joint name="1_2" type="revolute">
       <parent link="1"/>
       <child  link="2"/>
       <origin rpy="0 0 0" xyz="-0.30593228115327764 0 -0.43593272611989486" />
     <axis xyz="1 0 0"/>
       <limit effort="0.0" lower="-3.14159" upper="3.14159" velocity="0.0"/>
    </joint>
    <link name="2">
        <inertial>
            <origin xyz="0.0 0 -0.4546655251966895" rpy="0 0 0"/>
            <mass value="1" />
            <inertia ixx="100" ixy="0" ixz="0" iyy="100" iyz="0" izz="100" />
        </inertial>
        <visual>
            <origin xyz="0.0 0 -0.4546655251966895" rpy="0 0 0"/>
            <geometry>
                <box size="0.5221518087812809 0.723182451072547 0.909331050393379" />
            </geometry>
            <material name="sensor">
                <color rgba="0 1 0 1"/>
            </material>
        </visual>
        <collision>
            <origin xyz="0.0 0 -0.4546655251966895" rpy="0 0 0"/>
            <geometry>
                <box size="0.5221518087812809 0.723182451072547 0.909331050393379" />
            </geometry>
        </collision>
    </link>
    <joint name="1_4" type="revolute">
       <parent link="1"/>
       <child  link="4"/>
       <origin rpy="0 0 0" xyz="-0.30593228115327764 -0.007196705186047647 0.0" />
     <axis xyz="0 1 0"/>
       <limit effort="0.0" lower="-3.14159" upper="3.14159" velocity="0.0"/>
    </joint>
    <link name="4">
        <inertial>
            <origin xyz="0.0 -0.015528390170560069 0.0" rpy="0 0 0"/>
            <mass value="1" />
            <inertia ixx="100" ixy="0" ixz="0" iyy="100" iyz="0" izz="100" />
        </inertial>
        <visual>
            <origin xyz="0.0 -0.015528390170560069 0.0" rpy="0 0 0"/>
            <geometry>
                <box size="0.3254414149293031 0.031056780341120138 0.16980529929808297" />
            </geometry>
            <material name="sensor">
                <color rgba="0 1 0 1"/>
            </material>
        </visual>
        <collision>
            <origin xyz="0.0 -0.015528390170560069 0.0" rpy="0 0 0"/>
            <geometry>
                <box size="0.3254414149293031 0.031056780341120138 0.16980529929808297" />
            </geometry>
        </collision>
    </link>
</robot>