<robot name = "robot">
    <link name="0">
        <inertial>
            <origin xyz="0 0 1.203353507479663" rpy="0 0 0"/>
            <mass value="1" />
            <inertia ixx="100" ixy="0" ixz="0" iyy="100" iyz="0" izz="100" />
        </inertial>
        <visual>
            <origin xyz="0 0 1.203353507479663" rpy="0 0 0"/>
            <geometry>
                <box size="0.4789704272179115 0.4754548494172842 0.4616790242162536" />
            </geometry>
            <material name="not">
                <color rgba="0 1 1 1"/>
            </material>
        </visual>
        <collision>
            <origin xyz="0 0 1.203353507479663" rpy="0 0 0"/>
            <geometry>
                <box size="0.4789704272179115 0.4754548494172842 0.4616790242162536" />
            </geometry>
        </collision>
    </link>
    <joint name="0_1" type="revolute">
       <parent link="0"/>
       <child  link="1"/>
       <origin rpy="0 0 0" xyz="0.23948521360895575 0 1.203353507479663" />
     <axis xyz="0 1 0"/>
       <limit effort="0.0" lower="-3.14159" upper="3.14159" velocity="0.0"/>
    </joint>
    <link name="1">
        <inertial>
            <origin xyz="0.07046615687013114 0 0.0" rpy="0 0 0"/>
            <mass value="1" />
            <inertia ixx="100" ixy="0" ixz="0" iyy="100" iyz="0" izz="100" />
        </inertial>
        <visual>
            <origin xyz="0.07046615687013114 0 0.0" rpy="0 0 0"/>
            <geometry>
                <box size="0.14093231374026227 0.35670821153115884 0.11543126812360216" />
            </geometry>
            <material name="not">
                <color rgba="0 1 1 1"/>
            </material>
        </visual>
        <collision>
            <origin xyz="0.07046615687013114 0 0.0" rpy="0 0 0"/>
            <geometry>
                <box size="0.14093231374026227 0.35670821153115884 0.11543126812360216" />
            </geometry>
        </collision>
    </link>
    <joint name="1_3" type="revolute">
       <parent link="1"/>
       <child  link="3"/>
       <origin rpy="0 0 0" xyz="0.14093231374026227 0 0.0" />
     <axis xyz="0 1 0"/>
       <limit effort="0.0" lower="-3.14159" upper="3.14159" velocity="0.0"/>
    </joint>
    <link name="3">
        <inertial>
            <origin xyz="0.2394106916660868 0 0.0" rpy="0 0 0"/>
            <mass value="1" />
            <inertia ixx="100" ixy="0" ixz="0" iyy="100" iyz="0" izz="100" />
        </inertial>
        <visual>
            <origin xyz="0.2394106916660868 0 0.0" rpy="0 0 0"/>
            <geometry>
                <box size="0.4788213833321736 0.8595400955799134 0.8767560111669435" />
            </geometry>
            <material name="sensor">
                <color rgba="0 1 0 1"/>
            </material>
        </visual>
        <collision>
            <origin xyz="0.2394106916660868 0 0.0" rpy="0 0 0"/>
            <geometry>
                <box size="0.4788213833321736 0.8595400955799134 0.8767560111669435" />
            </geometry>
        </collision>
    </link>
    <joint name="1_4" type="revolute">
       <parent link="1"/>
       <child  link="4"/>
       <origin rpy="0 0 0" xyz="0.07046615687013114 0 -0.057715634061801024" />
     <axis xyz="1 0 0"/>
       <limit effort="0.0" lower="-3.14159" upper="3.14159" velocity="0.0"/>
    </joint>
    <link name="4">
        <inertial>
            <origin xyz="0.0 0 -0.4842447949876435" rpy="0 0 0"/>
            <mass value="1" />
            <inertia ixx="100" ixy="0" ixz="0" iyy="100" iyz="0" izz="100" />
        </inertial>
        <visual>
            <origin xyz="0.0 0 -0.4842447949876435" rpy="0 0 0"/>
            <geometry>
                <box size="0.91849245140848 0.27918011073456594 0.968489589975287" />
            </geometry>
            <material name="sensor">
                <color rgba="0 1 0 1"/>
            </material>
        </visual>
        <collision>
            <origin xyz="0.0 0 -0.4842447949876435" rpy="0 0 0"/>
            <geometry>
                <box size="0.91849245140848 0.27918011073456594 0.968489589975287" />
            </geometry>
        </collision>
    </link>
    <joint name="1_5" type="revolute">
       <parent link="1"/>
       <child  link="5"/>
       <origin rpy="0 0 0" xyz="0.07046615687013114 -0.17835410576557942 0.0" />
     <axis xyz="0 1 0"/>
       <limit effort="0.0" lower="-3.14159" upper="3.14159" velocity="0.0"/>
    </joint>
    <link name="5">
        <inertial>
            <origin xyz="0.0 -0.29337723468007043 0.0" rpy="0 0 0"/>
            <mass value="1" />
            <inertia ixx="100" ixy="0" ixz="0" iyy="100" iyz="0" izz="100" />
        </inertial>
        <visual>
            <origin xyz="0.0 -0.29337723468007043 0.0" rpy="0 0 0"/>
            <geometry>
                <box size="0.018863019451183294 0.5867544693601409 0.9526315745990082" />
            </geometry>
            <material name="not">
                <color rgba="0 1 1 1"/>
            </material>
        </visual>
        <collision>
            <origin xyz="0.0 -0.29337723468007043 0.0" rpy="0 0 0"/>
            <geometry>
                <box size="0.018863019451183294 0.5867544693601409 0.9526315745990082" />
            </geometry>
        </collision>
    </link>
    <joint name="0_2" type="revolute">
       <parent link="0"/>
       <child  link="2"/>
       <origin rpy="0 0 0" xyz="-0.23948521360895575 0 1.203353507479663" />
     <axis xyz="1 0 0"/>
       <limit effort="0.0" lower="-3.14159" upper="3.14159" velocity="0.0"/>
    </joint>
    <link name="2">
        <inertial>
            <origin xyz="-0.20427166854212225 0 0.0" rpy="0 0 0"/>
            <mass value="1" />
            <inertia ixx="100" ixy="0" ixz="0" iyy="100" iyz="0" izz="100" />
        </inertial>
        <visual>
            <origin xyz="-0.20427166854212225 0 0.0" rpy="0 0 0"/>
            <geometry>
                <box size="0.4085433370842445 0.4080109801314763 0.551457015979915" />
            </geometry>
            <material name="sensor">
                <color rgba="0 1 0 1"/>
            </material>
        </visual>
        <collision>
            <origin xyz="-0.20427166854212225 0 0.0" rpy="0 0 0"/>
            <geometry>
                <box size="0.4085433370842445 0.4080109801314763 0.551457015979915" />
            </geometry>
        </collision>
    </link>
</robot>